Workbook

Sheet Budgeted_Data
A1: Plant Name | B1: Date | C1: Month | D1: Month | E1: Daily_Gen | F1: Daily_GTI | G1: Daily_GHI | H1: Ambt_Temp | I1: PR_% | J1: CUF_% | K1: TArray | L1: TArrWtd | M1: Connected_DC
A2: Devki_Galol | B2: 45747 | M2: 2411
A3: Devki_Galol | B3: 45748 | E3: 13840.923 | F3: 6.912086 | G3: 6.70334 | H3: 26.93375 | I3: 0.83053646 | J3: 0.23919748 | M3: 2411
A4: Devki_Galol | B4: 45749 | E4: 14376.17 | F4: 7.239875 | G4: 7.020655 | H4: 27.329583 | I4: 0.8235973 | J4: 0.24844756 | M4: 2411
A5: Devki_Galol | B5: 45750 | E5: 15037.604 | F5: 7.636371 | G5: 7.409505 | H5: 28.335833 | I5: 0.8167599 | J5: 0.2598784 | M5: 2411
A6: Devki_Galol | B6: 45751 | E6: 15285.896 | F6: 7.804267 | G6: 7.575568 | H6: 28.312083 | I6: 0.81238438 | J6: 0.26416936 | M6: 2411
A7: Devki_Galol | B7: 45752 | E7: 11354.473 | F7: 5.709052 | G7: 5.48408 | H7: 31.057083 | I7: 0.82490847 | J7: 0.19622689 | M7: 2411
A8: Devki_Galol | B8: 45753 | E8: 7535.2082 | F8: 3.73304 | G8: 3.581261 | H8: 30.49625 | I8: 0.83721192 | J8: 0.13022273 | M8: 2411
A9: Devki_Galol | B9: 45754 | E9: 12448.484 | F9: 6.303896 | G9: 6.093292 | H9: 31.315417 | I9: 0.81904961 | J9: 0.21513348 | M9: 2411
A10: Devki_Galol | B10: 45755 | E10: 13600.049 | F10: 6.903413 | G10: 6.681604 | H10: 30.829583 | I10: 0.81710788 | J10: 0.23503472 | M10: 2411
A11: Devki_Galol | B11: 45756 | E11: 14605.407 | F11: 7.448123 | G11: 7.209586 | H11: 30.139167 | I11: 0.81333527 | J11: 0.25240921 | M11: 2411
A12: Devki_Galol | B12: 45757 | E12: 13864.935 | F12: 7.092537 | G12: 6.865894 | H12: 31.866667 | I12: 0.81080984 | J12: 0.23961245 | M12: 2411
A13: Devki_Galol | B13: 45758 | E13: 14736.226 | F13: 7.611165 | G13: 7.370474 | H13: 32.427917 | I13: 0.80304137 | J13: 0.25467002 | M13: 2411
A14: Devki_Galol | B14: 45759 | E14: 14692.529 | F14: 7.4782 | G14: 7.242306 | H14: 29.682917 | I14: 0.81489615 | J14: 0.25391485 | M14: 2411
... A366: Devki_Galol | B366: 46111 | E366: 13702.313 | F366: 6.93729 | G366: 6.724865 | H366: 29.510833 | I366: 0.81923183 | J366: 0.23680203 | M366: 2411
A367: Devki_Galol | B367: 46112 | E367: 14336.751 | F367: 7.350502 | G367: 7.130775 | H367: 30.856667 | I367: 0.80897765 | J367: 0.24776633

Sheet E-Mail_Copy
A1: Plant_Performance_of_Mandapara_GJ
B3: =DATE(YEAR(B4),MONTH(B4),1) -> 46174 | C3: =VLOOKUP(L3,Basic_Data!$A$28:$B$48,2,0) -> 45748 | L3: 25-26
A4: Date | B4: 46181 | C4: AC Capacity: | E4: =Basic_Data!F10 -> 1925 | F4: DC Capacity: | H4: =Basic_Data!G10 -> 2411.08 | I4: D.O.C.: | K4: =Basic_Data!B3 -> 45745
A5: Plant Name | C5: Daily | F5: MTD | I5: YTD
C6: Budgeted | D6: Actual | E6: Variation(%) | F6: Budgeted | G6: Actual | H6: Variation(%) | I6: Budgeted | J6: Actual | K6: Variation(%)
A7: Generation_MW | C7: =SUMIFS(Budgeted_Data!$E:$E,Budgeted_Data!$B:$B,'E-Mail_Copy'!$B$4) -> 0 | D7: =SUMIFS(Data_Entry!$T:$T,Data_Entry!$C:$C,'E-Mail_Copy'!$B$4) -> 12960 | E7: =(D7-C7)/C7 -> #DIV/0! | F7: =SUMIFS(Budgeted_Data!$E:$E,Budgeted_Data!$B:$B,">="&'E-Mail_Copy'!$B$3,Budgeted_Data!$B:$B,"<="&'E-Mail_Copy'!$B$4) -> 0 | G7: =SUMIFS(Data_Entry!$T:$T,Data_Entry!$C:$C,">="&'E-Mail_Copy'!$B$3,Data_Entry!$C:$C,"<="&'E-Mail_Copy'!$B$4) -> 95070 | H7: =(G7-F7)/F7 -> #DIV/0! | I7: =SUMIFS(Budgeted_Data!$E:$E,Budgeted_Data!$B:$B,">="&'E-Mail_Copy'!$C$3,Budgeted_Data!$B:$B,"<="&'E-Mail_Copy'!$B$4) -> 4073422.4 | J7: =SUMIFS(Data_Entry!$T:$T,Data_Entry!$C:$C,">="&'E-Mail_Copy'!$C$3,Data_Entry!$C:$C,"<="&'E-Mail_Copy'!$B$4) -> 4734060 | K7: =(J7-I7)/I7 -> 0.16218245
A8: GTI (Kwh/m2) | C8: =SUMIFS(Budgeted_Data!$F:$F,Budgeted_Data!$B:$B,'E-Mail_Copy'!$B$4) -> 0 | D8: =SUMIFS(Data_Entry!$V:$V,Data_Entry!$C:$C,'E-Mail_Copy'!B4) -> 4.36 | E8: =(D8-C8)/C8 -> #DIV/0! | F8: =SUMIFS(Budgeted_Data!$F:$F,Budgeted_Data!$B:$B,">="&'E-Mail_Copy'!$B$3,Budgeted_Data!$B:$B,"<="&'E-Mail_Copy'!$B$4) -> 0 | G8: =SUMIFS(Data_Entry!$V:$V,Data_Entry!$C:$C,">="&'E-Mail_Copy'!$B$3,Data_Entry!$C:$C,"<="&'E-Mail_Copy'!$B$4) -> 37.95 | H8: =(G8-F8)/F8 -> #DIV/0! | I8: =SUMIFS(Budgeted_Data!$F:$F,Budgeted_Data!$B:$B,">="&'E-Mail_Copy'!$C$3,Budgeted_Data!$B:$B,"<="&'E-Mail_Copy'!$B$4) -> 2079.3683 | J8: =SUMIFS(Data_Entry!$V:$V,Data_Entry!$C:$C,">="&'E-Mail_Copy'!$C$3,Data_Entry!$C:$C,"<="&'E-Mail_Copy'!$B$4) -> 1678.168 | K8: =(J8-I8)/I8 -> -0.19294335
A9: GHI (Kwh/m2) | C9: =SUMIFS(Budgeted_Data!$G:$G,Budgeted_Data!$B:$B,'E-Mail_Copy'!$B$4) -> 0 | D9: =SUMIFS(Data_Entry!$U:$U,Data_Entry!$C:$C,'E-Mail_Copy'!$B$4) -> 0 | E9: =(D9-C9)/C9 -> #DIV/0! | F9: =SUMIFS(Budgeted_Data!$G:$G,Budgeted_Data!$B:$B,">="&'E-Mail_Copy'!$B$3,Budgeted_Data!$B:$B,"<="&'E-Mail_Copy'!$B$4) -> 0 | G9: =SUMIFS(Data_Entry!$U:$U,Data_Entry!$C:$C,">="&'E-Mail_Copy'!$B$3,Data_Entry!$C:$C,"<="&'E-Mail_Copy'!$B$4) -> 0 | H9: =(G9-F9)/F9 -> #DIV/0! | I9: =SUMIFS(Budgeted_Data!$G:$G,Budgeted_Data!$B:$B,">="&'E-Mail_Copy'!$C$3,Budgeted_Data!$B:$B,"<="&'E-Mail_Copy'!$B$4) -> 2005.4308 | J9: =SUMIFS(Data_Entry!$U:$U,Data_Entry!$C:$C,">="&'E-Mail_Copy'!$C$3,Data_Entry!$C:$C,"<="&'E-Mail_Copy'!$B$4) -> 3.9 | K9: =(J9-I9)/I9 -> -0.99805528
A10: PR_(%) | C10: =C7/C8/H4 -> #DIV/0! | D10: =D7/D8/H4 -> 1.2328405 | E10: =(D10-C10)/C10 -> #DIV/0! | F10: =F7/F8/H4/(B4-B3+1) -> #DIV/0! | G10: =G7/G8/H4/(B4-B3+1) -> 0.12987636 | H10: =(G10-F10)/F10 -> #DIV/0! | I10: =I7/I8/H4/(($B$4-$C$3)+1) -> 0.0018720898 | J10: =J7/J8/H4/(($B$4-$C$3)+1) -> 0.0026958577 | K10: =(J10-I10)/I10 -> 0.44002586
A11: CUF_(%) | C11: =C7/E4/24 -> 0 | D11: =D7/24/E4 -> 0.28051948 | E11: =(D11-C11)/C11 -> #DIV/0! | F11: =F7/24/E4/(B4-B3+1) -> 0 | G11: =G7/24/E4/(B4-B3+1) -> 0.25722403 | H11: =(G11-F11)/F11 -> #DIV/0! | I11: =I7/24/$E$4/(($B$4-$C$3)+1) -> 0.2031551 | J11: =J7/24/$E$4/(($B$4-$C$3)+1) -> 0.2361033 | K11: =(J11-I11)/I11 -> 0.16218245
A12: Wtd_Module_Temp | C12: =AVERAGEIFS(Budgeted_Data!$L:$L,Budgeted_Data!$B:$B,'E-Mail_Copy'!$B$4) -> #DIV/0! | D12: =AVERAGEIFS(Data_Entry!$Y:$Y,Data_Entry!$C:$C,'E-Mail_Copy'!$B$4) -> #DIV/0! | E12: =(D12-C12)/C12 -> #DIV/0! | F12: =AVERAGEIFS(Budgeted_Data!$L:$L,Budgeted_Data!$B:$B,">="&'E-Mail_Copy'!$B$3,Budgeted_Data!$B:$B,"<="&'E-Mail_Copy'!$B$4) -> #DIV/0! | G12: =AVERAGEIFS(Data_Entry!$Y:$Y,Data_Entry!$C:$C,">="&'E-Mail_Copy'!$B$3,Data_Entry!$C:$C,"<="&'E-Mail_Copy'!$B$4) -> #DIV/0! | H12: =(G12-F12)/F12 -> #DIV/0! | I12: =AVERAGEIFS(Budgeted_Data!$L:$L,Budgeted_Data!$B:$B,">="&'E-Mail_Copy'!$C$3,Budgeted_Data!$B:$B,"<="&'E-Mail_Copy'!$B$4) -> #DIV/0! | J12: =AVERAGEIFS(Data_Entry!$Y:$Y,Data_Entry!$C:$C,">="&'E-Mail_Copy'!$C$3,Data_Entry!$C:$C,"<="&'E-Mail_Copy'!$B$4) -> #DIV/0! | K12: =(J12-I12)/I12 -> #DIV/0!
A13: Ambt._Temp_(0C) | C13: =AVERAGEIFS(Budgeted_Data!$H:$H,Budgeted_Data!$B:$B,'E-Mail_Copy'!$B$4) -> #DIV/0! | D13: =AVERAGEIFS(Data_Entry!$W:$W,Data_Entry!$C:$C,'E-Mail_Copy'!$B$4) -> 33.41 | E13: =(D13-C13)/C13 -> #DIV/0! | F13: =AVERAGEIFS(Budgeted_Data!$H:$H,Budgeted_Data!$B:$B,">="&'E-Mail_Copy'!$B$3,Budgeted_Data!$B:$B,"<="&'E-Mail_Copy'!$B$4) -> #DIV/0! | G13: =AVERAGEIFS(Data_Entry!$W:$W,Data_Entry!$C:$C,">="&'E-Mail_Copy'!$B$3,Data_Entry!$C:$C,"<="&'E-Mail_Copy'!$B$4) -> 34.145 | H13: =(G13-F13)/F13 -> #DIV/0! | I13: =AVERAGEIFS(Budgeted_Data!$H:$H,Budgeted_Data!$B:$B,">="&'E-Mail_Copy'!$C$3,Budgeted_Data!$B:$B,"<="&'E-Mail_Copy'!$B$4) -> 27.271073 | J13: =AVERAGEIFS(Data_Entry!$W:$W,Data_Entry!$C:$C,">="&'E-Mail_Copy'!$C$3,Data_Entry!$C:$C,"<="&'E-Mail_Copy'!$B$4) -> 30.220854 | K13: =(J13-I13)/I13 -> 0.1081652

Sheet DGR
A1: Daily_Generation_&_Performance_Report
A3: Inverter_No. | B3: ='E-Mail_Copy'!B4 -> 46181 | C3: =B3+1 -> 46182 | D3: =C3+1 -> 46183 | E3: =D3+1 -> 46184 | F3: =E3+1 -> 46185 | G3: =F3+1 -> 46186 | H3: =G3+1 -> 46187 | I3: =H3+1 -> 46188 | J3: =I3+1 -> 46189 | ... AF3: =AE3+1 -> 46211 | AG3: Total/Avg..
A4: Inv_1 | B4: =IFERROR(VLOOKUP(B$3,Data_Entry!$C:$AB,Data_Entry!$A2,0),"") -> 1843.22 | C4: =IFERROR(VLOOKUP(C$3,Data_Entry!$C:$AB,Data_Entry!$A2,0),"") -> 0 | D4: =IFERROR(VLOOKUP(D$3,Data_Entry!$C:$AB,Data_Entry!$A2,0),"") -> 0 | E4: =IFERROR(VLOOKUP(E$3,Data_Entry!$C:$AB,Data_Entry!$A2,0),"") -> 0 | F4: =IFERROR(VLOOKUP(F$3,Data_Entry!$C:$AB,Data_Entry!$A2,0),"") -> 0 | G4: =IFERROR(VLOOKUP(G$3,Data_Entry!$C:$AB,Data_Entry!$A2,0),"") -> 0 | H4: =IFERROR(VLOOKUP(H$3,Data_Entry!$C:$AB,Data_Entry!$A2,0),"") -> 0 | I4: =IFERROR(VLOOKUP(I$3,Data_Entry!$C:$AB,Data_Entry!$A2,0),"") -> 0 | ... AF4: =IFERROR(VLOOKUP(AF$3,Data_Entry!$C:$AB,Data_Entry!$A2,0),"") | AG4: =IFERROR(SUM(B4:AF4),"") -> 1843.22
A5: Inv_2 | B5: =IFERROR(VLOOKUP(B$3,Data_Entry!$C:$AB,Data_Entry!$A3,0),"") -> 1838.4 | C5: =IFERROR(VLOOKUP(C$3,Data_Entry!$C:$AB,Data_Entry!$A3,0),"") -> 0 | D5: =IFERROR(VLOOKUP(D$3,Data_Entry!$C:$AB,Data_Entry!$A3,0),"") -> 0 | E5: =IFERROR(VLOOKUP(E$3,Data_Entry!$C:$AB,Data_Entry!$A3,0),"") -> 0 | F5: =IFERROR(VLOOKUP(F$3,Data_Entry!$C:$AB,Data_Entry!$A3,0),"") -> 0 | G5: =IFERROR(VLOOKUP(G$3,Data_Entry!$C:$AB,Data_Entry!$A3,0),"") -> 0 | H5: =IFERROR(VLOOKUP(H$3,Data_Entry!$C:$AB,Data_Entry!$A3,0),"") -> 0 | I5: =IFERROR(VLOOKUP(I$3,Data_Entry!$C:$AB,Data_Entry!$A3,0),"") -> 0 | ... AF5: =IFERROR(VLOOKUP(AF$3,Data_Entry!$C:$AB,Data_Entry!$A3,0),"") | AG5: =IFERROR(SUM(B5:AF5),"") -> 1838.4
A6: Inv_3 | B6: =IFERROR(VLOOKUP(B$3,Data_Entry!$C:$AB,Data_Entry!$A4,0),"") -> 1835.24 | C6: =IFERROR(VLOOKUP(C$3,Data_Entry!$C:$AB,Data_Entry!$A4,0),"") -> 0 | D6: =IFERROR(VLOOKUP(D$3,Data_Entry!$C:$AB,Data_Entry!$A4,0),"") -> 0 | E6: =IFERROR(VLOOKUP(E$3,Data_Entry!$C:$AB,Data_Entry!$A4,0),"") -> 0 | F6: =IFERROR(VLOOKUP(F$3,Data_Entry!$C:$AB,Data_Entry!$A4,0),"") -> 0 | G6: =IFERROR(VLOOKUP(G$3,Data_Entry!$C:$AB,Data_Entry!$A4,0),"") -> 0 | H6: =IFERROR(VLOOKUP(H$3,Data_Entry!$C:$AB,Data_Entry!$A4,0),"") -> 0 | I6: =IFERROR(VLOOKUP(I$3,Data_Entry!$C:$AB,Data_Entry!$A4,0),"") -> 0 | ... AF6: =IFERROR(VLOOKUP(AF$3,Data_Entry!$C:$AB,Data_Entry!$A4,0),"") | AG6: =IFERROR(SUM(B6:AF6),"") -> 1835.24
A7: Inv_4 | B7: =IFERROR(VLOOKUP(B$3,Data_Entry!$C:$AB,Data_Entry!$A5,0),"") -> 1906.74 | C7: =IFERROR(VLOOKUP(C$3,Data_Entry!$C:$AB,Data_Entry!$A5,0),"") -> 0 | D7: =IFERROR(VLOOKUP(D$3,Data_Entry!$C:$AB,Data_Entry!$A5,0),"") -> 0 | E7: =IFERROR(VLOOKUP(E$3,Data_Entry!$C:$AB,Data_Entry!$A5,0),"") -> 0 | F7: =IFERROR(VLOOKUP(F$3,Data_Entry!$C:$AB,Data_Entry!$A5,0),"") -> 0 | G7: =IFERROR(VLOOKUP(G$3,Data_Entry!$C:$AB,Data_Entry!$A5,0),"") -> 0 | H7: =IFERROR(VLOOKUP(H$3,Data_Entry!$C:$AB,Data_Entry!$A5,0),"") -> 0 | I7: =IFERROR(VLOOKUP(I$3,Data_Entry!$C:$AB,Data_Entry!$A5,0),"") -> 0 | ... AF7: =IFERROR(VLOOKUP(AF$3,Data_Entry!$C:$AB,Data_Entry!$A5,0),"") | AG7: =IFERROR(SUM(B7:AF7),"") -> 1906.74
A8: Inv_5 | B8: =IFERROR(VLOOKUP(B$3,Data_Entry!$C:$AB,Data_Entry!$A6,0),"") -> 1900.18 | C8: =IFERROR(VLOOKUP(C$3,Data_Entry!$C:$AB,Data_Entry!$A6,0),"") -> 0 | D8: =IFERROR(VLOOKUP(D$3,Data_Entry!$C:$AB,Data_Entry!$A6,0),"") -> 0 | E8: =IFERROR(VLOOKUP(E$3,Data_Entry!$C:$AB,Data_Entry!$A6,0),"") -> 0 | F8: =IFERROR(VLOOKUP(F$3,Data_Entry!$C:$AB,Data_Entry!$A6,0),"") -> 0 | G8: =IFERROR(VLOOKUP(G$3,Data_Entry!$C:$AB,Data_Entry!$A6,0),"") -> 0 | H8: =IFERROR(VLOOKUP(H$3,Data_Entry!$C:$AB,Data_Entry!$A6,0),"") -> 0 | I8: =IFERROR(VLOOKUP(I$3,Data_Entry!$C:$AB,Data_Entry!$A6,0),"") -> 0 | ... AF8: =IFERROR(VLOOKUP(AF$3,Data_Entry!$C:$AB,Data_Entry!$A6,0),"") | AG8: =IFERROR(SUM(B8:AF8),"") -> 1900.18
A9: Inv_6 | B9: =IFERROR(VLOOKUP(B$3,Data_Entry!$C:$AB,Data_Entry!$A7,0),"") -> 1902.3 | C9: =IFERROR(VLOOKUP(C$3,Data_Entry!$C:$AB,Data_Entry!$A7,0),"") -> 0 | D9: =IFERROR(VLOOKUP(D$3,Data_Entry!$C:$AB,Data_Entry!$A7,0),"") -> 0 | E9: =IFERROR(VLOOKUP(E$3,Data_Entry!$C:$AB,Data_Entry!$A7,0),"") -> 0 | F9: =IFERROR(VLOOKUP(F$3,Data_Entry!$C:$AB,Data_Entry!$A7,0),"") -> 0 | G9: =IFERROR(VLOOKUP(G$3,Data_Entry!$C:$AB,Data_Entry!$A7,0),"") -> 0 | H9: =IFERROR(VLOOKUP(H$3,Data_Entry!$C:$AB,Data_Entry!$A7,0),"") -> 0 | I9: =IFERROR(VLOOKUP(I$3,Data_Entry!$C:$AB,Data_Entry!$A7,0),"") -> 0 | ... AF9: =IFERROR(VLOOKUP(AF$3,Data_Entry!$C:$AB,Data_Entry!$A7,0),"") | AG9: =IFERROR(SUM(B9:AF9),"") -> 1902.3
A10: Inv_7 | B10: =IFERROR(VLOOKUP(B$3,Data_Entry!$C:$AB,Data_Entry!$A8,0),"") -> 1902.22 | C10: =IFERROR(VLOOKUP(C$3,Data_Entry!$C:$AB,Data_Entry!$A8,0),"") -> 0 | D10: =IFERROR(VLOOKUP(D$3,Data_Entry!$C:$AB,Data_Entry!$A8,0),"") -> 0 | E10: =IFERROR(VLOOKUP(E$3,Data_Entry!$C:$AB,Data_Entry!$A8,0),"") -> 0 | F10: =IFERROR(VLOOKUP(F$3,Data_Entry!$C:$AB,Data_Entry!$A8,0),"") -> 0 | G10: =IFERROR(VLOOKUP(G$3,Data_Entry!$C:$AB,Data_Entry!$A8,0),"") -> 0 | H10: =IFERROR(VLOOKUP(H$3,Data_Entry!$C:$AB,Data_Entry!$A8,0),"") -> 0 | I10: =IFERROR(VLOOKUP(I$3,Data_Entry!$C:$AB,Data_Entry!$A8,0),"") -> 0 | ... AF10: =IFERROR(VLOOKUP(AF$3,Data_Entry!$C:$AB,Data_Entry!$A8,0),"") | AG10: =IFERROR(SUM(B10:AF10),"") -> 1902.22
A11: Total_Inverter_(kWh) | B11: =SUM(B4:B10) -> 13128.3 | C11: =SUM(C4:C10) -> 0 | D11: =SUM(D4:D10) -> 0 | E11: =SUM(E4:E10) -> 0 | F11: =SUM(F4:F10) -> 0 | G11: =SUM(G4:G10) -> 0 | H11: =SUM(H4:H10) -> 0 | I11: =SUM(I4:I10) -> 0 | ... AG11: =SUM(AG4:AG10) -> 13128.3
A12: Total_ABT_Meter_Export_(kWh) | B12: =IFERROR(VLOOKUP(B$3,Data_Entry!$C:$AB,14,0)," ") -> 12990 | C12: =IFERROR(VLOOKUP(C$3,Data_Entry!$C:$AB,14,0)," ") -> 0 | D12: =IFERROR(VLOOKUP(D$3,Data_Entry!$C:$AB,14,0)," ") -> 0 | E12: =IFERROR(VLOOKUP(E$3,Data_Entry!$C:$AB,14,0)," ") -> 0 | F12: =IFERROR(VLOOKUP(F$3,Data_Entry!$C:$AB,14,0)," ") -> 0 | G12: =IFERROR(VLOOKUP(G$3,Data_Entry!$C:$AB,14,0)," ") -> 0 | H12: =IFERROR(VLOOKUP(H$3,Data_Entry!$C:$AB,14,0)," ") -> 0 | I12: =IFERROR(VLOOKUP(I$3,Data_Entry!$C:$AB,14,0)," ") -> 0 | ... AG12: =IFERROR(VLOOKUP(AG$3,Data_Entry!$C:$AB,14,0)," ")
A13: Total_ABT_Meter_Import_(kWh) | B13: =IFERROR(VLOOKUP(B$3,Data_Entry!$C:$AB,17,0)," ") -> 30 | C13: =IFERROR(VLOOKUP(C$3,Data_Entry!$C:$AB,17,0)," ") -> 0 | D13: =IFERROR(VLOOKUP(D$3,Data_Entry!$C:$AB,17,0)," ") -> 0 | E13: =IFERROR(VLOOKUP(E$3,Data_Entry!$C:$AB,17,0)," ") -> 0 | F13: =IFERROR(VLOOKUP(F$3,Data_Entry!$C:$AB,17,0)," ") -> 0 | G13: =IFERROR(VLOOKUP(G$3,Data_Entry!$C:$AB,17,0)," ") -> 0 | H13: =IFERROR(VLOOKUP(H$3,Data_Entry!$C:$AB,17,0)," ") -> 0 | I13: =IFERROR(VLOOKUP(I$3,Data_Entry!$C:$AB,17,0)," ") -> 0 | ... AG13: =IFERROR(VLOOKUP(AG$3,Data_Entry!$C:$AB,17,0)," ")
A14: Total_ABT_Meter_Net_(kWh) | B14: =IFERROR(VLOOKUP(B$3,Data_Entry!$C:$AB,18,0)," ") -> 12960 | C14: =IFERROR(VLOOKUP(C$3,Data_Entry!$C:$AB,18,0)," ") -> 0 | D14: =IFERROR(VLOOKUP(D$3,Data_Entry!$C:$AB,18,0)," ") -> 0 | E14: =IFERROR(VLOOKUP(E$3,Data_Entry!$C:$AB,18,0)," ") -> 0 | F14: =IFERROR(VLOOKUP(F$3,Data_Entry!$C:$AB,18,0)," ") -> 0 | G14: =IFERROR(VLOOKUP(G$3,Data_Entry!$C:$AB,18,0)," ") -> 0 | H14: =IFERROR(VLOOKUP(H$3,Data_Entry!$C:$AB,18,0)," ") -> 0 | I14: =IFERROR(VLOOKUP(I$3,Data_Entry!$C:$AB,18,0)," ") -> 0 | ... AG14: =IFERROR(VLOOKUP(AG$3,Data_Entry!$C:$AB,18,0)," ")
A15: GTI | B15: =IFERROR(VLOOKUP(B$3,Data_Entry!$C:$AB,20,0)," ") -> 4.36 | C15: =IFERROR(VLOOKUP(C$3,Data_Entry!$C:$AB,20,0)," ") -> 0 | D15: =IFERROR(VLOOKUP(D$3,Data_Entry!$C:$AB,20,0)," ") -> 0 | E15: =IFERROR(VLOOKUP(E$3,Data_Entry!$C:$AB,20,0)," ") -> 0 | F15: =IFERROR(VLOOKUP(F$3,Data_Entry!$C:$AB,20,0)," ") -> 0 | G15: =IFERROR(VLOOKUP(G$3,Data_Entry!$C:$AB,20,0)," ") -> 0 | H15: =IFERROR(VLOOKUP(H$3,Data_Entry!$C:$AB,20,0)," ") -> 0 | I15: =IFERROR(VLOOKUP(I$3,Data_Entry!$C:$AB,20,0)," ") -> 0 | ... AF15: =IFERROR(VLOOKUP(AF$3,Data_Entry!$C:$AB,20,0)," ")
A16: GHI | B16: =IFERROR(VLOOKUP(B$3,Data_Entry!$C:$AB,19,0)," ") -> 0 | C16: =IFERROR(VLOOKUP(C$3,Data_Entry!$C:$AB,19,0)," ") -> 0 | D16: =IFERROR(VLOOKUP(D$3,Data_Entry!$C:$AB,19,0)," ") -> 0 | E16: =IFERROR(VLOOKUP(E$3,Data_Entry!$C:$AB,19,0)," ") -> 0 | F16: =IFERROR(VLOOKUP(F$3,Data_Entry!$C:$AB,19,0)," ") -> 0 | G16: =IFERROR(VLOOKUP(G$3,Data_Entry!$C:$AB,19,0)," ") -> 0 | H16: =IFERROR(VLOOKUP(H$3,Data_Entry!$C:$AB,19,0)," ") -> 0 | I16: =IFERROR(VLOOKUP(I$3,Data_Entry!$C:$AB,19,0)," ") -> 0 | ... AF16: =IFERROR(VLOOKUP(AF$3,Data_Entry!$C:$AB,19,0)," ")
A17: Module_Temp. | B17: =IFERROR(VLOOKUP(B$3,Data_Entry!$C:$AB,23,0)," ") -> 0 | C17: =IFERROR(VLOOKUP(C$3,Data_Entry!$C:$AB,23,0)," ") -> 0 | D17: =IFERROR(VLOOKUP(D$3,Data_Entry!$C:$AB,23,0)," ") -> 0 | E17: =IFERROR(VLOOKUP(E$3,Data_Entry!$C:$AB,23,0)," ") -> 0 | F17: =IFERROR(VLOOKUP(F$3,Data_Entry!$C:$AB,23,0)," ") -> 0 | G17: =IFERROR(VLOOKUP(G$3,Data_Entry!$C:$AB,23,0)," ") -> 0 | H17: =IFERROR(VLOOKUP(H$3,Data_Entry!$C:$AB,23,0)," ") -> 0 | I17: =IFERROR(VLOOKUP(I$3,Data_Entry!$C:$AB,23,0)," ") -> 0 | ... AF17: =IFERROR(VLOOKUP(AF$3,Data_Entry!$C:$AB,23,0)," ")
A18: Ambt._Temp. | B18: =IFERROR(VLOOKUP(B$3,Data_Entry!$C:$AB,21,0)," ") -> 33.41 | C18: =IFERROR(VLOOKUP(C$3,Data_Entry!$C:$AB,21,0)," ") -> 0 | D18: =IFERROR(VLOOKUP(D$3,Data_Entry!$C:$AB,21,0)," ") -> 0 | E18: =IFERROR(VLOOKUP(E$3,Data_Entry!$C:$AB,21,0)," ") -> 0 | F18: =IFERROR(VLOOKUP(F$3,Data_Entry!$C:$AB,21,0)," ") -> 0 | G18: =IFERROR(VLOOKUP(G$3,Data_Entry!$C:$AB,21,0)," ") -> 0 | H18: =IFERROR(VLOOKUP(H$3,Data_Entry!$C:$AB,21,0)," ") -> 0 | I18: =IFERROR(VLOOKUP(I$3,Data_Entry!$C:$AB,21,0)," ") -> 0 | ... AF18: =IFERROR(VLOOKUP(AF$3,Data_Entry!$C:$AB,21,0)," ")
A19: Performance_Ratio_(%) | B19: =IFERROR(B12/B15/(Basic_Data!$G$10),"") -> 1.2356943 | C19: =IFERROR(C12/C15/(Basic_Data!$G$10),"") | D19: =IFERROR(D12/D15/(Basic_Data!$G$10),"") | E19: =IFERROR(E12/E15/(Basic_Data!$G$10),"") | F19: =IFERROR(F12/F15/(Basic_Data!$G$10),"") | G19: =IFERROR(G12/G15/(Basic_Data!$G$10),"") | H19: =IFERROR(H12/H15/(Basic_Data!$G$10),"") | I19: =IFERROR(I12/I15/(Basic_Data!$G$10),"") | ... AG19: =IFERROR(AG12/AG15/(Basic_Data!$G$10),"")
A20: Capacity_Utilization_Factor_(%) | B20: =IFERROR(B12/(Basic_Data!$F$10*24),"") -> 0.28116883 | C20: =IFERROR(C12/(Basic_Data!$F$10*24),"") -> 0 | D20: =IFERROR(D12/(Basic_Data!$F$10*24),"") -> 0 | E20: =IFERROR(E12/(Basic_Data!$F$10*24),"") -> 0 | F20: =IFERROR(F12/(Basic_Data!$F$10*24),"") -> 0 | G20: =IFERROR(G12/(Basic_Data!$F$10*24),"") -> 0 | H20: =IFERROR(H12/(Basic_Data!$F$10*24),"") -> 0 | I20: =IFERROR(I12/(Basic_Data!$F$10*24),"") -> 0 | ... AG20: =IFERROR(AG12/(Basic_Data!$F$10*24),"")
A21: Aux_Consumption_Line_Loss_(%) | B21: =IFERROR((B11-B12)/B11,"") -> 0.010534494 | C21: =IFERROR((C11-C12)/C11,"") | D21: =IFERROR((D11-D12)/D11,"") | E21: =IFERROR((E11-E12)/E11,"") | F21: =IFERROR((F11-F12)/F11,"") | G21: =IFERROR((G11-G12)/G11,"") | H21: =IFERROR((H11-H12)/H11,"") | I21: =IFERROR((I11-I12)/I11,"") | ... AG21: =IFERROR((AG11-AG12)/AG11,"")

Sheet Data_Entry
B1: Month | C1: Date | D1: Plant_Up_Time | E1: Plant_Down_Time | F1: Inv_1 | G1: Inv_2 | H1: Inv_3 | I1: Inv_4 | J1: Inv_5 | K1: Inv_6 | L1: Inv_7 | M1: Total Inv Gen kWh | N1: ABT_Initial_Export | O1: ABT_Final_Export | P1: Total_Export | Q1: ABT_Initial_Import | R1: ABT_Final_Import | S1: Total_Import | T1: Net_Gen_kWh | U1: GHI (kwh/m2) | V1: GTI (kwh/m2) | W1: Ambt_Temp_Avg | X1: Module_Temp_Avg | Y1: Wtd_Module_Temp | Z1: Wind Speed | AA1: Rain_Gaug_MM | AB1: Weather_Condition
A2: 4 | B2: 45747 | C2: 45747 | M2: =SUM(F2:L2) -> 0 | P2: =MAX((O2-N2)*3000,0) -> 0 | S2: =MAX((R2-Q2)*3000,0) -> 0 | T2: =P2-S2 -> 0
A3: =A2+1 -> 5 | B3: 45748 | C3: 45748 | F3: 1907.18 | G3: 1939.32 | H3: 1904.51 | I3: 2007.77 | J3: 2023.7 | K3: 2022.23 | L3: 2004.7 | M3: =SUM(F3:L3) -> 13809.41 | N3: 12.12 | O3: 16.58 | P3: =MAX((O3-N3)*3000,0) -> 13380 | Q3: 1.94 | R3: 1.95 | S3: =MAX((R3-Q3)*3000,0) -> 30 | T3: =P3-S3 -> 13350 | V3: 4.70075
A4: =A3+1 -> 6 | B4: 45749 | C4: 45749 | F4: 1946.04 | G4: 1934.35 | H4: 1916.69 | I4: 2016.27 | J4: 1966.31 | K4: 1972.08 | L4: 1940.16 | M4: =SUM(F4:L4) -> 13691.9 | N4: 16.58 | O4: 21.09 | P4: =MAX((O4-N4)*3000,0) -> 13530 | Q4: 1.95 | R4: 1.96 | S4: =MAX((R4-Q4)*3000,0) -> 30 | T4: =P4-S4 -> 13500 | V4: 4.70525
A5: =A4+1 -> 7 | B5: 45750 | C5: 45750 | F5: 1851.77 | G5: 1838.41 | H5: 1826.56 | I5: 1920.42 | J5: 1872.57 | K5: 1880.64 | L5: 1846.67 | M5: =SUM(F5:L5) -> 13037.04 | N5: 21.09 | O5: 25.39 | P5: =MAX((O5-N5)*3000,0) -> 12900 | Q5: 1.96 | R5: 1.97 | S5: =MAX((R5-Q5)*3000,0) -> 30 | T5: =P5-S5 -> 12870 | V5: 4.574
A6: =A5+1 -> 8 | B6: 45751 | C6: 45751 | F6: 1922.67 | G6: 1906.56 | H6: 1894.57 | I6: 1994.46 | J6: 1942.86 | K6: 1954.23 | L6: 1915.01 | M6: =SUM(F6:L6) -> 13530.36 | N6: 25.39 | O6: 29.86 | P6: =MAX((O6-N6)*3000,0) -> 13410 | Q6: 1.97 | R6: 1.98 | S6: =MAX((R6-Q6)*3000,0) -> 30 | T6: =P6-S6 -> 13380 | V6: 4.706
A7: =A6+1 -> 9 | B7: 45752 | C7: 45752 | F7: 1900.72 | G7: 1888.35 | H7: 1873.9 | I7: 1974.18 | J7: 1922.82 | K7: 1934.16 | L7: 1806 | M7: =SUM(F7:L7) -> 13300.13 | N7: 29.86 | O7: 34.28 | P7: =MAX((O7-N7)*3000,0) -> 13260 | Q7: 1.98 | R7: 1.99 | S7: =MAX((R7-Q7)*3000,0) -> 30 | T7: =P7-S7 -> 13230 | V7: 4.71575
A8: =A7+1 -> 10 | B8: 45753 | C8: 45753 | F8: 1910.69 | G8: 1900.96 | H8: 1885.91 | I8: 1990.97 | J8: 1938.67 | K8: 1948.05 | L8: 1914.38 | M8: =SUM(F8:L8) -> 13489.63 | N8: 34.28 | O8: 38.73 | P8: =MAX((O8-N8)*3000,0) -> 13350 | Q8: 1.99 | R8: 2 | S8: =MAX((R8-Q8)*3000,0) -> 30 | T8: =P8-S8 -> 13320 | V8: 4.834
A9: =A8+1 -> 11 | B9: 45754 | C9: 45754 | F9: 1871.95 | G9: 1858.79 | H9: 1843.59 | I9: 1944.86 | J9: 1894.89 | K9: 1905.29 | L9: 1874.6 | M9: =SUM(F9:L9) -> 13193.97 | N9: 38.73 | O9: 43.09 | P9: =MAX((O9-N9)*3000,0) -> 13080 | Q9: 2 | R9: 2.01 | S9: =MAX((R9-Q9)*3000,0) -> 30 | T9: =P9-S9 -> 13050 | V9: 4.746
A10: =A9+1 -> 12 | B10: 45755 | C10: 45755 | F10: 1747.98 | G10: 1739.72 | H10: 1725.16 | I10: 1838.87 | J10: 1774.48 | K10: 1782.44 | L10: 1753.28 | M10: =SUM(F10:L10) -> 12361.93 | N10: 43.09 | O10: 47.17 | P10: =MAX((O10-N10)*3000,0) -> 12240 | Q10: 2.01 | R10: 2.02 | S10: =MAX((R10-Q10)*3000,0) -> 30 | T10: =P10-S10 -> 12210 | V10: 4.6445
A11: =A10+1 -> 13 | B11: 45756 | C11: 45756 | F11: 1795.76 | G11: 1784.89 | H11: 1771.68 | I11: 1904.8 | J11: 1819.83 | K11: 1827.37 | L11: 1798.97 | M11: =SUM(F11:L11) -> 12703.3 | N11: 47.17 | O11: 51.36 | P11: =MAX((O11-N11)*3000,0) -> 12570 | Q11: 2.02 | R11: 2.04 | S11: =MAX((R11-Q11)*3000,0) -> 60 | T11: =P11-S11 -> 12510 | V11: 4.74175
A12: =A11+1 -> 14 | B12: 45757 | C12: 45757 | F12: 1844.1 | G12: 1826.08 | H12: 1814.23 | I12: 1970.73 | J12: 1921.79 | K12: 1944.7 | L12: 1926.7 | M12: =SUM(F12:L12) -> 13248.33 | N12: =O11 -> 51.36 | O12: 55.73 | P12: =MAX((O12-N12)*3000,0) -> 13110 | Q12: =R11 -> 2.04 | R12: 2.05 | S12: =MAX((R12-Q12)*3000,0) -> 30 | T12: =P12-S12 -> 13080 | V12: 4.9
A13: =A12+1 -> 15 | B13: 45758 | C13: 45758 | F13: 1982.14 | G13: 1971.26 | H13: 1966.63 | I13: 2078.11 | J13: 2014.72 | K13: 2013.29 | L13: 2001.59 | M13: =SUM(F13:L13) -> 14027.74 | N13: =O12 -> 55.73 | O13: 60.36 | P13: =MAX((O13-N13)*3000,0) -> 13890 | Q13: =R12 -> 2.05 | R13: 2.06 | S13: =MAX((R13-Q13)*3000,0) -> 30 | T13: =P13-S13 -> 13860 | V13: 4.92 | W13: 60
A14: =A13+1 -> 16 | B14: 45759 | C14: 45759 | F14: 2000.12 | G14: 1989.96 | H14: 2054.8 | I14: 2103.08 | J14: 2033.46 | K14: 2028.7 | L14: 2016.47 | M14: =SUM(F14:L14) -> 14226.59 | N14: =O13 -> 60.36 | O14: 65.05 | P14: =MAX((O14-N14)*3000,0) -> 14070 | Q14: =R13 -> 2.06 | R14: 2.07 | S14: =MAX((R14-Q14)*3000,0) -> 30 | T14: =P14-S14 -> 14040 | V14: 5.08 | AB14: sunny
A15: =A14+1 -> 17 | B15: 45760 | C15: 45760 | F15: 2116.18 | G15: 2112.73 | H15: 2117 | I15: 2195.22 | J15: 2075.64 | K15: 2068.07 | L15: 2053.15 | M15: =SUM(F15:L15) -> 14737.99 | N15: =O14 -> 65.05 | O15: 69.91 | P15: =MAX((O15-N15)*3000,0) -> 14580 | Q15: =R14 -> 2.07 | R15: 2.08 | S15: =MAX((R15-Q15)*3000,0) -> 30 | T15: =P15-S15 -> 14550 | V15: 5.21 | AB15: sunny
A16: =A15+1 -> 18 | B16: 45761 | C16: 45761 | F16: 2102.77 | G16: 2079.13 | H16: 2090.55 | I16: 2200.6 | J16: 2172.37 | K16: 2164.42 | L16: 2154.04 | M16: =SUM(F16:L16) -> 14963.88 | N16: =O15 -> 69.91 | O16: 74.83 | P16: =MAX((O16-N16)*3000,0) -> 14760 | Q16: =R15 -> 2.08 | R16: 2.09 | S16: =MAX((R16-Q16)*3000,0) -> 30 | T16: =P16-S16 -> 14730 | V16: 5.14 | AB16: sunny
A17: =A16+1 -> 19 | B17: 45762 | C17: 45762 | F17: 2085.01 | G17: 2062.99 | H17: 2072.03 | I17: 2177.98 | J17: 2145.8 | K17: 2147.49 | L17: 2160.53 | M17: =SUM(F17:L17) -> 14851.83 | N17: =O16 -> 74.83 | O17: 79.73 | P17: =MAX((O17-N17)*3000,0) -> 14700 | Q17: =R16 -> 2.09 | R17: 2.1 | S17: =MAX((R17-Q17)*3000,0) -> 30 | T17: =P17-S17 -> 14670 | V17: 5.13 | AB17: sunny
A18: =A17+1 -> 20 | B18: 45763 | C18: 45763 | F18: 2045.52 | G18: 2024.81 | H18: 2028.81 | I18: 2132.32 | J18: 2108.15 | K18: 2115.88 | L18: 2127.22 | M18: =SUM(F18:L18) -> 14582.71 | N18: =O17 -> 79.73 | O18: 84.55 | P18: =MAX((O18-N18)*3000,0) -> 14460 | Q18: =R17 -> 2.1 | R18: 2.11 | S18: =MAX((R18-Q18)*3000,0) -> 30 | T18: =P18-S18 -> 14430 | V18: 5.04 | W18: 34.2 | AB18: sunny
A19: =A18+1 -> 21 | B19: 45764 | C19: 45764 | F19: 871.85 | G19: 870 | H19: 872.65 | I19: 911.72 | J19: 906.16 | K19: 901.18 | L19: 905.53 | M19: =SUM(F19:L19) -> 6239.09 | N19: =O18 -> 84.55 | O19: 86.6 | P19: =MAX((O19-N19)*3000,0) -> 6150 | Q19: =R18 -> 2.11 | R19: 2.12 | S19: =MAX((R19-Q19)*3000,0) -> 30 | T19: =P19-S19 -> 6120 | AB19: sunny
A20: =A19+1 -> 22 | B20: 45765 | C20: 45765 | F20: 0 | G20: 0 | H20: 0 | I20: 0 | J20: 0 | K20: 0 | L20: 0 | M20: =SUM(F20:L20) -> 0 | N20: =O19 -> 86.6 | O20: 86.6 | P20: =MAX((O20-N20)*3000,0) -> 0 | Q20: =R19 -> 2.12 | R20: 2.12 | S20: =MAX((R20-Q20)*3000,0) -> 0 | T20: =P20-S20 -> 0 | AB20: sunny
A21: =A20+1 -> 23 | B21: 45766 | C21: 45766 | F21: 0 | G21: 0 | H21: 0 | I21: 0 | J21: 0 | K21: 0 | L21: 0 | M21: =SUM(F21:L21) -> 0 | N21: =O20 -> 86.6 | O21: 86.6 | P21: =MAX((O21-N21)*3000,0) -> 0 | Q21: =R20 -> 2.12 | R21: 2.12 | S21: =MAX((R21-Q21)*3000,0) -> 0 | T21: =P21-S21 -> 0 | AB21: sunny
A22: =A21+1 -> 24 | B22: 45767 | C22: 45767 | F22: 2111.28 | G22: 2109.21 | H22: 2112.3 | I22: 2208.71 | J22: 2198.85 | K22: 2204.77 | L22: 2227.06 | M22: =SUM(F22:L22) -> 15172.18 | N22: =O21 -> 86.6 | O22: 91.6 | P22: =MAX((O22-N22)*3000,0) -> 15000 | Q22: =R21 -> 2.12 | R22: 2.13 | S22: =MAX((R22-Q22)*3000,0) -> 30 | T22: =P22-S22 -> 14970 | V22: 5.33 | W22: 33.9 | AB22: sunny
A23: =A22+1 -> 25 | B23: 45768 | C23: 45768 | F23: 2044.26 | G23: 2043.53 | H23: 2044.57 | I23: 2140.32 | J23: 2132.27 | K23: 2136.15 | L23: 2151.63 | M23: =SUM(F23:L23) -> 14692.73 | N23: =O22 -> 91.6 | O23: 96.45 | P23: =MAX((O23-N23)*3000,0) -> 14550 | Q23: =R22 -> 2.13 | R23: 2.14 | S23: =MAX((R23-Q23)*3000,0) -> 30 | T23: =P23-S23 -> 14520 | V23: 5.25 | W23: 35.25 | AB23: sunny
A24: =A23+1 -> 26 | B24: 45769 | C24: 45769 | F24: 2051.52 | G24: 2068.96 | H24: 2100.98 | I24: 2189.7 | J24: 2136.27 | K24: 2144.32 | L24: 2161.91 | M24: =SUM(F24:L24) -> 14853.66 | N24: =O23 -> 96.45 | O24: 101.35 | P24: =MAX((O24-N24)*3000,0) -> 14700 | Q24: =R23 -> 2.14 | R24: 2.15 | S24: =MAX((R24-Q24)*3000,0) -> 30 | T24: =P24-S24 -> 14670 | V24: 5.28 | W24: 37 | AB24: sunny
A25: =A24+1 -> 27 | B25: 45770 | C25: 45770 | F25: 2036.09 | G25: 2032.74 | H25: 2033.4 | I25: 2127.45 | J25: 2106.96 | K25: 2094.6 | L25: 2083.49 | M25: =SUM(F25:L25) -> 14514.73 | N25: =O24 -> 101.35 | O25: 106.14 | P25: =MAX((O25-N25)*3000,0) -> 14370 | Q25: =R24 -> 2.15 | R25: 2.16 | S25: =MAX((R25-Q25)*3000,0) -> 30 | T25: =P25-S25 -> 14340 | V25: 5.16 | W25: 37.04 | AB25: sunny
A26: =A25+1 -> 28 | B26: 45771 | C26: 45771 | F26: 2087.2 | G26: 2081.03 | H26: 2082.75 | I26: 2178.48 | J26: 2175.08 | K26: 2175.9 | L26: 2196.2 | M26: =SUM(F26:L26) -> 14976.64 | N26: =O25 -> 106.14 | O26: 111.07 | P26: =MAX((O26-N26)*3000,0) -> 14790 | Q26: =R25 -> 2.16 | R26: 2.17 | S26: =MAX((R26-Q26)*3000,0) -> 30 | T26: =P26-S26 -> 14760 | V26: 5.24 | W26: 35.34 | AB26: sunny
A27: =A26+1 -> 29 | B27: 45772 | C27: 45772 | F27: 2102.3 | G27: 2088.6 | H27: 2073 | I27: 2176.04 | J27: 2179.13 | K27: 2188.77 | L27: 2214.35 | M27: =SUM(F27:L27) -> 15022.19 | N27: =O26 -> 111.07 | O27: 116.04 | P27: =MAX((O27-N27)*3000,0) -> 14910 | Q27: =R26 -> 2.17 | R27: 2.18 | S27: =MAX((R27-Q27)*3000,0) -> 30 | T27: =P27-S27 -> 14880 | V27: 5.36 | W27: 31.86 | AB27: sunny
A28: =A27+1 -> 30 | B28: 45773 | C28: 45773 | F28: 2095.09 | G28: 2079.96 | H28: 2062.85 | I28: 2162.06 | J28: 2171.46 | K28: 2181.79 | L28: 2206.55 | M28: =SUM(F28:L28) -> 14959.76 | N28: =O27 -> 116.04 | O28: 120.98 | P28: =MAX((O28-N28)*3000,0) -> 14820 | Q28: =R27 -> 2.18 | R28: 2.19 | S28: =MAX((R28-Q28)*3000,0) -> 30 | T28: =P28-S28 -> 14790 | V28: 5.39 | W28: 34.96 | AB28: sunny
A29: =A28+1 -> 31 | B29: 45774 | C29: 45774 | F29: 2060 | G29: 2046.34 | H29: 2027.3 | I29: 2124.14 | J29: 2134.74 | K29: 2146.57 | L29: 2168.26 | M29: =SUM(F29:L29) -> 14707.35 | N29: =O28 -> 120.98 | O29: 125.84 | P29: =MAX((O29-N29)*3000,0) -> 14580 | Q29: =R28 -> 2.19 | R29: 2.2 | S29: =MAX((R29-Q29)*3000,0) -> 30 | T29: =P29-S29 -> 14550 | V29: 5.39 | W29: 35.68 | AB29: sunny
A30: =A29+1 -> 32 | B30: 45775 | C30: 45775 | D30: 0.28263889 | E30: 0.78125 | F30: 1845.54 | G30: 1806.3 | H30: 1785.4 | I30: 1867.44 | J30: 1876.8 | K30: 1888.4 | L30: 1906.11 | M30: =SUM(F30:L30) -> 12975.99 | N30: =O29 -> 125.84 | O30: 130.13 | P30: =MAX((O30-N30)*3000,0) -> 12870 | Q30: =R29 -> 2.2 | R30: 2.21 | S30: =MAX((R30-Q30)*3000,0) -> 30 | T30: =P30-S30 -> 12840 | V30: 5.28 | W30: 36.36 | AB30: sunny
A31: =A30+1 -> 33 | B31: 45776 | C31: 45776 | D31: 0.28125 | E31: 0.78125 | F31: 2121.64 | G31: 2111 | H31: 2100.88 | I31: 2189.97 | J31: 2155.82 | K31: 2160.51 | L31: 2181.7 | M31: =SUM(F31:L31) -> 15021.52 | N31: =O30 -> 130.13 | O31: 135.09 | P31: =MAX((O31-N31)*3000,0) -> 14880 | Q31: =R30 -> 2.21 | R31: 2.22 | S31: =MAX((R31-Q31)*3000,0) -> 30 | T31: =P31-S31 -> 14850 | V31: 5.55 | W31: 37.01 | AB31: sunny
A32: =A31+1 -> 34 | B32: 45777 | C32: 45777 | D32: 0.28125 | E32: 0.78125 | F32: 2090 | G32: 2081.16 | H32: 2071.47 | I32: 2172.86 | J32: 2165.84 | K32: 2130.54 | L32: 2143.81 | M32: =SUM(F32:L32) -> 14855.68 | N32: =O31 -> 135.09 | O32: 140 | P32: =MAX((O32-N32)*3000,0) -> 14730 | Q32: =R31 -> 2.22 | R32: 2.23 | S32: =MAX((R32-Q32)*3000,0) -> 30 | T32: =P32-S32 -> 14700 | V32: 5.47 | W32: 35.9 | AB32: sunny
A33: =A32+1 -> 35 | B33: 45778 | C33: 45778 | D33: 0.28125 | E33: 0.78194444 | F33: 2080.73 | G33: 2068.31 | H33: 2061.44 | I33: 2161.49 | J33: 2155.99 | K33: 2167.05 | L33: 2195.77 | M33: =SUM(F33:L33) -> 14890.78 | N33: =O32 -> 140 | O33: 144.91 | P33: =MAX((O33-N33)*3000,0) -> 14730 | Q33: =R32 -> 2.23 | R33: 2.24 | S33: =MAX((R33-Q33)*3000,0) -> 30 | T33: =P33-S33 -> 14700 | V33: 5.52 | W33: 35.78 | AB33: sunny
A34: =A33+1 -> 36 | B34: 45779 | C34: 45779 | D34: 0.28125 | E34: 0.78194444 | F34: 2167.71 | G34: 2144.78 | H34: 2138.28 | I34: 2242.8 | J34: 2237.89 | K34: 2250.4 | L34: 2268.68 | M34: =SUM(F34:L34) -> 15450.54 | N34: =O33 -> 144.91 | O34: 150 | P34: =MAX((O34-N34)*3000,0) -> 15270 | Q34: =R33 -> 2.24 | R34: 2.25 | S34: =MAX((R34-Q34)*3000,0) -> 30 | T34: =P34-S34 -> 15240 | V34: 5.85 | W34: 35.96 | AB34: sunny
A35: =A34+1 -> 37 | B35: 45780 | C35: 45780 | D35: 0.28125 | E35: 0.78194444 | F35: 2035.03 | G35: 2022.08 | H35: 2013.82 | I35: 2111.03 | J35: 2106.59 | K35: 2116.26 | L35: 2137.34 | M35: =SUM(F35:L35) -> 14542.15 | N35: =O34 -> 150 | O35: 154.8 | P35: =MAX((O35-N35)*3000,0) -> 14400 | Q35: =R34 -> 2.25 | R35: 2.26 | S35: =MAX((R35-Q35)*3000,0) -> 30 | T35: =P35-S35 -> 14370 | V35: 5.39 | W35: 33.54 | AB35: sunny
A36: =A35+1 -> 38 | B36: 45781 | C36: 45781 | D36: 0.28125 | E36: 0.78125 | F36: 1905.43 | G36: 1894.04 | H36: 1889.89 | I36: 1977.99 | J36: 1976.69 | K36: 1987.41 | L36: 2009.93 | M36: =SUM(F36:L36) -> 13641.38 | N36: =O35 -> 154.8 | O36: 159.31 | P36: =MAX((O36-N36)*3000,0) -> 13530 | Q36: =R35 -> 2.26 | R36: 2.27 | S36: =MAX((R36-Q36)*3000,0) -> 30 | T36: =P36-S36 -> 13500 | V36: 5.04 | W36: 33.37 | AB36: sunny
A37: =A36+1 -> 39 | B37: 45782 | C37: 45782 | D37: 0.28125 | E37: 0.78125 | F37: 1897.04 | G37: 1882.65 | H37: 1874.3 | I37: 1968.13 | J37: 1975.47 | K37: 1991.66 | L37: 2016.33 | M37: =SUM(F37:L37) -> 13605.58 | N37: =O36 -> 159.31 | O37: 163.8 | P37: =MAX((O37-N37)*3000,0) -> 13470 | Q37: =R36 -> 2.27 | R37: 2.28 | S37: =MAX((R37-Q37)*3000,0) -> 30 | T37: =P37-S37 -> 13440 | V37: 4.23 | W37: 31.68 | AB37: mostly cloudy
A38: =A37+1 -> 40 | B38: 45783 | C38: 45783 | D38: 0.29166667 | E38: 0.625 | F38: 1253.46 | G38: 1246.19 | H38: 1241.61 | I38: 1301.63 | J38: 1293.55 | K38: 1293.12 | L38: 1303.87 | M38: =SUM(F38:L38) -> 8933.43 | N38: =O37 -> 163.8 | O38: 166.67 | P38: =MAX((O38-N38)*3000,0) -> 8610 | Q38: =R37 -> 2.28 | R38: 2.29 | S38: =MAX((R38-Q38)*3000,0) -> 30 | T38: =P38-S38 -> 8580 | V38: 3.29 | W38: 30.13 | AB38: cloudy
A39: =A38+1 -> 41 | B39: 45784 | C39: 45784 | D39: 0.28125 | E39: 0.78125 | F39: 1015.68 | G39: 1010.52 | H39: 1004.47 | I39: 1051.98 | J39: 1055.87 | K39: 1060.14 | L39: 1074.74 | M39: =SUM(F39:L39) -> 7273.4 | N39: =O38 -> 166.67 | O39: 169.14 | P39: =MAX((O39-N39)*3000,0) -> 7410 | Q39: =R38 -> 2.29 | R39: 2.3 | S39: =MAX((R39-Q39)*3000,0) -> 30 | T39: =P39-S39 -> 7380 | V39: 2.65 | W39: 27.47 | AB39: rainy
A40: =A39+1 -> 42 | B40: 45785 | C40: 45785 | D40: 0.28125 | E40: 0.78125 | F40: 1953.56 | G40: 1949.73 | H40: 1946.56 | I40: 2033.03 | J40: 2026.38 | K40: 2030.49 | L40: 2049.24 | M40: =SUM(F40:L40) -> 13988.99 | N40: =O39 -> 169.14 | O40: 173.77 | P40: =MAX((O40-N40)*3000,0) -> 13890 | Q40: =R39 -> 2.3 | R40: 2.31 | S40: =MAX((R40-Q40)*3000,0) -> 30 | T40: =P40-S40 -> 13860 | V40: 5.95 | W40: 31.8 | AB40: cloudy
...

Sheet Inverter_PR
A1: Inverter_Availability_Sheet
C2: 335.72 | D2: 335.72 | E2: 335.72 | F2: 350.98 | G2: 350.98 | H2: 350.98 | I2: 350.98
C3: Inv_1 | D3: Inv_2 | E3: Inv_3 | F3: Inv_4 | G3: Inv_5 | H3: Inv_6 | I3: Inv_7
A4: 45747 | B4: 45747
A5: 45748 | B5: 45748 | C5: =IFERROR((Data_Entry!F3/Data_Entry!$V3/C$2),"") -> 1.2085018 | D5: =IFERROR((Data_Entry!G3/Data_Entry!$V3/D$2),"") -> 1.2288676 | E5: =IFERROR((Data_Entry!H3/Data_Entry!$V3/E$2),"") -> 1.20681 | F5: =IFERROR((Data_Entry!I3/Data_Entry!$V3/F$2),"") -> 1.2169267 | G5: =IFERROR((Data_Entry!J3/Data_Entry!$V3/G$2),"") -> 1.2265821 | H5: =IFERROR((Data_Entry!K3/Data_Entry!$V3/H$2),"") -> 1.2256911 | I5: =IFERROR((Data_Entry!L3/Data_Entry!$V3/I$2),"") -> 1.215066
A6: 45749 | B6: 45749 | C6: =IFERROR((Data_Entry!F4/Data_Entry!$V4/C$2),"") -> 1.2319465 | D6: =IFERROR((Data_Entry!G4/Data_Entry!$V4/D$2),"") -> 1.2245461 | E6: =IFERROR((Data_Entry!H4/Data_Entry!$V4/E$2),"") -> 1.2133664 | F6: =IFERROR((Data_Entry!I4/Data_Entry!$V4/F$2),"") -> 1.2209099 | G6: =IFERROR((Data_Entry!J4/Data_Entry!$V4/G$2),"") -> 1.1906577 | H6: =IFERROR((Data_Entry!K4/Data_Entry!$V4/H$2),"") -> 1.1941516 | I6: =IFERROR((Data_Entry!L4/Data_Entry!$V4/I$2),"") -> 1.1748231
A7: 45750 | B7: 45750 | C7: =IFERROR((Data_Entry!F5/Data_Entry!$V5/C$2),"") -> 1.2059066 | D7: =IFERROR((Data_Entry!G5/Data_Entry!$V5/D$2),"") -> 1.1972063 | E7: =IFERROR((Data_Entry!H5/Data_Entry!$V5/E$2),"") -> 1.1894894 | F7: =IFERROR((Data_Entry!I5/Data_Entry!$V5/F$2),"") -> 1.1962383 | G7: =IFERROR((Data_Entry!J5/Data_Entry!$V5/G$2),"") -> 1.1664323 | H7: =IFERROR((Data_Entry!K5/Data_Entry!$V5/H$2),"") -> 1.1714591 | I7: =IFERROR((Data_Entry!L5/Data_Entry!$V5/I$2),"") -> 1.1502991
A8: 45751 | B8: 45751 | C8: =IFERROR((Data_Entry!F6/Data_Entry!$V6/C$2),"") -> 1.2169581 | D8: =IFERROR((Data_Entry!G6/Data_Entry!$V6/D$2),"") -> 1.2067612 | E8: =IFERROR((Data_Entry!H6/Data_Entry!$V6/E$2),"") -> 1.1991721 | F8: =IFERROR((Data_Entry!I6/Data_Entry!$V6/F$2),"") -> 1.2075108 | G8: =IFERROR((Data_Entry!J6/Data_Entry!$V6/G$2),"") -> 1.1762705 | H8: =IFERROR((Data_Entry!K6/Data_Entry!$V6/H$2),"") -> 1.1831543 | I8: =IFERROR((Data_Entry!L6/Data_Entry!$V6/I$2),"") -> 1.1594092
A9: 45752 | B9: 45752 | C9: =IFERROR((Data_Entry!F7/Data_Entry!$V7/C$2),"") -> 1.2005774 | D9: =IFERROR((Data_Entry!G7/Data_Entry!$V7/D$2),"") -> 1.192764 | E9: =IFERROR((Data_Entry!H7/Data_Entry!$V7/E$2),"") -> 1.1836367 | F9: =IFERROR((Data_Entry!I7/Data_Entry!$V7/F$2),"") -> 1.1927615 | G9: =IFERROR((Data_Entry!J7/Data_Entry!$V7/G$2),"") -> 1.1617308 | H9: =IFERROR((Data_Entry!K7/Data_Entry!$V7/H$2),"") -> 1.1685822 | I9: =IFERROR((Data_Entry!L7/Data_Entry!$V7/I$2),"") -> 1.0911504
A10: 45753 | B10: 45753 | C10: =IFERROR((Data_Entry!F8/Data_Entry!$V8/C$2),"") -> 1.1773521 | D10: =IFERROR((Data_Entry!G8/Data_Entry!$V8/D$2),"") -> 1.1713566 | E10: =IFERROR((Data_Entry!H8/Data_Entry!$V8/E$2),"") -> 1.1620829 | F10: =IFERROR((Data_Entry!I8/Data_Entry!$V8/F$2),"") -> 1.17348 | G10: =IFERROR((Data_Entry!J8/Data_Entry!$V8/G$2),"") -> 1.1426543 | H10: =IFERROR((Data_Entry!K8/Data_Entry!$V8/H$2),"") -> 1.1481829 | I10: =IFERROR((Data_Entry!L8/Data_Entry!$V8/I$2),"") -> 1.1283378
A11: 45754 | B11: 45754 | C11: =IFERROR((Data_Entry!F9/Data_Entry!$V9/C$2),"") -> 1.1748686 | D11: =IFERROR((Data_Entry!G9/Data_Entry!$V9/D$2),"") -> 1.1666092 | E11: =IFERROR((Data_Entry!H9/Data_Entry!$V9/E$2),"") -> 1.1570694 | F11: =IFERROR((Data_Entry!I9/Data_Entry!$V9/F$2),"") -> 1.1675574 | G11: =IFERROR((Data_Entry!J9/Data_Entry!$V9/G$2),"") -> 1.1375589 | H11: =IFERROR((Data_Entry!K9/Data_Entry!$V9/H$2),"") -> 1.1438024 | I11: =IFERROR((Data_Entry!L9/Data_Entry!$V9/I$2),"") -> 1.1253782
A12: 45755 | B12: 45755 | C12: =IFERROR((Data_Entry!F10/Data_Entry!$V10/C$2),"") -> 1.1210379 | D12: =IFERROR((Data_Entry!G10/Data_Entry!$V10/D$2),"") -> 1.1157404 | E12: =IFERROR((Data_Entry!H10/Data_Entry!$V10/E$2),"") -> 1.1064026 | F12: =IFERROR((Data_Entry!I10/Data_Entry!$V10/F$2),"") -> 1.1280535 | G12: =IFERROR((Data_Entry!J10/Data_Entry!$V10/G$2),"") -> 1.0885535 | H12: =IFERROR((Data_Entry!K10/Data_Entry!$V10/H$2),"") -> 1.0934365 | I12: =IFERROR((Data_Entry!L10/Data_Entry!$V10/I$2),"") -> 1.0755484
A13: 45756 | B13: 45756 | C13: =IFERROR((Data_Entry!F11/Data_Entry!$V11/C$2),"") -> 1.1280606 | D13: =IFERROR((Data_Entry!G11/Data_Entry!$V11/D$2),"") -> 1.1212323 | E13: =IFERROR((Data_Entry!H11/Data_Entry!$V11/E$2),"") -> 1.112934 | F13: =IFERROR((Data_Entry!I11/Data_Entry!$V11/F$2),"") -> 1.1445331 | G13: =IFERROR((Data_Entry!J11/Data_Entry!$V11/G$2),"") -> 1.0934774 | H13: =IFERROR((Data_Entry!K11/Data_Entry!$V11/H$2),"") -> 1.0980079 | I13: =IFERROR((Data_Entry!L11/Data_Entry!$V11/I$2),"") -> 1.0809433
A14: 45757 | B14: 45757 | C14: =IFERROR((Data_Entry!F12/Data_Entry!$V12/C$2),"") -> 1.1210144 | D14: =IFERROR((Data_Entry!G12/Data_Entry!$V12/D$2),"") -> 1.1100601 | E14: =IFERROR((Data_Entry!H12/Data_Entry!$V12/E$2),"") -> 1.1028566 | F14: =IFERROR((Data_Entry!I12/Data_Entry!$V12/F$2),"") -> 1.1459052 | G14: =IFERROR((Data_Entry!J12/Data_Entry!$V12/G$2),"") -> 1.1174484 | H14: =IFERROR((Data_Entry!K12/Data_Entry!$V12/H$2),"") -> 1.1307697 | I14: =IFERROR((Data_Entry!L12/Data_Entry!$V12/I$2),"") -> 1.1203034
A15: 45758 | B15: 45758 | C15: =IFERROR((Data_Entry!F13/Data_Entry!$V13/C$2),"") -> 1.2000297 | D15: =IFERROR((Data_Entry!G13/Data_Entry!$V13/D$2),"") -> 1.1934428 | E15: =IFERROR((Data_Entry!H13/Data_Entry!$V13/E$2),"") -> 1.1906397 | F15: =IFERROR((Data_Entry!I13/Data_Entry!$V13/F$2),"") -> 1.2034306 | G15: =IFERROR((Data_Entry!J13/Data_Entry!$V13/G$2),"") -> 1.1667216 | H15: =IFERROR((Data_Entry!K13/Data_Entry!$V13/H$2),"") -> 1.1658935 | I15: =IFERROR((Data_Entry!L13/Data_Entry!$V13/I$2),"") -> 1.159118
A16: 45759 | B16: 45759 | C16: =IFERROR((Data_Entry!F14/Data_Entry!$V14/C$2),"") -> 1.1727762 | D16: =IFERROR((Data_Entry!G14/Data_Entry!$V14/D$2),"") -> 1.1668188 | E16: =IFERROR((Data_Entry!H14/Data_Entry!$V14/E$2),"") -> 1.2048379 | F16: =IFERROR((Data_Entry!I14/Data_Entry!$V14/F$2),"") -> 1.179532 | G16: =IFERROR((Data_Entry!J14/Data_Entry!$V14/G$2),"") -> 1.1404849 | H16: =IFERROR((Data_Entry!K14/Data_Entry!$V14/H$2),"") -> 1.1378152 | I16: =IFERROR((Data_Entry!L14/Data_Entry!$V14/I$2),"") -> 1.1309559
... A369: 46112 | B369: 46112 | C369: =IFERROR((Data_Entry!F367/Data_Entry!$V367/C$2),"") -> 0.95835235 | D369: =IFERROR((Data_Entry!G367/Data_Entry!$V367/D$2),"") -> 0.93648217 | E369: =IFERROR((Data_Entry!H367/Data_Entry!$V367/E$2),"") -> 0.94044044 | F369: =IFERROR((Data_Entry!I367/Data_Entry!$V367/F$2),"") -> 0.94154831 | G369: =IFERROR((Data_Entry!J367/Data_Entry!$V367/G$2),"") -> 0.91696269 | H369: =IFERROR((Data_Entry!K367/Data_Entry!$V367/H$2),"") -> 0.92668145 | I369: =IFERROR((Data_Entry!L367/Data_Entry!$V367/I$2),"") -> 0.95530929

Sheet Invt_Analysis_Gen_Per_KW &_PR
A1: Daily_Generation_Per_KW_Performance_Analysis
B2: Inverter_No. | C2: =DGR!B3 -> 46181 | D2: =DGR!C3 -> 46182 | E2: =DGR!D3 -> 46183 | F2: =DGR!E3 -> 46184 | G2: =DGR!F3 -> 46185 | H2: =DGR!G3 -> 46186 | I2: =DGR!H3 -> 46187 | J2: =DGR!I3 -> 46188 | ... AH2: =DGR!AG3 -> Total/Avg..
B3: Inv_1 | C3: =IFERROR(VLOOKUP(C$2,Data_Entry!$C:$L,Data_Entry!$A2,0)/VLOOKUP($B3,Basic_Data!$E$2:$G$10,3,0),"") -> 5.4903491 | D3: =IFERROR(VLOOKUP(D$2,Data_Entry!$C:$L,Data_Entry!$A2,0)/VLOOKUP($B3,Basic_Data!$E$2:$G$10,3,0),"") -> 0 | E3: =IFERROR(VLOOKUP(E$2,Data_Entry!$C:$L,Data_Entry!$A2,0)/VLOOKUP($B3,Basic_Data!$E$2:$G$10,3,0),"") -> 0 | F3: =IFERROR(VLOOKUP(F$2,Data_Entry!$C:$L,Data_Entry!$A2,0)/VLOOKUP($B3,Basic_Data!$E$2:$G$10,3,0),"") -> 0 | G3: =IFERROR(VLOOKUP(G$2,Data_Entry!$C:$L,Data_Entry!$A2,0)/VLOOKUP($B3,Basic_Data!$E$2:$G$10,3,0),"") -> 0 | H3: =IFERROR(VLOOKUP(H$2,Data_Entry!$C:$L,Data_Entry!$A2,0)/VLOOKUP($B3,Basic_Data!$E$2:$G$10,3,0),"") -> 0 | I3: =IFERROR(VLOOKUP(I$2,Data_Entry!$C:$L,Data_Entry!$A2,0)/VLOOKUP($B3,Basic_Data!$E$2:$G$10,3,0),"") -> 0 | J3: =IFERROR(VLOOKUP(J$2,Data_Entry!$C:$L,Data_Entry!$A2,0)/VLOOKUP($B3,Basic_Data!$E$2:$G$10,3,0),"") -> 0 | ... AG3: =IFERROR(VLOOKUP(AG$2,Data_Entry!$C:$L,Data_Entry!$A2,0)/VLOOKUP($B3,Basic_Data!$E$2:$G$10,3,0),"")
B4: Inv_2 | C4: =IFERROR(VLOOKUP(C$2,Data_Entry!$C:$L,Data_Entry!$A3,0)/VLOOKUP($B4,Basic_Data!$E$2:$G$10,3,0),"") -> 5.4759919 | D4: =IFERROR(VLOOKUP(D$2,Data_Entry!$C:$L,Data_Entry!$A3,0)/VLOOKUP($B4,Basic_Data!$E$2:$G$10,3,0),"") -> 0 | E4: =IFERROR(VLOOKUP(E$2,Data_Entry!$C:$L,Data_Entry!$A3,0)/VLOOKUP($B4,Basic_Data!$E$2:$G$10,3,0),"") -> 0 | F4: =IFERROR(VLOOKUP(F$2,Data_Entry!$C:$L,Data_Entry!$A3,0)/VLOOKUP($B4,Basic_Data!$E$2:$G$10,3,0),"") -> 0 | G4: =IFERROR(VLOOKUP(G$2,Data_Entry!$C:$L,Data_Entry!$A3,0)/VLOOKUP($B4,Basic_Data!$E$2:$G$10,3,0),"") -> 0 | H4: =IFERROR(VLOOKUP(H$2,Data_Entry!$C:$L,Data_Entry!$A3,0)/VLOOKUP($B4,Basic_Data!$E$2:$G$10,3,0),"") -> 0 | I4: =IFERROR(VLOOKUP(I$2,Data_Entry!$C:$L,Data_Entry!$A3,0)/VLOOKUP($B4,Basic_Data!$E$2:$G$10,3,0),"") -> 0 | J4: =IFERROR(VLOOKUP(J$2,Data_Entry!$C:$L,Data_Entry!$A3,0)/VLOOKUP($B4,Basic_Data!$E$2:$G$10,3,0),"") -> 0 | ... AG4: =IFERROR(VLOOKUP(AG$2,Data_Entry!$C:$L,Data_Entry!$A3,0)/VLOOKUP($B4,Basic_Data!$E$2:$G$10,3,0),"")
B5: Inv_3 | C5: =IFERROR(VLOOKUP(C$2,Data_Entry!$C:$L,Data_Entry!$A4,0)/VLOOKUP($B5,Basic_Data!$E$2:$G$10,3,0),"") -> 5.4665793 | D5: =IFERROR(VLOOKUP(D$2,Data_Entry!$C:$L,Data_Entry!$A4,0)/VLOOKUP($B5,Basic_Data!$E$2:$G$10,3,0),"") -> 0 | E5: =IFERROR(VLOOKUP(E$2,Data_Entry!$C:$L,Data_Entry!$A4,0)/VLOOKUP($B5,Basic_Data!$E$2:$G$10,3,0),"") -> 0 | F5: =IFERROR(VLOOKUP(F$2,Data_Entry!$C:$L,Data_Entry!$A4,0)/VLOOKUP($B5,Basic_Data!$E$2:$G$10,3,0),"") -> 0 | G5: =IFERROR(VLOOKUP(G$2,Data_Entry!$C:$L,Data_Entry!$A4,0)/VLOOKUP($B5,Basic_Data!$E$2:$G$10,3,0),"") -> 0 | H5: =IFERROR(VLOOKUP(H$2,Data_Entry!$C:$L,Data_Entry!$A4,0)/VLOOKUP($B5,Basic_Data!$E$2:$G$10,3,0),"") -> 0 | I5: =IFERROR(VLOOKUP(I$2,Data_Entry!$C:$L,Data_Entry!$A4,0)/VLOOKUP($B5,Basic_Data!$E$2:$G$10,3,0),"") -> 0 | J5: =IFERROR(VLOOKUP(J$2,Data_Entry!$C:$L,Data_Entry!$A4,0)/VLOOKUP($B5,Basic_Data!$E$2:$G$10,3,0),"") -> 0 | ... AG5: =IFERROR(VLOOKUP(AG$2,Data_Entry!$C:$L,Data_Entry!$A4,0)/VLOOKUP($B5,Basic_Data!$E$2:$G$10,3,0),"")
B6: Inv_4 | C6: =IFERROR(VLOOKUP(C$2,Data_Entry!$C:$L,Data_Entry!$A5,0)/VLOOKUP($B6,Basic_Data!$E$2:$G$10,3,0),"") -> 5.4326172 | D6: =IFERROR(VLOOKUP(D$2,Data_Entry!$C:$L,Data_Entry!$A5,0)/VLOOKUP($B6,Basic_Data!$E$2:$G$10,3,0),"") -> 0 | E6: =IFERROR(VLOOKUP(E$2,Data_Entry!$C:$L,Data_Entry!$A5,0)/VLOOKUP($B6,Basic_Data!$E$2:$G$10,3,0),"") -> 0 | F6: =IFERROR(VLOOKUP(F$2,Data_Entry!$C:$L,Data_Entry!$A5,0)/VLOOKUP($B6,Basic_Data!$E$2:$G$10,3,0),"") -> 0 | G6: =IFERROR(VLOOKUP(G$2,Data_Entry!$C:$L,Data_Entry!$A5,0)/VLOOKUP($B6,Basic_Data!$E$2:$G$10,3,0),"") -> 0 | H6: =IFERROR(VLOOKUP(H$2,Data_Entry!$C:$L,Data_Entry!$A5,0)/VLOOKUP($B6,Basic_Data!$E$2:$G$10,3,0),"") -> 0 | I6: =IFERROR(VLOOKUP(I$2,Data_Entry!$C:$L,Data_Entry!$A5,0)/VLOOKUP($B6,Basic_Data!$E$2:$G$10,3,0),"") -> 0 | J6: =IFERROR(VLOOKUP(J$2,Data_Entry!$C:$L,Data_Entry!$A5,0)/VLOOKUP($B6,Basic_Data!$E$2:$G$10,3,0),"") -> 0 | ... AG6: =IFERROR(VLOOKUP(AG$2,Data_Entry!$C:$L,Data_Entry!$A5,0)/VLOOKUP($B6,Basic_Data!$E$2:$G$10,3,0),"")
B7: Inv_5 | C7: =IFERROR(VLOOKUP(C$2,Data_Entry!$C:$L,Data_Entry!$A6,0)/VLOOKUP($B7,Basic_Data!$E$2:$G$10,3,0),"") -> 5.4139267 | D7: =IFERROR(VLOOKUP(D$2,Data_Entry!$C:$L,Data_Entry!$A6,0)/VLOOKUP($B7,Basic_Data!$E$2:$G$10,3,0),"") -> 0 | E7: =IFERROR(VLOOKUP(E$2,Data_Entry!$C:$L,Data_Entry!$A6,0)/VLOOKUP($B7,Basic_Data!$E$2:$G$10,3,0),"") -> 0 | F7: =IFERROR(VLOOKUP(F$2,Data_Entry!$C:$L,Data_Entry!$A6,0)/VLOOKUP($B7,Basic_Data!$E$2:$G$10,3,0),"") -> 0 | G7: =IFERROR(VLOOKUP(G$2,Data_Entry!$C:$L,Data_Entry!$A6,0)/VLOOKUP($B7,Basic_Data!$E$2:$G$10,3,0),"") -> 0 | H7: =IFERROR(VLOOKUP(H$2,Data_Entry!$C:$L,Data_Entry!$A6,0)/VLOOKUP($B7,Basic_Data!$E$2:$G$10,3,0),"") -> 0 | I7: =IFERROR(VLOOKUP(I$2,Data_Entry!$C:$L,Data_Entry!$A6,0)/VLOOKUP($B7,Basic_Data!$E$2:$G$10,3,0),"") -> 0 | J7: =IFERROR(VLOOKUP(J$2,Data_Entry!$C:$L,Data_Entry!$A6,0)/VLOOKUP($B7,Basic_Data!$E$2:$G$10,3,0),"") -> 0 | ... AG7: =IFERROR(VLOOKUP(AG$2,Data_Entry!$C:$L,Data_Entry!$A6,0)/VLOOKUP($B7,Basic_Data!$E$2:$G$10,3,0),"")
B8: Inv_6 | C8: =IFERROR(VLOOKUP(C$2,Data_Entry!$C:$L,Data_Entry!$A7,0)/VLOOKUP($B8,Basic_Data!$E$2:$G$10,3,0),"") -> 5.4199669 | D8: =IFERROR(VLOOKUP(D$2,Data_Entry!$C:$L,Data_Entry!$A7,0)/VLOOKUP($B8,Basic_Data!$E$2:$G$10,3,0),"") -> 0 | E8: =IFERROR(VLOOKUP(E$2,Data_Entry!$C:$L,Data_Entry!$A7,0)/VLOOKUP($B8,Basic_Data!$E$2:$G$10,3,0),"") -> 0 | F8: =IFERROR(VLOOKUP(F$2,Data_Entry!$C:$L,Data_Entry!$A7,0)/VLOOKUP($B8,Basic_Data!$E$2:$G$10,3,0),"") -> 0 | G8: =IFERROR(VLOOKUP(G$2,Data_Entry!$C:$L,Data_Entry!$A7,0)/VLOOKUP($B8,Basic_Data!$E$2:$G$10,3,0),"") -> 0 | H8: =IFERROR(VLOOKUP(H$2,Data_Entry!$C:$L,Data_Entry!$A7,0)/VLOOKUP($B8,Basic_Data!$E$2:$G$10,3,0),"") -> 0 | I8: =IFERROR(VLOOKUP(I$2,Data_Entry!$C:$L,Data_Entry!$A7,0)/VLOOKUP($B8,Basic_Data!$E$2:$G$10,3,0),"") -> 0 | J8: =IFERROR(VLOOKUP(J$2,Data_Entry!$C:$L,Data_Entry!$A7,0)/VLOOKUP($B8,Basic_Data!$E$2:$G$10,3,0),"") -> 0 | ... AG8: =IFERROR(VLOOKUP(AG$2,Data_Entry!$C:$L,Data_Entry!$A7,0)/VLOOKUP($B8,Basic_Data!$E$2:$G$10,3,0),"")
B9: Inv_7 | C9: =IFERROR(VLOOKUP(C$2,Data_Entry!$C:$L,Data_Entry!$A8,0)/VLOOKUP($B9,Basic_Data!$E$2:$G$10,3,0),"") -> 5.419739 | D9: =IFERROR(VLOOKUP(D$2,Data_Entry!$C:$L,Data_Entry!$A8,0)/VLOOKUP($B9,Basic_Data!$E$2:$G$10,3,0),"") -> 0 | E9: =IFERROR(VLOOKUP(E$2,Data_Entry!$C:$L,Data_Entry!$A8,0)/VLOOKUP($B9,Basic_Data!$E$2:$G$10,3,0),"") -> 0 | F9: =IFERROR(VLOOKUP(F$2,Data_Entry!$C:$L,Data_Entry!$A8,0)/VLOOKUP($B9,Basic_Data!$E$2:$G$10,3,0),"") -> 0 | G9: =IFERROR(VLOOKUP(G$2,Data_Entry!$C:$L,Data_Entry!$A8,0)/VLOOKUP($B9,Basic_Data!$E$2:$G$10,3,0),"") -> 0 | H9: =IFERROR(VLOOKUP(H$2,Data_Entry!$C:$L,Data_Entry!$A8,0)/VLOOKUP($B9,Basic_Data!$E$2:$G$10,3,0),"") -> 0 | I9: =IFERROR(VLOOKUP(I$2,Data_Entry!$C:$L,Data_Entry!$A8,0)/VLOOKUP($B9,Basic_Data!$E$2:$G$10,3,0),"") -> 0 | J9: =IFERROR(VLOOKUP(J$2,Data_Entry!$C:$L,Data_Entry!$A8,0)/VLOOKUP($B9,Basic_Data!$E$2:$G$10,3,0),"") -> 0 | ... AG9: =IFERROR(VLOOKUP(AG$2,Data_Entry!$C:$L,Data_Entry!$A8,0)/VLOOKUP($B9,Basic_Data!$E$2:$G$10,3,0),"")
B10: Avg_per_Kw | C10: =AVERAGE(C3:C9) -> 5.4455957 | D10: =AVERAGE(D3:D9) -> 0 | E10: =AVERAGE(E3:E9) -> 0 | F10: =AVERAGE(F3:F9) -> 0 | G10: =AVERAGE(G3:G9) -> 0 | H10: =AVERAGE(H3:H9) -> 0 | I10: =AVERAGE(I3:I9) -> 0 | J10: =AVERAGE(J3:J9) -> 0 | ... AH10: =AVERAGE(AH3:AH9) -> #DIV/0!
B13: Inverter_No. | C13: =DGR!B3 -> 46181 | D13: =DGR!C3 -> 46182 | E13: =DGR!D3 -> 46183 | F13: =DGR!E3 -> 46184 | G13: =DGR!F3 -> 46185 | H13: =DGR!G3 -> 46186 | I13: =DGR!H3 -> 46187 | J13: =DGR!I3 -> 46188 | ... AH13: =DGR!AG3 -> Total/Avg..
B14: Inv_1 | C14: =IFERROR(VLOOKUP(C$13,Data_Entry!$C:$M,Data_Entry!$A2,0)/VLOOKUP($B14,Basic_Data!$E$2:$G$9,3,0)/VLOOKUP(C$13,Data_Entry!$C:$V,20,0),"") -> 1.2592544 | D14: =IFERROR(VLOOKUP(D$13,Data_Entry!$C:$M,Data_Entry!$A2,0)/VLOOKUP($B14,Basic_Data!$E$2:$G$9,3,0)/VLOOKUP(D$13,Data_Entry!$C:$V,20,0),"") | E14: =IFERROR(VLOOKUP(E$13,Data_Entry!$C:$M,Data_Entry!$A2,0)/VLOOKUP($B14,Basic_Data!$E$2:$G$9,3,0)/VLOOKUP(E$13,Data_Entry!$C:$V,20,0),"") | F14: =IFERROR(VLOOKUP(F$13,Data_Entry!$C:$M,Data_Entry!$A2,0)/VLOOKUP($B14,Basic_Data!$E$2:$G$9,3,0)/VLOOKUP(F$13,Data_Entry!$C:$V,20,0),"") | G14: =IFERROR(VLOOKUP(G$13,Data_Entry!$C:$M,Data_Entry!$A2,0)/VLOOKUP($B14,Basic_Data!$E$2:$G$9,3,0)/VLOOKUP(G$13,Data_Entry!$C:$V,20,0),"") | H14: =IFERROR(VLOOKUP(H$13,Data_Entry!$C:$M,Data_Entry!$A2,0)/VLOOKUP($B14,Basic_Data!$E$2:$G$9,3,0)/VLOOKUP(H$13,Data_Entry!$C:$V,20,0),"") | I14: =IFERROR(VLOOKUP(I$13,Data_Entry!$C:$M,Data_Entry!$A2,0)/VLOOKUP($B14,Basic_Data!$E$2:$G$9,3,0)/VLOOKUP(I$13,Data_Entry!$C:$V,20,0),"") | J14: =IFERROR(VLOOKUP(J$13,Data_Entry!$C:$M,Data_Entry!$A2,0)/VLOOKUP($B14,Basic_Data!$E$2:$G$9,3,0)/VLOOKUP(J$13,Data_Entry!$C:$V,20,0),"") | ... AG14: =IFERROR(VLOOKUP(AG$13,Data_Entry!$C:$M,Data_Entry!$A2,0)/VLOOKUP($B14,Basic_Data!$E$2:$G$9,3,0)/VLOOKUP(AG$13,Data_Entry!$C:$V,20,0),"")
B15: Inv_2 | C15: =IFERROR(VLOOKUP(C$13,Data_Entry!$C:$M,Data_Entry!$A3,0)/VLOOKUP($B15,Basic_Data!$E$2:$G$9,3,0)/VLOOKUP(C$13,Data_Entry!$C:$V,20,0),"") -> 1.2559614 | D15: =IFERROR(VLOOKUP(D$13,Data_Entry!$C:$M,Data_Entry!$A3,0)/VLOOKUP($B15,Basic_Data!$E$2:$G$9,3,0)/VLOOKUP(D$13,Data_Entry!$C:$V,20,0),"") | E15: =IFERROR(VLOOKUP(E$13,Data_Entry!$C:$M,Data_Entry!$A3,0)/VLOOKUP($B15,Basic_Data!$E$2:$G$9,3,0)/VLOOKUP(E$13,Data_Entry!$C:$V,20,0),"") | F15: =IFERROR(VLOOKUP(F$13,Data_Entry!$C:$M,Data_Entry!$A3,0)/VLOOKUP($B15,Basic_Data!$E$2:$G$9,3,0)/VLOOKUP(F$13,Data_Entry!$C:$V,20,0),"") | G15: =IFERROR(VLOOKUP(G$13,Data_Entry!$C:$M,Data_Entry!$A3,0)/VLOOKUP($B15,Basic_Data!$E$2:$G$9,3,0)/VLOOKUP(G$13,Data_Entry!$C:$V,20,0),"") | H15: =IFERROR(VLOOKUP(H$13,Data_Entry!$C:$M,Data_Entry!$A3,0)/VLOOKUP($B15,Basic_Data!$E$2:$G$9,3,0)/VLOOKUP(H$13,Data_Entry!$C:$V,20,0),"") | I15: =IFERROR(VLOOKUP(I$13,Data_Entry!$C:$M,Data_Entry!$A3,0)/VLOOKUP($B15,Basic_Data!$E$2:$G$9,3,0)/VLOOKUP(I$13,Data_Entry!$C:$V,20,0),"") | J15: =IFERROR(VLOOKUP(J$13,Data_Entry!$C:$M,Data_Entry!$A3,0)/VLOOKUP($B15,Basic_Data!$E$2:$G$9,3,0)/VLOOKUP(J$13,Data_Entry!$C:$V,20,0),"") | ... AG15: =IFERROR(VLOOKUP(AG$13,Data_Entry!$C:$M,Data_Entry!$A3,0)/VLOOKUP($B15,Basic_Data!$E$2:$G$9,3,0)/VLOOKUP(AG$13,Data_Entry!$C:$V,20,0),"")
B16: Inv_3 | C16: =IFERROR(VLOOKUP(C$13,Data_Entry!$C:$M,Data_Entry!$A4,0)/VLOOKUP($B16,Basic_Data!$E$2:$G$9,3,0)/VLOOKUP(C$13,Data_Entry!$C:$V,20,0),"") -> 1.2538026 | D16: =IFERROR(VLOOKUP(D$13,Data_Entry!$C:$M,Data_Entry!$A4,0)/VLOOKUP($B16,Basic_Data!$E$2:$G$9,3,0)/VLOOKUP(D$13,Data_Entry!$C:$V,20,0),"") | E16: =IFERROR(VLOOKUP(E$13,Data_Entry!$C:$M,Data_Entry!$A4,0)/VLOOKUP($B16,Basic_Data!$E$2:$G$9,3,0)/VLOOKUP(E$13,Data_Entry!$C:$V,20,0),"") | F16: =IFERROR(VLOOKUP(F$13,Data_Entry!$C:$M,Data_Entry!$A4,0)/VLOOKUP($B16,Basic_Data!$E$2:$G$9,3,0)/VLOOKUP(F$13,Data_Entry!$C:$V,20,0),"") | G16: =IFERROR(VLOOKUP(G$13,Data_Entry!$C:$M,Data_Entry!$A4,0)/VLOOKUP($B16,Basic_Data!$E$2:$G$9,3,0)/VLOOKUP(G$13,Data_Entry!$C:$V,20,0),"") | H16: =IFERROR(VLOOKUP(H$13,Data_Entry!$C:$M,Data_Entry!$A4,0)/VLOOKUP($B16,Basic_Data!$E$2:$G$9,3,0)/VLOOKUP(H$13,Data_Entry!$C:$V,20,0),"") | I16: =IFERROR(VLOOKUP(I$13,Data_Entry!$C:$M,Data_Entry!$A4,0)/VLOOKUP($B16,Basic_Data!$E$2:$G$9,3,0)/VLOOKUP(I$13,Data_Entry!$C:$V,20,0),"") | J16: =IFERROR(VLOOKUP(J$13,Data_Entry!$C:$M,Data_Entry!$A4,0)/VLOOKUP($B16,Basic_Data!$E$2:$G$9,3,0)/VLOOKUP(J$13,Data_Entry!$C:$V,20,0),"") | ... AG16: =IFERROR(VLOOKUP(AG$13,Data_Entry!$C:$M,Data_Entry!$A4,0)/VLOOKUP($B16,Basic_Data!$E$2:$G$9,3,0)/VLOOKUP(AG$13,Data_Entry!$C:$V,20,0),"")
B17: Inv_4 | C17: =IFERROR(VLOOKUP(C$13,Data_Entry!$C:$M,Data_Entry!$A5,0)/VLOOKUP($B17,Basic_Data!$E$2:$G$9,3,0)/VLOOKUP(C$13,Data_Entry!$C:$V,20,0),"") -> 1.2460131 | D17: =IFERROR(VLOOKUP(D$13,Data_Entry!$C:$M,Data_Entry!$A5,0)/VLOOKUP($B17,Basic_Data!$E$2:$G$9,3,0)/VLOOKUP(D$13,Data_Entry!$C:$V,20,0),"") | E17: =IFERROR(VLOOKUP(E$13,Data_Entry!$C:$M,Data_Entry!$A5,0)/VLOOKUP($B17,Basic_Data!$E$2:$G$9,3,0)/VLOOKUP(E$13,Data_Entry!$C:$V,20,0),"") | F17: =IFERROR(VLOOKUP(F$13,Data_Entry!$C:$M,Data_Entry!$A5,0)/VLOOKUP($B17,Basic_Data!$E$2:$G$9,3,0)/VLOOKUP(F$13,Data_Entry!$C:$V,20,0),"") | G17: =IFERROR(VLOOKUP(G$13,Data_Entry!$C:$M,Data_Entry!$A5,0)/VLOOKUP($B17,Basic_Data!$E$2:$G$9,3,0)/VLOOKUP(G$13,Data_Entry!$C:$V,20,0),"") | H17: =IFERROR(VLOOKUP(H$13,Data_Entry!$C:$M,Data_Entry!$A5,0)/VLOOKUP($B17,Basic_Data!$E$2:$G$9,3,0)/VLOOKUP(H$13,Data_Entry!$C:$V,20,0),"") | I17: =IFERROR(VLOOKUP(I$13,Data_Entry!$C:$M,Data_Entry!$A5,0)/VLOOKUP($B17,Basic_Data!$E$2:$G$9,3,0)/VLOOKUP(I$13,Data_Entry!$C:$V,20,0),"") | J17: =IFERROR(VLOOKUP(J$13,Data_Entry!$C:$M,Data_Entry!$A5,0)/VLOOKUP($B17,Basic_Data!$E$2:$G$9,3,0)/VLOOKUP(J$13,Data_Entry!$C:$V,20,0),"") | ... AG17: =IFERROR(VLOOKUP(AG$13,Data_Entry!$C:$M,Data_Entry!$A5,0)/VLOOKUP($B17,Basic_Data!$E$2:$G$9,3,0)/VLOOKUP(AG$13,Data_Entry!$C:$V,20,0),"")
B18: Inv_5 | C18: =IFERROR(VLOOKUP(C$13,Data_Entry!$C:$M,Data_Entry!$A6,0)/VLOOKUP($B18,Basic_Data!$E$2:$G$9,3,0)/VLOOKUP(C$13,Data_Entry!$C:$V,20,0),"") -> 1.2417263 | D18: =IFERROR(VLOOKUP(D$13,Data_Entry!$C:$M,Data_Entry!$A6,0)/VLOOKUP($B18,Basic_Data!$E$2:$G$9,3,0)/VLOOKUP(D$13,Data_Entry!$C:$V,20,0),"") | E18: =IFERROR(VLOOKUP(E$13,Data_Entry!$C:$M,Data_Entry!$A6,0)/VLOOKUP($B18,Basic_Data!$E$2:$G$9,3,0)/VLOOKUP(E$13,Data_Entry!$C:$V,20,0),"") | F18: =IFERROR(VLOOKUP(F$13,Data_Entry!$C:$M,Data_Entry!$A6,0)/VLOOKUP($B18,Basic_Data!$E$2:$G$9,3,0)/VLOOKUP(F$13,Data_Entry!$C:$V,20,0),"") | G18: =IFERROR(VLOOKUP(G$13,Data_Entry!$C:$M,Data_Entry!$A6,0)/VLOOKUP($B18,Basic_Data!$E$2:$G$9,3,0)/VLOOKUP(G$13,Data_Entry!$C:$V,20,0),"") | H18: =IFERROR(VLOOKUP(H$13,Data_Entry!$C:$M,Data_Entry!$A6,0)/VLOOKUP($B18,Basic_Data!$E$2:$G$9,3,0)/VLOOKUP(H$13,Data_Entry!$C:$V,20,0),"") | I18: =IFERROR(VLOOKUP(I$13,Data_Entry!$C:$M,Data_Entry!$A6,0)/VLOOKUP($B18,Basic_Data!$E$2:$G$9,3,0)/VLOOKUP(I$13,Data_Entry!$C:$V,20,0),"") | J18: =IFERROR(VLOOKUP(J$13,Data_Entry!$C:$M,Data_Entry!$A6,0)/VLOOKUP($B18,Basic_Data!$E$2:$G$9,3,0)/VLOOKUP(J$13,Data_Entry!$C:$V,20,0),"") | ... AG18: =IFERROR(VLOOKUP(AG$13,Data_Entry!$C:$M,Data_Entry!$A6,0)/VLOOKUP($B18,Basic_Data!$E$2:$G$9,3,0)/VLOOKUP(AG$13,Data_Entry!$C:$V,20,0),"")
B19: Inv_6 | C19: =IFERROR(VLOOKUP(C$13,Data_Entry!$C:$M,Data_Entry!$A7,0)/VLOOKUP($B19,Basic_Data!$E$2:$G$9,3,0)/VLOOKUP(C$13,Data_Entry!$C:$V,20,0),"") -> 1.2431117 | D19: =IFERROR(VLOOKUP(D$13,Data_Entry!$C:$M,Data_Entry!$A7,0)/VLOOKUP($B19,Basic_Data!$E$2:$G$9,3,0)/VLOOKUP(D$13,Data_Entry!$C:$V,20,0),"") | E19: =IFERROR(VLOOKUP(E$13,Data_Entry!$C:$M,Data_Entry!$A7,0)/VLOOKUP($B19,Basic_Data!$E$2:$G$9,3,0)/VLOOKUP(E$13,Data_Entry!$C:$V,20,0),"") | F19: =IFERROR(VLOOKUP(F$13,Data_Entry!$C:$M,Data_Entry!$A7,0)/VLOOKUP($B19,Basic_Data!$E$2:$G$9,3,0)/VLOOKUP(F$13,Data_Entry!$C:$V,20,0),"") | G19: =IFERROR(VLOOKUP(G$13,Data_Entry!$C:$M,Data_Entry!$A7,0)/VLOOKUP($B19,Basic_Data!$E$2:$G$9,3,0)/VLOOKUP(G$13,Data_Entry!$C:$V,20,0),"") | H19: =IFERROR(VLOOKUP(H$13,Data_Entry!$C:$M,Data_Entry!$A7,0)/VLOOKUP($B19,Basic_Data!$E$2:$G$9,3,0)/VLOOKUP(H$13,Data_Entry!$C:$V,20,0),"") | I19: =IFERROR(VLOOKUP(I$13,Data_Entry!$C:$M,Data_Entry!$A7,0)/VLOOKUP($B19,Basic_Data!$E$2:$G$9,3,0)/VLOOKUP(I$13,Data_Entry!$C:$V,20,0),"") | J19: =IFERROR(VLOOKUP(J$13,Data_Entry!$C:$M,Data_Entry!$A7,0)/VLOOKUP($B19,Basic_Data!$E$2:$G$9,3,0)/VLOOKUP(J$13,Data_Entry!$C:$V,20,0),"") | ... AG19: =IFERROR(VLOOKUP(AG$13,Data_Entry!$C:$M,Data_Entry!$A7,0)/VLOOKUP($B19,Basic_Data!$E$2:$G$9,3,0)/VLOOKUP(AG$13,Data_Entry!$C:$V,20,0),"")
B20: Inv_7 | C20: =IFERROR(VLOOKUP(C$13,Data_Entry!$C:$M,Data_Entry!$A8,0)/VLOOKUP($B20,Basic_Data!$E$2:$G$9,3,0)/VLOOKUP(C$13,Data_Entry!$C:$V,20,0),"") -> 1.2430594 | D20: =IFERROR(VLOOKUP(D$13,Data_Entry!$C:$M,Data_Entry!$A8,0)/VLOOKUP($B20,Basic_Data!$E$2:$G$9,3,0)/VLOOKUP(D$13,Data_Entry!$C:$V,20,0),"") | E20: =IFERROR(VLOOKUP(E$13,Data_Entry!$C:$M,Data_Entry!$A8,0)/VLOOKUP($B20,Basic_Data!$E$2:$G$9,3,0)/VLOOKUP(E$13,Data_Entry!$C:$V,20,0),"") | F20: =IFERROR(VLOOKUP(F$13,Data_Entry!$C:$M,Data_Entry!$A8,0)/VLOOKUP($B20,Basic_Data!$E$2:$G$9,3,0)/VLOOKUP(F$13,Data_Entry!$C:$V,20,0),"") | G20: =IFERROR(VLOOKUP(G$13,Data_Entry!$C:$M,Data_Entry!$A8,0)/VLOOKUP($B20,Basic_Data!$E$2:$G$9,3,0)/VLOOKUP(G$13,Data_Entry!$C:$V,20,0),"") | H20: =IFERROR(VLOOKUP(H$13,Data_Entry!$C:$M,Data_Entry!$A8,0)/VLOOKUP($B20,Basic_Data!$E$2:$G$9,3,0)/VLOOKUP(H$13,Data_Entry!$C:$V,20,0),"") | I20: =IFERROR(VLOOKUP(I$13,Data_Entry!$C:$M,Data_Entry!$A8,0)/VLOOKUP($B20,Basic_Data!$E$2:$G$9,3,0)/VLOOKUP(I$13,Data_Entry!$C:$V,20,0),"") | J20: =IFERROR(VLOOKUP(J$13,Data_Entry!$C:$M,Data_Entry!$A8,0)/VLOOKUP($B20,Basic_Data!$E$2:$G$9,3,0)/VLOOKUP(J$13,Data_Entry!$C:$V,20,0),"") | ... AG20: =IFERROR(VLOOKUP(AG$13,Data_Entry!$C:$M,Data_Entry!$A8,0)/VLOOKUP($B20,Basic_Data!$E$2:$G$9,3,0)/VLOOKUP(AG$13,Data_Entry!$C:$V,20,0),"")
B21: Avg_PR% | C21: =AVERAGE(C14:C20) -> 1.2489898 | D21: =AVERAGE(D14:D20) -> #DIV/0! | E21: =AVERAGE(E14:E20) -> #DIV/0! | F21: =AVERAGE(F14:F20) -> #DIV/0! | G21: =AVERAGE(G14:G20) -> #DIV/0! | H21: =AVERAGE(H14:H20) -> #DIV/0! | I21: =AVERAGE(I14:I20) -> #DIV/0! | J21: =AVERAGE(J14:J20) -> #DIV/0! | ... AH21: =AVERAGE(AH14:AH20) -> #DIV/0!

Sheet Basic_Data
A2: Details_of_Plant | B2: Values | E2: Inverter_Name | F2: AC_Capacity_MW | G2: Connected_DC_MW | H2: No_Of_Module
A3: D.O.C(DD-MMM-YYY) | B3: 45745 | E3: Inv_1 | F3: 275 | G3: 335.72 | H3: =G3/0.545 -> 616 | I3: 2
A4: Plant_Name | B4: Devki Galol | E4: Inv_2 | F4: 275 | G4: 335.72 | H4: =G4/0.545 -> 616 | I4: 3
A5: Longitude_Of_Site | B5: 21.62 °N | E5: Inv_3 | F5: 275 | G5: 335.72 | H5: =G5/0.545 -> 616 | I5: 4
A6: Latitude_Of_Site | B6: 70.69 °E | E6: Inv_4 | F6: 275 | G6: 350.98 | H6: =G6/0.545 -> 644 | I6: 5
A7: DC_Capacity_(kWh) | B7: 2.411 | E7: Inv_5 | F7: 275 | G7: 350.98 | H7: =G7/0.545 -> 644 | I7: 6
A8: AC_Capacity_(kWh) | B8: 1.925 | E8: Inv_6 | F8: 275 | G8: 350.98 | H8: =G8/0.545 -> 644 | I8: 7
A9: Connected_DC_Capacity | B9: =SUM(G3:G94) -> 4822.16 | E9: Inv_7 | F9: 275 | G9: 350.98 | H9: =G9/0.545 -> 644 | I9: 8
A10: Multiplying_Factor_(MF) | B10: 3000 | E10: Total | F10: =SUM(F3:F9) -> 1925 | G10: =SUM(G3:G9) -> 2411.08 | H10: =SUM(H3:H9) -> 4424
A11: No._of_Power_Trafo. | B11: 1
A12: Power_Trafo._Make | B12: Gujrat_Trafo
A13: Inverter_Make | B13: Watt_power
A14: Inverter_Capacity | B14: 0.275
A15: No._of_Inverter | B15: 7
A16: Module_Make | B16: EMMVEE
A17: Module_Rating | B17: 545
A18: No._of_Strings/Table | B18: 158
A19: No._Of_Module_In_Table | B19: 28 for Bifacial
A20: Total_Module | B20: 4424
A21: Switch_Yard_Make_Vendors | B21: ABB
A22: Table_Configuration | B22: 2X28
A23: ABT Meter Make
A27: FY:Name | B27: From_FY | C27: To_FY
A28: 12-13 | B28: 41000 | C28: 41364 | D28: 365
A29: 13-14 | B29: 41365 | C29: 41729 | D29: 365
A30: 14-15 | B30: 41730 | C30: 42094 | D30: 365
A31: 15-16 | B31: 42095 | C31: 42460 | D31: 366
A32: 16-17 | B32: 42461 | C32: 42825 | D32: 365
A33: 17-18 | B33: 42826 | C33: 43190 | D33: 365
A34: 18-19 | B34: 43191 | C34: 43555 | D34: 365
A35: 19-20 | B35: 43556 | C35: 43921 | D35: 366
A36: 20-21 | B36: 43922 | C36: 44286 | D36: 365
A37: 21-22 | B37: 44287 | C37: 44651 | D37: 365
A38: 22-23 | B38: 44652 | C38: 45016 | D38: 365
A39: 23-24 | B39: 45017 | C39: 45382 | D39: 366
... A48: 32-33 | B48: 48305 | C48: 48669 | D48: 365

Sheet Plant_Down_Time Details
A1: Plant_Down_Time Details
