Workbook

Sheet Budgeted_Data
A1: Plant Name | B1: Date | C1: Month | D1: Month | E1: Daily_Gen | F1: Daily_GTI | G1: Daily_GHI | H1: Ambt_Temp | I1: PR_% | J1: CUF_% | K1: TArray | L1: TArrWtd | M1: Connected_DC
A2: Devki_Galol | B2: 45747 | M2: 2411
A3: Devki_Galol | B3: 45748 | E3: 14287.348 | F3: 6.91332 | G3: 6.707771 | H3: 27.415 | I3: 0.85717156 | J3: 0.24691255 | K3: 0 | L3: 21.811708 | M3: 2411
A4: Devki_Galol | B4: 45749 | E4: 14905.571 | F4: 7.241431 | G4: 7.025458 | H4: 26.8775 | I4: 0.85374271 | J4: 0.25759662 | K4: 0 | L4: 22.152667 | M4: 2411
A5: Devki_Galol | B5: 45750 | E5: 15554.62 | F5: 7.635258 | G5: 7.411582 | H5: 28.30125 | I5: 0.84496453 | J5: 0.26881342 | K5: 0 | L5: 23.39775 | M5: 2411
A6: Devki_Galol | B6: 45751 | E6: 15886.128 | F6: 7.804122 | G6: 7.578766 | H6: 28.33 | I6: 0.84430002 | J6: 0.27454251 | K6: 0 | L6: 23.414625 | M6: 2411
A7: Devki_Galol | B7: 45752 | E7: 11752.222 | F7: 5.715388 | G7: 5.503698 | H7: 31.082917 | I7: 0.85285865 | J7: 0.20310075 | K7: 0 | L7: 22.630708 | M7: 2411
A8: Devki_Galol | B8: 45753 | E8: 7771.589 | F8: 3.734185 | G8: 3.586375 | H8: 30.53375 | I8: 0.86321064 | J8: 0.13430784 | K8: 0 | L8: 18.429417 | M8: 2411
A9: Devki_Galol | B9: 45754 | E9: 12872.497 | F9: 6.305604 | G9: 6.099538 | H9: 31.335 | I9: 0.8467182 | J9: 0.22246124 | K9: 0 | L9: 23.464917 | M9: 2411
A10: Devki_Galol | B10: 45755 | E10: 14069.94 | F10: 6.904297 | G10: 6.687158 | H10: 30.85375 | I10: 0.8452313 | J10: 0.24315533 | K10: 0 | L10: 23.794875 | M10: 2411
A11: Devki_Galol | B11: 45756 | E11: 15120.66 | F11: 7.448638 | G11: 7.215121 | H11: 30.165833 | I11: 0.8419701 | J11: 0.26131377 | K11: 0 | L11: 24.040958 | M11: 2411
A12: Devki_Galol | B12: 45757 | E12: 14350.56 | F12: 7.092072 | G12: 6.870152 | H12: 31.859167 | I12: 0.83926382 | J12: 0.24800498 | K12: 0 | L12: 24.6445 | M12: 2411
A13: Devki_Galol | B13: 45758 | E13: 15262.67 | F13: 7.611885 | G13: 7.375544 | H13: 32.392917 | I13: 0.83165095 | J13: 0.26376797 | K13: 0 | L13: 25.622375 | M13: 2411
A14: Devki_Galol | B14: 45759 | E14: 15211.54 | F14: 7.477686 | G14: 7.245707 | H14: 29.71 | I14: 0.84374021 | J14: 0.26288435 | K14: 0 | L14: 23.86675 | M14: 2411
... A366: Devki_Galol | B366: 46111 | E366: 14156.897 | F366: 6.93562 | G366: 6.725163 | H366: 29.551667 | I366: 0.84661425 | J366: 0.24465811 | K366: 0 | L366: 23.354625 | M366: 2411
A367: Devki_Galol | B367: 46112 | E367: 14820.857 | F367: 7.348117 | G367: 7.130108 | H367: 30.895833 | I367: 0.83656568 | J367: 0.2561326 | K367: 0 | L367: 24.667625

Sheet Data_Entry
B1: Month | C1: Date | D1: Plant_Up_Time | E1: Plant_Down_Time | F1: Inv_1 | G1: Inv_2 | H1: Inv_3 | I1: Inv_4 | J1: Inv_5 | K1: Inv_6 | L1: Inv_7 | M1: Total Inv Gen kWh | N1: ABT_Initial_Export | O1: ABT_Final_Export | P1: Total_Export | Q1: ABT_Initial_Import | R1: ABT_Final_Import | S1: Total_Import | T1: Net_Gen_kWh | U1: GHI (kwh/m2) | V1: GTI (kwh/m2) | W1: Ambt_Temp_Avg | X1: Module_Temp_Avg | Y1: Wtd_Module_Temp | Z1: Wind Speed | AA1: Rain_Gaug_MM | AB1: Weather_Condition
A2: 4 | B2: 45747 | C2: 45747 | M2: =SUM(F2:L2) -> 0 | P2: =MAX((O2-N2)*3000,0) -> 0 | S2: =MAX((R2-Q2)*3000,0) -> 0 | T2: =P2-S2 -> 0
A3: =A2+1 -> 5 | B3: 45748 | C3: 45748 | F3: 1907.18 | G3: 1939.32 | H3: 1904.51 | I3: 2007.77 | J3: 2023.7 | K3: 2022.23 | L3: 2004.7 | M3: =SUM(F3:L3) -> 13809.41 | N3: 106.77 | O3: 111.31 | P3: =MAX((O3-N3)*3000,0) -> 13620 | Q3: 2.2 | R3: 2.21 | S3: =MAX((R3-Q3)*3000,0) -> 30 | T3: =P3-S3 -> 13590 | V3: 5.54
A4: =A3+1 -> 6 | B4: 45749 | C4: 45749 | F4: 1957.32 | G4: 1993 | H4: 1956.83 | I4: 2061.56 | J4: 2070.05 | K4: 2066.26 | L4: 2061.12 | M4: =SUM(F4:L4) -> 14166.14 | N4: 111.31 | O4: 115.99 | P4: =MAX((O4-N4)*3000,0) -> 14040 | Q4: 2.21 | R4: 2.23 | S4: =MAX((R4-Q4)*3000,0) -> 60 | T4: =P4-S4 -> 13980 | V4: 5.58
A5: =A4+1 -> 7 | B5: 45750 | C5: 45750 | F5: 1875.34 | G5: 1915.98 | H5: 1879.63 | I5: 1980.41 | J5: 1990.28 | K5: 1989.18 | L5: 1992.85 | M5: =SUM(F5:L5) -> 13623.67 | N5: 115.99 | O5: 120.46 | P5: =MAX((O5-N5)*3000,0) -> 13410 | Q5: 2.23 | R5: 2.24 | S5: =MAX((R5-Q5)*3000,0) -> 30 | T5: =P5-S5 -> 13380 | V5: 5.37
A6: =A5+1 -> 8 | B6: 45751 | C6: 45751 | F6: 1902.7 | G6: 1935.04 | H6: 1901.8 | I6: 2009.4 | J6: 2021.08 | K6: 2009.01 | L6: 2014.18 | M6: =SUM(F6:L6) -> 13793.21 | N6: 120.46 | O6: 125.04 | P6: =MAX((O6-N6)*3000,0) -> 13740 | Q6: 2.24 | R6: 2.25 | S6: =MAX((R6-Q6)*3000,0) -> 30 | T6: =P6-S6 -> 13710 | V6: 5.41
A7: =A6+1 -> 9 | B7: 45752 | C7: 45752 | F7: 1948.19 | G7: 1975.14 | H7: 1946 | I7: 2050.1 | J7: 2061.63 | K7: 2056.9 | L7: 2058.73 | M7: =SUM(F7:L7) -> 14096.69 | N7: 125.04 | O7: 129.79 | P7: =MAX((O7-N7)*3000,0) -> 14250 | Q7: 2.25 | R7: 2.26 | S7: =MAX((R7-Q7)*3000,0) -> 30 | T7: =P7-S7 -> 14220 | V7: 5.52
A8: =A7+1 -> 10 | B8: 45753 | C8: 45753 | F8: 1971.04 | G8: 1999.88 | H8: 1970.16 | I8: 2074.85 | J8: 2085.24 | K8: 2070.8 | L8: 2082.29 | M8: =SUM(F8:L8) -> 14254.26 | N8: 129.79 | O8: 134.39 | P8: =MAX((O8-N8)*3000,0) -> 13800 | Q8: 2.26 | R8: 2.27 | S8: =MAX((R8-Q8)*3000,0) -> 30 | T8: =P8-S8 -> 13770 | V8: 5.56
A9: =A8+1 -> 11 | B9: 45754 | C9: 45754 | F9: 1920.52 | G9: 1964.16 | H9: 1923.6 | I9: 2036.21 | J9: 2074.93 | K9: 2027.7 | L9: 2047.38 | M9: =SUM(F9:L9) -> 13994.5 | N9: 134.39 | O9: 139 | P9: =MAX((O9-N9)*3000,0) -> 13830 | Q9: 2.27 | R9: 2.28 | S9: =MAX((R9-Q9)*3000,0) -> 30 | T9: =P9-S9 -> 13800 | V9: 5.45
A10: =A9+1 -> 12 | B10: 45755 | C10: 45755 | F10: 1903.77 | G10: 1964.92 | H10: 1901.96 | I10: 2034.49 | J10: 2053.74 | K10: 2009.58 | L10: 2054.45 | M10: =SUM(F10:L10) -> 13922.91 | N10: 139 | O10: 143.61 | P10: =MAX((O10-N10)*3000,0) -> 13830 | Q10: 2.28 | R10: 2.29 | S10: =MAX((R10-Q10)*3000,0) -> 30 | T10: =P10-S10 -> 13800 | V10: 5.49
A11: =A10+1 -> 13 | B11: 45756 | C11: 45756 | F11: 1897.6 | G11: 1946.4 | H11: 1892.3 | I11: 2009.2 | J11: 2028.25 | K11: 2003.95 | L11: 2029.3 | M11: =SUM(F11:L11) -> 13807 | N11: 143.61 | O11: 148.16 | P11: =MAX((O11-N11)*3000,0) -> 13650 | Q11: 2.29 | R11: 2.3 | S11: =MAX((R11-Q11)*3000,0) -> 30 | T11: =P11-S11 -> 13620 | V11: 5.44
A12: =A11+1 -> 14 | B12: 45757 | C12: 45757 | F12: 1921.95 | G12: 1971.76 | H12: 1911.8 | I12: 2037.4 | J12: 2057.6 | K12: 2024.87 | L12: 2057.3 | M12: =SUM(F12:L12) -> 13982.68 | N12: =O11 -> 148.16 | O12: 152.8 | P12: =MAX((O12-N12)*3000,0) -> 13920 | Q12: =R11 -> 2.3 | R12: 2.32 | S12: =MAX((R12-Q12)*3000,0) -> 60 | T12: =P12-S12 -> 13860 | V12: 5.55
A13: =A12+1 -> 15 | B13: 45758 | C13: 45758 | F13: 1930.15 | G13: 1976.35 | H13: 1920.76 | I13: 2047.35 | J13: 2065.2 | K13: 2025.05 | L13: 2060.1 | M13: =SUM(F13:L13) -> 14024.96 | N13: =O12 -> 152.8 | O13: 157.43 | P13: =MAX((O13-N13)*3000,0) -> 13890 | Q13: =R12 -> 2.32 | R13: 2.33 | S13: =MAX((R13-Q13)*3000,0) -> 30 | T13: =P13-S13 -> 13860 | V13: 5.45
A14: =A13+1 -> 16 | B14: 45759 | C14: 45759 | F14: 1932.2 | G14: 1981.9 | H14: 1917.1 | I14: 2046.3 | J14: 2061.39 | K14: 2027.4 | L14: 2065.25 | M14: =SUM(F14:L14) -> 14031.54 | N14: =O13 -> 157.43 | O14: 162.07 | P14: =MAX((O14-N14)*3000,0) -> 13920 | Q14: =R13 -> 2.33 | R14: 2.34 | S14: =MAX((R14-Q14)*3000,0) -> 30 | T14: =P14-S14 -> 13890 | V14: 2.05
A15: =A14+1 -> 17 | B15: 45760 | C15: 45760 | F15: 2030.2 | G15: 2077.84 | H15: 2018.4 | I15: 2147.62 | J15: 2166.85 | K15: 2120.31 | L15: 2161.95 | M15: =SUM(F15:L15) -> 14723.17 | N15: =O14 -> 162.07 | O15: 166.91 | P15: =MAX((O15-N15)*3000,0) -> 14520 | Q15: =R14 -> 2.34 | R15: 2.35 | S15: =MAX((R15-Q15)*3000,0) -> 30 | T15: =P15-S15 -> 14490 | V15: 5.82 | AB15: sunny
A16: =A15+1 -> 18 | B16: 45761 | C16: 45761 | F16: 2109.55 | G16: 2135.49 | H16: 2000.86 | I16: 2245.16 | J16: 2289.4 | K16: 2235.85 | L16: 2329.39 | M16: =SUM(F16:L16) -> 15345.7 | N16: =O15 -> 166.91 | O16: 171.77 | P16: =MAX((O16-N16)*3000,0) -> 14580 | Q16: =R15 -> 2.35 | R16: 2.36 | S16: =MAX((R16-Q16)*3000,0) -> 30 | T16: =P16-S16 -> 14550 | V16: 5.75 | AB16: sunny
A17: =A16+1 -> 19 | B17: 45762 | C17: 45762 | F17: 1991.64 | G17: 2031.13 | H17: 1980.62 | I17: 2104.3 | J17: 2120.45 | K17: 2100.17 | L17: 2120.05 | M17: =SUM(F17:L17) -> 14448.36 | N17: =O16 -> 171.77 | O17: 176.53 | P17: =MAX((O17-N17)*3000,0) -> 14280 | Q17: =R16 -> 2.36 | R17: 2.37 | S17: =MAX((R17-Q17)*3000,0) -> 30 | T17: =P17-S17 -> 14250 | V17: 5.78 | AB17: sunny
A18: =A17+1 -> 20 | B18: 45763 | C18: 45763 | F18: 1978.28 | G18: 2020.18 | H18: 1968.1 | I18: 2089.42 | J18: 2102.49 | K18: 2078.15 | L18: 2097.84 | M18: =SUM(F18:L18) -> 14334.46 | N18: =O17 -> 176.53 | O18: 181.27 | P18: =MAX((O18-N18)*3000,0) -> 14220 | Q18: =R17 -> 2.37 | R18: 2.38 | S18: =MAX((R18-Q18)*3000,0) -> 30 | T18: =P18-S18 -> 14190 | V18: 5.39 | W18: 32.04 | AB18: sunny
A19: =A18+1 -> 21 | B19: 45764 | C19: 45764 | F19: 2055.86 | G19: 2095.44 | H19: 2047.4 | I19: 2161.11 | J19: 2175.87 | K19: 2149.63 | L19: 2165.43 | M19: =SUM(F19:L19) -> 14850.74 | N19: =O18 -> 181.27 | O19: 186.17 | P19: =MAX((O19-N19)*3000,0) -> 14700 | Q19: =R18 -> 2.38 | R19: 2.39 | S19: =MAX((R19-Q19)*3000,0) -> 30 | T19: =P19-S19 -> 14670 | AB19: sunny
A20: =A19+1 -> 22 | B20: 45765 | C20: 45765 | F20: 2020.17 | G20: 2064.25 | H20: 2010.12 | I20: 2130.49 | J20: 2147.19 | K20: 2112.04 | L20: 2137.09 | M20: =SUM(F20:L20) -> 14621.35 | N20: =O19 -> 186.17 | O20: 191.01 | P20: =MAX((O20-N20)*3000,0) -> 14520 | Q20: =R19 -> 2.39 | R20: 2.4 | S20: =MAX((R20-Q20)*3000,0) -> 30 | T20: =P20-S20 -> 14490 | V20: 5.74 | W20: 32.57 | AB20: sunny
A21: =A20+1 -> 23 | B21: 45766 | C21: 45766 | F21: 2022.37 | G21: 2062.45 | H21: 2011.8 | I21: 2137.56 | J21: 2150.1 | K21: 2122.31 | L21: 2146.2 | M21: =SUM(F21:L21) -> 14652.79 | N21: =O20 -> 191.01 | O21: 195.84 | P21: =MAX((O21-N21)*3000,0) -> 14490 | Q21: =R20 -> 2.4 | R21: 2.41 | S21: =MAX((R21-Q21)*3000,0) -> 30 | T21: =P21-S21 -> 14460 | V21: 5.79 | W21: 32.54 | AB21: sunny
A22: =A21+1 -> 24 | B22: 45767 | C22: 45767 | F22: 2028.35 | G22: 2071.3 | H22: 2019.75 | I22: 2145.57 | J22: 2157.59 | K22: 2129.99 | L22: 2151.68 | M22: =SUM(F22:L22) -> 14704.23 | N22: =O21 -> 195.84 | O22: 200.7 | P22: =MAX((O22-N22)*3000,0) -> 14580 | Q22: =R21 -> 2.41 | R22: 2.42 | S22: =MAX((R22-Q22)*3000,0) -> 30 | T22: =P22-S22 -> 14550 | V22: 5.79 | W22: 32.54 | AB22: sunny
A23: =A22+1 -> 25 | B23: 45768 | C23: 45768 | F23: 1952.39 | G23: 1992.37 | H23: 1946.21 | I23: 2065.1 | J23: 2075.12 | K23: 2048.19 | L23: 2072.52 | M23: =SUM(F23:L23) -> 14151.9 | N23: =O22 -> 200.7 | O23: 205.37 | P23: =MAX((O23-N23)*3000,0) -> 14010 | Q23: =R22 -> 2.42 | R23: 2.43 | S23: =MAX((R23-Q23)*3000,0) -> 30 | T23: =P23-S23 -> 13980 | V23: 5.62 | W23: 33.86 | AB23: sunny
A24: =A23+1 -> 26 | B24: 45769 | C24: 45769 | F24: 1980.8 | G24: 2032.01 | H24: 1973.63 | I24: 2123.46 | J24: 2127.85 | K24: 2070.41 | L24: 2156.24 | M24: =SUM(F24:L24) -> 14464.4 | N24: =O23 -> 205.37 | O24: 210.15 | P24: =MAX((O24-N24)*3000,0) -> 14340 | Q24: =R23 -> 2.43 | R24: 2.45 | S24: =MAX((R24-Q24)*3000,0) -> 60 | T24: =P24-S24 -> 14280 | V24: 5.69 | W24: 35.88 | AB24: sunny
A25: =A24+1 -> 27 | B25: 45770 | C25: 45770 | F25: 1705.1 | G25: 1771.69 | H25: 1680.18 | I25: 1835.74 | J25: 1846.94 | K25: 1791.65 | L25: 1853.57 | M25: =SUM(F25:L25) -> 12484.87 | N25: =O24 -> 210.15 | O25: 214.24 | P25: =MAX((O25-N25)*3000,0) -> 12270 | Q25: =R24 -> 2.45 | R25: 2.46 | S25: =MAX((R25-Q25)*3000,0) -> 30 | T25: =P25-S25 -> 12240 | V25: 5.01 | W25: 35.88 | AB25: sunny
A26: =A25+1 -> 28 | B26: 45771 | C26: 45771 | F26: 1798.55 | G26: 1819.95 | H26: 1766.97 | I26: 1885.19 | J26: 1897.64 | K26: 1899.92 | L26: 1902.58 | M26: =SUM(F26:L26) -> 12970.8 | N26: =O25 -> 214.24 | O26: 218.55 | P26: =MAX((O26-N26)*3000,0) -> 12930 | Q26: =R25 -> 2.46 | R26: 2.47 | S26: =MAX((R26-Q26)*3000,0) -> 30 | T26: =P26-S26 -> 12900 | V26: 5.26 | W26: 32.75 | AB26: sunny
A27: =A26+1 -> 29 | B27: 45772 | C27: 45772 | F27: 2070.27 | G27: 2088.85 | H27: 2062.27 | I27: 2160.95 | J27: 2173.7 | K27: 2168.64 | L27: 2170.25 | M27: =SUM(F27:L27) -> 14894.93 | N27: =O26 -> 218.55 | O27: 223.48 | P27: =MAX((O27-N27)*3000,0) -> 14790 | Q27: =R26 -> 2.47 | R27: 2.48 | S27: =MAX((R27-Q27)*3000,0) -> 30 | T27: =P27-S27 -> 14760 | V27: 5.61 | W27: 31.86 | AB27: sunny
A28: =A27+1 -> 30 | B28: 45773 | C28: 45773 | F28: 2100.76 | G28: 2109.04 | H28: 2086.42 | I28: 2160.95 | J28: 2194.72 | K28: 2202.69 | L28: 2195.02 | M28: =SUM(F28:L28) -> 15049.6 | N28: =O27 -> 223.48 | O28: 228.46 | P28: =MAX((O28-N28)*3000,0) -> 14940 | Q28: =R27 -> 2.48 | R28: 2.49 | S28: =MAX((R28-Q28)*3000,0) -> 30 | T28: =P28-S28 -> 14910 | V28: 5.68 | W28: 32.49 | AB28: sunny
A29: =A28+1 -> 31 | B29: 45774 | C29: 45774 | F29: 2078.31 | G29: 2080.32 | H29: 2074.81 | I29: 2163.68 | J29: 2189.77 | K29: 2198.39 | L29: 2212.3 | M29: =SUM(F29:L29) -> 14997.58 | N29: =O28 -> 228.46 | O29: 233.33 | P29: =MAX((O29-N29)*3000,0) -> 14610 | Q29: =R28 -> 2.49 | R29: 2.5 | S29: =MAX((R29-Q29)*3000,0) -> 30 | T29: =P29-S29 -> 14580 | V29: 5.77 | W29: 33.49 | AB29: sunny
A30: =A29+1 -> 32 | B30: 45775 | C30: 45775 | D30: 0.29166667 | E30: 0.78125 | F30: 2044.8 | G30: 2058.59 | H30: 2034.1 | I30: 2130.79 | J30: 2144.31 | K30: 2141.63 | L30: 2139.16 | M30: =SUM(F30:L30) -> 14693.38 | N30: =O29 -> 233.33 | O30: 238.21 | P30: =MAX((O30-N30)*3000,0) -> 14640 | Q30: =R29 -> 2.5 | R30: 2.51 | S30: =MAX((R30-Q30)*3000,0) -> 30 | T30: =P30-S30 -> 14610 | V30: 5.74 | W30: 34.14 | AB30: sunny
A31: =A30+1 -> 33 | B31: 45776 | C31: 45776 | D31: 0.28125 | E31: 0.78125 | F31: 2079.11 | G31: 2082.8 | H31: 2064.31 | I31: 2148.1 | J31: 2166.33 | K31: 2152.19 | L31: 2154.55 | M31: =SUM(F31:L31) -> 14847.39 | N31: =O30 -> 238.21 | O31: 243.13 | P31: =MAX((O31-N31)*3000,0) -> 14760 | Q31: =R30 -> 2.51 | R31: 2.52 | S31: =MAX((R31-Q31)*3000,0) -> 30 | T31: =P31-S31 -> 14730 | V31: 5.55 | W31: 37.01 | AB31: sunny
A32: =A31+1 -> 34 | B32: 45777 | C32: 45777 | D32: 0.28125 | E32: 0.78125 | F32: 2053.26 | G32: 2060.77 | H32: 2035.98 | I32: 2138.23 | J32: 2150.81 | K32: 2141.18 | L32: 2140.5 | M32: =SUM(F32:L32) -> 14720.73 | N32: =O31 -> 243.13 | O32: 248.02 | P32: =MAX((O32-N32)*3000,0) -> 14670 | Q32: =R31 -> 2.52 | R32: 2.53 | S32: =MAX((R32-Q32)*3000,0) -> 30 | T32: =P32-S32 -> 14640 | V32: 5.7 | W32: 33.92 | AB32: sunny
A33: =A32+1 -> 35 | B33: 45778 | C33: 45778 | D33: 0.28125 | E33: 0.78125 | F33: 2084.71 | G33: 2095.72 | H33: 2067.82 | I33: 2170.77 | J33: 2184.2 | K33: 2165.94 | L33: 2173.35 | M33: =SUM(F33:L33) -> 14942.51 | N33: =O32 -> 248.02 | O33: 252.96 | P33: =MAX((O33-N33)*3000,0) -> 14820 | Q33: =R32 -> 2.53 | R33: 2.54 | S33: =MAX((R33-Q33)*3000,0) -> 30 | T33: =P33-S33 -> 14790 | V33: 5.76 | W33: 34.66 | AB33: sunny
A34: =A33+1 -> 36 | B34: 45779 | C34: 45779 | D34: 0.28125 | E34: 0.78194444 | F34: 2155.08 | G34: 2159.61 | H34: 2035.18 | I34: 2224.39 | J34: 2232.17 | K34: 2208.1 | L34: 2210.45 | M34: =SUM(F34:L34) -> 15224.98 | N34: =O33 -> 252.96 | O34: 257.98 | P34: =MAX((O34-N34)*3000,0) -> 15060 | Q34: =R33 -> 2.54 | R34: 2.55 | S34: =MAX((R34-Q34)*3000,0) -> 30 | T34: =P34-S34 -> 15030 | V34: 5.91 | W34: 34.33 | AB34: sunny
A35: =A34+1 -> 37 | B35: 45780 | C35: 45780 | D35: 0.28125 | E35: 0.78194444 | F35: 1995.5 | G35: 2000.39 | H35: 1980.27 | I35: 2069.52 | J35: 2073.16 | K35: 2066.69 | L35: 2063.53 | M35: =SUM(F35:L35) -> 14249.06 | N35: =O34 -> 257.98 | O35: 262.68 | P35: =MAX((O35-N35)*3000,0) -> 14100 | Q35: =R34 -> 2.55 | R35: 2.56 | S35: =MAX((R35-Q35)*3000,0) -> 30 | T35: =P35-S35 -> 14070 | V35: 5.5 | W35: 31.78 | AB35: sunny
A36: =A35+1 -> 38 | B36: 45781 | C36: 45781 | D36: 0.28125 | E36: 0.78125 | F36: 1750.09 | G36: 1750.71 | H36: 1733.4 | I36: 1816.52 | J36: 1821.93 | K36: 1816.66 | L36: 1821.7 | M36: =SUM(F36:L36) -> 12511.01 | N36: =O35 -> 262.68 | O36: 266.83 | P36: =MAX((O36-N36)*3000,0) -> 12450 | Q36: =R35 -> 2.56 | R36: 2.57 | S36: =MAX((R36-Q36)*3000,0) -> 30 | T36: =P36-S36 -> 12420 | V36: 5.16 | W36: 32.01 | AB36: sunny
A37: =A36+1 -> 39 | B37: 45782 | C37: 45782 | D37: 0.28125 | E37: 0.78125 | F37: 1633.36 | G37: 1643.32 | H37: 1615.21 | I37: 1701.11 | J37: 1700.02 | K37: 1682.68 | L37: 1695.72 | M37: =SUM(F37:L37) -> 11671.42 | N37: =O36 -> 266.83 | O37: 270.69 | P37: =MAX((O37-N37)*3000,0) -> 11580 | Q37: =R36 -> 2.57 | R37: 2.58 | S37: =MAX((R37-Q37)*3000,0) -> 30 | T37: =P37-S37 -> 11550 | V37: 4.23 | W37: 31.68 | AB37: mostly cloudy
A38: =A37+1 -> 40 | B38: 45783 | C38: 45783 | D38: 0.58333333 | E38: 0.79166667 | F38: 386.75 | G38: 389.76 | H38: 383.31 | I38: 404.43 | J38: 403.57 | K38: 399.1 | L38: 402.66 | M38: =SUM(F38:L38) -> 2769.58 | N38: =O37 -> 270.69 | O38: 271.63 | P38: =MAX((O38-N38)*3000,0) -> 2820 | Q38: =R37 -> 2.58 | R38: 2.59 | S38: =MAX((R38-Q38)*3000,0) -> 30 | T38: =P38-S38 -> 2790 | V38: 1.44 | W38: 30.36 | AB38: cloudy
A39: =A38+1 -> 41 | B39: 45784 | C39: 45784 | D39: 0.28125 | E39: 0.78125 | F39: 956.61 | G39: 988.23 | H39: 978.43 | I39: 1053.59 | J39: 1041.57 | K39: 1066.45 | L39: 1069.71 | M39: =SUM(F39:L39) -> 7154.59 | N39: =O38 -> 271.63 | O39: 273.99 | P39: =MAX((O39-N39)*3000,0) -> 7080 | Q39: =R38 -> 2.59 | R39: 2.6 | S39: =MAX((R39-Q39)*3000,0) -> 30 | T39: =P39-S39 -> 7050 | V39: 3.33 | W39: 28.95 | AB39: rainy
A40: =A39+1 -> 42 | B40: 45785 | C40: 45785 | D40: 0.28125 | E40: 0.79166667 | F40: 1410.35 | G40: 1419.42 | H40: 1398.2 | I40: 1474.59 | J40: 1475.25 | K40: 1473.4 | L40: 1479.5 | M40: =SUM(F40:L40) -> 10130.71 | N40: =O39 -> 273.99 | O40: 277.97 | P40: =MAX((O40-N40)*3000,0) -> 11940 | Q40: =R39 -> 2.6 | R40: 2.62 | S40: =MAX((R40-Q40)*3000,0) -> 60 | T40: =P40-S40 -> 11880 | V40: 4.03 | W40: 30.19 | AB40: rainy
...

Sheet Inverter_PR
A1: Inverter_Availability_Sheet
C2: 335.72 | D2: 335.72 | E2: 335.72 | F2: 350.98 | G2: 350.98 | H2: 350.98 | I2: 350.98
C3: Inv_1 | D3: Inv_2 | E3: Inv_3 | F3: Inv_4 | G3: Inv_5 | H3: Inv_6 | I3: Inv_7
A4: 45747 | B4: 45747
A5: 45748 | B5: 45748 | C5: =IFERROR((Data_Entry!F3/Data_Entry!$V3/C$2),"") -> 1.0254269 | D5: =IFERROR((Data_Entry!G3/Data_Entry!$V3/D$2),"") -> 1.0427075 | E5: =IFERROR((Data_Entry!H3/Data_Entry!$V3/E$2),"") -> 1.0239913 | F5: =IFERROR((Data_Entry!I3/Data_Entry!$V3/F$2),"") -> 1.0325755 | G5: =IFERROR((Data_Entry!J3/Data_Entry!$V3/G$2),"") -> 1.0407682 | H5: =IFERROR((Data_Entry!K3/Data_Entry!$V3/H$2),"") -> 1.0400122 | I5: =IFERROR((Data_Entry!L3/Data_Entry!$V3/I$2),"") -> 1.0309967
A6: 45749 | B6: 45749 | C6: =IFERROR((Data_Entry!F4/Data_Entry!$V4/C$2),"") -> 1.0448415 | D6: =IFERROR((Data_Entry!G4/Data_Entry!$V4/D$2),"") -> 1.0638879 | E6: =IFERROR((Data_Entry!H4/Data_Entry!$V4/E$2),"") -> 1.0445799 | F6: =IFERROR((Data_Entry!I4/Data_Entry!$V4/F$2),"") -> 1.0526389 | G6: =IFERROR((Data_Entry!J4/Data_Entry!$V4/G$2),"") -> 1.0569739 | H6: =IFERROR((Data_Entry!K4/Data_Entry!$V4/H$2),"") -> 1.0550387 | I6: =IFERROR((Data_Entry!L4/Data_Entry!$V4/I$2),"") -> 1.0524142
A7: 45750 | B7: 45750 | C7: =IFERROR((Data_Entry!F5/Data_Entry!$V5/C$2),"") -> 1.0402279 | D7: =IFERROR((Data_Entry!G5/Data_Entry!$V5/D$2),"") -> 1.0627705 | E7: =IFERROR((Data_Entry!H5/Data_Entry!$V5/E$2),"") -> 1.0426076 | F7: =IFERROR((Data_Entry!I5/Data_Entry!$V5/F$2),"") -> 1.0507477 | G7: =IFERROR((Data_Entry!J5/Data_Entry!$V5/G$2),"") -> 1.0559845 | H7: =IFERROR((Data_Entry!K5/Data_Entry!$V5/H$2),"") -> 1.0554008 | I7: =IFERROR((Data_Entry!L5/Data_Entry!$V5/I$2),"") -> 1.057348
A8: 45751 | B8: 45751 | C8: =IFERROR((Data_Entry!F6/Data_Entry!$V6/C$2),"") -> 1.0476008 | D8: =IFERROR((Data_Entry!G6/Data_Entry!$V6/D$2),"") -> 1.0654068 | E8: =IFERROR((Data_Entry!H6/Data_Entry!$V6/E$2),"") -> 1.0471053 | F8: =IFERROR((Data_Entry!I6/Data_Entry!$V6/F$2),"") -> 1.0582463 | G8: =IFERROR((Data_Entry!J6/Data_Entry!$V6/G$2),"") -> 1.0643976 | H8: =IFERROR((Data_Entry!K6/Data_Entry!$V6/H$2),"") -> 1.0580409 | I8: =IFERROR((Data_Entry!L6/Data_Entry!$V6/I$2),"") -> 1.0607637
A9: 45752 | B9: 45752 | C9: =IFERROR((Data_Entry!F7/Data_Entry!$V7/C$2),"") -> 1.0512718 | D9: =IFERROR((Data_Entry!G7/Data_Entry!$V7/D$2),"") -> 1.0658144 | E9: =IFERROR((Data_Entry!H7/Data_Entry!$V7/E$2),"") -> 1.0500901 | F9: =IFERROR((Data_Entry!I7/Data_Entry!$V7/F$2),"") -> 1.0581655 | G9: =IFERROR((Data_Entry!J7/Data_Entry!$V7/G$2),"") -> 1.0641167 | H9: =IFERROR((Data_Entry!K7/Data_Entry!$V7/H$2),"") -> 1.0616753 | I9: =IFERROR((Data_Entry!L7/Data_Entry!$V7/I$2),"") -> 1.0626199
A10: 45753 | B10: 45753 | C10: =IFERROR((Data_Entry!F8/Data_Entry!$V8/C$2),"") -> 1.0559502 | D10: =IFERROR((Data_Entry!G8/Data_Entry!$V8/D$2),"") -> 1.0714007 | E10: =IFERROR((Data_Entry!H8/Data_Entry!$V8/E$2),"") -> 1.0554787 | F10: =IFERROR((Data_Entry!I8/Data_Entry!$V8/F$2),"") -> 1.0632357 | G10: =IFERROR((Data_Entry!J8/Data_Entry!$V8/G$2),"") -> 1.0685599 | H10: =IFERROR((Data_Entry!K8/Data_Entry!$V8/H$2),"") -> 1.0611603 | I10: =IFERROR((Data_Entry!L8/Data_Entry!$V8/I$2),"") -> 1.0670482
A11: 45754 | B11: 45754 | C11: =IFERROR((Data_Entry!F9/Data_Entry!$V9/C$2),"") -> 1.0496515 | D11: =IFERROR((Data_Entry!G9/Data_Entry!$V9/D$2),"") -> 1.0735027 | E11: =IFERROR((Data_Entry!H9/Data_Entry!$V9/E$2),"") -> 1.0513348 | F11: =IFERROR((Data_Entry!I9/Data_Entry!$V9/F$2),"") -> 1.0644952 | G11: =IFERROR((Data_Entry!J9/Data_Entry!$V9/G$2),"") -> 1.0847373 | H11: =IFERROR((Data_Entry!K9/Data_Entry!$V9/H$2),"") -> 1.0600463 | I11: =IFERROR((Data_Entry!L9/Data_Entry!$V9/I$2),"") -> 1.0703346
A12: 45755 | B12: 45755 | C12: =IFERROR((Data_Entry!F10/Data_Entry!$V10/C$2),"") -> 1.0329158 | D12: =IFERROR((Data_Entry!G10/Data_Entry!$V10/D$2),"") -> 1.0660935 | E12: =IFERROR((Data_Entry!H10/Data_Entry!$V10/E$2),"") -> 1.0319338 | F12: =IFERROR((Data_Entry!I10/Data_Entry!$V10/F$2),"") -> 1.0558466 | G12: =IFERROR((Data_Entry!J10/Data_Entry!$V10/G$2),"") -> 1.0658369 | H12: =IFERROR((Data_Entry!K10/Data_Entry!$V10/H$2),"") -> 1.042919 | I12: =IFERROR((Data_Entry!L10/Data_Entry!$V10/I$2),"") -> 1.0662054
A13: 45756 | B13: 45756 | C13: =IFERROR((Data_Entry!F11/Data_Entry!$V11/C$2),"") -> 1.0390311 | D13: =IFERROR((Data_Entry!G11/Data_Entry!$V11/D$2),"") -> 1.0657516 | E13: =IFERROR((Data_Entry!H11/Data_Entry!$V11/E$2),"") -> 1.0361291 | F13: =IFERROR((Data_Entry!I11/Data_Entry!$V11/F$2),"") -> 1.0523056 | G13: =IFERROR((Data_Entry!J11/Data_Entry!$V11/G$2),"") -> 1.062283 | H13: =IFERROR((Data_Entry!K11/Data_Entry!$V11/H$2),"") -> 1.049556 | I13: =IFERROR((Data_Entry!L11/Data_Entry!$V11/I$2),"") -> 1.0628329
A14: 45757 | B14: 45757 | C14: =IFERROR((Data_Entry!F12/Data_Entry!$V12/C$2),"") -> 1.0315063 | D14: =IFERROR((Data_Entry!G12/Data_Entry!$V12/D$2),"") -> 1.0582392 | E14: =IFERROR((Data_Entry!H12/Data_Entry!$V12/E$2),"") -> 1.0260588 | F14: =IFERROR((Data_Entry!I12/Data_Entry!$V12/F$2),"") -> 1.045926 | G14: =IFERROR((Data_Entry!J12/Data_Entry!$V12/G$2),"") -> 1.0562959 | H14: =IFERROR((Data_Entry!K12/Data_Entry!$V12/H$2),"") -> 1.0394935 | I14: =IFERROR((Data_Entry!L12/Data_Entry!$V12/I$2),"") -> 1.0561419
A15: 45758 | B15: 45758 | C15: =IFERROR((Data_Entry!F13/Data_Entry!$V13/C$2),"") -> 1.0549147 | D15: =IFERROR((Data_Entry!G13/Data_Entry!$V13/D$2),"") -> 1.0801651 | E15: =IFERROR((Data_Entry!H13/Data_Entry!$V13/E$2),"") -> 1.0497826 | F15: =IFERROR((Data_Entry!I13/Data_Entry!$V13/F$2),"") -> 1.070319 | G15: =IFERROR((Data_Entry!J13/Data_Entry!$V13/G$2),"") -> 1.0796506 | H15: =IFERROR((Data_Entry!K13/Data_Entry!$V13/H$2),"") -> 1.0586609 | I15: =IFERROR((Data_Entry!L13/Data_Entry!$V13/I$2),"") -> 1.0769844
A16: 45759 | B16: 45759 | C16: =IFERROR((Data_Entry!F14/Data_Entry!$V14/C$2),"") -> 2.807508 | D16: =IFERROR((Data_Entry!G14/Data_Entry!$V14/D$2),"") -> 2.8797226 | E16: =IFERROR((Data_Entry!H14/Data_Entry!$V14/E$2),"") -> 2.7855675 | F16: =IFERROR((Data_Entry!I14/Data_Entry!$V14/F$2),"") -> 2.8440228 | G16: =IFERROR((Data_Entry!J14/Data_Entry!$V14/G$2),"") -> 2.8649954 | H16: =IFERROR((Data_Entry!K14/Data_Entry!$V14/H$2),"") -> 2.8177549 | I16: =IFERROR((Data_Entry!L14/Data_Entry!$V14/I$2),"") -> 2.8703602
... A70: 45813 | B70: 45813 | C70: =IFERROR((Data_Entry!F68/Data_Entry!$V68/C$2),"") -> 1.0172508 | D70: =IFERROR((Data_Entry!G68/Data_Entry!$V68/D$2),"") -> 1.0195076 | E70: =IFERROR((Data_Entry!H68/Data_Entry!$V68/E$2),"") -> 1.0070188 | F70: =IFERROR((Data_Entry!I68/Data_Entry!$V68/F$2),"") -> 1.0121333 | G70: =IFERROR((Data_Entry!J68/Data_Entry!$V68/G$2),"") -> 1.0166082 | H70: =IFERROR((Data_Entry!K68/Data_Entry!$V68/H$2),"") -> 1.0132371 | I70: =IFERROR((Data_Entry!L68/Data_Entry!$V68/I$2),"") -> 1.0180709
A71: 45814 | B71: 45814 | C71: =IFERROR((Data_Entry!F69/Data_Entry!$V69/C$2),"") -> 1.0073058 | D71: =IFERROR((Data_Entry!G69/Data_Entry!$V69/D$2),"") -> 1.0123181 | E71: =IFERROR((Data_Entry!I69/Data_Entry!$V69/E$2),"") -> 1.0503709 | F71: =IFERROR((Data_Entry!J69/Data_Entry!$V69/F$2),"") -> 1.0108815 | G71: =IFERROR((Data_Entry!K69/Data_Entry!$V69/G$2),"") -> 1.0043307 | H71: =IFERROR((Data_Entry!L69/Data_Entry!$V69/H$2),"") -> 1.0128096 | I71: =IFERROR((Data_Entry!#REF!/Data_Entry!$V69/I$2),"")
A72: 45815 | B72: 45815 | C72: =IFERROR((Data_Entry!F70/Data_Entry!$V70/C$2),"") -> 0.97047296 | D72: =IFERROR((Data_Entry!G70/Data_Entry!$V70/D$2),"") -> 0.97349668 | E72: =IFERROR((Data_Entry!H70/Data_Entry!$V70/E$2),"") -> 0.96415525 | F72: =IFERROR((Data_Entry!I70/Data_Entry!$V70/F$2),"") -> 0.96677723 | G72: =IFERROR((Data_Entry!J70/Data_Entry!$V70/G$2),"") -> 0.97285257 | H72: =IFERROR((Data_Entry!K70/Data_Entry!$V70/H$2),"") -> 0.96705191 | I72: =IFERROR((Data_Entry!L70/Data_Entry!$V70/I$2),"") -> 0.97377357
A73: 45816 | B73: 45816 | C73: =IFERROR((Data_Entry!F71/Data_Entry!$V71/C$2),"") -> 0.95181307 | D73: =IFERROR((Data_Entry!G71/Data_Entry!$V71/D$2),"") -> 0.95384123 | E73: =IFERROR((Data_Entry!H71/Data_Entry!$V71/E$2),"") -> 0.9469031 | F73: =IFERROR((Data_Entry!I71/Data_Entry!$V71/F$2),"") -> 0.94635717 | G73: =IFERROR((Data_Entry!J71/Data_Entry!$V71/G$2),"") -> 0.95059617 | H73: =IFERROR((Data_Entry!K71/Data_Entry!$V71/H$2),"") -> 0.94572595 | I73: =IFERROR((Data_Entry!L71/Data_Entry!$V71/I$2),"") -> 0.94983755
A74: 45817 | B74: 45817 | C74: =IFERROR((Data_Entry!F72/Data_Entry!$V72/C$2),"") -> 0.99383523 | D74: =IFERROR((Data_Entry!G72/Data_Entry!$V72/D$2),"") -> 0.9972294 | E74: =IFERROR((Data_Entry!H72/Data_Entry!$V72/E$2),"") -> 0.98482366 | F74: =IFERROR((Data_Entry!I72/Data_Entry!$V72/F$2),"") -> 0.98743704 | G74: =IFERROR((Data_Entry!J72/Data_Entry!$V72/G$2),"") -> 0.99178821 | H74: =IFERROR((Data_Entry!K72/Data_Entry!$V72/H$2),"") -> 0.98125869 | I74: =IFERROR((Data_Entry!L72/Data_Entry!$V72/I$2),"") -> 0.99192757
A75: 45818 | B75: 45818 | C75: =IFERROR((Data_Entry!F73/Data_Entry!$V73/C$2),"") -> 1.0467094 | D75: =IFERROR((Data_Entry!G73/Data_Entry!$V73/D$2),"") -> 1.0366603 | E75: =IFERROR((Data_Entry!H73/Data_Entry!$V73/E$2),"") -> 1.0358951 | F75: =IFERROR((Data_Entry!I73/Data_Entry!$V73/F$2),"") -> 1.0411249 | G75: =IFERROR((Data_Entry!J73/Data_Entry!$V73/G$2),"") -> 1.0449359 | H75: =IFERROR((Data_Entry!K73/Data_Entry!$V73/H$2),"") -> 1.0305993 | I75: =IFERROR((Data_Entry!L73/Data_Entry!$V73/I$2),"") -> 1.0467204
A76: 45819 | B76: 45819 | C76: =IFERROR((Data_Entry!F74/Data_Entry!$V74/C$2),"") -> 1.040158 | D76: =IFERROR((Data_Entry!G74/Data_Entry!$V74/D$2),"") -> 1.0555227 | E76: =IFERROR((Data_Entry!H74/Data_Entry!$V74/E$2),"") -> 1.0292886 | F76: =IFERROR((Data_Entry!I74/Data_Entry!$V74/F$2),"") -> 1.0613206 | G76: =IFERROR((Data_Entry!J74/Data_Entry!$V74/G$2),"") -> 0.99707059 | H76: =IFERROR((Data_Entry!K74/Data_Entry!$V74/H$2),"") -> 1.0271044 | I76: =IFERROR((Data_Entry!L74/Data_Entry!$V74/I$2),"") -> 1.0909819
A77: 45820 | B77: 45820 | C77: =IFERROR((Data_Entry!F75/Data_Entry!$V75/C$2),"") -> 0.97229545 | D77: =IFERROR((Data_Entry!G75/Data_Entry!$V75/D$2),"") -> 1.0024862 | E77: =IFERROR((Data_Entry!H75/Data_Entry!$V75/E$2),"") -> 0.96978106 | F77: =IFERROR((Data_Entry!I75/Data_Entry!$V75/F$2),"") -> 0.99420293 | G77: =IFERROR((Data_Entry!J75/Data_Entry!$V75/G$2),"") -> 1.0009913 | H77: =IFERROR((Data_Entry!K75/Data_Entry!$V75/H$2),"") -> 0.98996955 | I77: =IFERROR((Data_Entry!L75/Data_Entry!$V75/I$2),"") -> 1.003033
A78: 45821 | B78: 45821 | C78: =IFERROR((Data_Entry!F76/Data_Entry!$V76/C$2),"") -> 0.96503188 | D78: =IFERROR((Data_Entry!G76/Data_Entry!$V76/D$2),"") -> 0.97118006 | E78: =IFERROR((Data_Entry!H76/Data_Entry!$V76/E$2),"") -> 0.96066758 | F78: =IFERROR((Data_Entry!I76/Data_Entry!$V76/F$2),"") -> 0.96568446 | G78: =IFERROR((Data_Entry!J76/Data_Entry!$V76/G$2),"") -> 0.96970822 | H78: =IFERROR((Data_Entry!K76/Data_Entry!$V76/H$2),"") -> 0.97454942 | I78: =IFERROR((Data_Entry!L76/Data_Entry!$V76/I$2),"") -> 0.97450973
A79: 45822 | B79: 45822 | C79: =IFERROR((Data_Entry!F77/Data_Entry!$V77/C$2),"") -> 0.9629118 | D79: =IFERROR((Data_Entry!G77/Data_Entry!$V77/D$2),"") -> 0.96571051 | E79: =IFERROR((Data_Entry!H77/Data_Entry!$V77/E$2),"") -> 0.95519207 | F79: =IFERROR((Data_Entry!I77/Data_Entry!$V77/F$2),"") -> 0.95774094 | G79: =IFERROR((Data_Entry!J77/Data_Entry!$V77/G$2),"") -> 0.96031706 | H79: =IFERROR((Data_Entry!K77/Data_Entry!$V77/H$2),"") -> 0.95960477 | I79: =IFERROR((Data_Entry!L77/Data_Entry!$V77/I$2),"") -> 0.96285163
A80: 45823 | B80: 45823 | C80: =IFERROR((Data_Entry!F78/Data_Entry!$V78/C$2),"") -> 0.69826359 | D80: =IFERROR((Data_Entry!G78/Data_Entry!$V78/D$2),"") -> 0.70152315 | E80: =IFERROR((Data_Entry!H78/Data_Entry!$V78/E$2),"") -> 0.69278309 | F80: =IFERROR((Data_Entry!I78/Data_Entry!$V78/F$2),"") -> 0.69720197 | G80: =IFERROR((Data_Entry!J78/Data_Entry!$V78/G$2),"") -> 0.69892022 | H80: =IFERROR((Data_Entry!K78/Data_Entry!$V78/H$2),"") -> 0.69951379 | I80: =IFERROR((Data_Entry!L78/Data_Entry!$V78/I$2),"") -> 0.701357
A81: 45824 | B81: 45824 | C81: =IFERROR((Data_Entry!F79/Data_Entry!$V79/C$2),"") -> 1.2718932 | D81: =IFERROR((Data_Entry!G79/Data_Entry!$V79/D$2),"") -> 1.2310984 | E81: =IFERROR((Data_Entry!H79/Data_Entry!$V79/E$2),"") -> 1.2191189 | F81: =IFERROR((Data_Entry!I79/Data_Entry!$V79/F$2),"") -> 1.3083243 | G81: =IFERROR((Data_Entry!J79/Data_Entry!$V79/G$2),"") -> 1.3601048 | H81: =IFERROR((Data_Entry!K79/Data_Entry!$V79/H$2),"") -> 1.3836413 | I81: =IFERROR((Data_Entry!L79/Data_Entry!$V79/I$2),"") -> 1.3952857
A82: 45825 | B82: 45825 | C82: =IFERROR((Data_Entry!F80/Data_Entry!$V80/C$2),"") -> 1.0991302 | D82: =IFERROR((Data_Entry!G80/Data_Entry!$V80/D$2),"") -> 1.1054795 | E82: =IFERROR((Data_Entry!H80/Data_Entry!$V80/E$2),"") -> 1.0912524 | F82: =IFERROR((Data_Entry!I80/Data_Entry!$V80/F$2),"") -> 1.0897682 | G82: =IFERROR((Data_Entry!J80/Data_Entry!$V80/G$2),"") -> 1.0855694 | H82: =IFERROR((Data_Entry!K80/Data_Entry!$V80/H$2),"") -> 1.105776 | I82: =IFERROR((Data_Entry!L80/Data_Entry!$V80/I$2),"") -> 1.1033767
A83: 45826 | B83: 45826 | C83: =IFERROR((Data_Entry!F81/Data_Entry!$V81/C$2),"") -> 1.0934659 | D83: =IFERROR((Data_Entry!G81/Data_Entry!$V81/D$2),"") -> 1.0862145 | E83: =IFERROR((Data_Entry!H81/Data_Entry!$V81/E$2),"") -> 1.0827231 | F83: =IFERROR((Data_Entry!I81/Data_Entry!$V81/F$2),"") -> 1.0634392 | G83: =IFERROR((Data_Entry!J81/Data_Entry!$V81/G$2),"") -> 1.0493802 | H83: =IFERROR((Data_Entry!K81/Data_Entry!$V81/H$2),"") -> 1.055896 | I83: =IFERROR((Data_Entry!L81/Data_Entry!$V81/I$2),"") -> 1.0954573
... A98: 45841 | B98: 45841 | C98: =IFERROR((Data_Entry!F96/Data_Entry!$V96/C$2),"") -> 2.0326172 | D98: =IFERROR((Data_Entry!G96/Data_Entry!$V96/D$2),"") -> 2.0029031 | E98: =IFERROR((Data_Entry!H96/Data_Entry!$V96/E$2),"") -> 2.0010869 | F98: =IFERROR((Data_Entry!I96/Data_Entry!$V96/F$2),"") -> 2.0354158 | G98: =IFERROR((Data_Entry!J96/Data_Entry!$V96/G$2),"") -> 2.0193632 | H98: =IFERROR((Data_Entry!K96/Data_Entry!$V96/H$2),"") -> 2.0345819 | I98: =IFERROR((Data_Entry!L96/Data_Entry!$V96/I$2),"") -> 2.0315243
A99: 45842 | B99: 45842 | C99: =IFERROR((Data_Entry!F97/Data_Entry!$V97/C$2),"") -> 2.6621714 | D99: =IFERROR((Data_Entry!G97/Data_Entry!$V97/D$2),"") -> 2.6844422 | E99: =IFERROR((Data_Entry!H97/Data_Entry!$V97/E$2),"") -> 2.6699644 | F99: =IFERROR((Data_Entry!I97/Data_Entry!$V97/F$2),"") -> 2.6767244 | G99: =IFERROR((Data_Entry!K97/Data_Entry!$V97/G$2),"") -> 2.7080653 | H99: =IFERROR((Data_Entry!L97/Data_Entry!$V97/H$2),"") -> 2.7063756 | I99: =IFERROR((Data_Entry!#REF!/Data_Entry!$V97/I$2),"")
A100: 45843 | B100: 45843 | C100: =IFERROR((Data_Entry!F98/Data_Entry!$V98/C$2),"") -> 1.895015 | D100: =IFERROR((Data_Entry!G98/Data_Entry!$V98/D$2),"") -> 2.0921039 | E100: =IFERROR((Data_Entry!H98/Data_Entry!$V98/E$2),"") -> 2.0693777 | F100: =IFERROR((Data_Entry!I98/Data_Entry!$V98/F$2),"") -> 2.0818956 | G100: =IFERROR((Data_Entry!J98/Data_Entry!$V98/G$2),"") -> 2.0702087 | H100: =IFERROR((Data_Entry!K98/Data_Entry!$V98/H$2),"") -> 2.0946377 | I100: =IFERROR((Data_Entry!L98/Data_Entry!$V98/I$2),"") -> 2.0936088
A101: 45844 | B101: 45844 | C101: =IFERROR((Data_Entry!F99/Data_Entry!$V99/C$2),"") -> 5.830938 | D101: =IFERROR((Data_Entry!G99/Data_Entry!$V99/D$2),"") -> 5.8270905 | E101: =IFERROR((Data_Entry!H99/Data_Entry!$V99/E$2),"") -> 5.7862579 | F101: =IFERROR((Data_Entry!I99/Data_Entry!$V99/F$2),"") -> 5.7933619 | G101: =IFERROR((Data_Entry!J99/Data_Entry!$V99/G$2),"") -> 5.7892069 | H101: =IFERROR((Data_Entry!K99/Data_Entry!$V99/H$2),"") -> 5.8381176 | I101: =IFERROR((Data_Entry!L99/Data_Entry!$V99/I$2),"") -> 5.8320037
A102: 45845 | B102: 45845 | C102: =IFERROR((Data_Entry!F100/Data_Entry!$V100/C$2),"") -> 5.241802 | D102: =IFERROR((Data_Entry!G100/Data_Entry!$V100/D$2),"") -> 5.9054944 | E102: =IFERROR((Data_Entry!H100/Data_Entry!$V100/E$2),"") -> 5.8662201 | F102: =IFERROR((Data_Entry!I100/Data_Entry!$V100/F$2),"") -> 5.8941841 | G102: =IFERROR((Data_Entry!J100/Data_Entry!$V100/G$2),"") -> 5.874451 | H102: =IFERROR((Data_Entry!K100/Data_Entry!$V100/H$2),"") -> 5.934178 | I102: =IFERROR((Data_Entry!L100/Data_Entry!$V100/I$2),"") -> 5.9196156
A103: 45846 | B103: 45846 | C103: =IFERROR((Data_Entry!F101/Data_Entry!$V101/C$2),"") -> 8.5288501 | D103: =IFERROR((Data_Entry!G101/Data_Entry!$V101/D$2),"") -> 8.5426678 | E103: =IFERROR((Data_Entry!H101/Data_Entry!$V101/E$2),"") -> 8.5078339 | F103: =IFERROR((Data_Entry!I101/Data_Entry!$V101/F$2),"") -> 8.5212991 | G103: =IFERROR((Data_Entry!J101/Data_Entry!$V101/G$2),"") -> 8.5360989 | H103: =IFERROR((Data_Entry!K101/Data_Entry!$V101/H$2),"") -> 8.5667274 | I103: =IFERROR((Data_Entry!L101/Data_Entry!$V101/I$2),"") -> 8.5304797
A104: 45847 | B104: 45847 | C104: =IFERROR((Data_Entry!F102/Data_Entry!$V102/C$2),"") | D104: =IFERROR((Data_Entry!G102/Data_Entry!$V102/D$2),"") | E104: =IFERROR((Data_Entry!H102/Data_Entry!$V102/E$2),"") | F104: =IFERROR((Data_Entry!I102/Data_Entry!$V102/F$2),"") | G104: =IFERROR((Data_Entry!J102/Data_Entry!$V102/G$2),"") | H104: =IFERROR((Data_Entry!K102/Data_Entry!$V102/H$2),"") | I104: =IFERROR((Data_Entry!L102/Data_Entry!$V102/I$2),"")
A105: 45848 | B105: 45848 | C105: =IFERROR((Data_Entry!F103/Data_Entry!$V103/C$2),"") | D105: =IFERROR((Data_Entry!G103/Data_Entry!$V103/D$2),"") | E105: =IFERROR((Data_Entry!H103/Data_Entry!$V103/E$2),"") | F105: =IFERROR((Data_Entry!I103/Data_Entry!$V103/F$2),"") | G105: =IFERROR((Data_Entry!J103/Data_Entry!$V103/G$2),"") | H105: =IFERROR((Data_Entry!K103/Data_Entry!$V103/H$2),"") | I105: =IFERROR((Data_Entry!L103/Data_Entry!$V103/I$2),"")
A106: 45849 | B106: 45849 | C106: =IFERROR((Data_Entry!F104/Data_Entry!$V104/C$2),"") -> 1.7805802 | D106: =IFERROR((Data_Entry!G104/Data_Entry!$V104/D$2),"") -> 1.7860936 | E106: =IFERROR((Data_Entry!H104/Data_Entry!$V104/E$2),"") -> 1.7670375 | F106: =IFERROR((Data_Entry!I104/Data_Entry!$V104/F$2),"") -> 1.7711366 | G106: =IFERROR((Data_Entry!J104/Data_Entry!$V104/G$2),"") -> 1.7637748 | H106: =IFERROR((Data_Entry!K104/Data_Entry!$V104/H$2),"") -> 1.7888333 | I106: =IFERROR((Data_Entry!L104/Data_Entry!$V104/I$2),"") -> 1.7853648
A107: 45850 | B107: 45850 | C107: =IFERROR((Data_Entry!F105/Data_Entry!$V105/C$2),"") -> 1.1030836 | D107: =IFERROR((Data_Entry!G105/Data_Entry!$V105/D$2),"") -> 1.1030562 | E107: =IFERROR((Data_Entry!H105/Data_Entry!$V105/E$2),"") -> 1.091433 | F107: =IFERROR((Data_Entry!I105/Data_Entry!$V105/F$2),"") -> 1.091422 | G107: =IFERROR((Data_Entry!J105/Data_Entry!$V105/G$2),"") -> 1.0846693 | H107: =IFERROR((Data_Entry!K105/Data_Entry!$V105/H$2),"") -> 1.1004574 | I107: =IFERROR((Data_Entry!L105/Data_Entry!$V105/I$2),"") -> 1.09631
...

Sheet DGR
A1: Daily_Generation_&_Performance_Report
A3: Inverter_No. | B3: ='E-Mail_Copy'!B4 -> 46178 | C3: =B3+1 -> 46179 | D3: =C3+1 -> 46180 | E3: =D3+1 -> 46181 | F3: =E3+1 -> 46182 | G3: =F3+1 -> 46183 | H3: =G3+1 -> 46184 | I3: =H3+1 -> 46185 | J3: =I3+1 -> 46186 | ... AF3: =AE3+1 -> 46208 | AG3: Total/Avg..
A4: Inv_1 | B4: =IFERROR(VLOOKUP(B$3,Data_Entry!$C:$AB,Data_Entry!$A2,0),"") -> 1580.3 | C4: =IFERROR(VLOOKUP(C$3,Data_Entry!$C:$AB,Data_Entry!$A2,0),"") -> 0 | D4: =IFERROR(VLOOKUP(D$3,Data_Entry!$C:$AB,Data_Entry!$A2,0),"") -> 0 | E4: =IFERROR(VLOOKUP(E$3,Data_Entry!$C:$AB,Data_Entry!$A2,0),"") -> 0 | F4: =IFERROR(VLOOKUP(F$3,Data_Entry!$C:$AB,Data_Entry!$A2,0),"") -> 0 | G4: =IFERROR(VLOOKUP(G$3,Data_Entry!$C:$AB,Data_Entry!$A2,0),"") -> 0 | H4: =IFERROR(VLOOKUP(H$3,Data_Entry!$C:$AB,Data_Entry!$A2,0),"") -> 0 | I4: =IFERROR(VLOOKUP(I$3,Data_Entry!$C:$AB,Data_Entry!$A2,0),"") -> 0 | ... AF4: =IFERROR(VLOOKUP(AF$3,Data_Entry!$C:$AB,Data_Entry!$A2,0),"") -> 0 | AG4: =IFERROR(SUM(B4:AF4),"") -> 1580.3
A5: Inv_2 | B5: =IFERROR(VLOOKUP(B$3,Data_Entry!$C:$AB,Data_Entry!$A3,0),"") -> 1583.54 | C5: =IFERROR(VLOOKUP(C$3,Data_Entry!$C:$AB,Data_Entry!$A3,0),"") -> 0 | D5: =IFERROR(VLOOKUP(D$3,Data_Entry!$C:$AB,Data_Entry!$A3,0),"") -> 0 | E5: =IFERROR(VLOOKUP(E$3,Data_Entry!$C:$AB,Data_Entry!$A3,0),"") -> 0 | F5: =IFERROR(VLOOKUP(F$3,Data_Entry!$C:$AB,Data_Entry!$A3,0),"") -> 0 | G5: =IFERROR(VLOOKUP(G$3,Data_Entry!$C:$AB,Data_Entry!$A3,0),"") -> 0 | H5: =IFERROR(VLOOKUP(H$3,Data_Entry!$C:$AB,Data_Entry!$A3,0),"") -> 0 | I5: =IFERROR(VLOOKUP(I$3,Data_Entry!$C:$AB,Data_Entry!$A3,0),"") -> 0 | ... AF5: =IFERROR(VLOOKUP(AF$3,Data_Entry!$C:$AB,Data_Entry!$A3,0),"") -> 0 | AG5: =IFERROR(SUM(B5:AF5),"") -> 1583.54
A6: Inv_3 | B6: =IFERROR(VLOOKUP(B$3,Data_Entry!$C:$AB,Data_Entry!$A4,0),"") -> 1563.5 | C6: =IFERROR(VLOOKUP(C$3,Data_Entry!$C:$AB,Data_Entry!$A4,0),"") -> 0 | D6: =IFERROR(VLOOKUP(D$3,Data_Entry!$C:$AB,Data_Entry!$A4,0),"") -> 0 | E6: =IFERROR(VLOOKUP(E$3,Data_Entry!$C:$AB,Data_Entry!$A4,0),"") -> 0 | F6: =IFERROR(VLOOKUP(F$3,Data_Entry!$C:$AB,Data_Entry!$A4,0),"") -> 0 | G6: =IFERROR(VLOOKUP(G$3,Data_Entry!$C:$AB,Data_Entry!$A4,0),"") -> 0 | H6: =IFERROR(VLOOKUP(H$3,Data_Entry!$C:$AB,Data_Entry!$A4,0),"") -> 0 | I6: =IFERROR(VLOOKUP(I$3,Data_Entry!$C:$AB,Data_Entry!$A4,0),"") -> 0 | ... AF6: =IFERROR(VLOOKUP(AF$3,Data_Entry!$C:$AB,Data_Entry!$A4,0),"") -> 0 | AG6: =IFERROR(SUM(B6:AF6),"") -> 1563.5
A7: Inv_4 | B7: =IFERROR(VLOOKUP(B$3,Data_Entry!$C:$AB,Data_Entry!$A5,0),"") -> 1643.94 | C7: =IFERROR(VLOOKUP(C$3,Data_Entry!$C:$AB,Data_Entry!$A5,0),"") -> 0 | D7: =IFERROR(VLOOKUP(D$3,Data_Entry!$C:$AB,Data_Entry!$A5,0),"") -> 0 | E7: =IFERROR(VLOOKUP(E$3,Data_Entry!$C:$AB,Data_Entry!$A5,0),"") -> 0 | F7: =IFERROR(VLOOKUP(F$3,Data_Entry!$C:$AB,Data_Entry!$A5,0),"") -> 0 | G7: =IFERROR(VLOOKUP(G$3,Data_Entry!$C:$AB,Data_Entry!$A5,0),"") -> 0 | H7: =IFERROR(VLOOKUP(H$3,Data_Entry!$C:$AB,Data_Entry!$A5,0),"") -> 0 | I7: =IFERROR(VLOOKUP(I$3,Data_Entry!$C:$AB,Data_Entry!$A5,0),"") -> 0 | ... AF7: =IFERROR(VLOOKUP(AF$3,Data_Entry!$C:$AB,Data_Entry!$A5,0),"") -> 0 | AG7: =IFERROR(SUM(B7:AF7),"") -> 1643.94
A8: Inv_5 | B8: =IFERROR(VLOOKUP(B$3,Data_Entry!$C:$AB,Data_Entry!$A6,0),"") -> 1663.13 | C8: =IFERROR(VLOOKUP(C$3,Data_Entry!$C:$AB,Data_Entry!$A6,0),"") -> 0 | D8: =IFERROR(VLOOKUP(D$3,Data_Entry!$C:$AB,Data_Entry!$A6,0),"") -> 0 | E8: =IFERROR(VLOOKUP(E$3,Data_Entry!$C:$AB,Data_Entry!$A6,0),"") -> 0 | F8: =IFERROR(VLOOKUP(F$3,Data_Entry!$C:$AB,Data_Entry!$A6,0),"") -> 0 | G8: =IFERROR(VLOOKUP(G$3,Data_Entry!$C:$AB,Data_Entry!$A6,0),"") -> 0 | H8: =IFERROR(VLOOKUP(H$3,Data_Entry!$C:$AB,Data_Entry!$A6,0),"") -> 0 | I8: =IFERROR(VLOOKUP(I$3,Data_Entry!$C:$AB,Data_Entry!$A6,0),"") -> 0 | ... AF8: =IFERROR(VLOOKUP(AF$3,Data_Entry!$C:$AB,Data_Entry!$A6,0),"") -> 0 | AG8: =IFERROR(SUM(B8:AF8),"") -> 1663.13
A9: Inv_6 | B9: =IFERROR(VLOOKUP(B$3,Data_Entry!$C:$AB,Data_Entry!$A7,0),"") -> 1653.37 | C9: =IFERROR(VLOOKUP(C$3,Data_Entry!$C:$AB,Data_Entry!$A7,0),"") -> 0 | D9: =IFERROR(VLOOKUP(D$3,Data_Entry!$C:$AB,Data_Entry!$A7,0),"") -> 0 | E9: =IFERROR(VLOOKUP(E$3,Data_Entry!$C:$AB,Data_Entry!$A7,0),"") -> 0 | F9: =IFERROR(VLOOKUP(F$3,Data_Entry!$C:$AB,Data_Entry!$A7,0),"") -> 0 | G9: =IFERROR(VLOOKUP(G$3,Data_Entry!$C:$AB,Data_Entry!$A7,0),"") -> 0 | H9: =IFERROR(VLOOKUP(H$3,Data_Entry!$C:$AB,Data_Entry!$A7,0),"") -> 0 | I9: =IFERROR(VLOOKUP(I$3,Data_Entry!$C:$AB,Data_Entry!$A7,0),"") -> 0 | ... AF9: =IFERROR(VLOOKUP(AF$3,Data_Entry!$C:$AB,Data_Entry!$A7,0),"") -> 0 | AG9: =IFERROR(SUM(B9:AF9),"") -> 1653.37
A10: Inv_7 | B10: =IFERROR(VLOOKUP(B$3,Data_Entry!$C:$AB,Data_Entry!$A8,0),"") -> 1662.44 | C10: =IFERROR(VLOOKUP(C$3,Data_Entry!$C:$AB,Data_Entry!$A8,0),"") -> 0 | D10: =IFERROR(VLOOKUP(D$3,Data_Entry!$C:$AB,Data_Entry!$A8,0),"") -> 0 | E10: =IFERROR(VLOOKUP(E$3,Data_Entry!$C:$AB,Data_Entry!$A8,0),"") -> 0 | F10: =IFERROR(VLOOKUP(F$3,Data_Entry!$C:$AB,Data_Entry!$A8,0),"") -> 0 | G10: =IFERROR(VLOOKUP(G$3,Data_Entry!$C:$AB,Data_Entry!$A8,0),"") -> 0 | H10: =IFERROR(VLOOKUP(H$3,Data_Entry!$C:$AB,Data_Entry!$A8,0),"") -> 0 | I10: =IFERROR(VLOOKUP(I$3,Data_Entry!$C:$AB,Data_Entry!$A8,0),"") -> 0 | ... AF10: =IFERROR(VLOOKUP(AF$3,Data_Entry!$C:$AB,Data_Entry!$A8,0),"") -> 0 | AG10: =IFERROR(SUM(B10:AF10),"") -> 1662.44
A11: Total_Inverter_(kWh) | B11: =SUM(B4:B10) -> 11350.22 | C11: =SUM(C4:C10) -> 0 | D11: =SUM(D4:D10) -> 0 | E11: =SUM(E4:E10) -> 0 | F11: =SUM(F4:F10) -> 0 | G11: =SUM(G4:G10) -> 0 | H11: =SUM(H4:H10) -> 0 | I11: =SUM(I4:I10) -> 0 | ... AG11: =SUM(AG4:AG10) -> 11350.22
A12: Total_ABT_Meter_Export_(kWh) | B12: =IFERROR(VLOOKUP(B$3,Data_Entry!$C:$AB,14,0)," ") -> 11310 | C12: =IFERROR(VLOOKUP(C$3,Data_Entry!$C:$AB,14,0)," ") -> 0 | D12: =IFERROR(VLOOKUP(D$3,Data_Entry!$C:$AB,14,0)," ") -> 0 | E12: =IFERROR(VLOOKUP(E$3,Data_Entry!$C:$AB,14,0)," ") -> 0 | F12: =IFERROR(VLOOKUP(F$3,Data_Entry!$C:$AB,14,0)," ") -> 0 | G12: =IFERROR(VLOOKUP(G$3,Data_Entry!$C:$AB,14,0)," ") -> 0 | H12: =IFERROR(VLOOKUP(H$3,Data_Entry!$C:$AB,14,0)," ") -> 0 | I12: =IFERROR(VLOOKUP(I$3,Data_Entry!$C:$AB,14,0)," ") -> 0 | ... AG12: =IFERROR(VLOOKUP(AG$3,Data_Entry!$C:$AB,14,0)," ")
A13: Total_ABT_Meter_Import_(kWh) | B13: =IFERROR(VLOOKUP(B$3,Data_Entry!$C:$AB,17,0)," ") -> 30 | C13: =IFERROR(VLOOKUP(C$3,Data_Entry!$C:$AB,17,0)," ") -> 0 | D13: =IFERROR(VLOOKUP(D$3,Data_Entry!$C:$AB,17,0)," ") -> 0 | E13: =IFERROR(VLOOKUP(E$3,Data_Entry!$C:$AB,17,0)," ") -> 0 | F13: =IFERROR(VLOOKUP(F$3,Data_Entry!$C:$AB,17,0)," ") -> 0 | G13: =IFERROR(VLOOKUP(G$3,Data_Entry!$C:$AB,17,0)," ") -> 0 | H13: =IFERROR(VLOOKUP(H$3,Data_Entry!$C:$AB,17,0)," ") -> 0 | I13: =IFERROR(VLOOKUP(I$3,Data_Entry!$C:$AB,17,0)," ") -> 0 | ... AG13: =IFERROR(VLOOKUP(AG$3,Data_Entry!$C:$AB,17,0)," ")
A14: Total_ABT_Meter_Net_(kWh) | B14: =IFERROR(VLOOKUP(B$3,Data_Entry!$C:$AB,18,0)," ") -> 11280 | C14: =IFERROR(VLOOKUP(C$3,Data_Entry!$C:$AB,18,0)," ") -> 0 | D14: =IFERROR(VLOOKUP(D$3,Data_Entry!$C:$AB,18,0)," ") -> 0 | E14: =IFERROR(VLOOKUP(E$3,Data_Entry!$C:$AB,18,0)," ") -> 0 | F14: =IFERROR(VLOOKUP(F$3,Data_Entry!$C:$AB,18,0)," ") -> 0 | G14: =IFERROR(VLOOKUP(G$3,Data_Entry!$C:$AB,18,0)," ") -> 0 | H14: =IFERROR(VLOOKUP(H$3,Data_Entry!$C:$AB,18,0)," ") -> 0 | I14: =IFERROR(VLOOKUP(I$3,Data_Entry!$C:$AB,18,0)," ") -> 0 | ... AG14: =IFERROR(VLOOKUP(AG$3,Data_Entry!$C:$AB,18,0)," ")
A15: GTI | B15: =IFERROR(VLOOKUP(B$3,Data_Entry!$C:$AB,20,0)," ") -> 4.71 | C15: =IFERROR(VLOOKUP(C$3,Data_Entry!$C:$AB,20,0)," ") -> 0 | D15: =IFERROR(VLOOKUP(D$3,Data_Entry!$C:$AB,20,0)," ") -> 0 | E15: =IFERROR(VLOOKUP(E$3,Data_Entry!$C:$AB,20,0)," ") -> 0 | F15: =IFERROR(VLOOKUP(F$3,Data_Entry!$C:$AB,20,0)," ") -> 0 | G15: =IFERROR(VLOOKUP(G$3,Data_Entry!$C:$AB,20,0)," ") -> 0 | H15: =IFERROR(VLOOKUP(H$3,Data_Entry!$C:$AB,20,0)," ") -> 0 | I15: =IFERROR(VLOOKUP(I$3,Data_Entry!$C:$AB,20,0)," ") -> 0 | ... AF15: =IFERROR(VLOOKUP(AF$3,Data_Entry!$C:$AB,20,0)," ") -> 0
A16: GHI | B16: =IFERROR(VLOOKUP(B$3,Data_Entry!$C:$AB,19,0)," ") -> 0 | C16: =IFERROR(VLOOKUP(C$3,Data_Entry!$C:$AB,19,0)," ") -> 0 | D16: =IFERROR(VLOOKUP(D$3,Data_Entry!$C:$AB,19,0)," ") -> 0 | E16: =IFERROR(VLOOKUP(E$3,Data_Entry!$C:$AB,19,0)," ") -> 0 | F16: =IFERROR(VLOOKUP(F$3,Data_Entry!$C:$AB,19,0)," ") -> 0 | G16: =IFERROR(VLOOKUP(G$3,Data_Entry!$C:$AB,19,0)," ") -> 0 | H16: =IFERROR(VLOOKUP(H$3,Data_Entry!$C:$AB,19,0)," ") -> 0 | I16: =IFERROR(VLOOKUP(I$3,Data_Entry!$C:$AB,19,0)," ") -> 0 | ... AF16: =IFERROR(VLOOKUP(AF$3,Data_Entry!$C:$AB,19,0)," ") -> 0
A17: Module_Temp. | B17: =IFERROR(VLOOKUP(B$3,Data_Entry!$C:$AB,23,0)," ") -> 0 | C17: =IFERROR(VLOOKUP(C$3,Data_Entry!$C:$AB,23,0)," ") -> 0 | D17: =IFERROR(VLOOKUP(D$3,Data_Entry!$C:$AB,23,0)," ") -> 0 | E17: =IFERROR(VLOOKUP(E$3,Data_Entry!$C:$AB,23,0)," ") -> 0 | F17: =IFERROR(VLOOKUP(F$3,Data_Entry!$C:$AB,23,0)," ") -> 0 | G17: =IFERROR(VLOOKUP(G$3,Data_Entry!$C:$AB,23,0)," ") -> 0 | H17: =IFERROR(VLOOKUP(H$3,Data_Entry!$C:$AB,23,0)," ") -> 0 | I17: =IFERROR(VLOOKUP(I$3,Data_Entry!$C:$AB,23,0)," ") -> 0 | ... AF17: =IFERROR(VLOOKUP(AF$3,Data_Entry!$C:$AB,23,0)," ") -> 0
A18: Ambt._Temp. | B18: =IFERROR(VLOOKUP(B$3,Data_Entry!$C:$AB,21,0)," ") -> 33.03 | C18: =IFERROR(VLOOKUP(C$3,Data_Entry!$C:$AB,21,0)," ") -> 0 | D18: =IFERROR(VLOOKUP(D$3,Data_Entry!$C:$AB,21,0)," ") -> 0 | E18: =IFERROR(VLOOKUP(E$3,Data_Entry!$C:$AB,21,0)," ") -> 0 | F18: =IFERROR(VLOOKUP(F$3,Data_Entry!$C:$AB,21,0)," ") -> 0 | G18: =IFERROR(VLOOKUP(G$3,Data_Entry!$C:$AB,21,0)," ") -> 0 | H18: =IFERROR(VLOOKUP(H$3,Data_Entry!$C:$AB,21,0)," ") -> 0 | I18: =IFERROR(VLOOKUP(I$3,Data_Entry!$C:$AB,21,0)," ") -> 0 | ... AF18: =IFERROR(VLOOKUP(AF$3,Data_Entry!$C:$AB,21,0)," ") -> 0
A19: Performance_Ratio_(%) | B19: =IFERROR(B12/B15/(Basic_Data!$G$10),"") -> 0.9959329 | C19: =IFERROR(C12/C15/(Basic_Data!$G$10),"") | D19: =IFERROR(D12/D15/(Basic_Data!$G$10),"") | E19: =IFERROR(E12/E15/(Basic_Data!$G$10),"") | F19: =IFERROR(F12/F15/(Basic_Data!$G$10),"") | G19: =IFERROR(G12/G15/(Basic_Data!$G$10),"") | H19: =IFERROR(H12/H15/(Basic_Data!$G$10),"") | I19: =IFERROR(I12/I15/(Basic_Data!$G$10),"") | ... AG19: =IFERROR(AG12/AG15/(Basic_Data!$G$10),"")
A20: Capacity_Utilization_Factor_(%) | B20: =IFERROR(B12/(Basic_Data!$F$10*24),"") -> 0.24480519 | C20: =IFERROR(C12/(Basic_Data!$F$10*24),"") -> 0 | D20: =IFERROR(D12/(Basic_Data!$F$10*24),"") -> 0 | E20: =IFERROR(E12/(Basic_Data!$F$10*24),"") -> 0 | F20: =IFERROR(F12/(Basic_Data!$F$10*24),"") -> 0 | G20: =IFERROR(G12/(Basic_Data!$F$10*24),"") -> 0 | H20: =IFERROR(H12/(Basic_Data!$F$10*24),"") -> 0 | I20: =IFERROR(I12/(Basic_Data!$F$10*24),"") -> 0 | ... AG20: =IFERROR(AG12/(Basic_Data!$F$10*24),"")
A21: Aux_Consumption_Line_Loss_(%) | B21: =IFERROR((B11-B12)/B11,"") -> 0.0035435436 | C21: =IFERROR((C11-C12)/C11,"") | D21: =IFERROR((D11-D12)/D11,"") | E21: =IFERROR((E11-E12)/E11,"") | F21: =IFERROR((F11-F12)/F11,"") | G21: =IFERROR((G11-G12)/G11,"") | H21: =IFERROR((H11-H12)/H11,"") | I21: =IFERROR((I11-I12)/I11,"") | ... AG21: =IFERROR((AG11-AG12)/AG11,"")

Sheet Invt_Analysis_Gen_Per_KW &_PR
A1: Daily_Generation_Per_KW_Performance_Analysis
B2: Inverter_No. | C2: =DGR!B3 -> 46178 | D2: =DGR!C3 -> 46179 | E2: =DGR!D3 -> 46180 | F2: =DGR!E3 -> 46181 | G2: =DGR!F3 -> 46182 | H2: =DGR!G3 -> 46183 | I2: =DGR!H3 -> 46184 | J2: =DGR!I3 -> 46185 | ... AH2: =DGR!AG3 -> Total/Avg..
B3: Inv_1 | C3: =IFERROR(VLOOKUP(C$2,Data_Entry!$C:$L,Data_Entry!$A2,0)/VLOOKUP($B3,Basic_Data!$E$2:$G$10,3,0),"") -> 4.7071965 | D3: =IFERROR(VLOOKUP(D$2,Data_Entry!$C:$L,Data_Entry!$A2,0)/VLOOKUP($B3,Basic_Data!$E$2:$G$10,3,0),"") -> 0 | E3: =IFERROR(VLOOKUP(E$2,Data_Entry!$C:$L,Data_Entry!$A2,0)/VLOOKUP($B3,Basic_Data!$E$2:$G$10,3,0),"") -> 0 | F3: =IFERROR(VLOOKUP(F$2,Data_Entry!$C:$L,Data_Entry!$A2,0)/VLOOKUP($B3,Basic_Data!$E$2:$G$10,3,0),"") -> 0 | G3: =IFERROR(VLOOKUP(G$2,Data_Entry!$C:$L,Data_Entry!$A2,0)/VLOOKUP($B3,Basic_Data!$E$2:$G$10,3,0),"") -> 0 | H3: =IFERROR(VLOOKUP(H$2,Data_Entry!$C:$L,Data_Entry!$A2,0)/VLOOKUP($B3,Basic_Data!$E$2:$G$10,3,0),"") -> 0 | I3: =IFERROR(VLOOKUP(I$2,Data_Entry!$C:$L,Data_Entry!$A2,0)/VLOOKUP($B3,Basic_Data!$E$2:$G$10,3,0),"") -> 0 | J3: =IFERROR(VLOOKUP(J$2,Data_Entry!$C:$L,Data_Entry!$A2,0)/VLOOKUP($B3,Basic_Data!$E$2:$G$10,3,0),"") -> 0 | ... AG3: =IFERROR(VLOOKUP(AG$2,Data_Entry!$C:$L,Data_Entry!$A2,0)/VLOOKUP($B3,Basic_Data!$E$2:$G$10,3,0),"") -> 0
B4: Inv_2 | C4: =IFERROR(VLOOKUP(C$2,Data_Entry!$C:$L,Data_Entry!$A3,0)/VLOOKUP($B4,Basic_Data!$E$2:$G$10,3,0),"") -> 4.7168474 | D4: =IFERROR(VLOOKUP(D$2,Data_Entry!$C:$L,Data_Entry!$A3,0)/VLOOKUP($B4,Basic_Data!$E$2:$G$10,3,0),"") -> 0 | E4: =IFERROR(VLOOKUP(E$2,Data_Entry!$C:$L,Data_Entry!$A3,0)/VLOOKUP($B4,Basic_Data!$E$2:$G$10,3,0),"") -> 0 | F4: =IFERROR(VLOOKUP(F$2,Data_Entry!$C:$L,Data_Entry!$A3,0)/VLOOKUP($B4,Basic_Data!$E$2:$G$10,3,0),"") -> 0 | G4: =IFERROR(VLOOKUP(G$2,Data_Entry!$C:$L,Data_Entry!$A3,0)/VLOOKUP($B4,Basic_Data!$E$2:$G$10,3,0),"") -> 0 | H4: =IFERROR(VLOOKUP(H$2,Data_Entry!$C:$L,Data_Entry!$A3,0)/VLOOKUP($B4,Basic_Data!$E$2:$G$10,3,0),"") -> 0 | I4: =IFERROR(VLOOKUP(I$2,Data_Entry!$C:$L,Data_Entry!$A3,0)/VLOOKUP($B4,Basic_Data!$E$2:$G$10,3,0),"") -> 0 | J4: =IFERROR(VLOOKUP(J$2,Data_Entry!$C:$L,Data_Entry!$A3,0)/VLOOKUP($B4,Basic_Data!$E$2:$G$10,3,0),"") -> 0 | ... AG4: =IFERROR(VLOOKUP(AG$2,Data_Entry!$C:$L,Data_Entry!$A3,0)/VLOOKUP($B4,Basic_Data!$E$2:$G$10,3,0),"") -> 0
B5: Inv_3 | C5: =IFERROR(VLOOKUP(C$2,Data_Entry!$C:$L,Data_Entry!$A4,0)/VLOOKUP($B5,Basic_Data!$E$2:$G$10,3,0),"") -> 4.6571548 | D5: =IFERROR(VLOOKUP(D$2,Data_Entry!$C:$L,Data_Entry!$A4,0)/VLOOKUP($B5,Basic_Data!$E$2:$G$10,3,0),"") -> 0 | E5: =IFERROR(VLOOKUP(E$2,Data_Entry!$C:$L,Data_Entry!$A4,0)/VLOOKUP($B5,Basic_Data!$E$2:$G$10,3,0),"") -> 0 | F5: =IFERROR(VLOOKUP(F$2,Data_Entry!$C:$L,Data_Entry!$A4,0)/VLOOKUP($B5,Basic_Data!$E$2:$G$10,3,0),"") -> 0 | G5: =IFERROR(VLOOKUP(G$2,Data_Entry!$C:$L,Data_Entry!$A4,0)/VLOOKUP($B5,Basic_Data!$E$2:$G$10,3,0),"") -> 0 | H5: =IFERROR(VLOOKUP(H$2,Data_Entry!$C:$L,Data_Entry!$A4,0)/VLOOKUP($B5,Basic_Data!$E$2:$G$10,3,0),"") -> 0 | I5: =IFERROR(VLOOKUP(I$2,Data_Entry!$C:$L,Data_Entry!$A4,0)/VLOOKUP($B5,Basic_Data!$E$2:$G$10,3,0),"") -> 0 | J5: =IFERROR(VLOOKUP(J$2,Data_Entry!$C:$L,Data_Entry!$A4,0)/VLOOKUP($B5,Basic_Data!$E$2:$G$10,3,0),"") -> 0 | ... AG5: =IFERROR(VLOOKUP(AG$2,Data_Entry!$C:$L,Data_Entry!$A4,0)/VLOOKUP($B5,Basic_Data!$E$2:$G$10,3,0),"") -> 0
B6: Inv_4 | C6: =IFERROR(VLOOKUP(C$2,Data_Entry!$C:$L,Data_Entry!$A5,0)/VLOOKUP($B6,Basic_Data!$E$2:$G$10,3,0),"") -> 4.6838566 | D6: =IFERROR(VLOOKUP(D$2,Data_Entry!$C:$L,Data_Entry!$A5,0)/VLOOKUP($B6,Basic_Data!$E$2:$G$10,3,0),"") -> 0 | E6: =IFERROR(VLOOKUP(E$2,Data_Entry!$C:$L,Data_Entry!$A5,0)/VLOOKUP($B6,Basic_Data!$E$2:$G$10,3,0),"") -> 0 | F6: =IFERROR(VLOOKUP(F$2,Data_Entry!$C:$L,Data_Entry!$A5,0)/VLOOKUP($B6,Basic_Data!$E$2:$G$10,3,0),"") -> 0 | G6: =IFERROR(VLOOKUP(G$2,Data_Entry!$C:$L,Data_Entry!$A5,0)/VLOOKUP($B6,Basic_Data!$E$2:$G$10,3,0),"") -> 0 | H6: =IFERROR(VLOOKUP(H$2,Data_Entry!$C:$L,Data_Entry!$A5,0)/VLOOKUP($B6,Basic_Data!$E$2:$G$10,3,0),"") -> 0 | I6: =IFERROR(VLOOKUP(I$2,Data_Entry!$C:$L,Data_Entry!$A5,0)/VLOOKUP($B6,Basic_Data!$E$2:$G$10,3,0),"") -> 0 | J6: =IFERROR(VLOOKUP(J$2,Data_Entry!$C:$L,Data_Entry!$A5,0)/VLOOKUP($B6,Basic_Data!$E$2:$G$10,3,0),"") -> 0 | ... AG6: =IFERROR(VLOOKUP(AG$2,Data_Entry!$C:$L,Data_Entry!$A5,0)/VLOOKUP($B6,Basic_Data!$E$2:$G$10,3,0),"") -> 0
B7: Inv_5 | C7: =IFERROR(VLOOKUP(C$2,Data_Entry!$C:$L,Data_Entry!$A6,0)/VLOOKUP($B7,Basic_Data!$E$2:$G$10,3,0),"") -> 4.7385321 | D7: =IFERROR(VLOOKUP(D$2,Data_Entry!$C:$L,Data_Entry!$A6,0)/VLOOKUP($B7,Basic_Data!$E$2:$G$10,3,0),"") -> 0 | E7: =IFERROR(VLOOKUP(E$2,Data_Entry!$C:$L,Data_Entry!$A6,0)/VLOOKUP($B7,Basic_Data!$E$2:$G$10,3,0),"") -> 0 | F7: =IFERROR(VLOOKUP(F$2,Data_Entry!$C:$L,Data_Entry!$A6,0)/VLOOKUP($B7,Basic_Data!$E$2:$G$10,3,0),"") -> 0 | G7: =IFERROR(VLOOKUP(G$2,Data_Entry!$C:$L,Data_Entry!$A6,0)/VLOOKUP($B7,Basic_Data!$E$2:$G$10,3,0),"") -> 0 | H7: =IFERROR(VLOOKUP(H$2,Data_Entry!$C:$L,Data_Entry!$A6,0)/VLOOKUP($B7,Basic_Data!$E$2:$G$10,3,0),"") -> 0 | I7: =IFERROR(VLOOKUP(I$2,Data_Entry!$C:$L,Data_Entry!$A6,0)/VLOOKUP($B7,Basic_Data!$E$2:$G$10,3,0),"") -> 0 | J7: =IFERROR(VLOOKUP(J$2,Data_Entry!$C:$L,Data_Entry!$A6,0)/VLOOKUP($B7,Basic_Data!$E$2:$G$10,3,0),"") -> 0 | ... AG7: =IFERROR(VLOOKUP(AG$2,Data_Entry!$C:$L,Data_Entry!$A6,0)/VLOOKUP($B7,Basic_Data!$E$2:$G$10,3,0),"") -> 0
B8: Inv_6 | C8: =IFERROR(VLOOKUP(C$2,Data_Entry!$C:$L,Data_Entry!$A7,0)/VLOOKUP($B8,Basic_Data!$E$2:$G$10,3,0),"") -> 4.7107243 | D8: =IFERROR(VLOOKUP(D$2,Data_Entry!$C:$L,Data_Entry!$A7,0)/VLOOKUP($B8,Basic_Data!$E$2:$G$10,3,0),"") -> 0 | E8: =IFERROR(VLOOKUP(E$2,Data_Entry!$C:$L,Data_Entry!$A7,0)/VLOOKUP($B8,Basic_Data!$E$2:$G$10,3,0),"") -> 0 | F8: =IFERROR(VLOOKUP(F$2,Data_Entry!$C:$L,Data_Entry!$A7,0)/VLOOKUP($B8,Basic_Data!$E$2:$G$10,3,0),"") -> 0 | G8: =IFERROR(VLOOKUP(G$2,Data_Entry!$C:$L,Data_Entry!$A7,0)/VLOOKUP($B8,Basic_Data!$E$2:$G$10,3,0),"") -> 0 | H8: =IFERROR(VLOOKUP(H$2,Data_Entry!$C:$L,Data_Entry!$A7,0)/VLOOKUP($B8,Basic_Data!$E$2:$G$10,3,0),"") -> 0 | I8: =IFERROR(VLOOKUP(I$2,Data_Entry!$C:$L,Data_Entry!$A7,0)/VLOOKUP($B8,Basic_Data!$E$2:$G$10,3,0),"") -> 0 | J8: =IFERROR(VLOOKUP(J$2,Data_Entry!$C:$L,Data_Entry!$A7,0)/VLOOKUP($B8,Basic_Data!$E$2:$G$10,3,0),"") -> 0 | ... AG8: =IFERROR(VLOOKUP(AG$2,Data_Entry!$C:$L,Data_Entry!$A7,0)/VLOOKUP($B8,Basic_Data!$E$2:$G$10,3,0),"") -> 0
B9: Inv_7 | C9: =IFERROR(VLOOKUP(C$2,Data_Entry!$C:$L,Data_Entry!$A8,0)/VLOOKUP($B9,Basic_Data!$E$2:$G$10,3,0),"") -> 4.7365662 | D9: =IFERROR(VLOOKUP(D$2,Data_Entry!$C:$L,Data_Entry!$A8,0)/VLOOKUP($B9,Basic_Data!$E$2:$G$10,3,0),"") -> 0 | E9: =IFERROR(VLOOKUP(E$2,Data_Entry!$C:$L,Data_Entry!$A8,0)/VLOOKUP($B9,Basic_Data!$E$2:$G$10,3,0),"") -> 0 | F9: =IFERROR(VLOOKUP(F$2,Data_Entry!$C:$L,Data_Entry!$A8,0)/VLOOKUP($B9,Basic_Data!$E$2:$G$10,3,0),"") -> 0 | G9: =IFERROR(VLOOKUP(G$2,Data_Entry!$C:$L,Data_Entry!$A8,0)/VLOOKUP($B9,Basic_Data!$E$2:$G$10,3,0),"") -> 0 | H9: =IFERROR(VLOOKUP(H$2,Data_Entry!$C:$L,Data_Entry!$A8,0)/VLOOKUP($B9,Basic_Data!$E$2:$G$10,3,0),"") -> 0 | I9: =IFERROR(VLOOKUP(I$2,Data_Entry!$C:$L,Data_Entry!$A8,0)/VLOOKUP($B9,Basic_Data!$E$2:$G$10,3,0),"") -> 0 | J9: =IFERROR(VLOOKUP(J$2,Data_Entry!$C:$L,Data_Entry!$A8,0)/VLOOKUP($B9,Basic_Data!$E$2:$G$10,3,0),"") -> 0 | ... AG9: =IFERROR(VLOOKUP(AG$2,Data_Entry!$C:$L,Data_Entry!$A8,0)/VLOOKUP($B9,Basic_Data!$E$2:$G$10,3,0),"") -> 0
B10: Avg_per_Kw | C10: =AVERAGE(C3:C9) -> 4.7072683 | D10: =AVERAGE(D3:D9) -> 0 | E10: =AVERAGE(E3:E9) -> 0 | F10: =AVERAGE(F3:F9) -> 0 | G10: =AVERAGE(G3:G9) -> 0 | H10: =AVERAGE(H3:H9) -> 0 | I10: =AVERAGE(I3:I9) -> 0 | J10: =AVERAGE(J3:J9) -> 0 | ... AH10: =AVERAGE(AH3:AH9) -> #DIV/0!
B13: Inverter_No. | C13: =DGR!B3 -> 46178 | D13: =DGR!C3 -> 46179 | E13: =DGR!D3 -> 46180 | F13: =DGR!E3 -> 46181 | G13: =DGR!F3 -> 46182 | H13: =DGR!G3 -> 46183 | I13: =DGR!H3 -> 46184 | J13: =DGR!I3 -> 46185 | ... AH13: =DGR!AG3 -> Total/Avg..
B14: Inv_1 | C14: =IFERROR(VLOOKUP(C$13,Data_Entry!$C:$M,Data_Entry!$A2,0)/VLOOKUP($B14,Basic_Data!$E$2:$G$9,3,0)/VLOOKUP(C$13,Data_Entry!$C:$V,20,0),"") -> 0.99940477 | D14: =IFERROR(VLOOKUP(D$13,Data_Entry!$C:$M,Data_Entry!$A2,0)/VLOOKUP($B14,Basic_Data!$E$2:$G$9,3,0)/VLOOKUP(D$13,Data_Entry!$C:$V,20,0),"") | E14: =IFERROR(VLOOKUP(E$13,Data_Entry!$C:$M,Data_Entry!$A2,0)/VLOOKUP($B14,Basic_Data!$E$2:$G$9,3,0)/VLOOKUP(E$13,Data_Entry!$C:$V,20,0),"") | F14: =IFERROR(VLOOKUP(F$13,Data_Entry!$C:$M,Data_Entry!$A2,0)/VLOOKUP($B14,Basic_Data!$E$2:$G$9,3,0)/VLOOKUP(F$13,Data_Entry!$C:$V,20,0),"") | G14: =IFERROR(VLOOKUP(G$13,Data_Entry!$C:$M,Data_Entry!$A2,0)/VLOOKUP($B14,Basic_Data!$E$2:$G$9,3,0)/VLOOKUP(G$13,Data_Entry!$C:$V,20,0),"") | H14: =IFERROR(VLOOKUP(H$13,Data_Entry!$C:$M,Data_Entry!$A2,0)/VLOOKUP($B14,Basic_Data!$E$2:$G$9,3,0)/VLOOKUP(H$13,Data_Entry!$C:$V,20,0),"") | I14: =IFERROR(VLOOKUP(I$13,Data_Entry!$C:$M,Data_Entry!$A2,0)/VLOOKUP($B14,Basic_Data!$E$2:$G$9,3,0)/VLOOKUP(I$13,Data_Entry!$C:$V,20,0),"") | J14: =IFERROR(VLOOKUP(J$13,Data_Entry!$C:$M,Data_Entry!$A2,0)/VLOOKUP($B14,Basic_Data!$E$2:$G$9,3,0)/VLOOKUP(J$13,Data_Entry!$C:$V,20,0),"") | ... AG14: =IFERROR(VLOOKUP(AG$13,Data_Entry!$C:$M,Data_Entry!$A2,0)/VLOOKUP($B14,Basic_Data!$E$2:$G$9,3,0)/VLOOKUP(AG$13,Data_Entry!$C:$V,20,0),"")
B15: Inv_2 | C15: =IFERROR(VLOOKUP(C$13,Data_Entry!$C:$M,Data_Entry!$A3,0)/VLOOKUP($B15,Basic_Data!$E$2:$G$9,3,0)/VLOOKUP(C$13,Data_Entry!$C:$V,20,0),"") -> 1.0014538 | D15: =IFERROR(VLOOKUP(D$13,Data_Entry!$C:$M,Data_Entry!$A3,0)/VLOOKUP($B15,Basic_Data!$E$2:$G$9,3,0)/VLOOKUP(D$13,Data_Entry!$C:$V,20,0),"") | E15: =IFERROR(VLOOKUP(E$13,Data_Entry!$C:$M,Data_Entry!$A3,0)/VLOOKUP($B15,Basic_Data!$E$2:$G$9,3,0)/VLOOKUP(E$13,Data_Entry!$C:$V,20,0),"") | F15: =IFERROR(VLOOKUP(F$13,Data_Entry!$C:$M,Data_Entry!$A3,0)/VLOOKUP($B15,Basic_Data!$E$2:$G$9,3,0)/VLOOKUP(F$13,Data_Entry!$C:$V,20,0),"") | G15: =IFERROR(VLOOKUP(G$13,Data_Entry!$C:$M,Data_Entry!$A3,0)/VLOOKUP($B15,Basic_Data!$E$2:$G$9,3,0)/VLOOKUP(G$13,Data_Entry!$C:$V,20,0),"") | H15: =IFERROR(VLOOKUP(H$13,Data_Entry!$C:$M,Data_Entry!$A3,0)/VLOOKUP($B15,Basic_Data!$E$2:$G$9,3,0)/VLOOKUP(H$13,Data_Entry!$C:$V,20,0),"") | I15: =IFERROR(VLOOKUP(I$13,Data_Entry!$C:$M,Data_Entry!$A3,0)/VLOOKUP($B15,Basic_Data!$E$2:$G$9,3,0)/VLOOKUP(I$13,Data_Entry!$C:$V,20,0),"") | J15: =IFERROR(VLOOKUP(J$13,Data_Entry!$C:$M,Data_Entry!$A3,0)/VLOOKUP($B15,Basic_Data!$E$2:$G$9,3,0)/VLOOKUP(J$13,Data_Entry!$C:$V,20,0),"") | ... AG15: =IFERROR(VLOOKUP(AG$13,Data_Entry!$C:$M,Data_Entry!$A3,0)/VLOOKUP($B15,Basic_Data!$E$2:$G$9,3,0)/VLOOKUP(AG$13,Data_Entry!$C:$V,20,0),"")
B16: Inv_3 | C16: =IFERROR(VLOOKUP(C$13,Data_Entry!$C:$M,Data_Entry!$A4,0)/VLOOKUP($B16,Basic_Data!$E$2:$G$9,3,0)/VLOOKUP(C$13,Data_Entry!$C:$V,20,0),"") -> 0.98878021 | D16: =IFERROR(VLOOKUP(D$13,Data_Entry!$C:$M,Data_Entry!$A4,0)/VLOOKUP($B16,Basic_Data!$E$2:$G$9,3,0)/VLOOKUP(D$13,Data_Entry!$C:$V,20,0),"") | E16: =IFERROR(VLOOKUP(E$13,Data_Entry!$C:$M,Data_Entry!$A4,0)/VLOOKUP($B16,Basic_Data!$E$2:$G$9,3,0)/VLOOKUP(E$13,Data_Entry!$C:$V,20,0),"") | F16: =IFERROR(VLOOKUP(F$13,Data_Entry!$C:$M,Data_Entry!$A4,0)/VLOOKUP($B16,Basic_Data!$E$2:$G$9,3,0)/VLOOKUP(F$13,Data_Entry!$C:$V,20,0),"") | G16: =IFERROR(VLOOKUP(G$13,Data_Entry!$C:$M,Data_Entry!$A4,0)/VLOOKUP($B16,Basic_Data!$E$2:$G$9,3,0)/VLOOKUP(G$13,Data_Entry!$C:$V,20,0),"") | H16: =IFERROR(VLOOKUP(H$13,Data_Entry!$C:$M,Data_Entry!$A4,0)/VLOOKUP($B16,Basic_Data!$E$2:$G$9,3,0)/VLOOKUP(H$13,Data_Entry!$C:$V,20,0),"") | I16: =IFERROR(VLOOKUP(I$13,Data_Entry!$C:$M,Data_Entry!$A4,0)/VLOOKUP($B16,Basic_Data!$E$2:$G$9,3,0)/VLOOKUP(I$13,Data_Entry!$C:$V,20,0),"") | J16: =IFERROR(VLOOKUP(J$13,Data_Entry!$C:$M,Data_Entry!$A4,0)/VLOOKUP($B16,Basic_Data!$E$2:$G$9,3,0)/VLOOKUP(J$13,Data_Entry!$C:$V,20,0),"") | ... AG16: =IFERROR(VLOOKUP(AG$13,Data_Entry!$C:$M,Data_Entry!$A4,0)/VLOOKUP($B16,Basic_Data!$E$2:$G$9,3,0)/VLOOKUP(AG$13,Data_Entry!$C:$V,20,0),"")
