Workbook

Sheet Budgeted_data
A1: Plant Name | B1: Date | C1: Month | D1: Month | E1: Daily_Gen | F1: Daily_GTI | G1: Daily_GHI | H1: Ambt_Temp | I1: PR_% | J1: CUF_% | K1: TArray | L1: TArrWtd | M1: Connected_DC
A2: Kanja | B2: 45658 | E2: 21731.502 | F2: 5.47253 | G2: 4.345315 | H2: 27.273333 | I2: 0.8148 | J2: =E2/24/M2 -> 0.18778085 | K2: 43.6059 | L2: 43.6059 | M2: 4822
A3: Kanja | B3: 45659 | E3: 22711.152 | F3: 5.69424 | G3: 4.481942 | H3: 25.555 | I3: 0.8188 | J3: =E3/24/M3 -> 0.19624596 | K3: 42.2575 | L3: 42.2575 | M3: 4822
A4: Kanja | B4: 45660 | E4: 21189.702 | F4: 5.30545 | G4: 4.2633838 | H4: 26.016667 | I4: 0.8209 | J4: =E4/24/M4 -> 0.18309918 | K4: 42.155 | L4: 42.155 | M4: 4822
A5: Kanja | B5: 45661 | E5: 23732.482 | F5: 5.9432 | G5: 4.6643305 | H5: 24.213333 | I5: 0.8208 | J5: =E5/24/M5 -> 0.20507122 | K5: 41.7867 | L5: 41.7867 | M5: 4822
A6: Kanja | B6: 45662 | E6: 23911.322 | F6: 5.98552 | G6: 4.7081898 | H6: 23.605417 | I6: 0.8224 | J6: =E6/24/M6 -> 0.20661657 | K6: 41.5419 | L6: 41.5419 | M6: 4822
A7: Kanja | B7: 45663 | E7: 22558.262 | F7: 5.60885 | G7: 4.4441987 | H7: 23.3175 | I7: 0.8276 | J7: =E7/24/M7 -> 0.19492484 | K7: 40.038 | L7: 40.038 | M7: 4822
A8: Kanja | B8: 45664 | E8: 23693.582 | F8: 5.92036 | G8: 4.6664676 | H8: 23.430833 | I8: 0.8244 | J8: =E8/24/M8 -> 0.20473509 | K8: 41.2841 | L8: 41.2841 | M8: 4822
A9: Kanja | B9: 45665 | E9: 23686.692 | F9: 5.90096 | G9: 4.6665587 | H9: 22.774167 | I9: 0.8276 | J9: =E9/24/M9 -> 0.20467555 | K9: 40.4263 | L9: 40.4263 | M9: 4822
A10: Kanja | B10: 45666 | E10: 23974.132 | F10: 5.97003 | G10: 4.7177087 | H10: 22.23 | I10: 0.8282 | J10: =E10/24/M10 -> 0.2071593 | K10: 40.1721 | L10: 40.1721 | M10: 4822
A11: Kanja | B11: 45667 | E11: 24191.272 | F11: 6.03196 | G11: 4.7673159 | H11: 22.38875 | I11: 0.8274 | J11: =E11/24/M11 -> 0.2090356 | K11: 40.5892 | L11: 40.5892 | M11: 4822
A12: Kanja | B12: 45668 | E12: 24730.552 | F12: 6.19892 | G12: 4.9104998 | H12: 23.040417 | I12: 0.8237 | J12: =E12/24/M12 -> 0.21369549 | K12: 41.8787 | L12: 41.8787 | M12: 4822
A13: Kanja | B13: 45669 | E13: 24236.612 | F13: 5.97777 | G13: 4.749791 | H13: 19.702917 | I13: 0.8372 | J13: =E13/24/M13 -> 0.20942738 | K13: 37.4108 | L13: 37.4108 | M13: 4822
... A366: Kanja | B366: 46022 | E366: 21626.042 | F366: 5.4422333 | G366: 4.2868251 | H366: 25.557083 | I366: 0.8152 | J366: =E366/24/M366 -> 0.18686957 | K366: 40.758727 | L366: 40.758727 | M366: 4822

Sheet E-Mail_Copy
A1: Plant_Performance_of_Kanja_GJ
B3: =DATE(YEAR(B4),MONTH(B4),1) -> 46143 | C3: =VLOOKUP(L3,[1]Basic_Data!$A$28:$B$48,2,0) -> 45748 | L3: 25-26
A4: Date | B4: 46173 | C4: AC Capacity: | E4: =Basic_Data!G18 -> 4125 | F4: DC Capacity: | H4: =Basic_Data!H18 -> 4822.16 | I4: D.O.C.: | K4: =Basic_Data!C3 -> 45818
A5: Plant Name | C5: Daily | F5: MTD | I5: YTD
C6: Budgeted | D6: Actual | E6: Variation(%) | F6: Budgeted | G6: Actual | H6: Variation(%) | I6: Budgeted | J6: Actual | K6: Variation(%)
A7: Generation_MW | C7: =SUMIFS(Budgeted_data!$E:$E,Budgeted_data!$B:$B,'E-Mail_Copy'!$B$4) -> 0 | D7: =SUMIFS(Data_Entry!$AB:$AB,Data_Entry!$C:$C,'E-Mail_Copy'!$B$4) -> 22750 | E7: =(D7-C7)/C7 -> #DIV/0! | F7: =SUMIFS(Budgeted_data!$E:$E,Budgeted_data!$B:$B,">="&'E-Mail_Copy'!$B$3,Budgeted_data!$B:$B,"<="&'E-Mail_Copy'!$B$4) -> 0 | G7: =SUMIFS(Data_Entry!$AB:$AB,Data_Entry!$C:$C,">="&'E-Mail_Copy'!$B$3,Data_Entry!$C:$C,"<="&'E-Mail_Copy'!$B$4) -> 795300 | H7: =(G7-F7)/F7 -> #DIV/0! | I7: =SUMIFS(Budgeted_data!$E:$E,Budgeted_data!$B:$B,">="&'E-Mail_Copy'!$C$3,Budgeted_data!$B:$B,"<="&'E-Mail_Copy'!$B$4) -> 5977312.5 | J7: =SUMIFS(Data_Entry!$AB:$AB,Data_Entry!$C:$C,">="&'E-Mail_Copy'!$C$3,Data_Entry!$C:$C,"<="&'E-Mail_Copy'!$B$4) -> 6866600 | K7: =(J7-I7)/I7 -> 0.14877714
A8: GTI (Kwh/m2) | C8: =SUMIFS(Budgeted_data!$F:$F,Budgeted_data!$B:$B,'E-Mail_Copy'!$B$4) -> 0 | D8: =SUMIFS(Data_Entry!$AD:$AD,Data_Entry!$C:$C,'E-Mail_Copy'!B4) -> 4.77 | E8: =(D8-C8)/C8 -> #DIV/0! | F8: =SUMIFS(Budgeted_data!$F:$F,Budgeted_data!$B:$B,">="&'E-Mail_Copy'!$B$3,Budgeted_data!$B:$B,"<="&'E-Mail_Copy'!$B$4) -> 0 | G8: =SUMIFS(Data_Entry!$AD:$AD,Data_Entry!$C:$C,">="&'E-Mail_Copy'!$B$3,Data_Entry!$C:$C,"<="&'E-Mail_Copy'!$B$4) -> 159.04 | H8: =(G8-F8)/F8 -> #DIV/0! | I8: =SUMIFS(Budgeted_data!$F:$F,Budgeted_data!$B:$B,">="&'E-Mail_Copy'!$C$3,Budgeted_data!$B:$B,"<="&'E-Mail_Copy'!$B$4) -> 1508.825 | J8: =SUMIFS(Data_Entry!$AD:$AD,Data_Entry!$C:$C,">="&'E-Mail_Copy'!$C$3,Data_Entry!$C:$C,"<="&'E-Mail_Copy'!$B$4) -> 1115.72 | K8: =(J8-I8)/I8 -> -0.26053719
A9: GHI (Kwh/m2) | C9: =SUMIFS(Budgeted_data!$G:$G,Budgeted_data!$B:$B,'E-Mail_Copy'!$B$4) -> 0 | D9: =SUMIFS(Data_Entry!$AC:$AC,Data_Entry!$C:$C,'E-Mail_Copy'!$B$4) -> 0 | E9: =(D9-C9)/C9 -> #DIV/0! | F9: =SUMIFS(Budgeted_data!$G:$G,Budgeted_data!$B:$B,">="&'E-Mail_Copy'!$B$3,Budgeted_data!$B:$B,"<="&'E-Mail_Copy'!$B$4) -> 0 | G9: =SUMIFS(Data_Entry!$AC:$AC,Data_Entry!$C:$C,">="&'E-Mail_Copy'!$B$3,Data_Entry!$C:$C,"<="&'E-Mail_Copy'!$B$4) -> 0 | H9: =(G9-F9)/F9 -> #DIV/0! | I9: =SUMIFS(Budgeted_data!$G:$G,Budgeted_data!$B:$B,">="&'E-Mail_Copy'!$C$3,Budgeted_data!$B:$B,"<="&'E-Mail_Copy'!$B$4) -> 1435.8387 | J9: =SUMIFS(Data_Entry!$AC:$AC,Data_Entry!$C:$C,">="&'E-Mail_Copy'!$C$3,Data_Entry!$C:$C,"<="&'E-Mail_Copy'!$B$4) -> 0 | K9: =(J9-I9)/I9 -> -1
A10: PR_(%) | C10: =C7/C8/H4 -> #DIV/0! | D10: =D7/D8/H4 -> 0.98905719 | E10: =(D10-C10)/C10 -> #DIV/0! | F10: =F7/F8/H4/(B4-B3+1) -> #DIV/0! | G10: =G7/G8/H4/(B4-B3+1) -> 0.03345194 | H10: =(G10-F10)/F10 -> #DIV/0! | I10: =I7/I8/H4/(($B$4-$C$3)+1) -> 0.0019284832 | J10: =J7/J8/H4/(($B$4-$C$3)+1) -> 0.0029959552 | K10: =(J10-I10)/I10 -> 0.5535293
A11: CUF_(%) | C11: =C7/E4/24 -> 0 | D11: =D7/24/E4 -> 0.22979798 | E11: =(D11-C11)/C11 -> #DIV/0! | F11: =F7/24/E4/(B4-B3+1) -> 0 | G11: =G7/24/E4/(B4-B3+1) -> 0.25913978 | H11: =(G11-F11)/F11 -> #DIV/0! | I11: =I7/24/$E$4/(($B$4-$C$3)+1) -> 0.1417298 | J11: =J7/24/$E$4/(($B$4-$C$3)+1) -> 0.16281595 | K11: =(J11-I11)/I11 -> 0.14877714
A12: Wtd_Module_Temp | C12: =AVERAGEIFS(Budgeted_data!$L:$L,Budgeted_data!$B:$B,'E-Mail_Copy'!$B$4) -> #DIV/0! | D12: =AVERAGEIFS(Data_Entry!$AG:$AG,Data_Entry!$C:$C,'E-Mail_Copy'!$B$4) -> #DIV/0! | E12: =(D12-C12)/C12 -> #DIV/0! | F12: =AVERAGEIFS(Budgeted_data!$L:$L,Budgeted_data!$B:$B,">="&'E-Mail_Copy'!$B$3,Budgeted_data!$B:$B,"<="&'E-Mail_Copy'!$B$4) -> #DIV/0! | G12: =AVERAGEIFS(Data_Entry!$AG:$AG,Data_Entry!$C:$C,">="&'E-Mail_Copy'!$B$3,Data_Entry!$C:$C,"<="&'E-Mail_Copy'!$B$4) -> #DIV/0! | H12: =(G12-F12)/F12 -> #DIV/0! | I12: =AVERAGEIFS(Budgeted_data!$L:$L,Budgeted_data!$B:$B,">="&'E-Mail_Copy'!$C$3,Budgeted_data!$B:$B,"<="&'E-Mail_Copy'!$B$4) -> 40.987154 | J12: =AVERAGEIFS(Data_Entry!$AG:$AG,Data_Entry!$C:$C,">="&'E-Mail_Copy'!$C$3,Data_Entry!$C:$C,"<="&'E-Mail_Copy'!$B$4) -> #DIV/0! | K12: =(J12-I12)/I12 -> #DIV/0!
A13: Ambt._Temp_(0C) | C13: =AVERAGEIFS(Budgeted_data!$H:$H,Budgeted_data!$B:$B,'E-Mail_Copy'!$B$4) -> #DIV/0! | D13: =AVERAGEIFS(Data_Entry!$AE:$AE,Data_Entry!$C:$C,'E-Mail_Copy'!$B$4) -> 33.34 | E13: =(D13-C13)/C13 -> #DIV/0! | F13: =AVERAGEIFS(Budgeted_data!$H:$H,Budgeted_data!$B:$B,">="&'E-Mail_Copy'!$B$3,Budgeted_data!$B:$B,"<="&'E-Mail_Copy'!$B$4) -> #DIV/0! | G13: =AVERAGEIFS(Data_Entry!$AE:$AE,Data_Entry!$C:$C,">="&'E-Mail_Copy'!$B$3,Data_Entry!$C:$C,"<="&'E-Mail_Copy'!$B$4) -> 34.263226 | H13: =(G13-F13)/F13 -> #DIV/0! | I13: =AVERAGEIFS(Budgeted_data!$H:$H,Budgeted_data!$B:$B,">="&'E-Mail_Copy'!$C$3,Budgeted_data!$B:$B,"<="&'E-Mail_Copy'!$B$4) -> 27.906308 | J13: =AVERAGEIFS(Data_Entry!$AE:$AE,Data_Entry!$C:$C,">="&'E-Mail_Copy'!$C$3,Data_Entry!$C:$C,"<="&'E-Mail_Copy'!$B$4) -> 29.529697 | K13: =(J13-I13)/I13 -> 0.058172844

Sheet DGR
A1: Daily_Generation_&_Performance_Report
A3: Inverter_No. | B3: ='E-Mail_Copy'!B4 -> 46173 | C3: =B3+1 -> 46174 | D3: =C3+1 -> 46175 | E3: =D3+1 -> 46176 | F3: =E3+1 -> 46177 | G3: =F3+1 -> 46178 | H3: =G3+1 -> 46179 | I3: =H3+1 -> 46180 | J3: =I3+1 -> 46181 | ... AF3: =AE3+1 -> 46203 | AG3: Total/Avg..
A4: Inv_1 | B4: =IFERROR(VLOOKUP(B$3,Data_Entry!$C:$AB,Data_Entry!$A2,0),"") -> 1570.81 | C4: =IFERROR(VLOOKUP(C$3,Data_Entry!$C:$AB,Data_Entry!$A2,0),"") -> 1624.57 | D4: =IFERROR(VLOOKUP(D$3,Data_Entry!$C:$AB,Data_Entry!$A2,0),"") -> 1230.72 | E4: =IFERROR(VLOOKUP(E$3,Data_Entry!$C:$AB,Data_Entry!$A2,0),"") -> 1649.4 | F4: =IFERROR(VLOOKUP(F$3,Data_Entry!$C:$AB,Data_Entry!$A2,0),"") -> 1308.79 | G4: =IFERROR(VLOOKUP(G$3,Data_Entry!$C:$AB,Data_Entry!$A2,0),"") -> 1592.87 | H4: =IFERROR(VLOOKUP(H$3,Data_Entry!$C:$AB,Data_Entry!$A2,0),"") -> 0 | I4: =IFERROR(VLOOKUP(I$3,Data_Entry!$C:$AB,Data_Entry!$A2,0),"") -> 0 | ... AF4: =IFERROR(VLOOKUP(AF$3,Data_Entry!$C:$AB,Data_Entry!$A2,0),"") -> 0 | AG4: =IFERROR(SUM(B4:AF4),"") -> 8977.16
A5: Inv_2 | B5: =IFERROR(VLOOKUP(B$3,Data_Entry!$C:$AB,Data_Entry!$A3,0),"") -> 1564.48 | C5: =IFERROR(VLOOKUP(C$3,Data_Entry!$C:$AB,Data_Entry!$A3,0),"") -> 1634.93 | D5: =IFERROR(VLOOKUP(D$3,Data_Entry!$C:$AB,Data_Entry!$A3,0),"") -> 1285.78 | E5: =IFERROR(VLOOKUP(E$3,Data_Entry!$C:$AB,Data_Entry!$A3,0),"") -> 1223.33 | F5: =IFERROR(VLOOKUP(F$3,Data_Entry!$C:$AB,Data_Entry!$A3,0),"") -> 1251.58 | G5: =IFERROR(VLOOKUP(G$3,Data_Entry!$C:$AB,Data_Entry!$A3,0),"") -> 1594.63 | H5: =IFERROR(VLOOKUP(H$3,Data_Entry!$C:$AB,Data_Entry!$A3,0),"") -> 0 | I5: =IFERROR(VLOOKUP(I$3,Data_Entry!$C:$AB,Data_Entry!$A3,0),"") -> 0 | ... AF5: =IFERROR(VLOOKUP(AF$3,Data_Entry!$C:$AB,Data_Entry!$A3,0),"") -> 0 | AG5: =IFERROR(SUM(B5:AF5),"") -> 8554.73
A6: Inv_3 | B6: =IFERROR(VLOOKUP(B$3,Data_Entry!$C:$AB,Data_Entry!$A4,0),"") -> 1575.03 | C6: =IFERROR(VLOOKUP(C$3,Data_Entry!$C:$AB,Data_Entry!$A4,0),"") -> 1630.4 | D6: =IFERROR(VLOOKUP(D$3,Data_Entry!$C:$AB,Data_Entry!$A4,0),"") -> 1457.01 | E6: =IFERROR(VLOOKUP(E$3,Data_Entry!$C:$AB,Data_Entry!$A4,0),"") -> 1685.12 | F6: =IFERROR(VLOOKUP(F$3,Data_Entry!$C:$AB,Data_Entry!$A4,0),"") -> 1567.34 | G6: =IFERROR(VLOOKUP(G$3,Data_Entry!$C:$AB,Data_Entry!$A4,0),"") -> 1600.23 | H6: =IFERROR(VLOOKUP(H$3,Data_Entry!$C:$AB,Data_Entry!$A4,0),"") -> 0 | I6: =IFERROR(VLOOKUP(I$3,Data_Entry!$C:$AB,Data_Entry!$A4,0),"") -> 0 | ... AF6: =IFERROR(VLOOKUP(AF$3,Data_Entry!$C:$AB,Data_Entry!$A4,0),"") -> 0 | AG6: =IFERROR(SUM(B6:AF6),"") -> 9515.13
A7: Inv_4 | B7: =IFERROR(VLOOKUP(B$3,Data_Entry!$C:$AB,Data_Entry!$A5,0),"") -> 1580.77 | C7: =IFERROR(VLOOKUP(C$3,Data_Entry!$C:$AB,Data_Entry!$A5,0),"") -> 1625.51 | D7: =IFERROR(VLOOKUP(D$3,Data_Entry!$C:$AB,Data_Entry!$A5,0),"") -> 1491.58 | E7: =IFERROR(VLOOKUP(E$3,Data_Entry!$C:$AB,Data_Entry!$A5,0),"") -> 1733.43 | F7: =IFERROR(VLOOKUP(F$3,Data_Entry!$C:$AB,Data_Entry!$A5,0),"") -> 1571.79 | G7: =IFERROR(VLOOKUP(G$3,Data_Entry!$C:$AB,Data_Entry!$A5,0),"") -> 1601.66 | H7: =IFERROR(VLOOKUP(H$3,Data_Entry!$C:$AB,Data_Entry!$A5,0),"") -> 0 | I7: =IFERROR(VLOOKUP(I$3,Data_Entry!$C:$AB,Data_Entry!$A5,0),"") -> 0 | ... AF7: =IFERROR(VLOOKUP(AF$3,Data_Entry!$C:$AB,Data_Entry!$A5,0),"") -> 0 | AG7: =IFERROR(SUM(B7:AF7),"") -> 9604.74
A8: Inv_5 | B8: =IFERROR(VLOOKUP(B$3,Data_Entry!$C:$AB,Data_Entry!$A6,0),"") -> 1539.11 | C8: =IFERROR(VLOOKUP(C$3,Data_Entry!$C:$AB,Data_Entry!$A6,0),"") -> 1614.91 | D8: =IFERROR(VLOOKUP(D$3,Data_Entry!$C:$AB,Data_Entry!$A6,0),"") -> 1501.86 | E8: =IFERROR(VLOOKUP(E$3,Data_Entry!$C:$AB,Data_Entry!$A6,0),"") -> 1734.76 | F8: =IFERROR(VLOOKUP(F$3,Data_Entry!$C:$AB,Data_Entry!$A6,0),"") -> 1564.08 | G8: =IFERROR(VLOOKUP(G$3,Data_Entry!$C:$AB,Data_Entry!$A6,0),"") -> 1587.14 | H8: =IFERROR(VLOOKUP(H$3,Data_Entry!$C:$AB,Data_Entry!$A6,0),"") -> 0 | I8: =IFERROR(VLOOKUP(I$3,Data_Entry!$C:$AB,Data_Entry!$A6,0),"") -> 0 | ... AF8: =IFERROR(VLOOKUP(AF$3,Data_Entry!$C:$AB,Data_Entry!$A6,0),"") -> 0 | AG8: =IFERROR(SUM(B8:AF8),"") -> 9541.86
A9: Inv_6 | B9: =IFERROR(VLOOKUP(B$3,Data_Entry!$C:$AB,Data_Entry!$A7,0),"") -> 1575.84 | C9: =IFERROR(VLOOKUP(C$3,Data_Entry!$C:$AB,Data_Entry!$A7,0),"") -> 1622.77 | D9: =IFERROR(VLOOKUP(D$3,Data_Entry!$C:$AB,Data_Entry!$A7,0),"") -> 1460.8 | E9: =IFERROR(VLOOKUP(E$3,Data_Entry!$C:$AB,Data_Entry!$A7,0),"") -> 1688.58 | F9: =IFERROR(VLOOKUP(F$3,Data_Entry!$C:$AB,Data_Entry!$A7,0),"") -> 1573.66 | G9: =IFERROR(VLOOKUP(G$3,Data_Entry!$C:$AB,Data_Entry!$A7,0),"") -> 1602.68 | H9: =IFERROR(VLOOKUP(H$3,Data_Entry!$C:$AB,Data_Entry!$A7,0),"") -> 0 | I9: =IFERROR(VLOOKUP(I$3,Data_Entry!$C:$AB,Data_Entry!$A7,0),"") -> 0 | ... AF9: =IFERROR(VLOOKUP(AF$3,Data_Entry!$C:$AB,Data_Entry!$A7,0),"") -> 0 | AG9: =IFERROR(SUM(B9:AF9),"") -> 9524.33
A10: Inv_7 | B10: =IFERROR(VLOOKUP(B$3,Data_Entry!$C:$AB,Data_Entry!$A8,0),"") -> 1574.55 | C10: =IFERROR(VLOOKUP(C$3,Data_Entry!$C:$AB,Data_Entry!$A8,0),"") -> 1631.91 | D10: =IFERROR(VLOOKUP(D$3,Data_Entry!$C:$AB,Data_Entry!$A8,0),"") -> 1490.55 | E10: =IFERROR(VLOOKUP(E$3,Data_Entry!$C:$AB,Data_Entry!$A8,0),"") -> 1724.34 | F10: =IFERROR(VLOOKUP(F$3,Data_Entry!$C:$AB,Data_Entry!$A8,0),"") -> 1564.87 | G10: =IFERROR(VLOOKUP(G$3,Data_Entry!$C:$AB,Data_Entry!$A8,0),"") -> 1584.38 | H10: =IFERROR(VLOOKUP(H$3,Data_Entry!$C:$AB,Data_Entry!$A8,0),"") -> 0 | I10: =IFERROR(VLOOKUP(I$3,Data_Entry!$C:$AB,Data_Entry!$A8,0),"") -> 0 | ... AF10: =IFERROR(VLOOKUP(AF$3,Data_Entry!$C:$AB,Data_Entry!$A8,0),"") -> 0 | AG10: =IFERROR(SUM(B10:AF10),"") -> 9570.6
A11: Inv_8 | B11: =IFERROR(VLOOKUP(B$3,Data_Entry!$C:$AB,Data_Entry!$A9,0),"") -> 1582.79 | C11: =IFERROR(VLOOKUP(C$3,Data_Entry!$C:$AB,Data_Entry!$A9,0),"") -> 1659.98 | D11: =IFERROR(VLOOKUP(D$3,Data_Entry!$C:$AB,Data_Entry!$A9,0),"") -> 1559.32 | E11: =IFERROR(VLOOKUP(E$3,Data_Entry!$C:$AB,Data_Entry!$A9,0),"") -> 1799.98 | F11: =IFERROR(VLOOKUP(F$3,Data_Entry!$C:$AB,Data_Entry!$A9,0),"") -> 1628.2 | G11: =IFERROR(VLOOKUP(G$3,Data_Entry!$C:$AB,Data_Entry!$A9,0),"") -> 1642.05 | H11: =IFERROR(VLOOKUP(H$3,Data_Entry!$C:$AB,Data_Entry!$A9,0),"") -> 0 | I11: =IFERROR(VLOOKUP(I$3,Data_Entry!$C:$AB,Data_Entry!$A9,0),"") -> 0 | ... AF11: =IFERROR(VLOOKUP(AF$3,Data_Entry!$C:$AB,Data_Entry!$A9,0),"") -> 0 | AG11: =IFERROR(SUM(B11:AF11),"") -> 9872.32
A12: Inv_9 | B12: =IFERROR(VLOOKUP(B$3,Data_Entry!$C:$AB,Data_Entry!$A10,0),"") -> 1493.82 | C12: =IFERROR(VLOOKUP(C$3,Data_Entry!$C:$AB,Data_Entry!$A10,0),"") -> 1564.89 | D12: =IFERROR(VLOOKUP(D$3,Data_Entry!$C:$AB,Data_Entry!$A10,0),"") -> 1458.21 | E12: =IFERROR(VLOOKUP(E$3,Data_Entry!$C:$AB,Data_Entry!$A10,0),"") -> 1683.11 | F12: =IFERROR(VLOOKUP(F$3,Data_Entry!$C:$AB,Data_Entry!$A10,0),"") -> 1537.8 | G12: =IFERROR(VLOOKUP(G$3,Data_Entry!$C:$AB,Data_Entry!$A10,0),"") -> 1555.85 | H12: =IFERROR(VLOOKUP(H$3,Data_Entry!$C:$AB,Data_Entry!$A10,0),"") -> 0 | I12: =IFERROR(VLOOKUP(I$3,Data_Entry!$C:$AB,Data_Entry!$A10,0),"") -> 0 | ... AF12: =IFERROR(VLOOKUP(AF$3,Data_Entry!$C:$AB,Data_Entry!$A10,0),"") -> 0 | AG12: =IFERROR(SUM(B12:AF12),"") -> 9293.68
A13: Inv_10 | B13: =IFERROR(VLOOKUP(B$3,Data_Entry!$C:$AB,Data_Entry!$A11,0),"") -> 1494.13 | C13: =IFERROR(VLOOKUP(C$3,Data_Entry!$C:$AB,Data_Entry!$A11,0),"") -> 1578.12 | D13: =IFERROR(VLOOKUP(D$3,Data_Entry!$C:$AB,Data_Entry!$A11,0),"") -> 1449.12 | E13: =IFERROR(VLOOKUP(E$3,Data_Entry!$C:$AB,Data_Entry!$A11,0),"") -> 1672.37 | F13: =IFERROR(VLOOKUP(F$3,Data_Entry!$C:$AB,Data_Entry!$A11,0),"") -> 1534.23 | G13: =IFERROR(VLOOKUP(G$3,Data_Entry!$C:$AB,Data_Entry!$A11,0),"") -> 1556.26 | H13: =IFERROR(VLOOKUP(H$3,Data_Entry!$C:$AB,Data_Entry!$A11,0),"") -> 0 | I13: =IFERROR(VLOOKUP(I$3,Data_Entry!$C:$AB,Data_Entry!$A11,0),"") -> 0 | ... AF13: =IFERROR(VLOOKUP(AF$3,Data_Entry!$C:$AB,Data_Entry!$A11,0),"") -> 0 | AG13: =IFERROR(SUM(B13:AF13),"") -> 9284.23
A14: Inv_11 | B14: =IFERROR(VLOOKUP(B$3,Data_Entry!$C:$AB,Data_Entry!$A12,0),"") -> 1495.98 | C14: =IFERROR(VLOOKUP(C$3,Data_Entry!$C:$AB,Data_Entry!$A12,0),"") -> 1566.52 | D14: =IFERROR(VLOOKUP(D$3,Data_Entry!$C:$AB,Data_Entry!$A12,0),"") -> 1449.37 | E14: =IFERROR(VLOOKUP(E$3,Data_Entry!$C:$AB,Data_Entry!$A12,0),"") -> 1678.1 | F14: =IFERROR(VLOOKUP(F$3,Data_Entry!$C:$AB,Data_Entry!$A12,0),"") -> 1527 | G14: =IFERROR(VLOOKUP(G$3,Data_Entry!$C:$AB,Data_Entry!$A12,0),"") -> 1561.11 | H14: =IFERROR(VLOOKUP(H$3,Data_Entry!$C:$AB,Data_Entry!$A12,0),"") -> 0 | I14: =IFERROR(VLOOKUP(I$3,Data_Entry!$C:$AB,Data_Entry!$A12,0),"") -> 0 | ... AF14: =IFERROR(VLOOKUP(AF$3,Data_Entry!$C:$AB,Data_Entry!$A12,0),"") -> 0 | AG14: =IFERROR(SUM(B14:AF14),"") -> 9278.08
A15: Inv_12 | B15: =IFERROR(VLOOKUP(B$3,Data_Entry!$C:$AB,Data_Entry!$A13,0),"") -> 1506.82 | C15: =IFERROR(VLOOKUP(C$3,Data_Entry!$C:$AB,Data_Entry!$A13,0),"") -> 1564.44 | D15: =IFERROR(VLOOKUP(D$3,Data_Entry!$C:$AB,Data_Entry!$A13,0),"") -> 1435.62 | E15: =IFERROR(VLOOKUP(E$3,Data_Entry!$C:$AB,Data_Entry!$A13,0),"") -> 1695.73 | F15: =IFERROR(VLOOKUP(F$3,Data_Entry!$C:$AB,Data_Entry!$A13,0),"") -> 1531.11 | G15: =IFERROR(VLOOKUP(G$3,Data_Entry!$C:$AB,Data_Entry!$A13,0),"") -> 1562.41 | H15: =IFERROR(VLOOKUP(H$3,Data_Entry!$C:$AB,Data_Entry!$A13,0),"") -> 0 | I15: =IFERROR(VLOOKUP(I$3,Data_Entry!$C:$AB,Data_Entry!$A13,0),"") -> 0 | ... AF15: =IFERROR(VLOOKUP(AF$3,Data_Entry!$C:$AB,Data_Entry!$A13,0),"") -> 0 | AG15: =IFERROR(SUM(B15:AF15),"") -> 9296.13
... A18: Inv_15 | B18: =IFERROR(VLOOKUP(B$3,Data_Entry!$C:$AB,Data_Entry!$A16,0),"") -> 1501.72 | C18: =IFERROR(VLOOKUP(C$3,Data_Entry!$C:$AB,Data_Entry!$A16,0),"") -> 1563.67 | D18: =IFERROR(VLOOKUP(D$3,Data_Entry!$C:$AB,Data_Entry!$A16,0),"") -> 1391.26 | E18: =IFERROR(VLOOKUP(E$3,Data_Entry!$C:$AB,Data_Entry!$A16,0),"") -> 1651.57 | F18: =IFERROR(VLOOKUP(F$3,Data_Entry!$C:$AB,Data_Entry!$A16,0),"") -> 1520.65 | G18: =IFERROR(VLOOKUP(G$3,Data_Entry!$C:$AB,Data_Entry!$A16,0),"") -> 1557.74 | H18: =IFERROR(VLOOKUP(H$3,Data_Entry!$C:$AB,Data_Entry!$A16,0),"") -> 0 | I18: =IFERROR(VLOOKUP(I$3,Data_Entry!$C:$AB,Data_Entry!$A16,0),"") -> 0 | ... AF18: =IFERROR(VLOOKUP(AF$3,Data_Entry!$C:$AB,Data_Entry!$A16,0),"") -> 0 | AG18: =IFERROR(SUM(B18:AF18),"") -> 9186.61
A19: Total_Inverter_(kWh) | B19: =SUM(B4:B18) -> 23074.17 | C19: =SUM(C4:C18) -> 24007.97 | D19: =SUM(D4:D18) -> 21449.81 | E19: =SUM(E4:E18) -> 24895.9 | F19: =SUM(F4:F18) -> 22732.48 | G19: =SUM(G4:G18) -> 23733.56 | H19: =SUM(H4:H18) -> 0 | I19: =SUM(I4:I18) -> 0 | ... AG19: =SUM(AG4:AG18) -> 139893.89
A20: Total_ABT_Meter_Export_(kWh) | B20: =IFERROR(VLOOKUP(B$3,Data_Entry!$C:$AB,22,0)," ") -> 22800 | C20: =IFERROR(VLOOKUP(C$3,Data_Entry!$C:$AB,22,0)," ") -> 23750 | D20: =IFERROR(VLOOKUP(D$3,Data_Entry!$C:$AB,22,0)," ") -> 21250 | E20: =IFERROR(VLOOKUP(E$3,Data_Entry!$C:$AB,22,0)," ") -> 24600 | F20: =IFERROR(VLOOKUP(F$3,Data_Entry!$C:$AB,22,0)," ") -> 22500 | G20: =IFERROR(VLOOKUP(G$3,Data_Entry!$C:$AB,22,0)," ") -> 23500 | H20: =IFERROR(VLOOKUP(H$3,Data_Entry!$C:$AB,22,0)," ") -> 0 | I20: =IFERROR(VLOOKUP(I$3,Data_Entry!$C:$AB,22,0)," ") -> 0 | ... AF20: =IFERROR(VLOOKUP(AF$3,Data_Entry!$C:$AB,22,0)," ") -> 0 | AG20: =IFERROR(VLOOKUP(AG$3,[1]Data_Entry!$C:$AB,14,0)," ")
A21: Total_ABT_Meter_Import_(kWh) | B21: =IFERROR(VLOOKUP(B$3,Data_Entry!$C:$AB,25,0)," ") -> 50 | C21: =IFERROR(VLOOKUP(C$3,Data_Entry!$C:$AB,25,0)," ") -> 50 | D21: =IFERROR(VLOOKUP(D$3,Data_Entry!$C:$AB,25,0)," ") -> 50 | E21: =IFERROR(VLOOKUP(E$3,Data_Entry!$C:$AB,25,0)," ") -> 50 | F21: =IFERROR(VLOOKUP(F$3,Data_Entry!$C:$AB,25,0)," ") -> 50 | G21: =IFERROR(VLOOKUP(G$3,Data_Entry!$C:$AB,25,0)," ") -> 50 | H21: =IFERROR(VLOOKUP(H$3,Data_Entry!$C:$AB,25,0)," ") -> 0 | I21: =IFERROR(VLOOKUP(I$3,Data_Entry!$C:$AB,25,0)," ") -> 0 | ... AF21: =IFERROR(VLOOKUP(AF$3,Data_Entry!$C:$AB,25,0)," ") -> 0 | AG21: =IFERROR(VLOOKUP(AG$3,[1]Data_Entry!$C:$AB,17,0)," ")
A22: Total_ABT_Meter_Net_(kWh) | B22: =IFERROR(VLOOKUP(B$3,Data_Entry!$C:$AB,26,0)," ") -> 22750 | C22: =IFERROR(VLOOKUP(C$3,Data_Entry!$C:$AB,26,0)," ") -> 23700 | D22: =IFERROR(VLOOKUP(D$3,Data_Entry!$C:$AB,26,0)," ") -> 21200 | E22: =IFERROR(VLOOKUP(E$3,Data_Entry!$C:$AB,26,0)," ") -> 24550 | F22: =IFERROR(VLOOKUP(F$3,Data_Entry!$C:$AB,26,0)," ") -> 22450 | G22: =IFERROR(VLOOKUP(G$3,Data_Entry!$C:$AB,26,0)," ") -> 23450 | H22: =IFERROR(VLOOKUP(H$3,Data_Entry!$C:$AB,26,0)," ") -> 0 | I22: =IFERROR(VLOOKUP(I$3,Data_Entry!$C:$AB,26,0)," ") -> 0 | ... AF22: =IFERROR(VLOOKUP(AF$3,Data_Entry!$C:$AB,26,0)," ") -> 0 | AG22: =IFERROR(VLOOKUP(AG$3,[1]Data_Entry!$C:$AB,18,0)," ")
A23: GTI | B23: =IFERROR(VLOOKUP(B$3,Data_Entry!$C:$AB,28,0)," ") | C23: =IFERROR(VLOOKUP(C$3,Data_Entry!$C:$AB,28,0)," ") | D23: =IFERROR(VLOOKUP(D$3,Data_Entry!$C:$AB,28,0)," ") | E23: =IFERROR(VLOOKUP(E$3,Data_Entry!$C:$AB,28,0)," ") | F23: =IFERROR(VLOOKUP(F$3,Data_Entry!$C:$AB,28,0)," ") | G23: =IFERROR(VLOOKUP(G$3,Data_Entry!$C:$AB,28,0)," ") | H23: =IFERROR(VLOOKUP(H$3,Data_Entry!$C:$AB,28,0)," ") | I23: =IFERROR(VLOOKUP(I$3,Data_Entry!$C:$AB,28,0)," ") | ... AF23: =IFERROR(VLOOKUP(AF$3,Data_Entry!$C:$AB,28,0)," ")
A24: GHI | B24: =IFERROR(VLOOKUP(B$3,Data_Entry!$C:$AB,27,0)," ") | C24: =IFERROR(VLOOKUP(C$3,Data_Entry!$C:$AB,27,0)," ") | D24: =IFERROR(VLOOKUP(D$3,Data_Entry!$C:$AB,27,0)," ") | E24: =IFERROR(VLOOKUP(E$3,Data_Entry!$C:$AB,27,0)," ") | F24: =IFERROR(VLOOKUP(F$3,Data_Entry!$C:$AB,27,0)," ") | G24: =IFERROR(VLOOKUP(G$3,Data_Entry!$C:$AB,27,0)," ") | H24: =IFERROR(VLOOKUP(H$3,Data_Entry!$C:$AB,27,0)," ") | I24: =IFERROR(VLOOKUP(I$3,Data_Entry!$C:$AB,27,0)," ") | ... AF24: =IFERROR(VLOOKUP(AF$3,Data_Entry!$C:$AB,27,0)," ")
A25: Module_Temp. | B25: =IFERROR(VLOOKUP(B$3,Data_Entry!$C:$AB,31,0)," ") | C25: =IFERROR(VLOOKUP(C$3,Data_Entry!$C:$AB,31,0)," ") | D25: =IFERROR(VLOOKUP(D$3,Data_Entry!$C:$AB,31,0)," ") | E25: =IFERROR(VLOOKUP(E$3,Data_Entry!$C:$AB,31,0)," ") | F25: =IFERROR(VLOOKUP(F$3,Data_Entry!$C:$AB,31,0)," ") | G25: =IFERROR(VLOOKUP(G$3,Data_Entry!$C:$AB,31,0)," ") | H25: =IFERROR(VLOOKUP(H$3,Data_Entry!$C:$AB,31,0)," ") | I25: =IFERROR(VLOOKUP(I$3,Data_Entry!$C:$AB,31,0)," ") | ... AF25: =IFERROR(VLOOKUP(AF$3,Data_Entry!$C:$AB,31,0)," ")
A26: Ambt._Temp. | B26: =IFERROR(VLOOKUP(B$3,Data_Entry!$C:$AB,29,0)," ") | C26: =IFERROR(VLOOKUP(C$3,Data_Entry!$C:$AB,29,0)," ") | D26: =IFERROR(VLOOKUP(D$3,Data_Entry!$C:$AB,29,0)," ") | E26: =IFERROR(VLOOKUP(E$3,Data_Entry!$C:$AB,29,0)," ") | F26: =IFERROR(VLOOKUP(F$3,Data_Entry!$C:$AB,29,0)," ") | G26: =IFERROR(VLOOKUP(G$3,Data_Entry!$C:$AB,29,0)," ") | H26: =IFERROR(VLOOKUP(H$3,Data_Entry!$C:$AB,29,0)," ") | I26: =IFERROR(VLOOKUP(I$3,Data_Entry!$C:$AB,29,0)," ") | ... AF26: =IFERROR(VLOOKUP(AF$3,Data_Entry!$C:$AB,29,0)," ")
A27: Performance_Ratio_(%) | B27: =IFERROR(B20/B23/(Basic_Data!$H$18),"") | C27: =IFERROR(C20/C23/(Basic_Data!$H$18),"") | D27: =IFERROR(D20/D23/(Basic_Data!$H$18),"") | E27: =IFERROR(E20/E23/(Basic_Data!$H$18),"") | F27: =IFERROR(F20/F23/(Basic_Data!$H$18),"") | G27: =IFERROR(G20/G23/(Basic_Data!$H$18),"") | H27: =IFERROR(H20/H23/(Basic_Data!$H$18),"") | I27: =IFERROR(I20/I23/(Basic_Data!$H$18),"") | ... AF27: =IFERROR(AF20/AF23/(Basic_Data!$H$18),"") | AG27: =IFERROR(AG20/AG23/([1]Basic_Data!$G$10),"")
A28: Capacity_Utilization_Factor_(%) | B28: =IFERROR(B20/(Basic_Data!$G$18*24),"") -> 0.23030303 | C28: =IFERROR(C20/(Basic_Data!$G$18*24),"") -> 0.23989899 | D28: =IFERROR(D20/(Basic_Data!$G$18*24),"") -> 0.21464646 | E28: =IFERROR(E20/(Basic_Data!$G$18*24),"") -> 0.24848485 | F28: =IFERROR(F20/(Basic_Data!$G$18*24),"") -> 0.22727273 | G28: =IFERROR(G20/(Basic_Data!$G$18*24),"") -> 0.23737374 | H28: =IFERROR(H20/(Basic_Data!$G$18*24),"") -> 0 | I28: =IFERROR(I20/(Basic_Data!$G$18*24),"") -> 0 | ... AF28: =IFERROR(AF20/(Basic_Data!$G$18*24),"") -> 0 | AG28: =IFERROR(AG20/([1]Basic_Data!$F$10*24),"")
A29: Aux_Consumption_Line_Loss_(%) | B29: =IFERROR((B19-B20)/B19,"") -> 0.011882118 | C29: =IFERROR((C19-C20)/C19,"") -> 0.010745182 | D29: =IFERROR((D19-D20)/D19,"") -> 0.009315234 | E29: =IFERROR((E19-E20)/E19,"") -> 0.011885491 | F29: =IFERROR((F19-F20)/F19,"") -> 0.010226777 | G29: =IFERROR((G19-G20)/G19,"") -> 0.0098409172 | H29: =IFERROR((H19-H20)/H19,"") | I29: =IFERROR((I19-I20)/I19,"") | ... AG29: =IFERROR((AG19-AG20)/AG19,"")

Sheet Data_Entry
B1: Month | C1: Date | D1: Plant_Up_Time | E1: Plant_Down_Time | F1: Inv_1 | G1: Inv_2 | H1: Inv_3 | I1: Inv_4 | J1: Inv_5 | K1: Inv_6 | L1: Inv_7 | M1: Inv_8 | N1: Inv_9 | O1: Inv_10 | P1: Inv_11 | Q1: Inv_12 | R1: Inv_13 | S1: Inv_14 | T1: Inv_15 | U1: Total Inv Gen kWh | V1: ABT_Initial_Export | W1: ABT_Final_Export | X1: Total_Export | Y1: ABT_Initial_Import | Z1: ABT_Final_Import | AA1: Total_Import | AB1: Net_Gen_kWh | AC1: GHI (kwh/m2) | AD1: GTI (kwh/m2) | AE1: Ambt_Temp_Avg | AF1: Module_Temp_Avg | AG1: Wtd_Module_Temp | AH1: Wind Speed | AI1: Rain_Gaug_MM | AJ1: Weather_Condition
A2: 4 | B2: 45747 | C2: 45747 | U2: =SUM(F2:T2) -> 0 | X2: =MAX((W2-V2)*5000,0) -> 0 | AA2: =MAX((Z2-Y2)*3000,0) -> 0 | AB2: =X2-AA2 -> 0
A3: =A2+1 -> 5 | B3: 45748 | C3: 45748 | U3: =SUM(F3:T3) -> 0 | X3: =MAX((W3-V3)*5000,0) -> 0 | AA3: =MAX((Z3-Y3)*5000,0) -> 0 | AB3: =X3-AA3 -> 0
A4: =A3+1 -> 6 | B4: 45749 | C4: 45749 | U4: =SUM(F4:T4) -> 0 | X4: =MAX((W4-V4)*5000,0) -> 0 | AA4: =MAX((Z4-Y4)*5000,0) -> 0 | AB4: =X4-AA4 -> 0
A5: =A4+1 -> 7 | B5: 45750 | C5: 45750 | U5: =SUM(F5:T5) -> 0 | X5: =MAX((W5-V5)*5000,0) -> 0 | AA5: =MAX((Z5-Y5)*5000,0) -> 0 | AB5: =X5-AA5 -> 0
A6: =A5+1 -> 8 | B6: 45751 | C6: 45751 | U6: =SUM(F6:T6) -> 0 | X6: =MAX((W6-V6)*5000,0) -> 0 | AA6: =MAX((Z6-Y6)*5000,0) -> 0 | AB6: =X6-AA6 -> 0
A7: =A6+1 -> 9 | B7: 45752 | C7: 45752 | U7: =SUM(F7:T7) -> 0 | X7: =MAX((W7-V7)*5000,0) -> 0 | AA7: =MAX((Z7-Y7)*5000,0) -> 0 | AB7: =X7-AA7 -> 0
A8: =A7+1 -> 10 | B8: 45753 | C8: 45753 | U8: =SUM(F8:T8) -> 0 | X8: =MAX((W8-V8)*5000,0) -> 0 | AA8: =MAX((Z8-Y8)*5000,0) -> 0 | AB8: =X8-AA8 -> 0
A9: =A8+1 -> 11 | B9: 45754 | C9: 45754 | U9: =SUM(F9:T9) -> 0 | X9: =MAX((W9-V9)*5000,0) -> 0 | AA9: =MAX((Z9-Y9)*5000,0) -> 0 | AB9: =X9-AA9 -> 0
A10: =A9+1 -> 12 | B10: 45755 | C10: 45755 | U10: =SUM(F10:T10) -> 0 | X10: =MAX((W10-V10)*5000,0) -> 0 | AA10: =MAX((Z10-Y10)*5000,0) -> 0 | AB10: =X10-AA10 -> 0
A11: =A10+1 -> 13 | B11: 45756 | C11: 45756 | U11: =SUM(F11:T11) -> 0 | X11: =MAX((W11-V11)*5000,0) -> 0 | AA11: =MAX((Z11-Y11)*5000,0) -> 0 | AB11: =X11-AA11 -> 0
A12: =A11+1 -> 14 | B12: 45757 | C12: 45757 | U12: =SUM(F12:T12) -> 0 | X12: =MAX((W12-V12)*5000,0) -> 0 | AA12: =MAX((Z12-Y12)*5000,0) -> 0 | AB12: =X12-AA12 -> 0
A13: =A12+1 -> 15 | B13: 45758 | C13: 45758 | U13: =SUM(F13:T13) -> 0 | X13: =MAX((W13-V13)*5000,0) -> 0 | AA13: =MAX((Z13-Y13)*5000,0) -> 0 | AB13: =X13-AA13 -> 0
A14: =A13+1 -> 16 | B14: 45759 | C14: 45759 | U14: =SUM(F14:T14) -> 0 | X14: =MAX((W14-V14)*5000,0) -> 0 | AA14: =MAX((Z14-Y14)*5000,0) -> 0 | AB14: =X14-AA14 -> 0
... A72: =A71+1 -> 74 | B72: 45817 | C72: 45817 | U72: =SUM(F72:T72) -> 0 | X72: =MAX((W72-V72)*5000,0) -> 0 | AA72: =MAX((Z72-Y72)*5000,0) -> 0 | AB72: =X72-AA72 -> 0
A73: =A72+1 -> 75 | B73: 45818 | C73: 45818 | F73: 479.05 | G73: 479.22 | H73: 475.46 | I73: 477.38 | J73: 473.68 | K73: 464.18 | L73: 473.68 | M73: 499.04 | N73: 480.76 | O73: 426.79 | P73: 461.88 | Q73: 482.59 | R73: 461.76 | S73: 483.65 | T73: 483.48 | U73: =SUM(F73:T73) -> 7102.6 | V73: 2.24 | W73: 2.24 | X73: =MAX((W73-V73)*5000,0) -> 0 | Z73: 1.92 | AA73: =MAX((Z73-Y73)*5000,0) -> 9600 | AB73: =X73-AA73 -> -9600
A74: =A73+1 -> 76 | B74: 45819 | C74: 45819 | F74: 1441.56 | G74: 1431.88 | H74: 1462.99 | I74: 1462.12 | J74: 1466.89 | K74: 1458.42 | L74: 1474.14 | M74: 1550.44 | N74: 1524.27 | O74: 1377.49 | P74: 1452.24 | Q74: 1524.69 | R74: 1447.08 | S74: 1514.83 | T74: 1516.35 | U74: =SUM(F74:T74) -> 22105.39 | V74: =W73 -> 2.24 | W74: 6.64 | X74: =MAX((W74-V74)*5000,0) -> 22000 | Y74: =Z73 -> 1.92 | Z74: 1.93 | AA74: =MAX((Z74-Y74)*5000,0) -> 50 | AB74: =X74-AA74 -> 21950
A75: =A74+1 -> 77 | B75: 45820 | C75: 45820 | F75: 1322.33 | G75: 1316.77 | H75: 1341.61 | I75: 1342.62 | J75: 1349.17 | K75: 1336.15 | L75: 1322.88 | M75: 1373.95 | N75: 1374.49 | O75: 1277.89 | P75: 1338.14 | Q75: 1389.75 | R75: 1340.7 | S75: 1395.84 | T75: 1394.87 | U75: =SUM(F75:T75) -> 20217.16 | V75: =W74 -> 6.64 | W75: 10.69 | X75: =MAX((W75-V75)*5000,0) -> 20250 | Y75: =Z74 -> 1.93 | Z75: 1.94 | AA75: =MAX((Z75-Y75)*5000,0) -> 50 | AB75: =X75-AA75 -> 20200
A76: =A75+1 -> 78 | B76: 45821 | C76: 45821 | F76: 843.05 | G76: 830.8 | H76: 824.39 | I76: 832.77 | J76: 839.85 | K76: 822.59 | L76: 842.08 | M76: 870.5 | N76: 879.66 | O76: 829.56 | P76: 791.82 | Q76: 863.33 | R76: 882.6 | S76: 834.56 | T76: 859.88 | U76: =SUM(F76:T76) -> 12647.44 | V76: =W75 -> 10.69 | W76: 13.23 | X76: =MAX((W76-V76)*5000,0) -> 12700 | Y76: =Z75 -> 1.94 | Z76: 1.95 | AA76: =MAX((Z76-Y76)*5000,0) -> 50 | AB76: =X76-AA76 -> 12650
A77: =A76+1 -> 79 | B77: 45822 | C77: 45822 | F77: 1356.34 | G77: 1348.14 | H77: 1384.25 | I77: 1380.56 | J77: 1383.57 | K77: 1376.78 | L77: 1394.83 | M77: 1466.25 | N77: 1451.11 | O77: 1316.87 | P77: 1380.97 | Q77: 1446.66 | R77: 1392.1 | S77: 1439.97 | T77: 1450.45 | U77: =SUM(F77:T77) -> 20968.85 | V77: =W76 -> 13.23 | W77: 17.4 | X77: =MAX((W77-V77)*5000,0) -> 20850 | Y77: =Z76 -> 1.95 | Z77: 1.96 | AA77: =MAX((Z77-Y77)*5000,0) -> 50 | AB77: =X77-AA77 -> 20800
A78: =A77+1 -> 80 | B78: 45823 | C78: 45823 | F78: 964.05 | G78: 923.78 | H78: 969.84 | I78: 970.07 | J78: 879.48 | K78: 939.9 | L78: 988.86 | M78: 988.86 | N78: 988.86 | O78: 988.86 | P78: 988.86 | Q78: 988.86 | R78: 988.86 | S78: 988.86 | T78: 988.86 | U78: =SUM(F78:T78) -> 14546.86 | V78: =W77 -> 17.4 | W78: 20.24 | X78: =MAX((W78-V78)*5000,0) -> 14200 | Y78: =Z77 -> 1.96 | Z78: 1.97 | AA78: =MAX((Z78-Y78)*5000,0) -> 50 | AB78: =X78-AA78 -> 14150
A79: =A78+1 -> 81 | B79: 45824 | C79: 45824 | F79: 129.9 | G79: 133.38 | H79: 133.24 | I79: 130.06 | J79: 128.28 | K79: 135.57 | L79: 130.8 | M79: 134.59 | N79: 138.72 | O79: 125.8 | P79: 121.1 | Q79: 133.85 | R79: 131.45 | S79: 125.76 | T79: 133.95 | U79: =SUM(F79:T79) -> 1966.45 | V79: =W78 -> 20.24 | W79: 20.6 | X79: =MAX((W79-V79)*5000,0) -> 1800 | Y79: =Z78 -> 1.97 | Z79: 1.98 | AA79: =MAX((Z79-Y79)*5000,0) -> 50 | AB79: =X79-AA79 -> 1750
A80: =A79+1 -> 82 | B80: 45825 | C80: 45825 | F80: 317.24 | G80: 317.17 | H80: 305.49 | I80: 314.32 | J80: 316.05 | K80: 300.88 | L80: 175.97 | M80: 317.4 | N80: 326.46 | O80: 314.7 | P80: 313.48 | Q80: 303.31 | R80: 291.84 | S80: 312.94 | T80: 317.24 | U80: =SUM(F80:T80) -> 4544.49 | V80: =W79 -> 20.6 | W80: 21.49 | X80: =MAX((W80-V80)*5000,0) -> 4450 | Y80: =Z79 -> 1.98 | Z80: 1.99 | AA80: =MAX((Z80-Y80)*5000,0) -> 50 | AB80: =X80-AA80 -> 4400
A81: =A80+1 -> 83 | B81: 45826 | C81: 45826 | F81: 396.53 | G81: 389.64 | H81: 374.53 | I81: 357.85 | J81: 387.9 | K81: 395.1 | L81: 376.3 | M81: 404.41 | N81: 396.55 | O81: 357.85 | P81: 376.3 | Q81: 395.1 | R81: 374.53 | S81: 393.4 | T81: 396.53 | U81: =SUM(F81:T81) -> 5772.52 | V81: =W80 -> 21.49 | W81: 22.65 | X81: =MAX((W81-V81)*5000,0) -> 5800 | Y81: =Z80 -> 1.99 | Z81: 2 | AA81: =MAX((Z81-Y81)*5000,0) -> 50 | AB81: =X81-AA81 -> 5750
A82: =A81+1 -> 84 | B82: 45827 | C82: 45827 | F82: 1210.15 | G82: 1215.19 | H82: 1205.25 | I82: 1280.05 | J82: 1213.54 | K82: 1189.09 | L82: 1146.6 | M82: 1265.7 | N82: 1211.62 | O82: 1097.67 | P82: 1154.76 | Q82: 1210.04 | R82: 1155.69 | S82: 1206.69 | T82: 1211.82 | U82: =SUM(F82:T82) -> 17973.86 | V82: =W81 -> 22.65 | W82: 26.23 | X82: =MAX((W82-V82)*5000,0) -> 17900 | Y82: =Z81 -> 2 | Z82: 2.01 | AA82: =MAX((Z82-Y82)*5000,0) -> 50 | AB82: =X82-AA82 -> 17850
A83: =A82+1 -> 85 | B83: 45828 | C83: 45828 | F83: 1071.73 | G83: 1075.4 | H83: 1066.09 | I83: 1067.53 | J83: 1070.69 | K83: 1053.62 | L83: 1012.46 | M83: 1090.43 | N83: 1082.73 | O83: 986.61 | P83: 1032.76 | Q83: 1083.19 | R83: 1038.32 | S83: 1074.73 | T83: 1082.76 | U83: =SUM(F83:T83) -> 15889.05 | V83: =W82 -> 26.23 | W83: 29.39 | X83: =MAX((W83-V83)*5000,0) -> 15800 | Y83: =Z82 -> 2.01 | Z83: 2.02 | AA83: =MAX((Z83-Y83)*5000,0) -> 50 | AB83: =X83-AA83 -> 15750
A84: =A83+1 -> 86 | B84: 45829 | C84: 45829 | F84: 922.1 | G84: 929.23 | H84: 920 | I84: 922.08 | J84: 927 | K84: 907.8 | L84: 873.21 | M84: 962.65 | N84: 930.76 | O84: 859.14 | P84: 885.84 | Q84: 928.28 | R84: 888.35 | S84: 926.41 | T84: 931.52 | U84: =SUM(F84:T84) -> 13714.37 | V84: =W83 -> 29.39 | W84: 32.12 | X84: =MAX((W84-V84)*5000,0) -> 13650 | Y84: =Z83 -> 2.02 | Z84: 2.03 | AA84: =MAX((Z84-Y84)*5000,0) -> 50 | AB84: =X84-AA84 -> 13600
A85: =A84+1 -> 87 | B85: 45830 | C85: 45830 | F85: 500.55 | G85: 553.25 | H85: 549.76 | I85: 546.57 | J85: 548.96 | K85: 542.52 | L85: 545.16 | M85: 569.69 | N85: 555.99 | O85: 553.13 | P85: 551.36 | Q85: 553.07 | R85: 549.58 | S85: 524.02 | T85: 550.7 | U85: =SUM(F85:T85) -> 8194.31 | V85: =W84 -> 32.12 | W85: 33.6 | X85: =MAX((W85-V85)*5000,0) -> 7400 | Y85: =Z84 -> 2.03 | Z85: 2.04 | AA85: =MAX((Z85-Y85)*5000,0) -> 50 | AB85: =X85-AA85 -> 7350
... A100: =A99+1 -> 102 | B100: 45845 | C100: 45845 | F100: 616.7 | G100: 624.06 | H100: 612.45 | I100: 618.66 | J100: 617.18 | K100: 610.24 | L100: 618.41 | M100: 643.9 | N100: 621.6 | O100: 617.7 | P100: 594.46 | Q100: 624.15 | R100: 622.01 | S100: 622.92 | T100: 621.33 | U100: =SUM(F100:T100) -> 9285.77 | V100: =W99 -> 63.89 | W100: 65.75 | X100: =MAX((W100-V100)*5000,0) -> 9300 | Y100: =Z99 -> 2.19 | Z100: 2.2 | AA100: =MAX((Z100-Y100)*5000,0) -> 50 | AB100: =X100-AA100 -> 9250
A101: =A100+1 -> 103 | B101: 45846 | C101: 45846 | F101: 1032.44 | G101: 1050.25 | H101: 1025.72 | I101: 1043.36 | J101: 1040.1 | K101: 1020.6 | L101: 1044.22 | M101: 1089.32 | N101: 1022.56 | O101: 1032.5 | P101: 995.17 | Q101: 1045.45 | R101: 1040.1 | S101: 1042.8 | T101: 1037.63 | U101: =SUM(F101:T101) -> 15562.22 | V101: =W100 -> 65.75 | W101: 68.86 | X101: =MAX((W101-V101)*5000,0) -> 15550 | Y101: =Z100 -> 2.2 | Z101: 2.21 | AA101: =MAX((Z101-Y101)*5000,0) -> 50 | AB101: =X101-AA101 -> 15500 | AE101: 0
A102: =A101+1 -> 104 | B102: 45847 | C102: 45847 | F102: 1470.45 | G102: 1480.93 | H102: 1450.17 | I102: 1470.58 | J102: 1452.51 | K102: 1438.5 | L102: 1465.27 | M102: 1496.76 | N102: 1458.68 | O102: 1466.52 | P102: 1415.2 | Q102: 1486.31 | R102: 1477.36 | S102: 1482.35 | T102: 1466.02 | U102: =SUM(F102:T102) -> 21977.61 | V102: =W101 -> 68.86 | W102: 73.25 | X102: =MAX((W102-V102)*5000,0) -> 21950 | Y102: =Z101 -> 2.21 | Z102: 2.22 | AA102: =MAX((Z102-Y102)*5000,0) -> 50 | AB102: =X102-AA102 -> 21900 | AE102: 0
A103: =A102+1 -> 105 | B103: 45848 | C103: 45848 | F103: 877.65 | G103: 890.62 | H103: 870.65 | I103: 882.7 | J103: 977.77 | K103: 863.4 | L103: 870.9 | M103: 850.95 | N103: 865.8 | O103: 893.71 | P103: 866.58 | Q103: 908.27 | R103: 897.58 | S103: 905.09 | T103: 891.97 | U103: =SUM(F103:T103) -> 13313.64 | V103: =W102 -> 73.25 | W103: 75.93 | X103: =MAX((W103-V103)*5000,0) -> 13400 | Y103: =Z102 -> 2.22 | Z103: 2.25 | AA103: =MAX((Z103-Y103)*5000,0) -> 150 | AB103: =X103-AA103 -> 13250 | AE103: 0
A104: =A103+1 -> 106 | B104: 45849 | C104: 45849 | F104: 778.85 | G104: 763.71 | H104: 734.18 | I104: 755.9 | J104: 751.54 | K104: 736.6 | L104: 750.73 | M104: 785.68 | N104: 772.89 | O104: 764.65 | P104: 737.99 | Q104: 775.39 | R104: 767.07 | S104: 771.62 | T104: 758.49 | U104: =SUM(F104:T104) -> 11405.29 | V104: =W103 -> 75.93 | W104: 78.25 | X104: =MAX((W104-V104)*5000,0) -> 11600 | Y104: =Z103 -> 2.25 | Z104: 2.26 | AA104: =MAX((Z104-Y104)*5000,0) -> 50 | AB104: =X104-AA104 -> 11550 | AE104: 0
A105: =A104+1 -> 107 | B105: 45850 | C105: 45850 | F105: 1297.6 | G105: 1321.5 | H105: 1276.62 | I105: 1316.5 | J105: 1305.2 | K105: 1261.16 | L105: 1253.37 | M105: 1265.09 | N105: 1239.26 | O105: 1309.19 | P105: 1259.83 | Q105: 1293 | R105: 1318.96 | S105: 1319.55 | T105: 1303.81 | U105: =SUM(F105:T105) -> 19340.64 | V105: =W104 -> 78.25 | W105: 82.12 | X105: =MAX((W105-V105)*5000,0) -> 19350 | Y105: =Z104 -> 2.26 | Z105: 2.27 | AA105: =MAX((Z105-Y105)*5000,0) -> 50 | AB105: =X105-AA105 -> 19300 | AE105: 0
A106: =A105+1 -> 108 | B106: 45851 | C106: 45851 | F106: 1093.8 | G106: 1122.93 | H106: 1071.55 | I106: 1115.6 | J106: 1112.18 | K106: 1088.6 | L106: 1110.61 | M106: 1165.57 | N106: 1114.93 | O106: 1107.28 | P106: 1068.59 | Q106: 1119.27 | R106: 1118.61 | S106: 1119.56 | T106: 1099.48 | U106: =SUM(F106:T106) -> 16628.56 | V106: =W105 -> 82.12 | W106: 85.48 | X106: =MAX((W106-V106)*5000,0) -> 16800 | Y106: =Z105 -> 2.27 | Z106: 2.28 | AA106: =MAX((Z106-Y106)*5000,0) -> 50 | AB106: =X106-AA106 -> 16750 | AE106: 0
A107: =A106+1 -> 109 | B107: 45852 | C107: 45852 | D107: 0.27083333 | E107: 0.80208333 | F107: 1412.43 | G107: 1486.07 | H107: 1417.51 | I107: 1480.09 | J107: 1472.92 | K107: 1400.64 | L107: 1346.68 | M107: 1371.07 | N107: 1343.55 | O107: 1434.97 | P107: 1390.1 | Q107: 1396.3 | R107: 1495.66 | S107: 1497.65 | T107: 1490.6 | U107: =SUM(F107:T107) -> 21436.24 | V107: 85.48 | W107: 89.78 | X107: =MAX((W107-V107)*5000,0) -> 21500 | Y107: =Z106 -> 2.28 | Z107: 2.29 | AA107: =MAX((Z107-Y107)*5000,0) -> 50 | AB107: =X107-AA107 -> 21450 | AD107: 3.44 | AE107: 30.32 | AJ107: cloudy
A108: =A107+1 -> 110 | B108: 45853 | C108: 45853 | D108: 0.27083333 | E108: 0.80208333 | F108: 874.24 | G108: 932.25 | H108: 902.78 | I108: 926.12 | J108: 926.17 | K108: 903.03 | L108: 918.08 | M108: 965.1 | N108: 943.59 | O108: 936.4 | P108: 905.23 | Q108: 946.68 | R108: 945.8 | S108: 944.56 | T108: 940.98 | U108: =SUM(F108:T108) -> 13911.01 | V108: =W107 -> 89.78 | W108: 92.58 | X108: =MAX((W108-V108)*5000,0) -> 14000 | Y108: =Z107 -> 2.29 | Z108: 2.3 | AA108: =MAX((Z108-Y108)*5000,0) -> 50 | AB108: =X108-AA108 -> 13950
A109: =A108+1 -> 111 | B109: 45854 | C109: 45854 | D109: 0.27083333 | E109: 0.80208333 | F109: 1578.35 | G109: 1651.2 | H109: 1599.78 | I109: 1640.62 | J109: 1625.99 | K109: 1567.68 | L109: 1486.43 | M109: 1514.96 | N109: 1509.09 | O109: 1671.42 | P109: 1574.64 | Q109: 1624.86 | R109: 1671.68 | S109: 1686.31 | T109: 1682.43 | U109: =SUM(F109:T109) -> 24085.44 | V109: =W108 -> 92.58 | W109: 97.37 | X109: =MAX((W109-V109)*5000,0) -> 23950 | Y109: =Z108 -> 2.3 | Z109: 2.31 | AA109: =MAX((Z109-Y109)*5000,0) -> 50 | AB109: =X109-AA109 -> 23900 | AD109: 4.4 | AE109: 30.74 | AJ109: cloudy
A110: =A109+1 -> 112 | B110: 45855 | C110: 45855 | D110: 0.27083333 | E110: 0.80208333 | F110: 1385.84 | G110: 1464.96 | H110: 1426.46 | I110: 1455.38 | J110: 1447.7 | K110: 1426.77 | L110: 1426.86 | M110: 1499.26 | N110: 1484.44 | O110: 1480.03 | P110: 1417.2 | Q110: 1483.16 | R110: 1485.23 | S110: 1478.18 | T110: 1480.4 | U110: =SUM(F110:T110) -> 21841.87 | V110: =W109 -> 97.37 | W110: 101.75 | X110: =MAX((W110-V110)*5000,0) -> 21900 | Y110: =Z109 -> 2.31 | Z110: 2.33 | AA110: =MAX((Z110-Y110)*5000,0) -> 100 | AB110: =X110-AA110 -> 21800 | AD110: 3.46 | AE110: 31.17 | AJ110: cloudy
A111: =A110+1 -> 113 | B111: 45856 | C111: 45856 | D111: 0.27083333 | E111: 0.80208333 | F111: 1177.37 | G111: 1243.36 | H111: 1221.3 | I111: 1241.29 | J111: 1233.92 | K111: 1229.02 | L111: 1227.34 | M111: 1290.91 | N111: 1263.85 | O111: 1258.41 | P111: 1213.84 | Q111: 1270.1 | R111: 1266.36 | S111: 1270.21 | T111: 1264.68 | U111: =SUM(F111:T111) -> 18671.96 | V111: =W110 -> 101.75 | W111: 105.5 | X111: =MAX((W111-V111)*5000,0) -> 18750 | Y111: =Z110 -> 2.33 | Z111: 2.34 | AA111: =MAX((Z111-Y111)*5000,0) -> 50 | AB111: =X111-AA111 -> 18700 | AD111: 3.13 | AE111: 30.54 | AJ111: cloudy
...

Sheet Basic_Data
B2: Details_of_Plant | C2: Values | F2: Inverter_Name | G2: AC_Capacity_MW | H2: Connected_DC_MW
B3: D.O.C(DD-MMM-YYY) | C3: 45818 | F3: Inv-1 | G3: 275
B4: Plant_Name | C4: Kanja | F4: Inv-2 | G4: 275
B5: Longitude_Of_Site | C5: 21.62 °N | F5: Inv-3 | G5: 275
B6: Latitude_Of_Site | C6: 70.69 °E | F6: Inv-4 | G6: 275
B7: DC_Capacity_(kWh) | C7: 4.82216 | F7: Inv-5 | G7: 275
B8: AC_Capacity_(kWh) | C8: 4 | F8: Inv-6 | G8: 275
B9: Connected_DC_Capacity | C9: =SUM(H3:H94) -> 4822.16 | F9: Inv-7 | G9: 275
B10: Multiplying_Factor_(MF) | F10: Inv-8 | G10: 275
B11: No._of_Power_Trafo. | C11: Gujrat_Trafo | F11: Inv-9 | G11: 275
B12: Power_Trafo._Make | C12: 2 | F12: Inv-10 | G12: 275
B13: Inverter_Make | C13: Watt_power | F13: Inv-11 | G13: 275
B14: Inverter_Capacity | C14: 0.275 | F14: Inv-12 | G14: 275
B15: No._of_Inverter | C15: 15 | F15: Inv-13 | G15: 275
B16: Module_Make | C16: EMMVEE | F16: Inv-14 | G16: 275
B17: Module_Rating | C17: 545 | F17: Inv-15 | G17: 275
B18: No._of_Strings/Table | C18: 316 | F18: Total | G18: =SUM(G3:G17) -> 4125 | H18: 4822.16
B19: No._Of_Module_In_Table | C19: 28 for Bifacial
B20: Total_Module | C20: 8848
B21: Switch_Yard_Make_Vendors | C21: ABB
B22: Table_Configuration | C22: 2X28
B23: ABT Meter Make

Sheet Module_Cleaning
C2: Water Consumption
A3: Months | B3: Date | C3: Tanker Qty | D3: Consumption (Capacity(Ltr)* Tanker) | E3: TDS (PPM) | F3: Cycle No. | G3: Invt. No | I3: Module | J3: Cleaned | K3: Before Cleaning PR% | L3: After Cleaning PR% | M3: Balance | N3: Remarks
A4: 45747 | B4: 45747
A5: 45748 | B5: 45748
A6: 45749 | B6: 45749
A7: 45750 | B7: 45750
A8: 45751 | B8: 45751
A9: 45752 | B9: 45752
A10: 45753 | B10: 45753
A11: 45754 | B11: 45754
A12: 45755 | B12: 45755
A13: 45756 | B13: 45756
A14: 45757 | B14: 45757
A15: 45758 | B15: 45758
... A103: 45820 | B103: 45820
A104: 45821 | B104: 45821 | C104: 4 | D104: 4000 | F104: 1 | G104: Inv_1 | H104: =IFERROR(VLOOKUP(G104,[2]Basic_Data!$E$2:$I$9,5,0),"") -> 2 | I104: =IFERROR(VLOOKUP($G104,[2]Basic_Data!$E$2:$H$10,4,0),"") -> 616 | J104: 616 | K104: =IFERROR(VLOOKUP($B104-1,[2]Inverter_PR!$B:$I,[2]Module_Cleaning!H104,0),"") | L104: =IFERROR(VLOOKUP($B104+1,[2]Inverter_PR!$B:$I,[2]Module_Cleaning!H104,0),"") | M104: =IFERROR(I104-J104,"") -> 0 | N104: wet cleaning
A105: 45822 | B105: 45822 | F105: 1 | G105: Inv_2 | H105: 3 | I105: 616 | J105: 616 | K105: =IFERROR(VLOOKUP($B105-1,[2]Inverter_PR!$B:$I,[2]Module_Cleaning!H105,0),"") | L105: =IFERROR(VLOOKUP($B105+1,[2]Inverter_PR!$B:$I,[2]Module_Cleaning!H105,0),"") | M105: 0 | N105: wet cleaning
A106: 45823 | B106: 45823 | F106: 1 | G106: Inv_3 | H106: 4 | I106: 616 | J106: 616 | K106: =IFERROR(VLOOKUP($B106-1,[2]Inverter_PR!$B:$I,[2]Module_Cleaning!H106,0),"") | L106: =IFERROR(VLOOKUP($B106+1,[2]Inverter_PR!$B:$I,[2]Module_Cleaning!H106,0),"") | M106: 0 | N106: wet cleaning
A107: 45824 | B107: 45824 | F107: 1 | G107: Inv_4 | H107: 5 | I107: 616 | J107: 616 | K107: =IFERROR(VLOOKUP($B107-1,[2]Inverter_PR!$B:$I,[2]Module_Cleaning!H107,0),"") | L107: =IFERROR(VLOOKUP($B107+1,[2]Inverter_PR!$B:$I,[2]Module_Cleaning!H107,0),"") | M107: 0 | N107: wet cleaning
A108: 45825 | B108: 45825 | C108: 3 | D108: 3000 | F108: 1 | G108: Inv_5 | H108: =IFERROR(VLOOKUP(G108,[2]Basic_Data!$E$2:$I$9,5,0),"") -> 6 | I108: =IFERROR(VLOOKUP($G108,[2]Basic_Data!$E$2:$H$10,4,0),"") -> 644 | J108: 644 | K108: =IFERROR(VLOOKUP($B108-1,[2]Inverter_PR!$B:$I,[2]Module_Cleaning!H108,0),"") | L108: =IFERROR(VLOOKUP($B108+1,[2]Inverter_PR!$B:$I,[2]Module_Cleaning!H108,0),"") | M108: =IFERROR(I108-J108,"") -> 0 | N108: wet cleaning
A109: 45826 | B109: 45826 | F109: 1 | G109: Inv_6 | H109: 7 | I109: =IFERROR(VLOOKUP($G109,[2]Basic_Data!$E$2:$H$10,4,0),"") -> 644 | J109: 644 | K109: =IFERROR(VLOOKUP($B109-1,[2]Inverter_PR!$B:$I,[2]Module_Cleaning!H109,0),"") | L109: =IFERROR(VLOOKUP($B109+1,[2]Inverter_PR!$B:$I,[2]Module_Cleaning!H109,0),"") | M109: =IFERROR(I109-J109,"") -> 0 | N109: wet cleaning
A110: 45827 | B110: 45827
A111: 45828 | B111: 45828
A112: 45829 | B112: 45829
A113: 45830 | B113: 45830
A114: 45831 | B114: 45831
A115: 45832 | B115: 45832
A116: 45833 | B116: 45833
A117: 45834 | B117: 45834
A118: 45835 | B118: 45835
A119: 45836 | B119: 45836
A120: 45837 | B120: 45837
A121: 45838 | B121: 45838
... A138: 45855 | B138: 45855
A139: 45856 | B139: 45856 | C139: 0 | D139: 0 | E139: 0 | F139: 0 | H139: 0 | I139: 0 | J139: 0 | K139: 0 | L139: 0 | M139: =IFERROR(I139-J139,"") -> 0 | N139: No cleaning
A140: 45857 | B140: 45857 | C140: 0 | D140: 0 | E140: 0 | F140: 0 | H140: 0 | I140: 0 | J140: 0 | K140: 0 | L140: 0 | M140: =IFERROR(I140-J140,"") -> 0 | N140: No cleaning
A141: 45858 | B141: 45858 | C141: 0 | D141: 0 | E141: 0 | F141: 0 | H141: 0 | I141: 0 | J141: 0 | K141: 0 | L141: 0 | M141: =IFERROR(I141-J141,"") -> 0 | N141: All module cleaned by rain
A142: 45859 | B142: 45859 | C142: 0 | D142: 0 | E142: 0 | F142: 0 | H142: 0 | I142: 0 | J142: 0 | K142: 0 | L142: 0 | M142: =IFERROR(I142-J142,"") -> 0 | N142: No cleaning
A143: 45860 | B143: 45860 | C143: 0 | D143: 0 | E143: 0 | F143: 0 | H143: 0 | I143: 0 | J143: 0 | K143: 0 | L143: 0 | M143: =IFERROR(I143-J143,"") -> 0 | N143: No cleaning
A144: 45861 | B144: 45861 | C144: 0 | D144: 0 | E144: 0 | F144: 0 | H144: 0 | I144: 0 | J144: 0 | K144: 0 | L144: 0 | M144: =IFERROR(I144-J144,"") -> 0 | N144: All module cleaned by rain
...

Sheet WMS
A1: Months | B1: Date | C1: GHI | D1: GTI | E1: Module_Temp | F1: Amb_Temp | G1: Derect_Irr | H1: Diffused_Irr | I1: Wind_Speed | J1: Wind_derection | K1: Rain Gauge

Sheet Plant_Down_Time Details
A1: KANZA Plant_Down_Time Details
A2: Month | B2: Date | C2: Power Trafo | D2: Down_Time_Start | E2: Down_Time_Stop | F2: Total_Down_Time | G2: Affected DC Capacity (in KW) | H2: Component Name | I2: Fault Description | J2: Reason_Of_Down | K2: Purposed Action Plan | L2: Corrective_Action_Taken_By_Site_Team
A3: 45833 | B3: 45827 | C3: 1 | D3: 0.48611111 | E3: 0.52083333 | F3: =E3-D3 -> 0.034722222 | G3: 4 | I3: Earth fault | J3: Do wire burinig | K3: Replace Do wire
A4: 45833 | B4: 45828 | C4: 1 | D4: 0.4875 | E4: 0.51736111 | F4: =E4-D4 -> 0.029861111 | G4: 4 | I4: over current | J4: Do wire burinig | K4: Replace Do wire
A5: 45833 | B5: 45828 | C5: 1 | D5: 0.55555556 | E5: 0.58333333 | F5: =E5-D5 -> 0.027777778 | G5: 4 | I5: over current | J5: Do wire burinig | K5: Replace Do wire | L5: complited work done by site team
A6: 45863 | B6: 15/07/25 | C6: 1 | D6: 0.48611111 | E6: 0.52777778 | F6: =E6-D6 -> 0.041666667 | G6: 4 | I6: over current | J6: R phase jumper burinig | K6: New jumper | L6: getco s/s site new DO work done
A7: 45863 | B7: 15/07/26 | C7: 1 | D7: 0.54027778 | E7: 0.58333333 | F7: =E7-D7 -> 0.043055556 | G7: 4 | I7: over current | J7: Do wire burinig
A8: 45863 | B8: 45856 | C8: 1 | D8: 0.49305556 | E8: 0.53819444 | F8: =E8-D8 -> 0.045138889 | G8: 4 | I8: over current | J8: Do wire burinig
A9: 45863 | B9: 45862 | C9: 1 | D9: 0.45833333 | E9: 0.51388889 | F9: =E9-D9 -> 0.055555556 | G9: 4 | I9: over current | J9: Do wire burinig
A10: 45863 | B10: 45868 | C10: 1 | D10: 0.52083333 | E10: 0.68402778 | F10: =E10-D10 -> 0.16319444 | G10: 4 | H10: 11KV CT/PT | I10: over current | J10: R phase ct/pt lug burinig | K10: replace lug
A11: 45872 | B11: 45872 | C11: 1 | D11: 0.70833333 | E11: 0.72916667 | F11: =E11-D11 -> 0.020833333 | G11: 4 | I11: over/undar voltage | J11: gird voltage high in s/s side
A12: 45876 | B12: 45876 | C12: 1 | D12: 0.50416667 | E12: 0.63541667 | F12: =E12-D12 -> 0.13125 | G12: 4 | H12: R Phase jumpar | I12: over/undar voltage | K12: replace lug
A13: 45878 | B13: 45878 | C13: 1 | D13: 0.29166667 | E13: 0.34722222 | F13: =E13-D13 -> 0.055555556 | G13: 4 | I13: over voltage | J13: gird voltage high in s/s side
A14: 228 | B14: 15/08/25 | C14: 1 | D14: 0.4375 | E14: 0.5625 | F14: =E14-D14 -> 0.125 | G14: 4 | H14: CT/PT LUGS | I14: over voltage | J14: lugs burinig | L14: complited work done by site team
A15: 45929 | B15: 29/09/25 | C15: 1 | D15: 0.29166667 | E15: 0.36805556 | F15: =E15-D15 -> 0.076388889 | G15: 4 | L15: GETCO S/S IN DARK
A16: 45932 | B16: 45698 | C16: 1 | D16: 0.625 | E16: 0.79166667 | F16: =E16-D16 -> 0.16666667 | G16: 4 | L16: again plant manully stopped for havey rain
A17: 45964 | B17: 45964 | C17: 1 | D17: 0.46527778 | E17: 0.48263889 | F17: =E17-D17 -> 0.017361111 | G17: 4 | L17: 11 kv bus maintance in GETCO SS SITE
A18: 45976 | B18: 15/11/2025 | C18: 1 | D18: 0.29166667 | E18: 0.51458333 | F18: =E18-D18 -> 0.22291667 | G18: 4 | H18: no fault | J18: GETCO S/S SITE PLANNED OUTAGE

Sheet Plant_Grid_Down_Time_Details
A1: Plant_Grid_Down_Time_Details
A3: Month | B3: Date | C3: Transformer_No. (T-1) | D3: Down_Time_Start | E3: Down_Time_Stop | F3: Total_Down_Time | G3: Comm. Insolation of the Period | H3: Module Temp of the Period | I3: Affected DC Capacity (in KW) | J3: Insolation*Capacity | K3: Generation Loss | L3: Revenue
A4: 45833 | B4: 17/06/25 | C4: 1 | D4: 0.29166667 | E4: 0.45833333 | F4: 0.16666667
A5: 45833 | B5: 17/06/25 | D5: 0.47916667 | E5: 0.57986111 | F5: =E5-D5 -> 0.10069444
A6: 45955 | B6: 4/10//25 | C6: 1 | D6: 0.5625 | E6: 0.58263889 | F6: =E6-D6 -> 0.020138889
A7: 45964 | B7: 45964 | C7: 1 | D7: 0.46527778 | E7: 0.48263889 | F7: =E7-D7 -> 0.017361111 | M7: plant manully stopped for GETCO ss site 11kv bus maintance
A8: 45986 | B8: 45982 | C8: 1 | D8: 0.40625 | E8: 0.42708333 | F8: =E8-D8 -> 0.020833333 | M8: plant manully stopped for GETCO ss site work getco team,
A9: 45986 | B9: 29/11/2025 | C9: 1 | D9: 0.49444444 | E9: 0.50069444 | F9: =E9-D9 -> 0.00625 | M9: plant undar brackdown from getco ss site tripped in over voltage
A10: 46016 | B10: 46008 | C10: 1 | D10: 0.3125 | E10: 0.35347222 | F10: =E10-D10 -> 0.040972222 | M10: LINE VVOLTAGE high in ss
A11: 46026 | B11: 46026 | C11: 1 | D11: 0.60416667 | E11: 0.60833333 | F11: =E11-D11 -> 0.0041666667 | M11: from getco site gried drop
A12: 46028 | B12: 46029 | C12: 1 | D12: 0.52291667 | E12: 0.525 | F12: =E12-D12 -> 0.0020833333 | M12: getco site grid voltage hige
A13: 46029 | B13: 46030 | C13: 1 | D13: 0.69861111 | E13: 0.69930556 | F13: =E13-D13 -> 0.00069444444
A14: 16/01/2026 | B14: 16/01/2026 | C14: 1 | D14: 0.4125 | E14: 0.41527778 | F14: =E14-D14 -> 0.0027777778 | M14: s/s site grid voltage low
A15: 16/01/2026 | B15: 16/01/2026 | C15: 1 | D15: 0.66805556 | E15: 0.67152778 | F15: =E15-D15 -> 0.0034722222 | M15: s/s site grid voltage low
A16: 24/01/2026 | B16: 24/01/2026 | C16: 1 | D16: 0.49722222 | E16: 0.50069444 | F16: =E16-D16 -> 0.0034722222 | M16: s/s site grid voltage high
A17: 46069 | B17: 46069 | C17: 1 | D17: 0.52638889 | E17: 0.53333333 | F17: =E17-D17 -> 0.0069444444 | M17: s/s site grid voltage high
A18: 46071 | B18: 46071 | C18: 1 | D18: 0.55138889 | E18: 0.55416667 | F18: =E18-D18 -> 0.0027777778 | M18: s/s site grid voltage high
A19: 46075 | B19: 46075 | C19: 1 | D19: 12.27 | E19: 12.31 | F19: =E19-D19 -> 0.04 | M19: s/s site grid voltage high
A20: 46076 | B20: 46076 | C20: 1 | D20: 0.44583333 | E20: 0.50694444 | F20: =E20-D20 -> 0.061111111 | M20: plant site Y pashe jumper burned
A21: 46079 | B21: 46079 | C21: 1 | D21: 0.49097222 | E21: 0.61111111 | F21: =E21-D21 -> 0.12013889 | M21: s/s site Y pashe B pashe jumper burned
A22: 46081 | B22: 46081 | C22: 1 | D22: 0.39652778 | E22: 0.65625 | F22: =E22-D22 -> 0.25972222 | M22: inverter 8 under breakdown 1 string foulty
A23: 46084 | B23: 46084 | C23: 1 | D23: 0.47083333 | E23: 0.53888889 | F23: =E23-D23 -> 0.068055556 | M23: s/s site B pashe jumper burenin
A24: 46085 | B24: 46085 | C24: 1 | D24: 0.51111111 | E24: 0.65694444 | F24: =E24-D24 -> 0.14583333 | M24: plant load shedding inv no 1 stop
A25: 46088 | B25: 46088 | C25: 1 | D25: 0.48888889 | E25: 0.5625 | F25: =E25-D25 -> 0.073611111 | M25: plant site Y pashe jumper burned
A26: 46106 | B26: 46106 | C26: 1 | D26: 0.37152778 | E26: 0.42708333 | F26: =E26-D26 -> 0.055555556 | M26: 8 number inveter 1 string fualty remove
A27: 46123 | B27: 46123 | C27: 1 | D27: 0.67916667 | E27: 0.68263889 | F27: =E27-D27 -> 0.0034722222 | M27: s/s site grid voltage high
A28: 46163 | B28: 46163 | C28: 1 | D28: 0.29166667 | E28: 0.61458333 | F28: =E28-D28 -> 0.32291667 | M28: substation site planned outage
... A30: 46172 | B30: 46172 | C30: 1 | D30: 0.49166667 | E30: 0.59166667 | F30: =E30-D30 -> 0.1 | M30: both site r phase jumper lugs burned

Sheet Plant Aviliblity
A1: Date | B1: ABT Export Gen | C1: Total inevrter off | D1: GHI | E1: CUF% | F1: Out | G1: In | H1: Total Minute | I1: Outage Hrs. | J1: Plant Capacity | K1: Outage Capacity | L1: Plant Capacity Ratio | M1: Outage Ratio | N1: Plant Availiblity | O1: PA.C CUF | P1: total curtailment | Q1: P.A.C Generation | R1: PA Unit Lose
A2: 45839 | B2: =Data_Entry!X94 -> 15900 | C2: 0 | D2: =Data_Entry!AD94 -> 0 | E2: =B2/(24*J2) -> 0.16060606 | F2: 0 | G2: 0 | H2: =(G2-F2)*24*60 -> 0 | I2: =H2/60 -> 0 | J2: 4125 | K2: 0 | L2: =J2*12 -> 49500 | M2: =K2*I2 -> 0 | N2: =(L2-M2)/L2 -> 1 | O2: =E2/N2 -> 0.16060606 | Q2: =O2*J2*24 -> 15900 | R2: =Q2-B2 -> 0
A3: 45840 | B3: =Data_Entry!X95 -> 12000 | C3: 0 | D3: =Data_Entry!AD95 -> 0 | E3: =B3/(24*J3) -> 0.12121212 | F3: 0 | G3: 0 | H3: =(G3-F3)*24*60 -> 0 | I3: =H3/60 -> 0 | J3: 4125 | K3: 0 | L3: =J3*12 -> 49500 | M3: =K3*I3 -> 0 | N3: =(L3-M3)/L3 -> 1 | O3: =E3/N3 -> 0.12121212 | Q3: =O3*J3*24 -> 12000 | R3: =Q3-B3 -> 0
A4: 45841 | B4: =Data_Entry!X96 -> 5150 | C4: 0 | D4: =Data_Entry!AD96 -> 0 | E4: =B4/(24*J4) -> 0.052020202 | F4: 0.041666667 | G4: 0.041666667 | H4: =(G4-F4)*24*60 -> 0 | I4: =H4/60 -> 0 | J4: 4125 | K4: 0 | L4: =J4*12 -> 49500 | M4: =K4*I4 -> 0 | N4: =(L4-M4)/L4 -> 1 | O4: =E4/N4 -> 0.052020202 | Q4: =O4*J4*24 -> 5150 | R4: =Q4-B4 -> 0
A5: 45842 | B5: =Data_Entry!X97 -> 9900 | C5: 0 | D5: =Data_Entry!AD97 -> 0 | E5: =B5/(24*J5) -> 0.1 | F5: 0.083333333 | G5: 0.083333333 | H5: =(G5-F5)*24*60 -> 0 | I5: =H5/60 -> 0 | J5: 4125 | K5: 0 | L5: =J5*12 -> 49500 | M5: =K5*I5 -> 0 | N5: =(L5-M5)/L5 -> 1 | O5: =E5/N5 -> 0.1 | Q5: =O5*J5*24 -> 9900 | R5: =Q5-B5 -> 0
A6: 45843 | B6: =Data_Entry!X98 -> 9450 | C6: 0 | D6: =Data_Entry!AD98 -> 0 | E6: =B6/(24*J6) -> 0.095454545 | F6: 0.41666667 | G6: 0.48958333 | H6: =(G6-F6)*24*60 -> 105 | I6: =H6/60 -> 1.75 | J6: 4125 | K6: 0 | L6: =J6*12 -> 49500 | M6: =K6*I6 -> 0 | N6: =(L6-M6)/L6 -> 1 | O6: =E6/N6 -> 0.095454545 | Q6: =O6*J6*24 -> 9450 | R6: =Q6-B6 -> 0
A7: 45844 | B7: =Data_Entry!X99 -> 13800 | C7: 0 | D7: =Data_Entry!AD99 -> 0 | E7: =B7/(24*J7) -> 0.13939394 | F7: 0 | G7: 0 | H7: =(G7-F7)*24*60 -> 0 | I7: =H7/60 -> 0 | J7: 4125 | K7: 0 | L7: =J7*12 -> 49500 | M7: =K7*I7 -> 0 | N7: =(L7-M7)/L7 -> 1 | O7: =E7/N7 -> 0.13939394 | Q7: =O7*J7*24 -> 13800 | R7: =Q7-B7 -> 0
A8: 45845 | B8: =Data_Entry!X100 -> 9300 | C8: 0 | D8: =Data_Entry!AD100 -> 0 | E8: =B8/(24*J8) -> 0.093939394 | F8: 0 | G8: 0 | H8: =(G8-F8)*24*60 -> 0 | I8: =H8/60 -> 0 | J8: 4125 | K8: 0 | L8: =J8*12 -> 49500 | M8: =K8*I8 -> 0 | N8: =(L8-M8)/L8 -> 1 | O8: =E8/N8 -> 0.093939394 | Q8: =O8*J8*24 -> 9300 | R8: =Q8-B8 -> 0
A9: 45846 | B9: =Data_Entry!X101 -> 15550 | C9: 0 | D9: =Data_Entry!AD101 -> 0 | E9: =B9/(24*J9) -> 0.15707071 | F9: 0 | G9: 0 | H9: =(G9-F9)*24*60 -> 0 | I9: =H9/60 -> 0 | J9: 4125 | K9: 0 | L9: =J9*12 -> 49500 | M9: =K9*I9 -> 0 | N9: =(L9-M9)/L9 -> 1 | O9: =E9/N9 -> 0.15707071 | Q9: =O9*J9*24 -> 15550 | R9: =Q9-B9 -> 0
A10: 45847 | B10: =Data_Entry!X102 -> 21950 | C10: 0 | D10: =Data_Entry!AD102 -> 0 | E10: =B10/(24*J10) -> 0.22171717 | F10: 0 | G10: 0 | H10: =(G10-F10)*24*60 -> 0 | I10: =H10/60 -> 0 | J10: 4125 | K10: 0 | L10: =J10*12 -> 49500 | M10: =K10*I10 -> 0 | N10: =(L10-M10)/L10 -> 1 | O10: =E10/N10 -> 0.22171717 | Q10: =O10*J10*24 -> 21950 | R10: =Q10-B10 -> 0
A11: 45848 | B11: =Data_Entry!X103 -> 13400 | C11: 0 | D11: =Data_Entry!AD103 -> 0 | E11: =B11/(24*J11) -> 0.13535354 | F11: 0 | G11: 0 | H11: =(G11-F11)*24*60 -> 0 | I11: =H11/60 -> 0 | J11: 4125 | K11: 0 | L11: =J11*12 -> 49500 | M11: =K11*I11 -> 0 | N11: =(L11-M11)/L11 -> 1 | O11: =E11/N11 -> 0.13535354 | Q11: =O11*J11*24 -> 13400 | R11: =Q11-B11 -> 0
A12: 45849 | B12: =Data_Entry!X104 -> 11600 | C12: 0 | D12: =Data_Entry!AD104 -> 0 | E12: =B12/(24*J12) -> 0.11717172 | F12: 0 | G12: 0 | H12: =(G12-F12)*24*60 -> 0 | I12: =H12/60 -> 0 | J12: 4125 | K12: 0 | L12: =J12*12 -> 49500 | M12: =K12*I12 -> 0 | N12: =(L12-M12)/L12 -> 1 | O12: =E12/N12 -> 0.11717172 | Q12: =O12*J12*24 -> 11600 | R12: =Q12-B12 -> 0
A13: 45850 | B13: =Data_Entry!X105 -> 19350 | C13: 0 | D13: =Data_Entry!AD105 -> 0 | E13: =B13/(24*J13) -> 0.19545455 | F13: 0 | G13: 0 | H13: =(G13-F13)*24*60 -> 0 | I13: =H13/60 -> 0 | J13: 4125 | K13: 0 | L13: =J13*12 -> 49500 | M13: =K13*I13 -> 0 | N13: =(L13-M13)/L13 -> 1 | O13: =E13/N13 -> 0.19545455 | Q13: =O13*J13*24 -> 19350 | R13: =Q13-B13 -> 0
... A15: 45852 | B15: =Data_Entry!X107 -> 21500 | C15: 0 | D15: =Data_Entry!AD107 -> 3.44 | E15: =B15/(24*J15) -> 0.21717172 | F15: 0 | G15: 0 | H15: =(G15-F15)*24*60 -> 0 | I15: =H15/60 -> 0 | J15: 4125 | K15: 0 | L15: =J15*12 -> 49500 | M15: =K15*I15 -> 0 | N15: =(L15-M15)/L15 -> 1 | O15: =E15/N15 -> 0.21717172 | Q15: =O15*J15*24 -> 21500 | R15: =Q15-B15 -> 0
A16: 45853 | B16: =Data_Entry!X108 -> 14000 | C16: 7 | D16: =Data_Entry!AD108 -> 0 | E16: =B16/(24*J16) -> 0.14141414 | F16: 0.48611111 | G16: 0.52777778 | H16: 125 | I16: =H16/60 -> 2.0833333 | J16: 4125 | K16: 4822.16 | L16: =J16*12 -> 49500 | M16: =K16*I16 -> 10046.167 | N16: =(L16-M16)/L16 -> 0.79704714 | O16: =E16/N16 -> 0.17742256 | Q16: =O16*J16*24 -> 17564.833 | R16: =Q16-B16 -> 3564.8332
A17: 45854 | B17: =Data_Entry!X109 -> 23950 | C17: 0 | D17: =Data_Entry!AD109 -> 4.4 | E17: =B17/(24*J17) -> 0.24191919 | F17: 0 | G17: 0 | H17: =(G17-F17)*24*60 -> 0 | I17: =H17/60 -> 0 | J17: 4125 | K17: 0 | L17: =J17*12 -> 49500 | M17: =K17*I17 -> 0 | N17: =(L17-M17)/L17 -> 1 | O17: =E17/N17 -> 0.24191919 | Q17: =O17*J17*24 -> 23950 | R17: =Q17-B17 -> 0
A18: 45855 | B18: =Data_Entry!X110 -> 21900 | C18: 0 | D18: =Data_Entry!AD110 -> 3.46 | E18: =B18/(24*J18) -> 0.22121212 | F18: 0 | G18: 0 | H18: =(G18-F18)*24*60 -> 0 | I18: =H18/60 -> 0 | J18: 4125 | K18: 0 | L18: =J18*12 -> 49500 | M18: =K18*I18 -> 0 | N18: =(L18-M18)/L18 -> 1 | O18: =E18/N18 -> 0.22121212 | Q18: =O18*J18*24 -> 21900 | R18: =Q18-B18 -> 0
A19: 45856 | B19: =Data_Entry!X111 -> 18750 | C19: 15 | D19: =Data_Entry!AD111 -> 3.13 | E19: =B19/(24*J19) -> 0.18939394 | F19: ='Plant_Down_Time Details'!D8 -> 0.49305556 | G19: ='Plant_Down_Time Details'!E8 -> 0.53819444 | H19: =(G19-F19)*24*60 -> 65 | I19: =H19/60 -> 1.0833333 | J19: 4125 | K19: 4822.16 | L19: =J19*12 -> 49500 | M19: =K19*I19 -> 5224.0067 | N19: =(L19-M19)/L19 -> 0.89446451 | O19: =E19/N19 -> 0.21174003 | Q19: =O19*J19*24 -> 20962.263 | R19: =Q19-B19 -> 2212.2626
A20: 45857 | B20: =Data_Entry!X112 -> 13050 | C20: 0 | D20: =Data_Entry!AD112 -> 1.9 | E20: =B20/(24*J20) -> 0.13181818 | F20: 0 | G20: 0 | H20: =(G20-F20)*24*60 -> 0 | I20: =H20/60 -> 0 | J20: 4125 | K20: 0 | L20: =J20*12 -> 49500 | M20: =K20*I20 -> 0 | N20: =(L20-M20)/L20 -> 1 | O20: =E20/N20 -> 0.13181818 | Q20: =O20*J20*24 -> 13050 | R20: =Q20-B20 -> 0
A21: 45858 | B21: =Data_Entry!X113 -> 12400 | C21: 0 | D21: =Data_Entry!AD113 -> 1.81 | E21: =B21/(24*J21) -> 0.12525253 | F21: 0 | G21: 0 | H21: =(G21-F21)*24*60 -> 0 | I21: =H21/60 -> 0 | J21: 4125 | K21: 0 | L21: =J21*12 -> 49500 | M21: =K21*I21 -> 0 | N21: =(L21-M21)/L21 -> 1 | O21: =E21/N21 -> 0.12525253 | Q21: =O21*J21*24 -> 12400 | R21: =Q21-B21 -> 0
A22: 45859 | B22: =Data_Entry!X114 -> 15000 | C22: 0 | D22: =Data_Entry!AD114 -> 2.13 | E22: =B22/(24*J22) -> 0.15151515 | F22: 0 | G22: 0 | H22: =(G22-F22)*24*60 -> 0 | I22: =H22/60 -> 0 | J22: 4125 | K22: 0 | L22: =J22*12 -> 49500 | M22: =K22*I22 -> 0 | N22: =(L22-M22)/L22 -> 1 | O22: =E22/N22 -> 0.15151515 | Q22: =O22*J22*24 -> 15000 | R22: =Q22-B22 -> 0
A23: 45860 | B23: =Data_Entry!X115 -> 13800 | C23: 0 | D23: =Data_Entry!AD115 -> 2.01 | E23: =B23/(24*J23) -> 0.13939394 | F23: 0 | G23: 0 | H23: =(G23-F23)*24*60 -> 0 | I23: =H23/60 -> 0 | J23: 4125 | K23: 0 | L23: =J23*12 -> 49500 | M23: =K23*I23 -> 0 | N23: =(L23-M23)/L23 -> 1 | O23: =E23/N23 -> 0.13939394 | Q23: =O23*J23*24 -> 13800 | R23: =Q23-B23 -> 0
A24: 45861 | B24: =Data_Entry!X116 -> 18550 | C24: 0 | D24: =Data_Entry!AD116 -> 2.89 | E24: =B24/(24*J24) -> 0.18737374 | F24: 0 | G24: 0 | H24: =(G24-F24)*24*60 -> 0 | I24: =H24/60 -> 0 | J24: 4125 | K24: 0 | L24: =J24*12 -> 49500 | M24: =K24*I24 -> 0 | N24: =(L24-M24)/L24 -> 1 | O24: =E24/N24 -> 0.18737374 | Q24: =O24*J24*24 -> 18550 | R24: =Q24-B24 -> 0
A25: 45862 | B25: =Data_Entry!X117 -> 15000 | C25: 0 | D25: =Data_Entry!AD117 -> 2.28 | E25: =B25/(24*J25) -> 0.15151515 | F25: 0 | G25: 0 | H25: =(G25-F25)*24*60 -> 0 | I25: =H25/60 -> 0 | J25: 4125 | K25: 0 | L25: =J25*12 -> 49500 | M25: =K25*I25 -> 0 | N25: =(L25-M25)/L25 -> 1 | O25: =E25/N25 -> 0.15151515 | Q25: =O25*J25*24 -> 15000 | R25: =Q25-B25 -> 0
