Workbook

Sheet Budgeted_Data
A1: Plant Name | B1: Date | C1: Month | D1: Month | E1: Daily_Gen | F1: Daily_GTI | G1: Daily_GHI | H1: Ambt_Temp | I1: PR_% | J1: CUF_% | K1: TArray | L1: TArrWtd | M1: Connected_DC
A2: Devki_Galol | B2: 45747 | M2: 2411
A3: Devki_Galol | B3: 45748 | E3: 13793.656 | F3: 6.91332 | G3: 6.706944 | H3: 27.415 | I3: 0.82755242 | J3: 0.23838061 | K3: 21.811375 | L3: 21.811375 | M3: 2411
A4: Devki_Galol | B4: 45749 | E4: 14382.297 | F4: 7.241431 | G4: 7.024582 | H4: 26.8775 | I4: 0.82377127 | J4: 0.24855345 | K4: 22.152292 | L4: 22.152292 | M4: 2411
A5: Devki_Galol | B5: 45750 | E5: 15006.04 | F5: 7.635258 | G5: 7.41063 | H5: 28.30125 | I5: 0.81516433 | J5: 0.25933292 | K5: 23.397417 | L5: 23.397417 | M5: 2411
A6: Devki_Galol | B6: 45751 | E6: 15318.708 | F6: 7.804122 | G6: 7.577929 | H6: 28.33 | I6: 0.81414333 | J6: 0.26473641 | K6: 23.414333 | L6: 23.414333 | M6: 2411
A7: Devki_Galol | B7: 45752 | E7: 11372.591 | F7: 5.715388 | G7: 5.502656 | H7: 31.082917 | I7: 0.82530882 | J7: 0.19654 | K7: 22.630083 | L7: 22.630083 | M7: 2411
A8: Devki_Galol | B8: 45753 | E8: 7534.1062 | F8: 3.734185 | G8: 3.585435 | H8: 30.53375 | I8: 0.83683281 | J8: 0.13020369 | K8: 18.428792 | L8: 18.428792 | M8: 2411
A9: Devki_Galol | B9: 45754 | E9: 12437.248 | F9: 6.305604 | G9: 6.098628 | H9: 31.335 | I9: 0.81808868 | J9: 0.2149393 | K9: 23.464417 | L9: 23.464417 | M9: 2411
A10: Devki_Galol | B10: 45755 | E10: 13584.717 | F10: 6.904297 | G10: 6.68637 | H10: 30.85375 | I10: 0.81608222 | J10: 0.23476975 | K10: 23.794542 | L10: 23.794542 | M10: 2411
A11: Devki_Galol | B11: 45756 | E11: 14586.557 | F11: 7.448638 | G11: 7.214318 | H11: 30.165833 | I11: 0.81222941 | J11: 0.25208345 | K11: 24.040792 | L11: 24.040792 | M11: 2411
A12: Devki_Galol | B12: 45757 | E12: 13848.104 | F12: 7.092072 | G12: 6.869304 | H12: 31.859167 | I12: 0.80987868 | J12: 0.23932158 | K12: 24.644167 | L12: 24.644167 | M12: 2411
A13: Devki_Galol | B13: 45758 | E13: 14722.199 | F13: 7.611885 | G13: 7.374694 | H13: 32.392917 | I13: 0.80220109 | J13: 0.2544276 | K13: 25.622083 | L13: 25.622083 | M13: 2411
A14: Devki_Galol | B14: 45759 | E14: 14667.795 | F14: 7.477686 | G14: 7.244865 | H14: 29.71 | I14: 0.81358024 | J14: 0.2534874 | K14: 23.866417 | L14: 23.866417 | M14: 2411
... A367: Devki_Galol | B367: 46112 | E367: 14312.664 | F367: 7.348117 | G367: 7.129453 | H367: 30.895833 | I367: 0.80788063 | J367: 0.24735006 | K367: 24.667167 | L367: 24.667167 | M367: 2411

Sheet E-Mail_Copy
A1: Plant_Performance_of_Devki_Galol_GJ
B3: =DATE(YEAR(B4),MONTH(B4),1) -> 46174 | C3: =VLOOKUP(L3,Basic_Data!$A$28:$B$48,2,0) -> 45748 | L3: 25-26
A4: Date | B4: 46178 | C4: AC Capacity: | E4: =Basic_Data!F10 -> 1925 | F4: DC Capacity: | H4: =Basic_Data!G10 -> 2411.08 | I4: D.O.C.: | K4: =Basic_Data!B3 -> 45720
A5: Plant Name | C5: Daily | F5: MTD | I5: YTD
C6: Budgeted | D6: Actual | E6: Variation(%) | F6: Budgeted | G6: Actual | H6: Variation(%) | I6: Budgeted | J6: Actual | K6: Variation(%)
A7: Generation_MW | C7: =SUMIFS(Budgeted_Data!$E:$E,Budgeted_Data!$B:$B,'E-Mail_Copy'!$B$4) -> 0 | D7: =SUMIFS(Data_Entry!$T:$T,Data_Entry!$C:$C,'E-Mail_Copy'!$B$4) -> 10350 | E7: =(D7-C7)/C7 -> #DIV/0! | F7: =SUMIFS(Budgeted_Data!$E:$E,Budgeted_Data!$B:$B,">="&'E-Mail_Copy'!$B$3,Budgeted_Data!$B:$B,"<="&'E-Mail_Copy'!$B$4) -> 0 | G7: =SUMIFS(Data_Entry!$T:$T,Data_Entry!$C:$C,">="&'E-Mail_Copy'!$B$3,Data_Entry!$C:$C,"<="&'E-Mail_Copy'!$B$4) -> 56010 | H7: =(G7-F7)/F7 -> #DIV/0! | I7: =SUMIFS(Budgeted_Data!$E:$E,Budgeted_Data!$B:$B,">="&'E-Mail_Copy'!$C$3,Budgeted_Data!$B:$B,"<="&'E-Mail_Copy'!$B$4) -> 4129749.1 | J7: =SUMIFS(Data_Entry!$T:$T,Data_Entry!$C:$C,">="&'E-Mail_Copy'!$C$3,Data_Entry!$C:$C,"<="&'E-Mail_Copy'!$B$4) -> 4625010 | K7: =(J7-I7)/I7 -> 0.11992518
A8: GTI (Kwh/m2) | C8: =SUMIFS(Budgeted_Data!$F:$F,Budgeted_Data!$B:$B,'E-Mail_Copy'!$B$4) -> 0 | D8: =SUMIFS(Data_Entry!$V:$V,Data_Entry!$C:$C,'E-Mail_Copy'!B4) -> 3.66 | E8: =(D8-C8)/C8 -> #DIV/0! | F8: =SUMIFS(Budgeted_Data!$F:$F,Budgeted_Data!$B:$B,">="&'E-Mail_Copy'!$B$3,Budgeted_Data!$B:$B,"<="&'E-Mail_Copy'!$B$4) -> 0 | G8: =SUMIFS(Data_Entry!$V:$V,Data_Entry!$C:$C,">="&'E-Mail_Copy'!$B$3,Data_Entry!$C:$C,"<="&'E-Mail_Copy'!$B$4) -> 23.67 | H8: =(G8-F8)/F8 -> #DIV/0! | I8: =SUMIFS(Budgeted_Data!$F:$F,Budgeted_Data!$B:$B,">="&'E-Mail_Copy'!$C$3,Budgeted_Data!$B:$B,"<="&'E-Mail_Copy'!$B$4) -> 2080.1765 | J8: =SUMIFS(Data_Entry!$V:$V,Data_Entry!$C:$C,">="&'E-Mail_Copy'!$C$3,Data_Entry!$C:$C,"<="&'E-Mail_Copy'!$B$4) -> 1555.6445 | K8: =(J8-I8)/I8 -> -0.25215744
A9: GHI (Kwh/m2) | C9: =SUMIFS(Budgeted_Data!$G:$G,Budgeted_Data!$B:$B,'E-Mail_Copy'!$B$4) -> 0 | D9: =SUMIFS(Data_Entry!$U:$U,Data_Entry!$C:$C,'E-Mail_Copy'!$B$4) -> 0 | E9: =(D9-C9)/C9 -> #DIV/0! | F9: =SUMIFS(Budgeted_Data!$G:$G,Budgeted_Data!$B:$B,">="&'E-Mail_Copy'!$B$3,Budgeted_Data!$B:$B,"<="&'E-Mail_Copy'!$B$4) -> 0 | G9: =SUMIFS(Data_Entry!$U:$U,Data_Entry!$C:$C,">="&'E-Mail_Copy'!$B$3,Data_Entry!$C:$C,"<="&'E-Mail_Copy'!$B$4) -> 0 | H9: =(G9-F9)/F9 -> #DIV/0! | I9: =SUMIFS(Budgeted_Data!$G:$G,Budgeted_Data!$B:$B,">="&'E-Mail_Copy'!$C$3,Budgeted_Data!$B:$B,"<="&'E-Mail_Copy'!$B$4) -> 2008.1028 | J9: =SUMIFS(Data_Entry!$U:$U,Data_Entry!$C:$C,">="&'E-Mail_Copy'!$C$3,Data_Entry!$C:$C,"<="&'E-Mail_Copy'!$B$4) -> 0 | K9: =(J9-I9)/I9 -> -1
A10: PR_(%) | C10: =C7/C8/H4 -> #DIV/0! | D10: =D7/D8/H4 -> 1.172864 | E10: =(D10-C10)/C10 -> #DIV/0! | F10: =F7/F8/H4/(B4-B3+1) -> #DIV/0! | G10: =G7/G8/H4/(B4-B3+1) -> 0.19628436 | H10: =(G10-F10)/F10 -> #DIV/0! | I10: =I7/I8/H4/(($B$4-$C$3)+1) -> 0.0019104453 | J10: =J7/J8/H4/(($B$4-$C$3)+1) -> 0.0028609708 | K10: =(J10-I10)/I10 -> 0.49754138
A11: CUF_(%) | C11: =C7/E4/24 -> 0 | D11: =D7/24/E4 -> 0.22402597 | E11: =(D11-C11)/C11 -> #DIV/0! | F11: =F7/24/E4/(B4-B3+1) -> 0 | G11: =G7/24/E4/(B4-B3+1) -> 0.24246753 | H11: =(G11-F11)/F11 -> #DIV/0! | I11: =I7/24/$E$4/(($B$4-$C$3)+1) -> 0.20739793 | J11: =J7/24/$E$4/(($B$4-$C$3)+1) -> 0.23227017 | K11: =(J11-I11)/I11 -> 0.11992518
A12: Wtd_Module_Temp | C12: =AVERAGEIFS(Budgeted_Data!$L:$L,Budgeted_Data!$B:$B,'E-Mail_Copy'!$B$4) -> #DIV/0! | D12: =AVERAGEIFS(Data_Entry!$Y:$Y,Data_Entry!$C:$C,'E-Mail_Copy'!$B$4) -> #DIV/0! | E12: =(D12-C12)/C12 -> #DIV/0! | F12: =AVERAGEIFS(Budgeted_Data!$L:$L,Budgeted_Data!$B:$B,">="&'E-Mail_Copy'!$B$3,Budgeted_Data!$B:$B,"<="&'E-Mail_Copy'!$B$4) -> #DIV/0! | G12: =AVERAGEIFS(Data_Entry!$Y:$Y,Data_Entry!$C:$C,">="&'E-Mail_Copy'!$B$3,Data_Entry!$C:$C,"<="&'E-Mail_Copy'!$B$4) -> #DIV/0! | H12: =(G12-F12)/F12 -> #DIV/0! | I12: =AVERAGEIFS(Budgeted_Data!$L:$L,Budgeted_Data!$B:$B,">="&'E-Mail_Copy'!$C$3,Budgeted_Data!$B:$B,"<="&'E-Mail_Copy'!$B$4) -> 20.137807 | J12: =AVERAGEIFS(Data_Entry!$Y:$Y,Data_Entry!$C:$C,">="&'E-Mail_Copy'!$C$3,Data_Entry!$C:$C,"<="&'E-Mail_Copy'!$B$4) -> #DIV/0! | K12: =(J12-I12)/I12 -> #DIV/0!
A13: Ambt._Temp_(0C) | C13: =AVERAGEIFS(Budgeted_Data!$H:$H,Budgeted_Data!$B:$B,'E-Mail_Copy'!$B$4) -> #DIV/0! | D13: =AVERAGEIFS(Data_Entry!$W:$W,Data_Entry!$C:$C,'E-Mail_Copy'!$B$4) -> 34.09 | E13: =(D13-C13)/C13 -> #DIV/0! | F13: =AVERAGEIFS(Budgeted_Data!$H:$H,Budgeted_Data!$B:$B,">="&'E-Mail_Copy'!$B$3,Budgeted_Data!$B:$B,"<="&'E-Mail_Copy'!$B$4) -> #DIV/0! | G13: =AVERAGEIFS(Data_Entry!$W:$W,Data_Entry!$C:$C,">="&'E-Mail_Copy'!$B$3,Data_Entry!$C:$C,"<="&'E-Mail_Copy'!$B$4) -> 34.292 | H13: =(G13-F13)/F13 -> #DIV/0! | I13: =AVERAGEIFS(Budgeted_Data!$H:$H,Budgeted_Data!$B:$B,">="&'E-Mail_Copy'!$C$3,Budgeted_Data!$B:$B,"<="&'E-Mail_Copy'!$B$4) -> 27.271039 | J13: =AVERAGEIFS(Data_Entry!$W:$W,Data_Entry!$C:$C,">="&'E-Mail_Copy'!$C$3,Data_Entry!$C:$C,"<="&'E-Mail_Copy'!$B$4) -> 28.886026 | K13: =(J13-I13)/I13 -> 0.059219875

Sheet DGR
A1: Daily_Generation_&_Performance_Report
A3: Inverter_No. | B3: ='E-Mail_Copy'!B4 -> 46178 | C3: =B3+1 -> 46179 | D3: =C3+1 -> 46180 | E3: =D3+1 -> 46181 | F3: =E3+1 -> 46182 | G3: =F3+1 -> 46183 | H3: =G3+1 -> 46184 | I3: =H3+1 -> 46185 | J3: =I3+1 -> 46186 | ... AF3: =AE3+1 -> 46208 | AG3: Total/Avg..
A4: Inv_1 | B4: =IFERROR(VLOOKUP(B$3,Data_Entry!$C:$AB,Data_Entry!$A2,0),"") -> 1463.28 | C4: =IFERROR(VLOOKUP(C$3,Data_Entry!$C:$AB,Data_Entry!$A2,0),"") -> 0 | D4: =IFERROR(VLOOKUP(D$3,Data_Entry!$C:$AB,Data_Entry!$A2,0),"") -> 0 | E4: =IFERROR(VLOOKUP(E$3,Data_Entry!$C:$AB,Data_Entry!$A2,0),"") -> 0 | F4: =IFERROR(VLOOKUP(F$3,Data_Entry!$C:$AB,Data_Entry!$A2,0),"") -> 0 | G4: =IFERROR(VLOOKUP(G$3,Data_Entry!$C:$AB,Data_Entry!$A2,0),"") -> 0 | H4: =IFERROR(VLOOKUP(H$3,Data_Entry!$C:$AB,Data_Entry!$A2,0),"") -> 0 | I4: =IFERROR(VLOOKUP(I$3,Data_Entry!$C:$AB,Data_Entry!$A2,0),"") -> 0 | ... AF4: =IFERROR(VLOOKUP(AF$3,Data_Entry!$C:$AB,Data_Entry!$A2,0),"") -> 0 | AG4: =IFERROR(SUM(B4:AF4),"") -> 1463.28
A5: Inv_2 | B5: =IFERROR(VLOOKUP(B$3,Data_Entry!$C:$AB,Data_Entry!$A3,0),"") -> 1456.63 | C5: =IFERROR(VLOOKUP(C$3,Data_Entry!$C:$AB,Data_Entry!$A3,0),"") -> 0 | D5: =IFERROR(VLOOKUP(D$3,Data_Entry!$C:$AB,Data_Entry!$A3,0),"") -> 0 | E5: =IFERROR(VLOOKUP(E$3,Data_Entry!$C:$AB,Data_Entry!$A3,0),"") -> 0 | F5: =IFERROR(VLOOKUP(F$3,Data_Entry!$C:$AB,Data_Entry!$A3,0),"") -> 0 | G5: =IFERROR(VLOOKUP(G$3,Data_Entry!$C:$AB,Data_Entry!$A3,0),"") -> 0 | H5: =IFERROR(VLOOKUP(H$3,Data_Entry!$C:$AB,Data_Entry!$A3,0),"") -> 0 | I5: =IFERROR(VLOOKUP(I$3,Data_Entry!$C:$AB,Data_Entry!$A3,0),"") -> 0 | ... AF5: =IFERROR(VLOOKUP(AF$3,Data_Entry!$C:$AB,Data_Entry!$A3,0),"") -> 0 | AG5: =IFERROR(SUM(B5:AF5),"") -> 1456.63
A6: Inv_3 | B6: =IFERROR(VLOOKUP(B$3,Data_Entry!$C:$AB,Data_Entry!$A4,0),"") -> 1461.19 | C6: =IFERROR(VLOOKUP(C$3,Data_Entry!$C:$AB,Data_Entry!$A4,0),"") -> 0 | D6: =IFERROR(VLOOKUP(D$3,Data_Entry!$C:$AB,Data_Entry!$A4,0),"") -> 0 | E6: =IFERROR(VLOOKUP(E$3,Data_Entry!$C:$AB,Data_Entry!$A4,0),"") -> 0 | F6: =IFERROR(VLOOKUP(F$3,Data_Entry!$C:$AB,Data_Entry!$A4,0),"") -> 0 | G6: =IFERROR(VLOOKUP(G$3,Data_Entry!$C:$AB,Data_Entry!$A4,0),"") -> 0 | H6: =IFERROR(VLOOKUP(H$3,Data_Entry!$C:$AB,Data_Entry!$A4,0),"") -> 0 | I6: =IFERROR(VLOOKUP(I$3,Data_Entry!$C:$AB,Data_Entry!$A4,0),"") -> 0 | ... AF6: =IFERROR(VLOOKUP(AF$3,Data_Entry!$C:$AB,Data_Entry!$A4,0),"") -> 0 | AG6: =IFERROR(SUM(B6:AF6),"") -> 1461.19
A7: Inv_4 | B7: =IFERROR(VLOOKUP(B$3,Data_Entry!$C:$AB,Data_Entry!$A5,0),"") -> 1520.01 | C7: =IFERROR(VLOOKUP(C$3,Data_Entry!$C:$AB,Data_Entry!$A5,0),"") -> 0 | D7: =IFERROR(VLOOKUP(D$3,Data_Entry!$C:$AB,Data_Entry!$A5,0),"") -> 0 | E7: =IFERROR(VLOOKUP(E$3,Data_Entry!$C:$AB,Data_Entry!$A5,0),"") -> 0 | F7: =IFERROR(VLOOKUP(F$3,Data_Entry!$C:$AB,Data_Entry!$A5,0),"") -> 0 | G7: =IFERROR(VLOOKUP(G$3,Data_Entry!$C:$AB,Data_Entry!$A5,0),"") -> 0 | H7: =IFERROR(VLOOKUP(H$3,Data_Entry!$C:$AB,Data_Entry!$A5,0),"") -> 0 | I7: =IFERROR(VLOOKUP(I$3,Data_Entry!$C:$AB,Data_Entry!$A5,0),"") -> 0 | ... AF7: =IFERROR(VLOOKUP(AF$3,Data_Entry!$C:$AB,Data_Entry!$A5,0),"") -> 0 | AG7: =IFERROR(SUM(B7:AF7),"") -> 1520.01
A8: Inv_5 | B8: =IFERROR(VLOOKUP(B$3,Data_Entry!$C:$AB,Data_Entry!$A6,0),"") -> 1507.08 | C8: =IFERROR(VLOOKUP(C$3,Data_Entry!$C:$AB,Data_Entry!$A6,0),"") -> 0 | D8: =IFERROR(VLOOKUP(D$3,Data_Entry!$C:$AB,Data_Entry!$A6,0),"") -> 0 | E8: =IFERROR(VLOOKUP(E$3,Data_Entry!$C:$AB,Data_Entry!$A6,0),"") -> 0 | F8: =IFERROR(VLOOKUP(F$3,Data_Entry!$C:$AB,Data_Entry!$A6,0),"") -> 0 | G8: =IFERROR(VLOOKUP(G$3,Data_Entry!$C:$AB,Data_Entry!$A6,0),"") -> 0 | H8: =IFERROR(VLOOKUP(H$3,Data_Entry!$C:$AB,Data_Entry!$A6,0),"") -> 0 | I8: =IFERROR(VLOOKUP(I$3,Data_Entry!$C:$AB,Data_Entry!$A6,0),"") -> 0 | ... AF8: =IFERROR(VLOOKUP(AF$3,Data_Entry!$C:$AB,Data_Entry!$A6,0),"") -> 0 | AG8: =IFERROR(SUM(B8:AF8),"") -> 1507.08
A9: Inv_6 | B9: =IFERROR(VLOOKUP(B$3,Data_Entry!$C:$AB,Data_Entry!$A7,0),"") -> 1500.1 | C9: =IFERROR(VLOOKUP(C$3,Data_Entry!$C:$AB,Data_Entry!$A7,0),"") -> 0 | D9: =IFERROR(VLOOKUP(D$3,Data_Entry!$C:$AB,Data_Entry!$A7,0),"") -> 0 | E9: =IFERROR(VLOOKUP(E$3,Data_Entry!$C:$AB,Data_Entry!$A7,0),"") -> 0 | F9: =IFERROR(VLOOKUP(F$3,Data_Entry!$C:$AB,Data_Entry!$A7,0),"") -> 0 | G9: =IFERROR(VLOOKUP(G$3,Data_Entry!$C:$AB,Data_Entry!$A7,0),"") -> 0 | H9: =IFERROR(VLOOKUP(H$3,Data_Entry!$C:$AB,Data_Entry!$A7,0),"") -> 0 | I9: =IFERROR(VLOOKUP(I$3,Data_Entry!$C:$AB,Data_Entry!$A7,0),"") -> 0 | ... AF9: =IFERROR(VLOOKUP(AF$3,Data_Entry!$C:$AB,Data_Entry!$A7,0),"") -> 0 | AG9: =IFERROR(SUM(B9:AF9),"") -> 1500.1
A10: Inv_7 | B10: =IFERROR(VLOOKUP(B$3,Data_Entry!$C:$AB,Data_Entry!$A8,0),"") -> 1455.77 | C10: =IFERROR(VLOOKUP(C$3,Data_Entry!$C:$AB,Data_Entry!$A8,0),"") -> 0 | D10: =IFERROR(VLOOKUP(D$3,Data_Entry!$C:$AB,Data_Entry!$A8,0),"") -> 0 | E10: =IFERROR(VLOOKUP(E$3,Data_Entry!$C:$AB,Data_Entry!$A8,0),"") -> 0 | F10: =IFERROR(VLOOKUP(F$3,Data_Entry!$C:$AB,Data_Entry!$A8,0),"") -> 0 | G10: =IFERROR(VLOOKUP(G$3,Data_Entry!$C:$AB,Data_Entry!$A8,0),"") -> 0 | H10: =IFERROR(VLOOKUP(H$3,Data_Entry!$C:$AB,Data_Entry!$A8,0),"") -> 0 | I10: =IFERROR(VLOOKUP(I$3,Data_Entry!$C:$AB,Data_Entry!$A8,0),"") -> 0 | ... AF10: =IFERROR(VLOOKUP(AF$3,Data_Entry!$C:$AB,Data_Entry!$A8,0),"") -> 0 | AG10: =IFERROR(SUM(B10:AF10),"") -> 1455.77
A11: Total_Inverter_(kWh) | B11: =SUM(B4:B10) -> 10364.06 | C11: =SUM(C4:C10) -> 0 | D11: =SUM(D4:D10) -> 0 | E11: =SUM(E4:E10) -> 0 | F11: =SUM(F4:F10) -> 0 | G11: =SUM(G4:G10) -> 0 | H11: =SUM(H4:H10) -> 0 | I11: =SUM(I4:I10) -> 0 | ... AG11: =SUM(AG4:AG10) -> 10364.06
A12: Total_ABT_Meter_Export_(kWh) | B12: =IFERROR(VLOOKUP(B$3,Data_Entry!$C:$AB,14,0)," ") -> 10410 | C12: =IFERROR(VLOOKUP(C$3,Data_Entry!$C:$AB,14,0)," ") -> 0 | D12: =IFERROR(VLOOKUP(D$3,Data_Entry!$C:$AB,14,0)," ") -> 0 | E12: =IFERROR(VLOOKUP(E$3,Data_Entry!$C:$AB,14,0)," ") -> 0 | F12: =IFERROR(VLOOKUP(F$3,Data_Entry!$C:$AB,14,0)," ") -> 0 | G12: =IFERROR(VLOOKUP(G$3,Data_Entry!$C:$AB,14,0)," ") -> 0 | H12: =IFERROR(VLOOKUP(H$3,Data_Entry!$C:$AB,14,0)," ") -> 0 | I12: =IFERROR(VLOOKUP(I$3,Data_Entry!$C:$AB,14,0)," ") -> 0 | ... AG12: =IFERROR(VLOOKUP(AG$3,Data_Entry!$C:$AB,14,0)," ")
A13: Total_ABT_Meter_Import_(kWh) | B13: =IFERROR(VLOOKUP(B$3,Data_Entry!$C:$AB,17,0)," ") -> 60 | C13: =IFERROR(VLOOKUP(C$3,Data_Entry!$C:$AB,17,0)," ") -> 0 | D13: =IFERROR(VLOOKUP(D$3,Data_Entry!$C:$AB,17,0)," ") -> 0 | E13: =IFERROR(VLOOKUP(E$3,Data_Entry!$C:$AB,17,0)," ") -> 0 | F13: =IFERROR(VLOOKUP(F$3,Data_Entry!$C:$AB,17,0)," ") -> 0 | G13: =IFERROR(VLOOKUP(G$3,Data_Entry!$C:$AB,17,0)," ") -> 0 | H13: =IFERROR(VLOOKUP(H$3,Data_Entry!$C:$AB,17,0)," ") -> 0 | I13: =IFERROR(VLOOKUP(I$3,Data_Entry!$C:$AB,17,0)," ") -> 0 | ... AG13: =IFERROR(VLOOKUP(AG$3,Data_Entry!$C:$AB,17,0)," ")
A14: Total_ABT_Meter_Net_(kWh) | B14: =IFERROR(VLOOKUP(B$3,Data_Entry!$C:$AB,18,0)," ") -> 10350 | C14: =IFERROR(VLOOKUP(C$3,Data_Entry!$C:$AB,18,0)," ") -> 0 | D14: =IFERROR(VLOOKUP(D$3,Data_Entry!$C:$AB,18,0)," ") -> 0 | E14: =IFERROR(VLOOKUP(E$3,Data_Entry!$C:$AB,18,0)," ") -> 0 | F14: =IFERROR(VLOOKUP(F$3,Data_Entry!$C:$AB,18,0)," ") -> 0 | G14: =IFERROR(VLOOKUP(G$3,Data_Entry!$C:$AB,18,0)," ") -> 0 | H14: =IFERROR(VLOOKUP(H$3,Data_Entry!$C:$AB,18,0)," ") -> 0 | I14: =IFERROR(VLOOKUP(I$3,Data_Entry!$C:$AB,18,0)," ") -> 0 | ... AG14: =IFERROR(VLOOKUP(AG$3,Data_Entry!$C:$AB,18,0)," ")
A15: GTI | B15: =IFERROR(VLOOKUP(B$3,Data_Entry!$C:$AB,20,0)," ") -> 3.66 | C15: =IFERROR(VLOOKUP(C$3,Data_Entry!$C:$AB,20,0)," ") -> 0 | D15: =IFERROR(VLOOKUP(D$3,Data_Entry!$C:$AB,20,0)," ") -> 0 | E15: =IFERROR(VLOOKUP(E$3,Data_Entry!$C:$AB,20,0)," ") -> 0 | F15: =IFERROR(VLOOKUP(F$3,Data_Entry!$C:$AB,20,0)," ") -> 0 | G15: =IFERROR(VLOOKUP(G$3,Data_Entry!$C:$AB,20,0)," ") -> 0 | H15: =IFERROR(VLOOKUP(H$3,Data_Entry!$C:$AB,20,0)," ") -> 0 | I15: =IFERROR(VLOOKUP(I$3,Data_Entry!$C:$AB,20,0)," ") -> 0 | ... AF15: =IFERROR(VLOOKUP(AF$3,Data_Entry!$C:$AB,20,0)," ") -> 0
A16: GHI | B16: =IFERROR(VLOOKUP(B$3,Data_Entry!$C:$AB,19,0)," ") -> 0 | C16: =IFERROR(VLOOKUP(C$3,Data_Entry!$C:$AB,19,0)," ") -> 0 | D16: =IFERROR(VLOOKUP(D$3,Data_Entry!$C:$AB,19,0)," ") -> 0 | E16: =IFERROR(VLOOKUP(E$3,Data_Entry!$C:$AB,19,0)," ") -> 0 | F16: =IFERROR(VLOOKUP(F$3,Data_Entry!$C:$AB,19,0)," ") -> 0 | G16: =IFERROR(VLOOKUP(G$3,Data_Entry!$C:$AB,19,0)," ") -> 0 | H16: =IFERROR(VLOOKUP(H$3,Data_Entry!$C:$AB,19,0)," ") -> 0 | I16: =IFERROR(VLOOKUP(I$3,Data_Entry!$C:$AB,19,0)," ") -> 0 | ... AF16: =IFERROR(VLOOKUP(AF$3,Data_Entry!$C:$AB,19,0)," ") -> 0
A17: Module_Temp. | B17: =IFERROR(VLOOKUP(B$3,Data_Entry!$C:$AB,23,0)," ") -> 0 | C17: =IFERROR(VLOOKUP(C$3,Data_Entry!$C:$AB,23,0)," ") -> 0 | D17: =IFERROR(VLOOKUP(D$3,Data_Entry!$C:$AB,23,0)," ") -> 0 | E17: =IFERROR(VLOOKUP(E$3,Data_Entry!$C:$AB,23,0)," ") -> 0 | F17: =IFERROR(VLOOKUP(F$3,Data_Entry!$C:$AB,23,0)," ") -> 0 | G17: =IFERROR(VLOOKUP(G$3,Data_Entry!$C:$AB,23,0)," ") -> 0 | H17: =IFERROR(VLOOKUP(H$3,Data_Entry!$C:$AB,23,0)," ") -> 0 | I17: =IFERROR(VLOOKUP(I$3,Data_Entry!$C:$AB,23,0)," ") -> 0 | ... AF17: =IFERROR(VLOOKUP(AF$3,Data_Entry!$C:$AB,23,0)," ") -> 0
A18: Ambt._Temp. | B18: =IFERROR(VLOOKUP(B$3,Data_Entry!$C:$AB,21,0)," ") -> 34.09 | C18: =IFERROR(VLOOKUP(C$3,Data_Entry!$C:$AB,21,0)," ") -> 0 | D18: =IFERROR(VLOOKUP(D$3,Data_Entry!$C:$AB,21,0)," ") -> 0 | E18: =IFERROR(VLOOKUP(E$3,Data_Entry!$C:$AB,21,0)," ") -> 0 | F18: =IFERROR(VLOOKUP(F$3,Data_Entry!$C:$AB,21,0)," ") -> 0 | G18: =IFERROR(VLOOKUP(G$3,Data_Entry!$C:$AB,21,0)," ") -> 0 | H18: =IFERROR(VLOOKUP(H$3,Data_Entry!$C:$AB,21,0)," ") -> 0 | I18: =IFERROR(VLOOKUP(I$3,Data_Entry!$C:$AB,21,0)," ") -> 0 | ... AF18: =IFERROR(VLOOKUP(AF$3,Data_Entry!$C:$AB,21,0)," ") -> 0
A19: Performance_Ratio_(%) | B19: =IFERROR(B12/B15/(Basic_Data!$G$10),"") -> 1.1796632 | C19: =IFERROR(C12/C15/(Basic_Data!$G$10),"") | D19: =IFERROR(D12/D15/(Basic_Data!$G$10),"") | E19: =IFERROR(E12/E15/(Basic_Data!$G$10),"") | F19: =IFERROR(F12/F15/(Basic_Data!$G$10),"") | G19: =IFERROR(G12/G15/(Basic_Data!$G$10),"") | H19: =IFERROR(H12/H15/(Basic_Data!$G$10),"") | I19: =IFERROR(I12/I15/(Basic_Data!$G$10),"") | ... AG19: =IFERROR(AG12/AG15/(Basic_Data!$G$10),"")
A20: Capacity_Utilization_Factor_(%) | B20: =IFERROR(B12/(Basic_Data!$F$10*24),"") -> 0.22532468 | C20: =IFERROR(C12/(Basic_Data!$F$10*24),"") -> 0 | D20: =IFERROR(D12/(Basic_Data!$F$10*24),"") -> 0 | E20: =IFERROR(E12/(Basic_Data!$F$10*24),"") -> 0 | F20: =IFERROR(F12/(Basic_Data!$F$10*24),"") -> 0 | G20: =IFERROR(G12/(Basic_Data!$F$10*24),"") -> 0 | H20: =IFERROR(H12/(Basic_Data!$F$10*24),"") -> 0 | I20: =IFERROR(I12/(Basic_Data!$F$10*24),"") -> 0 | ... AG20: =IFERROR(AG12/(Basic_Data!$F$10*24),"")
A21: Aux_Consumption_Line_Loss_(%) | B21: =IFERROR((B11-B12)/B11,"") -> -0.0044326258 | C21: =IFERROR((C11-C12)/C11,"") | D21: =IFERROR((D11-D12)/D11,"") | E21: =IFERROR((E11-E12)/E11,"") | F21: =IFERROR((F11-F12)/F11,"") | G21: =IFERROR((G11-G12)/G11,"") | H21: =IFERROR((H11-H12)/H11,"") | I21: =IFERROR((I11-I12)/I11,"") | ... AG21: =IFERROR((AG11-AG12)/AG11,"")

Sheet Data_Entry
B1: Month | C1: Date | D1: Plant_Up_Time | E1: Plant_Down_Time | F1: Inv_1 | G1: Inv_2 | H1: Inv_3 | I1: Inv_4 | J1: Inv_5 | K1: Inv_6 | L1: Inv_7 | M1: Total Inv Gen kWh | N1: ABT_Initial_Export | O1: ABT_Final_Export | P1: Total_Export | Q1: ABT_Initial_Import | R1: ABT_Final_Import | S1: Total_Import | T1: Net_Gen_kWh | U1: GHI (kwh/m2) | V1: GTI (kwh/m2) | W1: Ambt_Temp_Avg | X1: Module_Temp_Avg | Y1: Wtd_Module_Temp | Z1: Wind Speed | AA1: Rain_Gaug_MM | AB1: Weather_Condition
A2: 4 | B2: 45747 | C2: 45747 | M2: =SUM(F2:L2) -> 0 | P2: =MAX((O2-N2)*3000,0) -> 0 | S2: =MAX((R2-Q2)*3000,0) -> 0 | T2: =P2-S2 -> 0
A3: =A2+1 -> 5 | B3: 45748 | C3: 45748 | F3: 1835.13 | G3: 1870.19 | H3: 1924.81 | I3: 2024.97 | J3: 2015.38 | K3: 1981.68 | L3: 1940.1 | M3: =SUM(F3:L3) -> 13592.26 | N3: 115.74 | O3: 120.23 | P3: =MAX((O3-N3)*3000,0) -> 13470 | Q3: 2.22 | R3: 2.23 | S3: =MAX((R3-Q3)*3000,0) -> 30 | T3: =P3-S3 -> 13440 | V3: 5.62675
A4: =A3+1 -> 6 | B4: 45749 | C4: 45749 | F4: 2030.21 | G4: 2070.38 | H4: 2050.23 | I4: 2090.84 | J4: 1976.97 | K4: 1954.77 | L4: 1964.11 | M4: =SUM(F4:L4) -> 14137.51 | N4: 120.23 | O4: 124.9 | P4: =MAX((O4-N4)*3000,0) -> 14010 | Q4: 2.23 | R4: 2.24 | S4: =MAX((R4-Q4)*3000,0) -> 30 | T4: =P4-S4 -> 13980 | V4: 5.84225
A5: =A4+1 -> 7 | B5: 45750 | C5: 45750 | F5: 1839.07 | G5: 1835.52 | H5: 1842.65 | I5: 1952.53 | J5: 1926.93 | K5: 1892.93 | L5: 1877.62 | M5: =SUM(F5:L5) -> 13167.25 | N5: 124.9 | O5: 129.26 | P5: =MAX((O5-N5)*3000,0) -> 13080 | Q5: 2.24 | R5: 2.25 | S5: =MAX((R5-Q5)*3000,0) -> 30 | T5: =P5-S5 -> 13050 | V5: 5.57625
A6: =A5+1 -> 8 | B6: 45751 | C6: 45751 | F6: 1204.78 | G6: 1204.82 | H6: 1209.34 | I6: 1280.18 | J6: 1263.44 | K6: 1261.51 | L6: 1215.94 | M6: =SUM(F6:L6) -> 8640.01 | N6: 129.26 | O6: 132.13 | P6: =MAX((O6-N6)*3000,0) -> 8610 | Q6: 2.25 | R6: 2.26 | S6: =MAX((R6-Q6)*3000,0) -> 30 | T6: =P6-S6 -> 8580 | V6: 3.7295
A7: =A6+1 -> 9 | B7: 45752 | C7: 45752 | F7: 1901.4 | G7: 1902.92 | H7: 1912.27 | I7: 2020.94 | J7: 2001.33 | K7: 2001.08 | L7: 1996.49 | M7: =SUM(F7:L7) -> 13736.43 | N7: 132.13 | O7: 136.67 | P7: =MAX((O7-N7)*3000,0) -> 13620 | Q7: 2.26 | R7: 2.27 | S7: =MAX((R7-Q7)*3000,0) -> 30 | T7: =P7-S7 -> 13590 | V7: 5.72925
A8: =A7+1 -> 10 | B8: 45753 | C8: 45753 | F8: 1512.52 | G8: 1506.96 | H8: 1516.89 | I8: 1599.98 | J8: 1580.61 | K8: 1529.11 | L8: 1521.58 | M8: =SUM(F8:L8) -> 10767.65 | N8: 136.67 | O8: 140.24 | P8: =MAX((O8-N8)*3000,0) -> 10710 | Q8: 2.27 | R8: 2.28 | S8: =MAX((R8-Q8)*3000,0) -> 30 | T8: =P8-S8 -> 10680 | V8: 4.59325
A9: =A8+1 -> 11 | B9: 45754 | C9: 45754 | F9: 1924.03 | G9: 1913.17 | H9: 1908.55 | I9: 2018.33 | J9: 1998.44 | K9: 1967.54 | L9: 1961.47 | M9: =SUM(F9:L9) -> 13691.53 | N9: 140.24 | O9: 144.77 | P9: =MAX((O9-N9)*3000,0) -> 13590 | Q9: 2.28 | R9: 2.29 | S9: =MAX((R9-Q9)*3000,0) -> 30 | T9: =P9-S9 -> 13560 | V9: 5.81075
A10: =A9+1 -> 12 | B10: 45755 | C10: 45755 | F10: 1848.32 | G10: 1867.75 | H10: 1875.25 | I10: 1959.29 | J10: 1935.92 | K10: 1903.02 | L10: 1896.16 | M10: =SUM(F10:L10) -> 13285.71 | N10: 144.77 | O10: 149.18 | P10: =MAX((O10-N10)*3000,0) -> 13230 | Q10: 2.29 | R10: 2.3 | S10: =MAX((R10-Q10)*3000,0) -> 30 | T10: =P10-S10 -> 13200 | V10: 5.62575
A11: =A10+1 -> 13 | B11: 45756 | C11: 45756 | F11: 1821.74 | G11: 1815.37 | H11: 1854.46 | I11: 1962.77 | J11: 1919.49 | K11: 1822.93 | L11: 1816.06 | M11: =SUM(F11:L11) -> 13012.82 | N11: 149.18 | O11: 153.49 | P11: =MAX((O11-N11)*3000,0) -> 12930 | Q11: 2.3 | R11: 2.31 | S11: =MAX((R11-Q11)*3000,0) -> 30 | T11: =P11-S11 -> 12900 | V11: 5.58175
A12: =A11+1 -> 14 | B12: 45757 | C12: 45757 | F12: 1842.03 | G12: 1834.36 | H12: 1847.15 | I12: 1960.9 | J12: 1944.94 | K12: 1833.69 | L12: 1833.3 | M12: =SUM(F12:L12) -> 13096.37 | N12: =O11 -> 153.49 | O12: 157.83 | P12: =MAX((O12-N12)*3000,0) -> 13020 | Q12: =R11 -> 2.31 | R12: 2.32 | S12: =MAX((R12-Q12)*3000,0) -> 30 | T12: =P12-S12 -> 12990 | V12: 5.5 | AB12: sunny
A13: =A12+1 -> 15 | B13: 45758 | C13: 45758 | F13: 1963.34 | G13: 1954.17 | H13: 1964.66 | I13: 2086.81 | J13: 2068.93 | K13: 1968.66 | L13: 1945.98 | M13: =SUM(F13:L13) -> 13952.55 | N13: =O12 -> 157.83 | O13: 162.47 | P13: =MAX((O13-N13)*3000,0) -> 13920 | Q13: =R12 -> 2.32 | R13: 2.33 | S13: =MAX((R13-Q13)*3000,0) -> 30 | T13: =P13-S13 -> 13890 | V13: 5.84
A14: =A13+1 -> 16 | B14: 45759 | C14: 45759 | F14: 1842.4 | G14: 1918.81 | H14: 1928.86 | I14: 2067.29 | J14: 2060.71 | K14: 1961.26 | L14: 1889.97 | M14: =SUM(F14:L14) -> 13669.3 | N14: =O13 -> 162.47 | O14: 167 | P14: =MAX((O14-N14)*3000,0) -> 13590 | Q14: =R13 -> 2.33 | R14: 2.34 | S14: =MAX((R14-Q14)*3000,0) -> 30 | T14: =P14-S14 -> 13560 | V14: 5.8 | AB14: sunny
A15: =A14+1 -> 17 | B15: 45760 | C15: 45760 | F15: 1673.29 | G15: 1672.24 | H15: 1680.55 | I15: 1774.79 | J15: 1766.34 | K15: 1756.63 | L15: 1707.53 | M15: =SUM(F15:L15) -> 12031.37 | N15: =O14 -> 167 | O15: 171 | P15: =MAX((O15-N15)*3000,0) -> 12000 | Q15: =R14 -> 2.34 | R15: 2.35 | S15: =MAX((R15-Q15)*3000,0) -> 30 | T15: =P15-S15 -> 11970 | V15: 5.18 | AB15: sunny
A16: =A15+1 -> 18 | B16: 45761 | C16: 45761 | F16: 1952.59 | G16: 1988.01 | H16: 2002.92 | I16: 2108.16 | J16: 2100.86 | K16: 2029.73 | L16: 1974.38 | M16: =SUM(F16:L16) -> 14156.65 | N16: =O15 -> 171 | O16: 175.69 | P16: =MAX((O16-N16)*3000,0) -> 14070 | Q16: =R15 -> 2.35 | R16: 2.36 | S16: =MAX((R16-Q16)*3000,0) -> 30 | T16: =P16-S16 -> 14040 | V16: 6 | AB16: sunny
A17: =A16+1 -> 19 | B17: 45762 | C17: 45762 | F17: 1974.76 | G17: 1993.71 | H17: 1977.81 | I17: 2076.65 | J17: 2065.61 | K17: 2004.68 | L17: 2001.35 | M17: =SUM(F17:L17) -> 14094.57 | N17: =O16 -> 175.69 | O17: 180.36 | P17: =MAX((O17-N17)*3000,0) -> 14010 | Q17: =R16 -> 2.36 | R17: 2.37 | S17: =MAX((R17-Q17)*3000,0) -> 30 | T17: =P17-S17 -> 13980 | V17: 5.85 | AB17: sunny
A18: =A17+1 -> 20 | B18: 45763 | C18: 45763 | F18: 788.49 | G18: 785.73 | H18: 787.52 | I18: 828.68 | J18: 830.1 | K18: 827.23 | L18: 811.94 | M18: =SUM(F18:L18) -> 5659.69 | N18: =O17 -> 180.36 | O18: 182.25 | P18: =MAX((O18-N18)*3000,0) -> 5670 | Q18: =R17 -> 2.37 | R18: 2.38 | S18: =MAX((R18-Q18)*3000,0) -> 30 | T18: =P18-S18 -> 5640 | V18: 2.29 | W18: 35.67 | AB18: sunny
A19: =A18+1 -> 21 | B19: 45764 | C19: 45764 | F19: 1977.99 | G19: 2035.23 | H19: 2039.84 | I19: 2145.76 | J19: 2143.04 | K19: 2103.82 | L19: 2056.41 | M19: =SUM(F19:L19) -> 14502.09 | N19: =O18 -> 182.25 | O19: 187.05 | P19: =MAX((O19-N19)*3000,0) -> 14400 | Q19: =R18 -> 2.38 | R19: 2.39 | S19: =MAX((R19-Q19)*3000,0) -> 30 | T19: =P19-S19 -> 14370 | V19: 6.08 | AB19: sunny
A20: =A19+1 -> 22 | B20: 45765 | C20: 45765 | F20: 2025.69 | G20: 2028.78 | H20: 2034.75 | I20: 2034.88 | J20: 2139.47 | K20: 2088.99 | L20: 2045.64 | M20: =SUM(F20:L20) -> 14398.2 | N20: =O19 -> 187.05 | O20: 191.86 | P20: =MAX((O20-N20)*3000,0) -> 14430 | Q20: =R19 -> 2.39 | R20: 2.4 | S20: =MAX((R20-Q20)*3000,0) -> 30 | T20: =P20-S20 -> 14400 | V20: 6.08 | W20: 35.57 | AB20: sunny
A21: =A20+1 -> 23 | B21: 45766 | C21: 45766 | F21: 1951.34 | G21: 2008.08 | H21: 2010.19 | I21: 2138.15 | J21: 2148.49 | K21: 2018.81 | L21: 1290.67 | M21: =SUM(F21:L21) -> 13565.73 | N21: =O20 -> 191.86 | O21: 196.36 | P21: =MAX((O21-N21)*3000,0) -> 13500 | Q21: =R20 -> 2.4 | R21: 2.41 | S21: =MAX((R21-Q21)*3000,0) -> 30 | T21: =P21-S21 -> 13470 | V21: 6.04 | W21: 33.8 | AB21: sunny
A22: =A21+1 -> 24 | B22: 45767 | C22: 45767 | F22: 1975.37 | G22: 2007.14 | H22: 2040.76 | I22: 2160.72 | J22: 2156.02 | K22: 2057.98 | L22: 1189.68 | M22: =SUM(F22:L22) -> 13587.67 | N22: =O21 -> 196.36 | O22: 200.87 | P22: =MAX((O22-N22)*3000,0) -> 13530 | Q22: =R21 -> 2.41 | R22: 2.42 | S22: =MAX((R22-Q22)*3000,0) -> 30 | T22: =P22-S22 -> 13500 | V22: 6.13 | W22: 34.14 | AB22: sunny
A23: =A22+1 -> 25 | B23: 45768 | C23: 45768 | F23: 1788.16 | G23: 1896.38 | H23: 1951.13 | I23: 2079.83 | J23: 2062.5 | K23: 1839.86 | L23: 1795.23 | M23: =SUM(F23:L23) -> 13413.09 | N23: =O22 -> 200.87 | O23: 205.32 | P23: =MAX((O23-N23)*3000,0) -> 13350 | Q23: =R22 -> 2.42 | R23: 2.43 | S23: =MAX((R23-Q23)*3000,0) -> 30 | T23: =P23-S23 -> 13320 | V23: 6.1 | W23: 34.98 | AB23: sunny
A24: =A23+1 -> 26 | B24: 45769 | C24: 45769 | F24: 1901.85 | G24: 1985.07 | H24: 2029.06 | I24: 2114.2 | J24: 2117.29 | K24: 2022.86 | L24: 1985.33 | M24: =SUM(F24:L24) -> 14155.66 | N24: =O23 -> 205.32 | O24: 210 | P24: =MAX((O24-N24)*3000,0) -> 14040 | Q24: =R23 -> 2.43 | R24: 2.44 | S24: =MAX((R24-Q24)*3000,0) -> 30 | T24: =P24-S24 -> 14010 | V24: 6.18 | W24: 36.39 | AB24: sunny
A25: =A24+1 -> 27 | B25: 45770 | C25: 45770 | F25: 1878.4 | G25: 1882.51 | H25: 1884.98 | I25: 1996.83 | J25: 1975.88 | K25: 1966.1 | L25: 1934.02 | M25: =SUM(F25:L25) -> 13518.72 | N25: =O24 -> 210 | O25: 214.47 | P25: =MAX((O25-N25)*3000,0) -> 13410 | Q25: =R24 -> 2.44 | R25: 2.45 | S25: =MAX((R25-Q25)*3000,0) -> 30 | T25: =P25-S25 -> 13380 | V25: 6 | W25: 36.39 | AB25: sunny
A26: =A25+1 -> 28 | B26: 45771 | C26: 45771 | F26: 1995.4 | G26: 1987.48 | H26: 1989.32 | I26: 2083.5 | J26: 2094.35 | K26: 2090.27 | L26: 2077.18 | M26: =SUM(F26:L26) -> 14317.5 | N26: =O25 -> 214.47 | O26: 219.22 | P26: =MAX((O26-N26)*3000,0) -> 14250 | Q26: =R25 -> 2.45 | R26: 2.46 | S26: =MAX((R26-Q26)*3000,0) -> 30 | T26: =P26-S26 -> 14220 | V26: 6.14 | W26: 35.07 | AB26: sunny
A27: =A26+1 -> 29 | B27: 45772 | C27: 45772 | F27: 2028.14 | G27: 2036.48 | H27: 2041.13 | I27: 2130.61 | J27: 2116.63 | K27: 2114.42 | L27: 2089.69 | M27: =SUM(F27:L27) -> 14557.1 | N27: =O26 -> 219.22 | O27: 224.05 | P27: =MAX((O27-N27)*3000,0) -> 14490 | Q27: =R26 -> 2.46 | R27: 2.47 | S27: =MAX((R27-Q27)*3000,0) -> 30 | T27: =P27-S27 -> 14460 | V27: 6.26 | W27: 34.21 | AB27: sunny
A28: =A27+1 -> 30 | B28: 45773 | C28: 45773 | F28: 2029.62 | G28: 2024.87 | H28: 2030.4 | I28: 2126.02 | J28: 2110.91 | K28: 2111.38 | L28: 2085.91 | M28: =SUM(F28:L28) -> 14519.11 | N28: =O27 -> 224.05 | O28: 228.86 | P28: =MAX((O28-N28)*3000,0) -> 14430 | Q28: =R27 -> 2.47 | R28: 2.48 | S28: =MAX((R28-Q28)*3000,0) -> 30 | T28: =P28-S28 -> 14400 | V28: 4.79 | W28: 34.5 | AB28: sunny
A29: =A28+1 -> 31 | B29: 45774 | C29: 45774 | F29: 1994.33 | G29: 1989.53 | H29: 1995.49 | I29: 2088.54 | J29: 2074.3 | K29: 2077.1 | L29: 2048.8 | M29: =SUM(F29:L29) -> 14268.09 | N29: =O28 -> 228.86 | O29: 233.6 | P29: =MAX((O29-N29)*3000,0) -> 14220 | Q29: =R28 -> 2.48 | R29: 2.49 | S29: =MAX((R29-Q29)*3000,0) -> 30 | T29: =P29-S29 -> 14190 | V29: 5.39 | W29: 35.93 | AB29: sunny
A30: =A29+1 -> 32 | B30: 45775 | C30: 45775 | D30: 0.28125 | E30: 0.78125 | F30: 1996.71 | G30: 1984.21 | H30: 1988.57 | I30: 2088.69 | J30: 2073.65 | K30: 2076.25 | L30: 2045.55 | M30: =SUM(F30:L30) -> 14253.63 | N30: =O29 -> 233.6 | O30: 238.33 | P30: =MAX((O30-N30)*3000,0) -> 14190 | Q30: =R29 -> 2.49 | R30: 2.5 | S30: =MAX((R30-Q30)*3000,0) -> 30 | T30: =P30-S30 -> 14160 | V30: 6.19 | W30: 36.38 | AB30: sunny
A31: =A30+1 -> 33 | B31: 45776 | C31: 45776 | D31: 0.28125 | E31: 0.78125 | F31: 2044.76 | G31: 2019.81 | H31: 2026.65 | I31: 2130.06 | J31: 2115.2 | K31: 2112.2 | L31: 2083.24 | M31: =SUM(F31:L31) -> 14531.92 | N31: =O30 -> 238.33 | O31: 243.15 | P31: =MAX((O31-N31)*3000,0) -> 14460 | Q31: =R30 -> 2.5 | R31: 2.51 | S31: =MAX((R31-Q31)*3000,0) -> 30 | T31: =P31-S31 -> 14430 | V31: 6.29 | W31: 36.86 | AB31: sunny
A32: =A31+1 -> 34 | B32: 45777 | C32: 45777 | D32: 0.28125 | E32: 0.78125 | F32: 1996.33 | G32: 1970.12 | H32: 1975.8 | I32: 2077.24 | J32: 2057.78 | K32: 2054.03 | L32: 2030.39 | M32: =SUM(F32:L32) -> 14161.69 | N32: =O31 -> 243.15 | O32: 247.85 | P32: =MAX((O32-N32)*3000,0) -> 14100 | Q32: =R31 -> 2.51 | R32: 2.52 | S32: =MAX((R32-Q32)*3000,0) -> 30 | T32: =P32-S32 -> 14070 | V32: 6.11 | W32: 35.7 | AB32: sunny
A33: =A32+1 -> 35 | B33: 45778 | C33: 45778 | D33: 0.28125 | E33: 0.78125 | F33: 2026.21 | G33: 2013.32 | H33: 1985.18 | I33: 2083.83 | J33: 2062.34 | K33: 2062.25 | L33: 2033.98 | M33: =SUM(F33:L33) -> 14267.11 | N33: =O32 -> 247.85 | O33: 252.57 | P33: =MAX((O33-N33)*3000,0) -> 14160 | Q33: =R32 -> 2.52 | R33: 2.54 | S33: =MAX((R33-Q33)*3000,0) -> 60 | T33: =P33-S33 -> 14100 | V33: 6.15 | W33: 35.41 | AB33: sunny
A34: =A33+1 -> 36 | B34: 45779 | C34: 45779 | D34: 0.28125 | E34: 0.78125 | F34: 2090.6 | G34: 2100.55 | H34: 2084.02 | I34: 2136.4 | J34: 2108.4 | K34: 2077.87 | L34: 2059.08 | M34: =SUM(F34:L34) -> 14656.92 | N34: =O33 -> 252.57 | O34: 257.43 | P34: =MAX((O34-N34)*3000,0) -> 14580 | Q34: =R33 -> 2.54 | R34: 2.55 | S34: =MAX((R34-Q34)*3000,0) -> 30 | T34: =P34-S34 -> 14550 | V34: 6.37 | W34: 35.15 | AB34: sunny
A35: =A34+1 -> 37 | B35: 45780 | C35: 45780 | D35: 0.28125 | E35: 0.78125 | F35: 2017.9 | G35: 2001.08 | H35: 1998.29 | I35: 2107.24 | J35: 2090.08 | K35: 2072.24 | L35: 2064.53 | M35: =SUM(F35:L35) -> 14351.36 | N35: =O34 -> 257.43 | O35: 262.19 | P35: =MAX((O35-N35)*3000,0) -> 14280 | Q35: =R34 -> 2.55 | R35: 2.56 | S35: =MAX((R35-Q35)*3000,0) -> 30 | T35: =P35-S35 -> 14250 | V35: 6.04 | W35: 33.5 | AB35: sunny
A36: =A35+1 -> 38 | B36: 45781 | C36: 45781 | D36: 0.28125 | E36: 0.78125 | F36: 1834.03 | G36: 1817.55 | H36: 1818.25 | I36: 1922.44 | J36: 1908 | K36: 1891.53 | L36: 1895.28 | M36: =SUM(F36:L36) -> 13087.08 | N36: =O35 -> 262.19 | O36: 266.54 | P36: =MAX((O36-N36)*3000,0) -> 13050 | Q36: =R35 -> 2.56 | R36: 2.57 | S36: =MAX((R36-Q36)*3000,0) -> 30 | T36: =P36-S36 -> 13020 | V36: 5.46 | W36: 33.43 | AB36: sunny
A37: =A36+1 -> 39 | B37: 45782 | C37: 45782 | D37: 0.28125 | E37: 0.78125 | F37: 1806.97 | G37: 1791.49 | H37: 1791.72 | I37: 1888.35 | J37: 1876.54 | K37: 1858.44 | L37: 1859.93 | M37: =SUM(F37:L37) -> 12873.44 | N37: =O36 -> 266.54 | O37: 270.82 | P37: =MAX((O37-N37)*3000,0) -> 12840 | Q37: =R36 -> 2.57 | R37: 2.58 | S37: =MAX((R37-Q37)*3000,0) -> 30 | T37: =P37-S37 -> 12810 | V37: 5.35 | W37: 33.26 | AB37: mostly cloudy
A38: =A37+1 -> 40 | B38: 45783 | C38: 45783 | D38: 0.34583333 | E38: 0.6875 | F38: 1317.3 | G38: 1309.2 | H38: 1313.71 | I38: 1373.91 | J38: 1370.27 | K38: 1376.01 | L38: 1363.9 | M38: =SUM(F38:L38) -> 9424.3 | N38: =O37 -> 270.82 | O38: 273.96 | P38: =MAX((O38-N38)*3000,0) -> 9420 | Q38: =R37 -> 2.58 | R38: 2.59 | S38: =MAX((R38-Q38)*3000,0) -> 30 | T38: =P38-S38 -> 9390 | V38: 3.55 | W38: 31.94 | AB38: cloudy
A39: =A38+1 -> 41 | B39: 45784 | C39: 45784 | D39: 0.28125 | E39: 0.77083333 | F39: 929.05 | G39: 925.15 | H39: 927.51 | I39: 966.02 | J39: 956.79 | K39: 959.16 | L39: 951.02 | M39: =SUM(F39:L39) -> 6614.7 | N39: =O38 -> 273.96 | O39: 276.14 | P39: =MAX((O39-N39)*3000,0) -> 6540 | Q39: =R38 -> 2.59 | R39: 2.6 | S39: =MAX((R39-Q39)*3000,0) -> 30 | T39: =P39-S39 -> 6510 | V39: 3.33 | W39: 26.75 | AB39: rainy
A40: =A39+1 -> 42 | B40: 45785 | C40: 45785 | D40: 0.28125 | E40: 0.77083333 | F40: 1838.54 | G40: 1835.84 | H40: 1842.84 | I40: 1939.87 | J40: 1933.94 | K40: 1918.22 | L40: 1889.83 | M40: =SUM(F40:L40) -> 13199.08 | N40: =O39 -> 276.14 | O40: 280.55 | P40: =MAX((O40-N40)*3000,0) -> 13230 | Q40: =R39 -> 2.6 | R40: 2.61 | S40: =MAX((R40-Q40)*3000,0) -> 30 | T40: =P40-S40 -> 13200 | V40: 5.53 | W40: 31.24 | AB40: cloudy
...

Sheet Inverter_PR
A1: Inverter_Availability_Sheet
C2: 335.72 | D2: 335.72 | E2: 335.72 | F2: 350.98 | G2: 350.98 | H2: 350.98 | I2: 350.98
C3: Inv_1 | D3: Inv_2 | E3: Inv_3 | F3: Inv_4 | G3: Inv_5 | H3: Inv_6 | I3: Inv_7
A4: 45747 | B4: 45747
A5: 45748 | B5: 45748 | C5: =IFERROR((Data_Entry!F3/Data_Entry!$V3/C$2),"") -> 0.97147583 | D5: =IFERROR((Data_Entry!G3/Data_Entry!$V3/D$2),"") -> 0.99003579 | E5: =IFERROR((Data_Entry!H3/Data_Entry!$V3/E$2),"") -> 1.0189504 | F5: =IFERROR((Data_Entry!I3/Data_Entry!$V3/F$2),"") -> 1.0253653 | G5: =IFERROR((Data_Entry!J3/Data_Entry!$V3/G$2),"") -> 1.0205093 | H5: =IFERROR((Data_Entry!K3/Data_Entry!$V3/H$2),"") -> 1.0034449 | I5: =IFERROR((Data_Entry!L3/Data_Entry!$V3/I$2),"") -> 0.98239044
A6: 45749 | B6: 45749 | C6: =IFERROR((Data_Entry!F4/Data_Entry!$V4/C$2),"") -> 1.0351031 | D6: =IFERROR((Data_Entry!G4/Data_Entry!$V4/D$2),"") -> 1.0555838 | E6: =IFERROR((Data_Entry!H4/Data_Entry!$V4/E$2),"") -> 1.0453103 | F6: =IFERROR((Data_Entry!I4/Data_Entry!$V4/F$2),"") -> 1.0196668 | G6: =IFERROR((Data_Entry!J4/Data_Entry!$V4/G$2),"") -> 0.96413439 | H6: =IFERROR((Data_Entry!K4/Data_Entry!$V4/H$2),"") -> 0.95330783 | I6: =IFERROR((Data_Entry!L4/Data_Entry!$V4/I$2),"") -> 0.95786278
A7: 45750 | B7: 45750 | C7: =IFERROR((Data_Entry!F5/Data_Entry!$V5/C$2),"") -> 0.98237841 | D7: =IFERROR((Data_Entry!G5/Data_Entry!$V5/D$2),"") -> 0.9804821 | E7: =IFERROR((Data_Entry!H5/Data_Entry!$V5/E$2),"") -> 0.98429074 | F7: =IFERROR((Data_Entry!I5/Data_Entry!$V5/F$2),"") -> 0.99763829 | G7: =IFERROR((Data_Entry!J5/Data_Entry!$V5/G$2),"") -> 0.98455806 | H7: =IFERROR((Data_Entry!K5/Data_Entry!$V5/H$2),"") -> 0.96718588 | I7: =IFERROR((Data_Entry!L5/Data_Entry!$V5/I$2),"") -> 0.95936329
A8: 45751 | B8: 45751 | C8: =IFERROR((Data_Entry!F6/Data_Entry!$V6/C$2),"") -> 0.96223228 | D8: =IFERROR((Data_Entry!G6/Data_Entry!$V6/D$2),"") -> 0.96226423 | E8: =IFERROR((Data_Entry!H6/Data_Entry!$V6/E$2),"") -> 0.96587426 | F8: =IFERROR((Data_Entry!I6/Data_Entry!$V6/F$2),"") -> 0.9779982 | G8: =IFERROR((Data_Entry!J6/Data_Entry!$V6/G$2),"") -> 0.96520962 | H8: =IFERROR((Data_Entry!K6/Data_Entry!$V6/H$2),"") -> 0.96373519 | I8: =IFERROR((Data_Entry!L6/Data_Entry!$V6/I$2),"") -> 0.92892182
A9: 45752 | B9: 45752 | C9: =IFERROR((Data_Entry!F7/Data_Entry!$V7/C$2),"") -> 0.98854968 | D9: =IFERROR((Data_Entry!G7/Data_Entry!$V7/D$2),"") -> 0.98933994 | E9: =IFERROR((Data_Entry!H7/Data_Entry!$V7/E$2),"") -> 0.99420106 | F9: =IFERROR((Data_Entry!I7/Data_Entry!$V7/F$2),"") -> 1.0050167 | G9: =IFERROR((Data_Entry!J7/Data_Entry!$V7/G$2),"") -> 0.99526461 | H9: =IFERROR((Data_Entry!K7/Data_Entry!$V7/H$2),"") -> 0.99514029 | I9: =IFERROR((Data_Entry!L7/Data_Entry!$V7/I$2),"") -> 0.99285767
A10: 45753 | B10: 45753 | C10: =IFERROR((Data_Entry!F8/Data_Entry!$V8/C$2),"") -> 0.98085278 | D10: =IFERROR((Data_Entry!G8/Data_Entry!$V8/D$2),"") -> 0.97724718 | E10: =IFERROR((Data_Entry!H8/Data_Entry!$V8/E$2),"") -> 0.98368668 | F10: =IFERROR((Data_Entry!I8/Data_Entry!$V8/F$2),"") -> 0.99245792 | G10: =IFERROR((Data_Entry!J8/Data_Entry!$V8/G$2),"") -> 0.98044282 | H10: =IFERROR((Data_Entry!K8/Data_Entry!$V8/H$2),"") -> 0.94849768 | I10: =IFERROR((Data_Entry!L8/Data_Entry!$V8/I$2),"") -> 0.94382687
A11: 45754 | B11: 45754 | C11: =IFERROR((Data_Entry!F9/Data_Entry!$V9/C$2),"") -> 0.98628501 | D11: =IFERROR((Data_Entry!G9/Data_Entry!$V9/D$2),"") -> 0.98071802 | E11: =IFERROR((Data_Entry!H9/Data_Entry!$V9/E$2),"") -> 0.97834975 | F11: =IFERROR((Data_Entry!I9/Data_Entry!$V9/F$2),"") -> 0.98964085 | G11: =IFERROR((Data_Entry!J9/Data_Entry!$V9/G$2),"") -> 0.97988826 | H11: =IFERROR((Data_Entry!K9/Data_Entry!$V9/H$2),"") -> 0.96473717 | I11: =IFERROR((Data_Entry!L9/Data_Entry!$V9/I$2),"") -> 0.96176088
A12: 45755 | B12: 45755 | C12: =IFERROR((Data_Entry!F10/Data_Entry!$V10/C$2),"") -> 0.97863224 | D12: =IFERROR((Data_Entry!G10/Data_Entry!$V10/D$2),"") -> 0.98891987 | E12: =IFERROR((Data_Entry!H10/Data_Entry!$V10/E$2),"") -> 0.9928909 | F12: =IFERROR((Data_Entry!I10/Data_Entry!$V10/F$2),"") -> 0.99228385 | G12: =IFERROR((Data_Entry!J10/Data_Entry!$V10/G$2),"") -> 0.9804481 | H12: =IFERROR((Data_Entry!K10/Data_Entry!$V10/H$2),"") -> 0.96378587 | I12: =IFERROR((Data_Entry!L10/Data_Entry!$V10/I$2),"") -> 0.96031162
A13: 45756 | B13: 45756 | C13: =IFERROR((Data_Entry!F11/Data_Entry!$V11/C$2),"") -> 0.97216235 | D13: =IFERROR((Data_Entry!G11/Data_Entry!$V11/D$2),"") -> 0.96876303 | E13: =IFERROR((Data_Entry!H11/Data_Entry!$V11/E$2),"") -> 0.98962322 | F13: =IFERROR((Data_Entry!I11/Data_Entry!$V11/F$2),"") -> 1.0018822 | G13: =IFERROR((Data_Entry!J11/Data_Entry!$V11/G$2),"") -> 0.97979023 | H13: =IFERROR((Data_Entry!K11/Data_Entry!$V11/H$2),"") -> 0.93050185 | I13: =IFERROR((Data_Entry!L11/Data_Entry!$V11/I$2),"") -> 0.92699511
A14: 45757 | B14: 45757 | C14: =IFERROR((Data_Entry!F12/Data_Entry!$V12/C$2),"") -> 0.99760081 | D14: =IFERROR((Data_Entry!G12/Data_Entry!$V12/D$2),"") -> 0.99344692 | E14: =IFERROR((Data_Entry!H12/Data_Entry!$V12/E$2),"") -> 1.0003737 | F14: =IFERROR((Data_Entry!I12/Data_Entry!$V12/F$2),"") -> 1.0158051 | G14: =IFERROR((Data_Entry!J12/Data_Entry!$V12/G$2),"") -> 1.0075373 | H14: =IFERROR((Data_Entry!K12/Data_Entry!$V12/H$2),"") -> 0.9499065 | I14: =IFERROR((Data_Entry!L12/Data_Entry!$V12/I$2),"") -> 0.94970446
A15: 45758 | B15: 45758 | C15: =IFERROR((Data_Entry!F13/Data_Entry!$V13/C$2),"") -> 1.0013951 | D15: =IFERROR((Data_Entry!G13/Data_Entry!$V13/D$2),"") -> 0.99671795 | E15: =IFERROR((Data_Entry!H13/Data_Entry!$V13/E$2),"") -> 1.0020683 | F15: =IFERROR((Data_Entry!I13/Data_Entry!$V13/F$2),"") -> 1.0180936 | G15: =IFERROR((Data_Entry!J13/Data_Entry!$V13/G$2),"") -> 1.0093704 | H15: =IFERROR((Data_Entry!K13/Data_Entry!$V13/H$2),"") -> 0.96045164 | I15: =IFERROR((Data_Entry!L13/Data_Entry!$V13/I$2),"") -> 0.94938673
A16: 45759 | B16: 45759 | C16: =IFERROR((Data_Entry!F14/Data_Entry!$V14/C$2),"") -> 0.94619079 | D16: =IFERROR((Data_Entry!G14/Data_Entry!$V14/D$2),"") -> 0.98543224 | E16: =IFERROR((Data_Entry!H14/Data_Entry!$V14/E$2),"") -> 0.99059356 | F16: =IFERROR((Data_Entry!I14/Data_Entry!$V14/F$2),"") -> 1.015526 | G16: =IFERROR((Data_Entry!J14/Data_Entry!$V14/G$2),"") -> 1.0122937 | H16: =IFERROR((Data_Entry!K14/Data_Entry!$V14/H$2),"") -> 0.9634403 | I16: =IFERROR((Data_Entry!L14/Data_Entry!$V14/I$2),"") -> 0.92842013
... A21: 45764 | B21: 45764 | C21: =IFERROR((Data_Entry!F19/Data_Entry!$V19/C$2),"") -> 0.96904356 | D21: =IFERROR((Data_Entry!G19/Data_Entry!$V19/D$2),"") -> 0.99708619 | E21: =IFERROR((Data_Entry!H19/Data_Entry!$V19/E$2),"") -> 0.99934469 | F21: =IFERROR((Data_Entry!I19/Data_Entry!$V19/F$2),"") -> 1.0055304 | G21: =IFERROR((Data_Entry!J19/Data_Entry!$V19/G$2),"") -> 1.0042558 | H21: =IFERROR((Data_Entry!K19/Data_Entry!$V19/H$2),"") -> 0.98587676 | I21: =IFERROR((Data_Entry!L19/Data_Entry!$V19/I$2),"") -> 0.96365984
A22: 45765 | B22: 45765 | C22: =IFERROR((Data_Entry!F20/Data_Entry!$V20/C$2),"") -> 0.99241242 | D22: =IFERROR((Data_Entry!G20/Data_Entry!$V20/D$2),"") -> 0.99392625 | E22: =IFERROR((Data_Entry!I20/Data_Entry!$V20/E$2),"") -> 0.99691472 | F22: =IFERROR((Data_Entry!J20/Data_Entry!$V20/F$2),"") -> 1.0025828 | G22: =IFERROR((Data_Entry!K20/Data_Entry!$V20/G$2),"") -> 0.97892724 | H22: =IFERROR((Data_Entry!L20/Data_Entry!$V20/H$2),"") -> 0.95861288 | I22: =IFERROR((Data_Entry!#REF!/Data_Entry!$V20/I$2),"")
A23: 45766 | B23: 45766 | C23: =IFERROR((Data_Entry!F21/Data_Entry!$V21/C$2),"") -> 0.96231841 | D23: =IFERROR((Data_Entry!G21/Data_Entry!$V21/D$2),"") -> 0.99030018 | E23: =IFERROR((Data_Entry!H21/Data_Entry!$V21/E$2),"") -> 0.99134074 | F23: =IFERROR((Data_Entry!I21/Data_Entry!$V21/F$2),"") -> 1.0085998 | G23: =IFERROR((Data_Entry!J21/Data_Entry!$V21/G$2),"") -> 1.0134773 | H23: =IFERROR((Data_Entry!K21/Data_Entry!$V21/H$2),"") -> 0.95230516 | I23: =IFERROR((Data_Entry!L21/Data_Entry!$V21/I$2),"") -> 0.60882981
A24: 45767 | B24: 45767 | C24: =IFERROR((Data_Entry!F22/Data_Entry!$V22/C$2),"") -> 0.95986635 | D24: =IFERROR((Data_Entry!G22/Data_Entry!$V22/D$2),"") -> 0.97530394 | E24: =IFERROR((Data_Entry!H22/Data_Entry!$V22/E$2),"") -> 0.99164047 | F24: =IFERROR((Data_Entry!I22/Data_Entry!$V22/F$2),"") -> 1.0042819 | G24: =IFERROR((Data_Entry!J22/Data_Entry!$V22/G$2),"") -> 1.0020974 | H24: =IFERROR((Data_Entry!K22/Data_Entry!$V22/H$2),"") -> 0.95652936 | I24: =IFERROR((Data_Entry!L22/Data_Entry!$V22/I$2),"") -> 0.55295185
A25: 45768 | B25: 45768 | C25: =IFERROR((Data_Entry!F23/Data_Entry!$V23/C$2),"") -> 0.87317105 | D25: =IFERROR((Data_Entry!G23/Data_Entry!$V23/D$2),"") -> 0.92601563 | E25: =IFERROR((Data_Entry!H23/Data_Entry!$V23/E$2),"") -> 0.95275044 | F25: =IFERROR((Data_Entry!I23/Data_Entry!$V23/F$2),"") -> 0.97143922 | G25: =IFERROR((Data_Entry!J23/Data_Entry!$V23/G$2),"") -> 0.96334479 | H25: =IFERROR((Data_Entry!K23/Data_Entry!$V23/H$2),"") -> 0.85935493 | I25: =IFERROR((Data_Entry!L23/Data_Entry!$V23/I$2),"") -> 0.83850932
A26: 45769 | B26: 45769 | C26: =IFERROR((Data_Entry!F24/Data_Entry!$V24/C$2),"") -> 0.91666484 | D26: =IFERROR((Data_Entry!G24/Data_Entry!$V24/D$2),"") -> 0.9567757 | E26: =IFERROR((Data_Entry!H24/Data_Entry!$V24/E$2),"") -> 0.97797826 | F26: =IFERROR((Data_Entry!I24/Data_Entry!$V24/F$2),"") -> 0.97470956 | G26: =IFERROR((Data_Entry!J24/Data_Entry!$V24/G$2),"") -> 0.97613414 | H26: =IFERROR((Data_Entry!K24/Data_Entry!$V24/H$2),"") -> 0.93259908 | I26: =IFERROR((Data_Entry!L24/Data_Entry!$V24/I$2),"") -> 0.91529662
A27: 45770 | B27: 45770 | C27: =IFERROR((Data_Entry!F25/Data_Entry!$V25/C$2),"") -> 0.93252313 | D27: =IFERROR((Data_Entry!G25/Data_Entry!$V25/D$2),"") -> 0.93456353 | E27: =IFERROR((Data_Entry!H25/Data_Entry!$V25/E$2),"") -> 0.93578975 | F27: =IFERROR((Data_Entry!I25/Data_Entry!$V25/F$2),"") -> 0.94821642 | G27: =IFERROR((Data_Entry!J25/Data_Entry!$V25/G$2),"") -> 0.93826809 | H27: =IFERROR((Data_Entry!K25/Data_Entry!$V25/H$2),"") -> 0.93362395 | I27: =IFERROR((Data_Entry!L25/Data_Entry!$V25/I$2),"") -> 0.91839041
A28: 45771 | B28: 45771 | C28: =IFERROR((Data_Entry!F26/Data_Entry!$V26/C$2),"") -> 0.96802012 | D28: =IFERROR((Data_Entry!G26/Data_Entry!$V26/D$2),"") -> 0.96417792 | E28: =IFERROR((Data_Entry!H26/Data_Entry!$V26/E$2),"") -> 0.96507055 | F28: =IFERROR((Data_Entry!I26/Data_Entry!$V26/F$2),"") -> 0.96681363 | G28: =IFERROR((Data_Entry!J26/Data_Entry!$V26/G$2),"") -> 0.97184839 | H28: =IFERROR((Data_Entry!K26/Data_Entry!$V26/H$2),"") -> 0.96995514 | I28: =IFERROR((Data_Entry!L26/Data_Entry!$V26/I$2),"") -> 0.96388094
A29: 45772 | B29: 45772 | C29: =IFERROR((Data_Entry!F27/Data_Entry!$V27/C$2),"") -> 0.96504237 | D29: =IFERROR((Data_Entry!G27/Data_Entry!$V27/D$2),"") -> 0.96901076 | E29: =IFERROR((Data_Entry!H27/Data_Entry!$V27/E$2),"") -> 0.97122336 | F29: =IFERROR((Data_Entry!I27/Data_Entry!$V27/F$2),"") -> 0.96972202 | G29: =IFERROR((Data_Entry!J27/Data_Entry!$V27/G$2),"") -> 0.96335919 | H29: =IFERROR((Data_Entry!K27/Data_Entry!$V27/H$2),"") -> 0.96235333 | I29: =IFERROR((Data_Entry!L27/Data_Entry!$V27/I$2),"") -> 0.95109777
A30: 45773 | B30: 45773 | C30: =IFERROR((Data_Entry!F28/Data_Entry!$V28/C$2),"") -> 1.2621239 | D30: =IFERROR((Data_Entry!G28/Data_Entry!$V28/D$2),"") -> 1.2591701 | E30: =IFERROR((Data_Entry!H28/Data_Entry!$V28/E$2),"") -> 1.262609 | F30: =IFERROR((Data_Entry!I28/Data_Entry!$V28/F$2),"") -> 1.2645892 | G30: =IFERROR((Data_Entry!J28/Data_Entry!$V28/G$2),"") -> 1.2556015 | H30: =IFERROR((Data_Entry!K28/Data_Entry!$V28/H$2),"") -> 1.2558811 | I30: =IFERROR((Data_Entry!L28/Data_Entry!$V28/I$2),"") -> 1.2407311
A31: 45774 | B31: 45774 | C31: =IFERROR((Data_Entry!F29/Data_Entry!$V29/C$2),"") -> 1.1021255 | D31: =IFERROR((Data_Entry!G29/Data_Entry!$V29/D$2),"") -> 1.0994729 | E31: =IFERROR((Data_Entry!H29/Data_Entry!$V29/E$2),"") -> 1.1027665 | F31: =IFERROR((Data_Entry!I29/Data_Entry!$V29/F$2),"") -> 1.1040066 | G31: =IFERROR((Data_Entry!J29/Data_Entry!$V29/G$2),"") -> 1.0964793 | H31: =IFERROR((Data_Entry!K29/Data_Entry!$V29/H$2),"") -> 1.0979594 | I31: =IFERROR((Data_Entry!L29/Data_Entry!$V29/I$2),"") -> 1.0829999
A32: 45775 | B32: 45775 | C32: =IFERROR((Data_Entry!F30/Data_Entry!$V30/C$2),"") -> 0.96083127 | D32: =IFERROR((Data_Entry!G30/Data_Entry!$V30/D$2),"") -> 0.95481618 | E32: =IFERROR((Data_Entry!H30/Data_Entry!$V30/E$2),"") -> 0.95691425 | F32: =IFERROR((Data_Entry!I30/Data_Entry!$V30/F$2),"") -> 0.96139303 | G32: =IFERROR((Data_Entry!J30/Data_Entry!$V30/G$2),"") -> 0.95447034 | H32: =IFERROR((Data_Entry!K30/Data_Entry!$V30/H$2),"") -> 0.95566708 | I32: =IFERROR((Data_Entry!L30/Data_Entry!$V30/I$2),"") -> 0.94153633
A33: 45776 | B33: 45776 | C33: =IFERROR((Data_Entry!F31/Data_Entry!$V31/C$2),"") -> 0.96831014 | D33: =IFERROR((Data_Entry!G31/Data_Entry!$V31/D$2),"") -> 0.9564949 | E33: =IFERROR((Data_Entry!H31/Data_Entry!$V31/E$2),"") -> 0.95973403 | F33: =IFERROR((Data_Entry!I31/Data_Entry!$V31/F$2),"") -> 0.96484782 | G33: =IFERROR((Data_Entry!J31/Data_Entry!$V31/G$2),"") -> 0.95811673 | H33: =IFERROR((Data_Entry!K31/Data_Entry!$V31/H$2),"") -> 0.95675783 | I33: =IFERROR((Data_Entry!L31/Data_Entry!$V31/I$2),"") -> 0.94363989
A34: 45777 | B34: 45777 | C34: =IFERROR((Data_Entry!F32/Data_Entry!$V32/C$2),"") -> 0.97322646 | D34: =IFERROR((Data_Entry!G32/Data_Entry!$V32/D$2),"") -> 0.96044888 | E34: =IFERROR((Data_Entry!H32/Data_Entry!$V32/E$2),"") -> 0.96321793 | F34: =IFERROR((Data_Entry!I32/Data_Entry!$V32/F$2),"") -> 0.96864156 | G34: =IFERROR((Data_Entry!J32/Data_Entry!$V32/G$2),"") -> 0.95956713 | H34: =IFERROR((Data_Entry!K32/Data_Entry!$V32/H$2),"") -> 0.95781846 | I34: =IFERROR((Data_Entry!L32/Data_Entry!$V32/I$2),"") -> 0.94679485
... A129: 45872 | B129: 45872 | C129: =IFERROR((Data_Entry!F127/Data_Entry!$V127/C$2),"") -> 1.0187168 | D129: =IFERROR((Data_Entry!G127/Data_Entry!$V127/D$2),"") -> 1.0131344 | E129: =IFERROR((Data_Entry!H127/Data_Entry!$V127/E$2),"") -> 1.0181489 | F129: =IFERROR((Data_Entry!I127/Data_Entry!$V127/F$2),"") -> 1.0227581 | G129: =IFERROR((Data_Entry!J127/Data_Entry!$V127/G$2),"") -> 1.0118738 | H129: =IFERROR((Data_Entry!K127/Data_Entry!$V127/H$2),"") -> 1.0142208 | I129: =IFERROR((Data_Entry!L127/Data_Entry!$V127/I$2),"") -> 0.99364124
A130: 45873 | B130: 45873 | C130: =IFERROR((Data_Entry!F128/Data_Entry!$V128/C$2),"") -> 1.146086 | D130: =IFERROR((Data_Entry!G128/Data_Entry!$V128/D$2),"") -> 1.1408555 | E130: =IFERROR((Data_Entry!H128/Data_Entry!$V128/E$2),"") -> 1.1443703 | F130: =IFERROR((Data_Entry!J128/Data_Entry!$V128/F$2),"") -> 1.1404752 | G130: =IFERROR((Data_Entry!K128/Data_Entry!$V128/G$2),"") -> 1.1424013 | H130: =IFERROR((Data_Entry!L128/Data_Entry!$V128/H$2),"") -> 1.1240071 | I130: =IFERROR((Data_Entry!#REF!/Data_Entry!$V128/I$2),"")
A131: 45874 | B131: 45874 | C131: =IFERROR((Data_Entry!F129/Data_Entry!$V129/C$2),"") -> 1.0454351 | D131: =IFERROR((Data_Entry!G129/Data_Entry!$V129/D$2),"") -> 1.0407866 | E131: =IFERROR((Data_Entry!H129/Data_Entry!$V129/E$2),"") -> 1.0461008 | F131: =IFERROR((Data_Entry!I129/Data_Entry!$V129/F$2),"") -> 1.0522917 | G131: =IFERROR((Data_Entry!J129/Data_Entry!$V129/G$2),"") -> 1.0480719 | H131: =IFERROR((Data_Entry!K129/Data_Entry!$V129/H$2),"") -> 1.0515578 | I131: =IFERROR((Data_Entry!L129/Data_Entry!$V129/I$2),"") -> 1.0307395
A132: 45875 | B132: 45875 | C132: =IFERROR((Data_Entry!F130/Data_Entry!$V130/C$2),"") -> 1.0684894 | D132: =IFERROR((Data_Entry!G130/Data_Entry!$V130/D$2),"") -> 1.0637594 | E132: =IFERROR((Data_Entry!H130/Data_Entry!$V130/E$2),"") -> 1.0667955 | F132: =IFERROR((Data_Entry!I130/Data_Entry!$V130/F$2),"") -> 1.0629583 | G132: =IFERROR((Data_Entry!J130/Data_Entry!$V130/G$2),"") -> 1.0546923 | H132: =IFERROR((Data_Entry!K130/Data_Entry!$V130/H$2),"") -> 1.055166 | I132: =IFERROR((Data_Entry!L130/Data_Entry!$V130/I$2),"") -> 1.0391352
A133: 45876 | B133: 45876 | C133: =IFERROR((Data_Entry!F131/Data_Entry!$V131/C$2),"") -> 0.99353907 | D133: =IFERROR((Data_Entry!G131/Data_Entry!$V131/D$2),"") -> 0.99700077 | E133: =IFERROR((Data_Entry!H131/Data_Entry!$V131/E$2),"") -> 0.99441223 | F133: =IFERROR((Data_Entry!I131/Data_Entry!$V131/F$2),"") -> 0.99561442 | G133: =IFERROR((Data_Entry!J131/Data_Entry!$V131/G$2),"") -> 0.98617841 | H133: =IFERROR((Data_Entry!K131/Data_Entry!$V131/H$2),"") -> 0.98285537 | I133: =IFERROR((Data_Entry!L131/Data_Entry!$V131/I$2),"") -> 0.9597955
A134: 45877 | B134: 45877 | C134: =IFERROR((Data_Entry!F132/Data_Entry!$V132/C$2),"") -> 1.0306646 | D134: =IFERROR((Data_Entry!G132/Data_Entry!$V132/D$2),"") -> 1.0271665 | E134: =IFERROR((Data_Entry!H132/Data_Entry!$V132/E$2),"") -> 1.0297196 | F134: =IFERROR((Data_Entry!I132/Data_Entry!$V132/F$2),"") -> 1.0379162 | G134: =IFERROR((Data_Entry!J132/Data_Entry!$V132/G$2),"") -> 1.0343547 | H134: =IFERROR((Data_Entry!K132/Data_Entry!$V132/H$2),"") -> 1.0363479 | I134: =IFERROR((Data_Entry!L132/Data_Entry!$V132/I$2),"") -> 1.0194744
A135: 45878 | B135: 45878 | C135: =IFERROR((Data_Entry!F133/Data_Entry!$V133/C$2),"") -> 0.95481211 | D135: =IFERROR((Data_Entry!G133/Data_Entry!$V133/D$2),"") -> 0.94926397 | E135: =IFERROR((Data_Entry!H133/Data_Entry!$V133/E$2),"") -> 0.95298493 | F135: =IFERROR((Data_Entry!I133/Data_Entry!$V133/F$2),"") -> 0.95588127 | G135: =IFERROR((Data_Entry!J133/Data_Entry!$V133/G$2),"") -> 0.94504898 | H135: =IFERROR((Data_Entry!K133/Data_Entry!$V133/H$2),"") -> 0.94476679 | I135: =IFERROR((Data_Entry!L133/Data_Entry!$V133/I$2),"") -> 0.92648844
A136: 45879 | B136: 45879 | C136: =IFERROR((Data_Entry!F134/Data_Entry!$V134/C$2),"") -> 1.0750911 | D136: =IFERROR((Data_Entry!G134/Data_Entry!$V134/D$2),"") -> 1.0731109 | E136: =IFERROR((Data_Entry!H134/Data_Entry!$V134/E$2),"") -> 1.0775411 | F136: =IFERROR((Data_Entry!I134/Data_Entry!$V134/F$2),"") -> 1.0808208 | G136: =IFERROR((Data_Entry!J134/Data_Entry!$V134/G$2),"") -> 1.0675782 | H136: =IFERROR((Data_Entry!K134/Data_Entry!$V134/H$2),"") -> 1.0654674 | I136: =IFERROR((Data_Entry!L134/Data_Entry!$V134/I$2),"") -> 1.053228
A137: 45880 | B137: 45880 | C137: =IFERROR((Data_Entry!F135/Data_Entry!$V135/C$2),"") -> 0.76255837 | D137: =IFERROR((Data_Entry!G135/Data_Entry!$V135/D$2),"") -> 0.76008826 | E137: =IFERROR((Data_Entry!H135/Data_Entry!$V135/E$2),"") -> 0.7620589 | F137: =IFERROR((Data_Entry!I135/Data_Entry!$V135/F$2),"") -> 0.76652968 | G137: =IFERROR((Data_Entry!J135/Data_Entry!$V135/G$2),"") -> 0.76074448 | H137: =IFERROR((Data_Entry!K135/Data_Entry!$V135/H$2),"") -> 0.76008431 | I137: =IFERROR((Data_Entry!L135/Data_Entry!$V135/I$2),"") -> 0.74426623
A138: 45881 | B138: 45881 | C138: =IFERROR((Data_Entry!F136/Data_Entry!$V136/C$2),"") -> 1.1349243 | D138: =IFERROR((Data_Entry!G136/Data_Entry!$V136/D$2),"") -> 1.1318756 | E138: =IFERROR((Data_Entry!H136/Data_Entry!$V136/E$2),"") -> 1.1352741 | F138: =IFERROR((Data_Entry!I136/Data_Entry!$V136/F$2),"") -> 1.124904 | G138: =IFERROR((Data_Entry!J136/Data_Entry!$V136/G$2),"") -> 1.1258027 | H138: =IFERROR((Data_Entry!K136/Data_Entry!$V136/H$2),"") -> 1.1258409 | I138: =IFERROR((Data_Entry!L136/Data_Entry!$V136/I$2),"") -> 1.106719
...

Sheet Invt_Analysis_Gen_Per_KW &_PR
A1: Daily_Generation_Per_KW_Performance_Analysis
B2: Inverter_No. | C2: =DGR!B3 -> 46178 | D2: =DGR!C3 -> 46179 | E2: =DGR!D3 -> 46180 | F2: =DGR!E3 -> 46181 | G2: =DGR!F3 -> 46182 | H2: =DGR!G3 -> 46183 | I2: =DGR!H3 -> 46184 | J2: =DGR!I3 -> 46185 | ... AH2: =DGR!AG3 -> Total/Avg..
B3: Inv_1 | C3: =IFERROR(VLOOKUP(C$2,Data_Entry!$C:$L,Data_Entry!$A2,0)/VLOOKUP($B3,Basic_Data!$E$2:$G$10,3,0),"") -> 4.3586322 | D3: =IFERROR(VLOOKUP(D$2,Data_Entry!$C:$L,Data_Entry!$A2,0)/VLOOKUP($B3,Basic_Data!$E$2:$G$10,3,0),"") -> 0 | E3: =IFERROR(VLOOKUP(E$2,Data_Entry!$C:$L,Data_Entry!$A2,0)/VLOOKUP($B3,Basic_Data!$E$2:$G$10,3,0),"") -> 0 | F3: =IFERROR(VLOOKUP(F$2,Data_Entry!$C:$L,Data_Entry!$A2,0)/VLOOKUP($B3,Basic_Data!$E$2:$G$10,3,0),"") -> 0 | G3: =IFERROR(VLOOKUP(G$2,Data_Entry!$C:$L,Data_Entry!$A2,0)/VLOOKUP($B3,Basic_Data!$E$2:$G$10,3,0),"") -> 0 | H3: =IFERROR(VLOOKUP(H$2,Data_Entry!$C:$L,Data_Entry!$A2,0)/VLOOKUP($B3,Basic_Data!$E$2:$G$10,3,0),"") -> 0 | I3: =IFERROR(VLOOKUP(I$2,Data_Entry!$C:$L,Data_Entry!$A2,0)/VLOOKUP($B3,Basic_Data!$E$2:$G$10,3,0),"") -> 0 | J3: =IFERROR(VLOOKUP(J$2,Data_Entry!$C:$L,Data_Entry!$A2,0)/VLOOKUP($B3,Basic_Data!$E$2:$G$10,3,0),"") -> 0 | ... AG3: =IFERROR(VLOOKUP(AG$2,Data_Entry!$C:$L,Data_Entry!$A2,0)/VLOOKUP($B3,Basic_Data!$E$2:$G$10,3,0),"") -> 0
B4: Inv_2 | C4: =IFERROR(VLOOKUP(C$2,Data_Entry!$C:$L,Data_Entry!$A3,0)/VLOOKUP($B4,Basic_Data!$E$2:$G$10,3,0),"") -> 4.338824 | D4: =IFERROR(VLOOKUP(D$2,Data_Entry!$C:$L,Data_Entry!$A3,0)/VLOOKUP($B4,Basic_Data!$E$2:$G$10,3,0),"") -> 0 | E4: =IFERROR(VLOOKUP(E$2,Data_Entry!$C:$L,Data_Entry!$A3,0)/VLOOKUP($B4,Basic_Data!$E$2:$G$10,3,0),"") -> 0 | F4: =IFERROR(VLOOKUP(F$2,Data_Entry!$C:$L,Data_Entry!$A3,0)/VLOOKUP($B4,Basic_Data!$E$2:$G$10,3,0),"") -> 0 | G4: =IFERROR(VLOOKUP(G$2,Data_Entry!$C:$L,Data_Entry!$A3,0)/VLOOKUP($B4,Basic_Data!$E$2:$G$10,3,0),"") -> 0 | H4: =IFERROR(VLOOKUP(H$2,Data_Entry!$C:$L,Data_Entry!$A3,0)/VLOOKUP($B4,Basic_Data!$E$2:$G$10,3,0),"") -> 0 | I4: =IFERROR(VLOOKUP(I$2,Data_Entry!$C:$L,Data_Entry!$A3,0)/VLOOKUP($B4,Basic_Data!$E$2:$G$10,3,0),"") -> 0 | J4: =IFERROR(VLOOKUP(J$2,Data_Entry!$C:$L,Data_Entry!$A3,0)/VLOOKUP($B4,Basic_Data!$E$2:$G$10,3,0),"") -> 0 | ... AG4: =IFERROR(VLOOKUP(AG$2,Data_Entry!$C:$L,Data_Entry!$A3,0)/VLOOKUP($B4,Basic_Data!$E$2:$G$10,3,0),"") -> 0
B5: Inv_3 | C5: =IFERROR(VLOOKUP(C$2,Data_Entry!$C:$L,Data_Entry!$A4,0)/VLOOKUP($B5,Basic_Data!$E$2:$G$10,3,0),"") -> 4.3524068 | D5: =IFERROR(VLOOKUP(D$2,Data_Entry!$C:$L,Data_Entry!$A4,0)/VLOOKUP($B5,Basic_Data!$E$2:$G$10,3,0),"") -> 0 | E5: =IFERROR(VLOOKUP(E$2,Data_Entry!$C:$L,Data_Entry!$A4,0)/VLOOKUP($B5,Basic_Data!$E$2:$G$10,3,0),"") -> 0 | F5: =IFERROR(VLOOKUP(F$2,Data_Entry!$C:$L,Data_Entry!$A4,0)/VLOOKUP($B5,Basic_Data!$E$2:$G$10,3,0),"") -> 0 | G5: =IFERROR(VLOOKUP(G$2,Data_Entry!$C:$L,Data_Entry!$A4,0)/VLOOKUP($B5,Basic_Data!$E$2:$G$10,3,0),"") -> 0 | H5: =IFERROR(VLOOKUP(H$2,Data_Entry!$C:$L,Data_Entry!$A4,0)/VLOOKUP($B5,Basic_Data!$E$2:$G$10,3,0),"") -> 0 | I5: =IFERROR(VLOOKUP(I$2,Data_Entry!$C:$L,Data_Entry!$A4,0)/VLOOKUP($B5,Basic_Data!$E$2:$G$10,3,0),"") -> 0 | J5: =IFERROR(VLOOKUP(J$2,Data_Entry!$C:$L,Data_Entry!$A4,0)/VLOOKUP($B5,Basic_Data!$E$2:$G$10,3,0),"") -> 0 | ... AG5: =IFERROR(VLOOKUP(AG$2,Data_Entry!$C:$L,Data_Entry!$A4,0)/VLOOKUP($B5,Basic_Data!$E$2:$G$10,3,0),"") -> 0
B6: Inv_4 | C6: =IFERROR(VLOOKUP(C$2,Data_Entry!$C:$L,Data_Entry!$A5,0)/VLOOKUP($B6,Basic_Data!$E$2:$G$10,3,0),"") -> 4.3307596 | D6: =IFERROR(VLOOKUP(D$2,Data_Entry!$C:$L,Data_Entry!$A5,0)/VLOOKUP($B6,Basic_Data!$E$2:$G$10,3,0),"") -> 0 | E6: =IFERROR(VLOOKUP(E$2,Data_Entry!$C:$L,Data_Entry!$A5,0)/VLOOKUP($B6,Basic_Data!$E$2:$G$10,3,0),"") -> 0 | F6: =IFERROR(VLOOKUP(F$2,Data_Entry!$C:$L,Data_Entry!$A5,0)/VLOOKUP($B6,Basic_Data!$E$2:$G$10,3,0),"") -> 0 | G6: =IFERROR(VLOOKUP(G$2,Data_Entry!$C:$L,Data_Entry!$A5,0)/VLOOKUP($B6,Basic_Data!$E$2:$G$10,3,0),"") -> 0 | H6: =IFERROR(VLOOKUP(H$2,Data_Entry!$C:$L,Data_Entry!$A5,0)/VLOOKUP($B6,Basic_Data!$E$2:$G$10,3,0),"") -> 0 | I6: =IFERROR(VLOOKUP(I$2,Data_Entry!$C:$L,Data_Entry!$A5,0)/VLOOKUP($B6,Basic_Data!$E$2:$G$10,3,0),"") -> 0 | J6: =IFERROR(VLOOKUP(J$2,Data_Entry!$C:$L,Data_Entry!$A5,0)/VLOOKUP($B6,Basic_Data!$E$2:$G$10,3,0),"") -> 0 | ... AG6: =IFERROR(VLOOKUP(AG$2,Data_Entry!$C:$L,Data_Entry!$A5,0)/VLOOKUP($B6,Basic_Data!$E$2:$G$10,3,0),"") -> 0
B7: Inv_5 | C7: =IFERROR(VLOOKUP(C$2,Data_Entry!$C:$L,Data_Entry!$A6,0)/VLOOKUP($B7,Basic_Data!$E$2:$G$10,3,0),"") -> 4.2939199 | D7: =IFERROR(VLOOKUP(D$2,Data_Entry!$C:$L,Data_Entry!$A6,0)/VLOOKUP($B7,Basic_Data!$E$2:$G$10,3,0),"") -> 0 | E7: =IFERROR(VLOOKUP(E$2,Data_Entry!$C:$L,Data_Entry!$A6,0)/VLOOKUP($B7,Basic_Data!$E$2:$G$10,3,0),"") -> 0 | F7: =IFERROR(VLOOKUP(F$2,Data_Entry!$C:$L,Data_Entry!$A6,0)/VLOOKUP($B7,Basic_Data!$E$2:$G$10,3,0),"") -> 0 | G7: =IFERROR(VLOOKUP(G$2,Data_Entry!$C:$L,Data_Entry!$A6,0)/VLOOKUP($B7,Basic_Data!$E$2:$G$10,3,0),"") -> 0 | H7: =IFERROR(VLOOKUP(H$2,Data_Entry!$C:$L,Data_Entry!$A6,0)/VLOOKUP($B7,Basic_Data!$E$2:$G$10,3,0),"") -> 0 | I7: =IFERROR(VLOOKUP(I$2,Data_Entry!$C:$L,Data_Entry!$A6,0)/VLOOKUP($B7,Basic_Data!$E$2:$G$10,3,0),"") -> 0 | J7: =IFERROR(VLOOKUP(J$2,Data_Entry!$C:$L,Data_Entry!$A6,0)/VLOOKUP($B7,Basic_Data!$E$2:$G$10,3,0),"") -> 0 | ... AG7: =IFERROR(VLOOKUP(AG$2,Data_Entry!$C:$L,Data_Entry!$A6,0)/VLOOKUP($B7,Basic_Data!$E$2:$G$10,3,0),"") -> 0
B8: Inv_6 | C8: =IFERROR(VLOOKUP(C$2,Data_Entry!$C:$L,Data_Entry!$A7,0)/VLOOKUP($B8,Basic_Data!$E$2:$G$10,3,0),"") -> 4.2740327 | D8: =IFERROR(VLOOKUP(D$2,Data_Entry!$C:$L,Data_Entry!$A7,0)/VLOOKUP($B8,Basic_Data!$E$2:$G$10,3,0),"") -> 0 | E8: =IFERROR(VLOOKUP(E$2,Data_Entry!$C:$L,Data_Entry!$A7,0)/VLOOKUP($B8,Basic_Data!$E$2:$G$10,3,0),"") -> 0 | F8: =IFERROR(VLOOKUP(F$2,Data_Entry!$C:$L,Data_Entry!$A7,0)/VLOOKUP($B8,Basic_Data!$E$2:$G$10,3,0),"") -> 0 | G8: =IFERROR(VLOOKUP(G$2,Data_Entry!$C:$L,Data_Entry!$A7,0)/VLOOKUP($B8,Basic_Data!$E$2:$G$10,3,0),"") -> 0 | H8: =IFERROR(VLOOKUP(H$2,Data_Entry!$C:$L,Data_Entry!$A7,0)/VLOOKUP($B8,Basic_Data!$E$2:$G$10,3,0),"") -> 0 | I8: =IFERROR(VLOOKUP(I$2,Data_Entry!$C:$L,Data_Entry!$A7,0)/VLOOKUP($B8,Basic_Data!$E$2:$G$10,3,0),"") -> 0 | J8: =IFERROR(VLOOKUP(J$2,Data_Entry!$C:$L,Data_Entry!$A7,0)/VLOOKUP($B8,Basic_Data!$E$2:$G$10,3,0),"") -> 0 | ... AG8: =IFERROR(VLOOKUP(AG$2,Data_Entry!$C:$L,Data_Entry!$A7,0)/VLOOKUP($B8,Basic_Data!$E$2:$G$10,3,0),"") -> 0
